{
  "registryname": "Advanced_Planetary_Drilling_Plant",
  "localizedname": "Advanced Planetary Drilling Plant",
   "color": "ff0400",
    "parts": [
        {
            "x": -1,
            "y": 0,
            "z": 0,
            "elements": [
                "modularmachinery:blockfluidinputhatch"
            ]
        },
        {
            "x": -2,
            "y": 0,
            "z": 0,
            "elements": [
                "gregtech:metal_casing@4"
            ]
        },
        {
            "x": 1,
            "y": 0,
            "z": 0,
            "elements": [
                "modularmachinery:blockinputbus"
            ]
        },
        {
            "x": 2,
            "y": 0,
            "z": 0,
            "elements": [
                "gregtech:metal_casing@4"
            ]
        },
        {
            "x": -3,
            "y": 15,
            "z": 7,
            "elements": [
                "gregtech:meta_block_frame_20@3"
            ]
        },
        {
            "x": -1,
            "y": 15,
            "z": 7,
            "elements": [
                "gregtech:metal_casing@4"
            ]
        },
        {
            "x": 0,
            "y": 17,
            "z": 8,
            "elements": [
                "gregtech:metal_casing@4"
            ]
        },
        {
            "x": 0,
            "y": 15,
            "z": 7,
            "elements": [
                "gregtech:boiler_casing@1"
            ]
        },
        {
            "x": 1,
            "y": 15,
            "z": 7,
            "elements": [
                "gregtech:metal_casing@4"
            ]
        },
        {
            "x": 0,
            "y": 13,
            "z": 6,
            "elements": [
                "gregtech:metal_casing@4"
            ]
        },
        {
            "x": 3,
            "y": 15,
            "z": 7,
            "elements": [
                "gregtech:meta_block_frame_20@3"
            ]
        },
        {
            "x": 0,
            "y": 3,
            "z": 1,
            "elements": [
                "gregtech:meta_block_frame_20@3"
            ]
        },
        {
            "x": 0,
            "y": 1,
            "z": 0,
            "elements": [
                "gregtech:meta_block_frame_20@3"
            ]
        },
        {
            "x": -3,
            "y": 16,
            "z": 7,
            "elements": [
                "gregtech:meta_block_frame_20@3"
            ]
        },
        {
            "x": 0,
            "y": 20,
            "z": 9,
            "elements": [
                "gregtech:meta_block_frame_20@3"
            ]
        },
        {
            "x": -1,
            "y": 16,
            "z": 7,
            "elements": [
                "gregtech:metal_casing@4"
            ]
        },
        {
            "x": 0,
            "y": 18,
            "z": 8,
            "elements": [
                "gregtech:metal_casing@4"
            ]
        },
        {
            "x": 0,
            "y": 16,
            "z": 7,
            "elements": [
                "gregtech:boiler_casing@1"
            ]
        },
        {
            "x": 1,
            "y": 16,
            "z": 7,
            "elements": [
                "gregtech:metal_casing@4"
            ]
        },
        {
            "x": 0,
            "y": 14,
            "z": 6,
            "elements": [
                "gregtech:metal_casing@4"
            ]
        },
        {
            "x": 3,
            "y": 16,
            "z": 7,
            "elements": [
                "gregtech:meta_block_frame_20@3"
            ]
        },
        {
            "x": 0,
            "y": 6,
            "z": 2,
            "elements": [
                "gregtech:meta_block_frame_20@3"
            ]
        },
        {
            "x": 0,
            "y": 4,
            "z": 1,
            "elements": [
                "gregtech:meta_block_frame_20@3"
            ]
        },
        {
            "x": 0,
            "y": 2,
            "z": 0,
            "elements": [
                "gregtech:meta_block_frame_20@3"
            ]
        },
        {
            "x": -3,
            "y": 17,
            "z": 7,
            "elements": [
                "gregtech:meta_block_frame_20@3"
            ]
        },
        {
            "x": 0,
            "y": 21,
            "z": 9,
            "elements": [
                "gregtech:meta_block_frame_20@3"
            ]
        },
        {
            "x": -1,
            "y": 17,
            "z": 7,
            "elements": [
                "gregtech:metal_casing@4"
            ]
        },
        {
            "x": 0,
            "y": 19,
            "z": 8,
            "elements": [
                "gregtech:metal_casing@4"
            ]
        },
        {
            "x": 0,
            "y": 17,
            "z": 7,
            "elements": [
                "gregtech:boiler_casing@1"
            ]
        },
        {
            "x": 1,
            "y": 17,
            "z": 7,
            "elements": [
                "gregtech:metal_casing@4"
            ]
        },
        {
            "x": 0,
            "y": 15,
            "z": 6,
            "elements": [
                "gregtech:metal_casing@4"
            ]
        },
        {
            "x": 3,
            "y": 17,
            "z": 7,
            "elements": [
                "gregtech:meta_block_frame_20@3"
            ]
        },
        {
            "x": 0,
            "y": 7,
            "z": 2,
            "elements": [
                "gregtech:meta_block_frame_20@3"
            ]
        },
        {
            "x": 0,
            "y": 5,
            "z": 1,
            "elements": [
                "gregtech:meta_block_frame_20@3"
            ]
        },
        {
            "x": -3,
            "y": 18,
            "z": 7,
            "elements": [
                "gregtech:meta_block_frame_20@3"
            ]
        },
        {
            "x": 0,
            "y": 22,
            "z": 9,
            "elements": [
                "gregtech:meta_block_frame_20@3"
            ]
        },
        {
            "x": -1,
            "y": 18,
            "z": 7,
            "elements": [
                "gregtech:metal_casing@4"
            ]
        },
        {
            "x": 0,
            "y": 20,
            "z": 8,
            "elements": [
                "gregtech:metal_casing@4"
            ]
        },
        {
            "x": 0,
            "y": 18,
            "z": 7,
            "elements": [
                "gregtech:boiler_casing@1"
            ]
        },
        {
            "x": 1,
            "y": 18,
            "z": 7,
            "elements": [
                "gregtech:metal_casing@4"
            ]
        },
        {
            "x": 0,
            "y": 16,
            "z": 6,
            "elements": [
                "gregtech:metal_casing@4"
            ]
        },
        {
            "x": 3,
            "y": 18,
            "z": 7,
            "elements": [
                "gregtech:meta_block_frame_20@3"
            ]
        },
        {
            "x": 0,
            "y": 10,
            "z": 3,
            "elements": [
                "gregtech:meta_block_frame_20@3"
            ]
        },
        {
            "x": 0,
            "y": 8,
            "z": 2,
            "elements": [
                "gregtech:meta_block_frame_20@3"
            ]
        },
        {
            "x": -2,
            "y": 0,
            "z": 14,
            "elements": [
                "gregtech:metal_casing@4"
            ]
        },
        {
            "x": -1,
            "y": 0,
            "z": 14,
            "elements": [
                "modularmachinery:blockenergyinputhatch"
            ]
        },
        {
            "x": 0,
            "y": 0,
            "z": 14,
            "elements": [
                "modularmachinery:blockenergyinputhatch"
            ]
        },
        {
            "x": 1,
            "y": 0,
            "z": 14,
            "elements": [
                "modularmachinery:blockenergyinputhatch"
            ]
        },
        {
            "x": 2,
            "y": 0,
            "z": 14,
            "elements": [
                "gregtech:metal_casing@4"
            ]
        },
        {
            "x": -3,
            "y": 19,
            "z": 7,
            "elements": [
                "gregtech:meta_block_frame_20@3"
            ]
        },
        {
            "x": -1,
            "y": 19,
            "z": 7,
            "elements": [
                "gregtech:metal_casing@4"
            ]
        },
        {
            "x": 0,
            "y": 21,
            "z": 8,
            "elements": [
                "gregtech:metal_casing@4"
            ]
        },
        {
            "x": 0,
            "y": 19,
            "z": 7,
            "elements": [
                "gregtech:boiler_casing@1"
            ]
        },
        {
            "x": 1,
            "y": 19,
            "z": 7,
            "elements": [
                "gregtech:metal_casing@4"
            ]
        },
        {
            "x": 0,
            "y": 17,
            "z": 6,
            "elements": [
                "gregtech:metal_casing@4"
            ]
        },
        {
            "x": 3,
            "y": 19,
            "z": 7,
            "elements": [
                "gregtech:meta_block_frame_20@3"
            ]
        },
        {
            "x": 0,
            "y": 11,
            "z": 3,
            "elements": [
                "gregtech:meta_block_frame_20@3"
            ]
        },
        {
            "x": 0,
            "y": 9,
            "z": 2,
            "elements": [
                "gregtech:meta_block_frame_20@3"
            ]
        },
        {
            "x": 0,
            "y": 1,
            "z": 14,
            "elements": [
                "gregtech:meta_block_frame_20@3"
            ]
        },
        {
            "x": -2,
            "y": 20,
            "z": 7,
            "elements": [
                "gregtech:meta_block_frame_20@3"
            ]
        },
        {
            "x": -1,
            "y": 20,
            "z": 7,
            "elements": [
                "gregtech:metal_casing@4"
            ]
        },
        {
            "x": 0,
            "y": 22,
            "z": 8,
            "elements": [
                "gregtech:metal_casing@4"
            ]
        },
        {
            "x": 0,
            "y": 20,
            "z": 7,
            "elements": [
                "gregtech:boiler_casing@1"
            ]
        },
        {
            "x": 1,
            "y": 20,
            "z": 7,
            "elements": [
                "gregtech:metal_casing@4"
            ]
        },
        {
            "x": 0,
            "y": 18,
            "z": 6,
            "elements": [
                "gregtech:metal_casing@4"
            ]
        },
        {
            "x": 2,
            "y": 20,
            "z": 7,
            "elements": [
                "gregtech:meta_block_frame_20@3"
            ]
        },
        {
            "x": 0,
            "y": 12,
            "z": 3,
            "elements": [
                "gregtech:meta_block_frame_20@3"
            ]
        },
        {
            "x": -4,
            "y": 0,
            "z": 13,
            "elements": [
                "gregtech:metal_casing@4"
            ]
        },
        {
            "x": -3,
            "y": 0,
            "z": 13,
            "elements": [
                "gregtech:metal_casing@4"
            ]
        },
        {
            "x": -2,
            "y": 0,
            "z": 13,
            "elements": [
                "gregtech:metal_casing@4"
            ]
        },
        {
            "x": 0,
            "y": 2,
            "z": 14,
            "elements": [
                "gregtech:meta_block_frame_20@3"
            ]
        },
        {
            "x": -1,
            "y": 0,
            "z": 13,
            "elements": [
                "gregtech:metal_casing@4"
            ]
        },
        {
            "x": 0,
            "y": 0,
            "z": 13,
            "elements": [
                "gregtech:metal_casing@4"
            ]
        },
        {
            "x": 1,
            "y": 0,
            "z": 13,
            "elements": [
                "gregtech:metal_casing@4"
            ]
        },
        {
            "x": 2,
            "y": 0,
            "z": 13,
            "elements": [
                "gregtech:metal_casing@4"
            ]
        },
        {
            "x": -2,
            "y": 21,
            "z": 7,
            "elements": [
                "gregtech:meta_block_frame_20@3"
            ]
        },
        {
            "x": 3,
            "y": 0,
            "z": 13,
            "elements": [
                "gregtech:metal_casing@4"
            ]
        },
        {
            "x": -1,
            "y": 21,
            "z": 7,
            "elements": [
                "gregtech:metal_casing@4"
            ]
        },
        {
            "x": 0,
            "y": 23,
            "z": 8,
            "elements": [
                "gregtech:meta_block_frame_20@3"
            ]
        },
        {
            "x": 4,
            "y": 0,
            "z": 13,
            "elements": [
                "gregtech:metal_casing@4"
            ]
        },
        {
            "x": 0,
            "y": 21,
            "z": 7,
            "elements": [
                "gregtech:boiler_casing@1"
            ]
        },
        {
            "x": 1,
            "y": 21,
            "z": 7,
            "elements": [
                "gregtech:metal_casing@4"
            ]
        },
        {
            "x": 0,
            "y": 19,
            "z": 6,
            "elements": [
                "gregtech:metal_casing@4"
            ]
        },
        {
            "x": 2,
            "y": 21,
            "z": 7,
            "elements": [
                "gregtech:meta_block_frame_20@3"
            ]
        },
        {
            "x": 0,
            "y": 15,
            "z": 4,
            "elements": [
                "gregtech:meta_block_frame_20@3"
            ]
        },
        {
            "x": 0,
            "y": 13,
            "z": 3,
            "elements": [
                "gregtech:meta_block_frame_20@3"
            ]
        },
        {
            "x": -2,
            "y": 22,
            "z": 7,
            "elements": [
                "gregtech:meta_block_frame_20@3"
            ]
        },
        {
            "x": -1,
            "y": 22,
            "z": 7,
            "elements": [
                "gregtech:metal_casing@4"
            ]
        },
        {
            "x": 0,
            "y": 24,
            "z": 8,
            "elements": [
                "gregtech:meta_block_frame_20@3"
            ]
        },
        {
            "x": 0,
            "y": 22,
            "z": 7,
            "elements": [
                "gregtech:boiler_casing@1"
            ]
        },
        {
            "x": 1,
            "y": 22,
            "z": 7,
            "elements": [
                "gregtech:metal_casing@4"
            ]
        },
        {
            "x": 0,
            "y": 20,
            "z": 6,
            "elements": [
                "gregtech:metal_casing@4"
            ]
        },
        {
            "x": 2,
            "y": 22,
            "z": 7,
            "elements": [
                "gregtech:meta_block_frame_20@3"
            ]
        },
        {
            "x": 0,
            "y": 16,
            "z": 4,
            "elements": [
                "gregtech:meta_block_frame_20@3"
            ]
        },
        {
            "x": 0,
            "y": 14,
            "z": 3,
            "elements": [
                "gregtech:meta_block_frame_20@3"
            ]
        },
        {
            "x": -5,
            "y": 0,
            "z": 12,
            "elements": [
                "gregtech:metal_casing@4"
            ]
        },
        {
            "x": -4,
            "y": 0,
            "z": 12,
            "elements": [
                "gregtech:metal_casing@4"
            ]
        },
        {
            "x": -3,
            "y": 0,
            "z": 12,
            "elements": [
                "gregtech:metal_casing@4"
            ]
        },
        {
            "x": -2,
            "y": 0,
            "z": 12,
            "elements": [
                "gregtech:metal_casing@4"
            ]
        },
        {
            "x": -1,
            "y": 0,
            "z": 12,
            "elements": [
                "gregtech:metal_casing@4"
            ]
        },
        {
            "x": 0,
            "y": 0,
            "z": 12,
            "elements": [
                "gregtech:metal_casing@4"
            ]
        },
        {
            "x": 1,
            "y": 0,
            "z": 12,
            "elements": [
                "gregtech:metal_casing@4"
            ]
        },
        {
            "x": 2,
            "y": 0,
            "z": 12,
            "elements": [
                "gregtech:metal_casing@4"
            ]
        },
        {
            "x": -1,
            "y": 23,
            "z": 7,
            "elements": [
                "gregtech:meta_block_frame_20@3"
            ]
        },
        {
            "x": 3,
            "y": 0,
            "z": 12,
            "elements": [
                "gregtech:metal_casing@4"
            ]
        },
        {
            "x": 0,
            "y": 23,
            "z": 7,
            "elements": [
                "gregtech:metal_casing@4"
            ]
        },
        {
            "x": 4,
            "y": 0,
            "z": 12,
            "elements": [
                "gregtech:metal_casing@4"
            ]
        },
        {
            "x": 1,
            "y": 23,
            "z": 7,
            "elements": [
                "gregtech:meta_block_frame_20@3"
            ]
        },
        {
            "x": 0,
            "y": 21,
            "z": 6,
            "elements": [
                "gregtech:metal_casing@4"
            ]
        },
        {
            "x": 5,
            "y": 0,
            "z": 12,
            "elements": [
                "gregtech:metal_casing@4"
            ]
        },
        {
            "x": 0,
            "y": 17,
            "z": 4,
            "elements": [
                "gregtech:meta_block_frame_20@3"
            ]
        },
        {
            "x": 0,
            "y": 3,
            "z": 13,
            "elements": [
                "gregtech:meta_block_frame_20@3"
            ]
        },
        {
            "x": -1,
            "y": 24,
            "z": 7,
            "elements": [
                "gregtech:meta_block_frame_20@3"
            ]
        },
        {
            "x": 0,
            "y": 24,
            "z": 7,
            "elements": [
                "gregtech:metal_casing@4"
            ]
        },
        {
            "x": 1,
            "y": 24,
            "z": 7,
            "elements": [
                "gregtech:meta_block_frame_20@3"
            ]
        },
        {
            "x": 0,
            "y": 22,
            "z": 6,
            "elements": [
                "gregtech:metal_casing@4"
            ]
        },
        {
            "x": 0,
            "y": 20,
            "z": 5,
            "elements": [
                "gregtech:meta_block_frame_20@3"
            ]
        },
        {
            "x": 0,
            "y": 18,
            "z": 4,
            "elements": [
                "gregtech:meta_block_frame_20@3"
            ]
        },
        {
            "x": -6,
            "y": 0,
            "z": 11,
            "elements": [
                "gregtech:metal_casing@4"
            ]
        },
        {
            "x": -5,
            "y": 0,
            "z": 11,
            "elements": [
                "gregtech:metal_casing@4"
            ]
        },
        {
            "x": -4,
            "y": 0,
            "z": 11,
            "elements": [
                "gregtech:metal_casing@4"
            ]
        },
        {
            "x": -3,
            "y": 0,
            "z": 11,
            "elements": [
                "gregtech:metal_casing@4"
            ]
        },
        {
            "x": 0,
            "y": 4,
            "z": 13,
            "elements": [
                "gregtech:meta_block_frame_20@3"
            ]
        },
        {
            "x": -2,
            "y": 0,
            "z": 11,
            "elements": [
                "gregtech:metal_casing@4"
            ]
        },
        {
            "x": -1,
            "y": 0,
            "z": 11,
            "elements": [
                "gregtech:metal_casing@4"
            ]
        },
        {
            "x": 0,
            "y": 0,
            "z": 11,
            "elements": [
                "gregtech:metal_casing@4"
            ]
        },
        {
            "x": 1,
            "y": 0,
            "z": 11,
            "elements": [
                "gregtech:metal_casing@4"
            ]
        },
        {
            "x": 2,
            "y": 0,
            "z": 11,
            "elements": [
                "gregtech:metal_casing@4"
            ]
        },
        {
            "x": 0,
            "y": 25,
            "z": 7,
            "elements": [
                "gregtech:metal_casing@4"
            ]
        },
        {
            "x": 3,
            "y": 0,
            "z": 11,
            "elements": [
                "gregtech:metal_casing@4"
            ]
        },
        {
            "x": 0,
            "y": 23,
            "z": 6,
            "elements": [
                "gregtech:meta_block_frame_20@3"
            ]
        },
        {
            "x": 4,
            "y": 0,
            "z": 11,
            "elements": [
                "gregtech:metal_casing@4"
            ]
        },
        {
            "x": 0,
            "y": 21,
            "z": 5,
            "elements": [
                "gregtech:meta_block_frame_20@3"
            ]
        },
        {
            "x": 5,
            "y": 0,
            "z": 11,
            "elements": [
                "gregtech:metal_casing@4"
            ]
        },
        {
            "x": 0,
            "y": 19,
            "z": 4,
            "elements": [
                "gregtech:meta_block_frame_20@3"
            ]
        },
        {
            "x": 6,
            "y": 0,
            "z": 11,
            "elements": [
                "gregtech:metal_casing@4"
            ]
        },
        {
            "x": 0,
            "y": 5,
            "z": 13,
            "elements": [
                "gregtech:meta_block_frame_20@3"
            ]
        },
        {
            "x": 0,
            "y": 26,
            "z": 7,
            "elements": [
                "gregtech:metal_casing@4"
            ]
        },
        {
            "x": 0,
            "y": 24,
            "z": 6,
            "elements": [
                "gregtech:meta_block_frame_20@3"
            ]
        },
        {
            "x": 0,
            "y": 22,
            "z": 5,
            "elements": [
                "gregtech:meta_block_frame_20@3"
            ]
        },
        {
            "x": -6,
            "y": 0,
            "z": 10,
            "elements": [
                "gregtech:metal_casing@4"
            ]
        },
        {
            "x": -5,
            "y": 0,
            "z": 10,
            "elements": [
                "gregtech:metal_casing@4"
            ]
        },
        {
            "x": -4,
            "y": 0,
            "z": 10,
            "elements": [
                "gregtech:metal_casing@4"
            ]
        },
        {
            "x": -3,
            "y": 0,
            "z": 10,
            "elements": [
                "gregtech:metal_casing@4"
            ]
        },
        {
            "x": -2,
            "y": 0,
            "z": 10,
            "elements": [
                "gregtech:metal_casing@4"
            ]
        },
        {
            "x": -1,
            "y": 0,
            "z": 10,
            "elements": [
                "gregtech:metal_casing@4"
            ]
        },
        {
            "x": 0,
            "y": 0,
            "z": 10,
            "elements": [
                "gregtech:metal_casing@4"
            ]
        },
        {
            "x": 1,
            "y": 0,
            "z": 10,
            "elements": [
                "gregtech:metal_casing@4"
            ]
        },
        {
            "x": 0,
            "y": 27,
            "z": 7,
            "elements": [
                "gregtech:metal_casing@4"
            ]
        },
        {
            "x": 2,
            "y": 0,
            "z": 10,
            "elements": [
                "gregtech:metal_casing@4"
            ]
        },
        {
            "x": 3,
            "y": 0,
            "z": 10,
            "elements": [
                "gregtech:metal_casing@4"
            ]
        },
        {
            "x": 4,
            "y": 0,
            "z": 10,
            "elements": [
                "gregtech:metal_casing@4"
            ]
        },
        {
            "x": 5,
            "y": 0,
            "z": 10,
            "elements": [
                "gregtech:metal_casing@4"
            ]
        },
        {
            "x": 6,
            "y": 0,
            "z": 10,
            "elements": [
                "gregtech:metal_casing@4"
            ]
        },
        {
            "x": -3,
            "y": 1,
            "z": 10,
            "elements": [
                "gregtech:boiler_casing@1"
            ]
        },
        {
            "x": 0,
            "y": 28,
            "z": 7,
            "elements": [
                "gregtech:metal_casing@4"
            ]
        },
        {
            "x": 3,
            "y": 1,
            "z": 10,
            "elements": [
                "gregtech:boiler_casing@1"
            ]
        },
        {
            "x": -7,
            "y": 0,
            "z": 9,
            "elements": [
                "gregtech:metal_casing@4"
            ]
        },
        {
            "x": -6,
            "y": 0,
            "z": 9,
            "elements": [
                "gregtech:metal_casing@4"
            ]
        },
        {
            "x": -5,
            "y": 0,
            "z": 9,
            "elements": [
                "gregtech:metal_casing@4"
            ]
        },
        {
            "x": -4,
            "y": 0,
            "z": 9,
            "elements": [
                "gregtech:metal_casing@4"
            ]
        },
        {
            "x": -3,
            "y": 2,
            "z": 10,
            "elements": [
                "gregtech:boiler_casing@1"
            ]
        },
        {
            "x": 0,
            "y": 6,
            "z": 12,
            "elements": [
                "gregtech:meta_block_frame_20@3"
            ]
        },
        {
            "x": -3,
            "y": 0,
            "z": 9,
            "elements": [
                "gregtech:metal_casing@4"
            ]
        },
        {
            "x": -2,
            "y": 0,
            "z": 9,
            "elements": [
                "gregtech:metal_casing@4"
            ]
        },
        {
            "x": -1,
            "y": 0,
            "z": 9,
            "elements": [
                "gregtech:metal_casing@4"
            ]
        },
        {
            "x": 0,
            "y": 0,
            "z": 9,
            "elements": [
                "gregtech:metal_casing@4"
            ]
        },
        {
            "x": 0,
            "y": 29,
            "z": 7,
            "elements": [
                "gregtech:metal_casing@4"
            ]
        },
        {
            "x": 1,
            "y": 0,
            "z": 9,
            "elements": [
                "gregtech:metal_casing@4"
            ]
        },
        {
            "x": 3,
            "y": 2,
            "z": 10,
            "elements": [
                "gregtech:boiler_casing@1"
            ]
        },
        {
            "x": 2,
            "y": 0,
            "z": 9,
            "elements": [
                "gregtech:metal_casing@4"
            ]
        },
        {
            "x": 3,
            "y": 0,
            "z": 9,
            "elements": [
                "gregtech:metal_casing@4"
            ]
        },
        {
            "x": 4,
            "y": 0,
            "z": 9,
            "elements": [
                "gregtech:metal_casing@4"
            ]
        },
        {
            "x": 5,
            "y": 0,
            "z": 9,
            "elements": [
                "gregtech:metal_casing@4"
            ]
        },
        {
            "x": 6,
            "y": 0,
            "z": 9,
            "elements": [
                "gregtech:metal_casing@4"
            ]
        },
        {
            "x": 7,
            "y": 0,
            "z": 9,
            "elements": [
                "gregtech:metal_casing@4"
            ]
        },
        {
            "x": -3,
            "y": 3,
            "z": 10,
            "elements": [
                "gregtech:boiler_casing@1"
            ]
        },
        {
            "x": 0,
            "y": 7,
            "z": 12,
            "elements": [
                "gregtech:meta_block_frame_20@3"
            ]
        },
        {
            "x": 0,
            "y": 30,
            "z": 7,
            "elements": [
                "gregtech:metal_casing@4"
            ]
        },
        {
            "x": 3,
            "y": 3,
            "z": 10,
            "elements": [
                "gregtech:boiler_casing@1"
            ]
        },
        {
            "x": -7,
            "y": 0,
            "z": 8,
            "elements": [
                "modularmachinery:blockoutputbus"
            ]
        },
        {
            "x": -6,
            "y": 0,
            "z": 8,
            "elements": [
                "gregtech:metal_casing@4"
            ]
        },
        {
            "x": -5,
            "y": 0,
            "z": 8,
            "elements": [
                "gregtech:metal_casing@4"
            ]
        },
        {
            "x": -3,
            "y": 4,
            "z": 10,
            "elements": [
                "gregtech:boiler_casing@1"
            ]
        },
        {
            "x": 0,
            "y": 8,
            "z": 12,
            "elements": [
                "gregtech:meta_block_frame_20@3"
            ]
        },
        {
            "x": -4,
            "y": 0,
            "z": 8,
            "elements": [
                "gregtech:metal_casing@4"
            ]
        },
        {
            "x": -3,
            "y": 0,
            "z": 8,
            "elements": [
                "gregtech:metal_casing@4"
            ]
        },
        {
            "x": -2,
            "y": 0,
            "z": 8,
            "elements": [
                "gregtech:metal_casing@4"
            ]
        },
        {
            "x": -1,
            "y": 0,
            "z": 8,
            "elements": [
                "gregtech:metal_casing@4"
            ]
        },
        {
            "x": 0,
            "y": 0,
            "z": 8,
            "elements": [
                "gregtech:metal_casing@4"
            ]
        },
        {
            "x": 0,
            "y": 31,
            "z": 7,
            "elements": [
                "gregtech:metal_casing@4"
            ]
        },
        {
            "x": 3,
            "y": 4,
            "z": 10,
            "elements": [
                "gregtech:boiler_casing@1"
            ]
        },
        {
            "x": 1,
            "y": 0,
            "z": 8,
            "elements": [
                "gregtech:metal_casing@4"
            ]
        },
        {
            "x": 2,
            "y": 0,
            "z": 8,
            "elements": [
                "gregtech:metal_casing@4"
            ]
        },
        {
            "x": 3,
            "y": 0,
            "z": 8,
            "elements": [
                "gregtech:metal_casing@4"
            ]
        },
        {
            "x": 4,
            "y": 0,
            "z": 8,
            "elements": [
                "gregtech:metal_casing@4"
            ]
        },
        {
            "x": 5,
            "y": 0,
            "z": 8,
            "elements": [
                "gregtech:metal_casing@4"
            ]
        },
        {
            "x": 6,
            "y": 0,
            "z": 8,
            "elements": [
                "gregtech:metal_casing@4"
            ]
        },
        {
            "x": 7,
            "y": 0,
            "z": 8,
            "elements": [
                "modularmachinery:blockoutputbus"
            ]
        },
        {
            "x": -3,
            "y": 5,
            "z": 10,
            "elements": [
                "gregtech:boiler_casing@1"
            ]
        },
        {
            "x": 0,
            "y": 9,
            "z": 12,
            "elements": [
                "gregtech:meta_block_frame_20@3"
            ]
        },
        {
            "x": 0,
            "y": 1,
            "z": 8,
            "elements": [
                "gregtech:metal_casing@4"
            ]
        },
        {
            "x": 0,
            "y": 32,
            "z": 7,
            "elements": [
                "gregtech:metal_casing@4"
            ]
        },
        {
            "x": 3,
            "y": 5,
            "z": 10,
            "elements": [
                "gregtech:boiler_casing@1"
            ]
        },
        {
            "x": -7,
            "y": 0,
            "z": 7,
            "elements": [
                "modularmachinery:blockoutputbus"
            ]
        },
        {
            "x": -6,
            "y": 0,
            "z": 7,
            "elements": [
                "gregtech:metal_casing@4"
            ]
        },
        {
            "x": -3,
            "y": 6,
            "z": 10,
            "elements": [
                "gregtech:boiler_casing@1"
            ]
        },
        {
            "x": -5,
            "y": 0,
            "z": 7,
            "elements": [
                "gregtech:metal_casing@4"
            ]
        },
        {
            "x": -4,
            "y": 0,
            "z": 7,
            "elements": [
                "gregtech:metal_casing@4"
            ]
        },
        {
            "x": -3,
            "y": 0,
            "z": 7,
            "elements": [
                "gregtech:metal_casing@4"
            ]
        },
        {
            "x": -2,
            "y": 0,
            "z": 7,
            "elements": [
                "gregtech:metal_casing@4"
            ]
        },
        {
            "x": 0,
            "y": 2,
            "z": 8,
            "elements": [
                "gregtech:metal_casing@4"
            ]
        },
        {
            "x": -1,
            "y": 0,
            "z": 7,
            "elements": [
                "gregtech:metal_casing@4"
            ]
        },
        {
            "x": 0,
            "y": 33,
            "z": 7,
            "elements": [
                "gregtech:metal_casing@4"
            ]
        },
        {
            "x": 0,
            "y": 0,
            "z": 7,
            "elements": [
                "gregtech:boiler_casing@1"
            ]
        },
        {
            "x": 3,
            "y": 6,
            "z": 10,
            "elements": [
                "gregtech:boiler_casing@1"
            ]
        },
        {
            "x": 1,
            "y": 0,
            "z": 7,
            "elements": [
                "gregtech:metal_casing@4"
            ]
        },
        {
            "x": 2,
            "y": 0,
            "z": 7,
            "elements": [
                "gregtech:metal_casing@4"
            ]
        },
        {
            "x": 3,
            "y": 0,
            "z": 7,
            "elements": [
                "gregtech:metal_casing@4"
            ]
        },
        {
            "x": 4,
            "y": 0,
            "z": 7,
            "elements": [
                "gregtech:metal_casing@4"
            ]
        },
        {
            "x": 5,
            "y": 0,
            "z": 7,
            "elements": [
                "gregtech:metal_casing@4"
            ]
        },
        {
            "x": 6,
            "y": 0,
            "z": 7,
            "elements": [
                "gregtech:metal_casing@4"
            ]
        },
        {
            "x": 7,
            "y": 0,
            "z": 7,
            "elements": [
                "modularmachinery:blockoutputbus"
            ]
        },
        {
            "x": -7,
            "y": 1,
            "z": 7,
            "elements": [
                "gregtech:meta_block_frame_20@3"
            ]
        },
        {
            "x": 0,
            "y": 34,
            "z": 7,
            "elements": [
                "gregtech:metal_casing@4"
            ]
        },
        {
            "x": 0,
            "y": 3,
            "z": 8,
            "elements": [
                "gregtech:metal_casing@4"
            ]
        },
        {
            "x": -1,
            "y": 1,
            "z": 7,
            "elements": [
                "gregtech:metal_casing@4"
            ]
        },
        {
            "x": 0,
            "y": 1,
            "z": 7,
            "elements": [
                "gregtech:boiler_casing@1"
            ]
        },
        {
            "x": 1,
            "y": 1,
            "z": 7,
            "elements": [
                "gregtech:metal_casing@4"
            ]
        },
        {
            "x": 7,
            "y": 1,
            "z": 7,
            "elements": [
                "gregtech:meta_block_frame_20@3"
            ]
        },
        {
            "x": -7,
            "y": 2,
            "z": 7,
            "elements": [
                "gregtech:meta_block_frame_20@3"
            ]
        },
        {
            "x": -7,
            "y": 0,
            "z": 6,
            "elements": [
                "modularmachinery:blockoutputbus"
            ]
        },
        {
            "x": -6,
            "y": 0,
            "z": 6,
            "elements": [
                "gregtech:metal_casing@4"
            ]
        },
        {
            "x": 0,
            "y": 10,
            "z": 11,
            "elements": [
                "gregtech:meta_block_frame_20@3"
            ]
        },
        {
            "x": -5,
            "y": 0,
            "z": 6,
            "elements": [
                "gregtech:metal_casing@4"
            ]
        },
        {
            "x": -4,
            "y": 0,
            "z": 6,
            "elements": [
                "gregtech:metal_casing@4"
            ]
        },
        {
            "x": -3,
            "y": 0,
            "z": 6,
            "elements": [
                "gregtech:metal_casing@4"
            ]
        },
        {
            "x": 0,
            "y": 35,
            "z": 7,
            "elements": [
                "gregtech:metal_casing@4"
            ]
        },
        {
            "x": 0,
            "y": 4,
            "z": 8,
            "elements": [
                "gregtech:metal_casing@4"
            ]
        },
        {
            "x": -2,
            "y": 0,
            "z": 6,
            "elements": [
                "gregtech:metal_casing@4"
            ]
        },
        {
            "x": -1,
            "y": 2,
            "z": 7,
            "elements": [
                "gregtech:metal_casing@4"
            ]
        },
        {
            "x": 0,
            "y": 2,
            "z": 7,
            "elements": [
                "gregtech:boiler_casing@1"
            ]
        },
        {
            "x": -1,
            "y": 0,
            "z": 6,
            "elements": [
                "gregtech:metal_casing@4"
            ]
        },
        {
            "x": 0,
            "y": 0,
            "z": 6,
            "elements": [
                "gregtech:metal_casing@4"
            ]
        },
        {
            "x": 1,
            "y": 2,
            "z": 7,
            "elements": [
                "gregtech:metal_casing@4"
            ]
        },
        {
            "x": 1,
            "y": 0,
            "z": 6,
            "elements": [
                "gregtech:metal_casing@4"
            ]
        },
        {
            "x": 2,
            "y": 0,
            "z": 6,
            "elements": [
                "gregtech:metal_casing@4"
            ]
        },
        {
            "x": 3,
            "y": 0,
            "z": 6,
            "elements": [
                "gregtech:metal_casing@4"
            ]
        },
        {
            "x": 4,
            "y": 0,
            "z": 6,
            "elements": [
                "gregtech:metal_casing@4"
            ]
        },
        {
            "x": 5,
            "y": 0,
            "z": 6,
            "elements": [
                "gregtech:metal_casing@4"
            ]
        },
        {
            "x": 7,
            "y": 2,
            "z": 7,
            "elements": [
                "gregtech:meta_block_frame_20@3"
            ]
        },
        {
            "x": 6,
            "y": 0,
            "z": 6,
            "elements": [
                "gregtech:metal_casing@4"
            ]
        },
        {
            "x": 7,
            "y": 0,
            "z": 6,
            "elements": [
                "modularmachinery:blockoutputbus"
            ]
        },
        {
            "x": -6,
            "y": 3,
            "z": 7,
            "elements": [
                "gregtech:meta_block_frame_20@3"
            ]
        },
        {
            "x": 0,
            "y": 11,
            "z": 11,
            "elements": [
                "gregtech:meta_block_frame_20@3"
            ]
        },
        {
            "x": 0,
            "y": 36,
            "z": 7,
            "elements": [
                "gregtech:metal_casing@4"
            ]
        },
        {
            "x": 0,
            "y": 5,
            "z": 8,
            "elements": [
                "gregtech:metal_casing@4"
            ]
        },
        {
            "x": -1,
            "y": 3,
            "z": 7,
            "elements": [
                "gregtech:metal_casing@4"
            ]
        },
        {
            "x": 0,
            "y": 3,
            "z": 7,
            "elements": [
                "gregtech:boiler_casing@1"
            ]
        },
        {
            "x": 1,
            "y": 3,
            "z": 7,
            "elements": [
                "gregtech:metal_casing@4"
            ]
        },
        {
            "x": 0,
            "y": 1,
            "z": 6,
            "elements": [
                "gregtech:metal_casing@4"
            ]
        },
        {
            "x": 6,
            "y": 3,
            "z": 7,
            "elements": [
                "gregtech:meta_block_frame_20@3"
            ]
        },
        {
            "x": -6,
            "y": 4,
            "z": 7,
            "elements": [
                "gregtech:meta_block_frame_20@3"
            ]
        },
        {
            "x": -7,
            "y": 0,
            "z": 5,
            "elements": [
                "gregtech:metal_casing@4"
            ]
        },
        {
            "x": 0,
            "y": 12,
            "z": 11,
            "elements": [
                "gregtech:meta_block_frame_20@3"
            ]
        },
        {
            "x": -6,
            "y": 0,
            "z": 5,
            "elements": [
                "gregtech:metal_casing@4"
            ]
        },
        {
            "x": -5,
            "y": 0,
            "z": 5,
            "elements": [
                "gregtech:metal_casing@4"
            ]
        },
        {
            "x": -4,
            "y": 0,
            "z": 5,
            "elements": [
                "gregtech:metal_casing@4"
            ]
        },
        {
            "x": 0,
            "y": 37,
            "z": 7,
            "elements": [
                "gregtech:metal_casing@4"
            ]
        },
        {
            "x": 0,
            "y": 6,
            "z": 8,
            "elements": [
                "gregtech:metal_casing@4"
            ]
        },
        {
            "x": -3,
            "y": 0,
            "z": 5,
            "elements": [
                "gregtech:metal_casing@4"
            ]
        },
        {
            "x": -1,
            "y": 4,
            "z": 7,
            "elements": [
                "gregtech:metal_casing@4"
            ]
        },
        {
            "x": 0,
            "y": 4,
            "z": 7,
            "elements": [
                "gregtech:boiler_casing@1"
            ]
        },
        {
            "x": -2,
            "y": 0,
            "z": 5,
            "elements": [
                "gregtech:metal_casing@4"
            ]
        },
        {
            "x": 1,
            "y": 4,
            "z": 7,
            "elements": [
                "gregtech:metal_casing@4"
            ]
        },
        {
            "x": 0,
            "y": 2,
            "z": 6,
            "elements": [
                "gregtech:metal_casing@4"
            ]
        },
        {
            "x": -1,
            "y": 0,
            "z": 5,
            "elements": [
                "gregtech:metal_casing@4"
            ]
        },
        {
            "x": 0,
            "y": 0,
            "z": 5,
            "elements": [
                "gregtech:metal_casing@4"
            ]
        },
        {
            "x": 1,
            "y": 0,
            "z": 5,
            "elements": [
                "gregtech:metal_casing@4"
            ]
        },
        {
            "x": 2,
            "y": 0,
            "z": 5,
            "elements": [
                "gregtech:metal_casing@4"
            ]
        },
        {
            "x": 3,
            "y": 0,
            "z": 5,
            "elements": [
                "gregtech:metal_casing@4"
            ]
        },
        {
            "x": 6,
            "y": 4,
            "z": 7,
            "elements": [
                "gregtech:meta_block_frame_20@3"
            ]
        },
        {
            "x": 4,
            "y": 0,
            "z": 5,
            "elements": [
                "gregtech:metal_casing@4"
            ]
        },
        {
            "x": 5,
            "y": 0,
            "z": 5,
            "elements": [
                "gregtech:metal_casing@4"
            ]
        },
        {
            "x": 6,
            "y": 0,
            "z": 5,
            "elements": [
                "gregtech:metal_casing@4"
            ]
        },
        {
            "x": 7,
            "y": 0,
            "z": 5,
            "elements": [
                "gregtech:metal_casing@4"
            ]
        },
        {
            "x": -6,
            "y": 5,
            "z": 7,
            "elements": [
                "gregtech:meta_block_frame_20@3"
            ]
        },
        {
            "x": 0,
            "y": 13,
            "z": 11,
            "elements": [
                "gregtech:meta_block_frame_20@3"
            ]
        },
        {
            "x": 0,
            "y": 38,
            "z": 7,
            "elements": [
                "gregtech:metal_casing@4"
            ]
        },
        {
            "x": 0,
            "y": 7,
            "z": 8,
            "elements": [
                "gregtech:metal_casing@4"
            ]
        },
        {
            "x": -1,
            "y": 5,
            "z": 7,
            "elements": [
                "gregtech:metal_casing@4"
            ]
        },
        {
            "x": 0,
            "y": 5,
            "z": 7,
            "elements": [
                "gregtech:boiler_casing@1"
            ]
        },
        {
            "x": 1,
            "y": 5,
            "z": 7,
            "elements": [
                "gregtech:metal_casing@4"
            ]
        },
        {
            "x": 0,
            "y": 3,
            "z": 6,
            "elements": [
                "gregtech:metal_casing@4"
            ]
        },
        {
            "x": 6,
            "y": 5,
            "z": 7,
            "elements": [
                "gregtech:meta_block_frame_20@3"
            ]
        },
        {
            "x": -5,
            "y": 6,
            "z": 7,
            "elements": [
                "gregtech:meta_block_frame_20@3"
            ]
        },
        {
            "x": 0,
            "y": 14,
            "z": 11,
            "elements": [
                "gregtech:meta_block_frame_20@3"
            ]
        },
        {
            "x": -6,
            "y": 0,
            "z": 4,
            "elements": [
                "gregtech:metal_casing@4"
            ]
        },
        {
            "x": -5,
            "y": 0,
            "z": 4,
            "elements": [
                "gregtech:metal_casing@4"
            ]
        },
        {
            "x": 0,
            "y": 8,
            "z": 8,
            "elements": [
                "gregtech:metal_casing@4"
            ]
        },
        {
            "x": -4,
            "y": 0,
            "z": 4,
            "elements": [
                "gregtech:metal_casing@4"
            ]
        },
        {
            "x": -1,
            "y": 6,
            "z": 7,
            "elements": [
                "gregtech:metal_casing@4"
            ]
        },
        {
            "x": 0,
            "y": 6,
            "z": 7,
            "elements": [
                "gregtech:boiler_casing@1"
            ]
        },
        {
            "x": -3,
            "y": 0,
            "z": 4,
            "elements": [
                "gregtech:metal_casing@4"
            ]
        },
        {
            "x": 1,
            "y": 6,
            "z": 7,
            "elements": [
                "gregtech:metal_casing@4"
            ]
        },
        {
            "x": 0,
            "y": 4,
            "z": 6,
            "elements": [
                "gregtech:metal_casing@4"
            ]
        },
        {
            "x": -2,
            "y": 0,
            "z": 4,
            "elements": [
                "gregtech:metal_casing@4"
            ]
        },
        {
            "x": -1,
            "y": 0,
            "z": 4,
            "elements": [
                "gregtech:metal_casing@4"
            ]
        },
        {
            "x": 0,
            "y": 0,
            "z": 4,
            "elements": [
                "gregtech:metal_casing@4"
            ]
        },
        {
            "x": 1,
            "y": 0,
            "z": 4,
            "elements": [
                "gregtech:metal_casing@4"
            ]
        },
        {
            "x": 5,
            "y": 6,
            "z": 7,
            "elements": [
                "gregtech:meta_block_frame_20@3"
            ]
        },
        {
            "x": 2,
            "y": 0,
            "z": 4,
            "elements": [
                "gregtech:metal_casing@4"
            ]
        },
        {
            "x": 3,
            "y": 0,
            "z": 4,
            "elements": [
                "gregtech:metal_casing@4"
            ]
        },
        {
            "x": 4,
            "y": 0,
            "z": 4,
            "elements": [
                "gregtech:metal_casing@4"
            ]
        },
        {
            "x": 5,
            "y": 0,
            "z": 4,
            "elements": [
                "gregtech:metal_casing@4"
            ]
        },
        {
            "x": 6,
            "y": 0,
            "z": 4,
            "elements": [
                "gregtech:metal_casing@4"
            ]
        },
        {
            "x": -5,
            "y": 7,
            "z": 7,
            "elements": [
                "gregtech:meta_block_frame_20@3"
            ]
        },
        {
            "x": 0,
            "y": 9,
            "z": 8,
            "elements": [
                "gregtech:metal_casing@4"
            ]
        },
        {
            "x": -1,
            "y": 7,
            "z": 7,
            "elements": [
                "gregtech:metal_casing@4"
            ]
        },
        {
            "x": 0,
            "y": 7,
            "z": 7,
            "elements": [
                "gregtech:boiler_casing@1"
            ]
        },
        {
            "x": -3,
            "y": 1,
            "z": 4,
            "elements": [
                "gregtech:boiler_casing@1"
            ]
        },
        {
            "x": 1,
            "y": 7,
            "z": 7,
            "elements": [
                "gregtech:metal_casing@4"
            ]
        },
        {
            "x": 0,
            "y": 5,
            "z": 6,
            "elements": [
                "gregtech:metal_casing@4"
            ]
        },
        {
            "x": 5,
            "y": 7,
            "z": 7,
            "elements": [
                "gregtech:meta_block_frame_20@3"
            ]
        },
        {
            "x": 3,
            "y": 1,
            "z": 4,
            "elements": [
                "gregtech:boiler_casing@1"
            ]
        },
        {
            "x": -5,
            "y": 8,
            "z": 7,
            "elements": [
                "gregtech:meta_block_frame_20@3"
            ]
        },
        {
            "x": -6,
            "y": 0,
            "z": 3,
            "elements": [
                "gregtech:metal_casing@4"
            ]
        },
        {
            "x": 0,
            "y": 10,
            "z": 8,
            "elements": [
                "gregtech:metal_casing@4"
            ]
        },
        {
            "x": -5,
            "y": 0,
            "z": 3,
            "elements": [
                "gregtech:metal_casing@4"
            ]
        },
        {
            "x": -1,
            "y": 8,
            "z": 7,
            "elements": [
                "gregtech:metal_casing@4"
            ]
        },
        {
            "x": 0,
            "y": 8,
            "z": 7,
            "elements": [
                "gregtech:boiler_casing@1"
            ]
        },
        {
            "x": -4,
            "y": 0,
            "z": 3,
            "elements": [
                "gregtech:metal_casing@4"
            ]
        },
        {
            "x": -3,
            "y": 2,
            "z": 4,
            "elements": [
                "gregtech:boiler_casing@1"
            ]
        },
        {
            "x": 1,
            "y": 8,
            "z": 7,
            "elements": [
                "gregtech:metal_casing@4"
            ]
        },
        {
            "x": 0,
            "y": 6,
            "z": 6,
            "elements": [
                "gregtech:metal_casing@4"
            ]
        },
        {
            "x": -3,
            "y": 0,
            "z": 3,
            "elements": [
                "gregtech:metal_casing@4"
            ]
        },
        {
            "x": -2,
            "y": 0,
            "z": 3,
            "elements": [
                "gregtech:metal_casing@4"
            ]
        },
        {
            "x": -1,
            "y": 0,
            "z": 3,
            "elements": [
                "gregtech:metal_casing@4"
            ]
        },
        {
            "x": 0,
            "y": 0,
            "z": 3,
            "elements": [
                "gregtech:metal_casing@4"
            ]
        },
        {
            "x": 5,
            "y": 8,
            "z": 7,
            "elements": [
                "gregtech:meta_block_frame_20@3"
            ]
        },
        {
            "x": 1,
            "y": 0,
            "z": 3,
            "elements": [
                "gregtech:metal_casing@4"
            ]
        },
        {
            "x": 3,
            "y": 2,
            "z": 4,
            "elements": [
                "gregtech:boiler_casing@1"
            ]
        },
        {
            "x": 2,
            "y": 0,
            "z": 3,
            "elements": [
                "gregtech:metal_casing@4"
            ]
        },
        {
            "x": 3,
            "y": 0,
            "z": 3,
            "elements": [
                "gregtech:metal_casing@4"
            ]
        },
        {
            "x": 4,
            "y": 0,
            "z": 3,
            "elements": [
                "gregtech:metal_casing@4"
            ]
        },
        {
            "x": 5,
            "y": 0,
            "z": 3,
            "elements": [
                "gregtech:metal_casing@4"
            ]
        },
        {
            "x": 6,
            "y": 0,
            "z": 3,
            "elements": [
                "gregtech:metal_casing@4"
            ]
        },
        {
            "x": -5,
            "y": 9,
            "z": 7,
            "elements": [
                "gregtech:meta_block_frame_20@3"
            ]
        },
        {
            "x": 0,
            "y": 15,
            "z": 10,
            "elements": [
                "gregtech:meta_block_frame_20@3"
            ]
        },
        {
            "x": 0,
            "y": 11,
            "z": 8,
            "elements": [
                "gregtech:metal_casing@4"
            ]
        },
        {
            "x": -1,
            "y": 9,
            "z": 7,
            "elements": [
                "gregtech:metal_casing@4"
            ]
        },
        {
            "x": 0,
            "y": 9,
            "z": 7,
            "elements": [
                "gregtech:boiler_casing@1"
            ]
        },
        {
            "x": -3,
            "y": 3,
            "z": 4,
            "elements": [
                "gregtech:boiler_casing@1"
            ]
        },
        {
            "x": 1,
            "y": 9,
            "z": 7,
            "elements": [
                "gregtech:metal_casing@4"
            ]
        },
        {
            "x": 0,
            "y": 7,
            "z": 6,
            "elements": [
                "gregtech:metal_casing@4"
            ]
        },
        {
            "x": 5,
            "y": 9,
            "z": 7,
            "elements": [
                "gregtech:meta_block_frame_20@3"
            ]
        },
        {
            "x": 3,
            "y": 3,
            "z": 4,
            "elements": [
                "gregtech:boiler_casing@1"
            ]
        },
        {
            "x": -4,
            "y": 10,
            "z": 7,
            "elements": [
                "gregtech:meta_block_frame_20@3"
            ]
        },
        {
            "x": 0,
            "y": 16,
            "z": 10,
            "elements": [
                "gregtech:meta_block_frame_20@3"
            ]
        },
        {
            "x": 0,
            "y": 12,
            "z": 8,
            "elements": [
                "gregtech:metal_casing@4"
            ]
        },
        {
            "x": -1,
            "y": 10,
            "z": 7,
            "elements": [
                "gregtech:metal_casing@4"
            ]
        },
        {
            "x": 0,
            "y": 10,
            "z": 7,
            "elements": [
                "gregtech:boiler_casing@1"
            ]
        },
        {
            "x": -5,
            "y": 0,
            "z": 2,
            "elements": [
                "gregtech:metal_casing@4"
            ]
        },
        {
            "x": -3,
            "y": 4,
            "z": 4,
            "elements": [
                "gregtech:boiler_casing@1"
            ]
        },
        {
            "x": 1,
            "y": 10,
            "z": 7,
            "elements": [
                "gregtech:metal_casing@4"
            ]
        },
        {
            "x": 0,
            "y": 8,
            "z": 6,
            "elements": [
                "gregtech:metal_casing@4"
            ]
        },
        {
            "x": -4,
            "y": 0,
            "z": 2,
            "elements": [
                "gregtech:metal_casing@4"
            ]
        },
        {
            "x": -3,
            "y": 0,
            "z": 2,
            "elements": [
                "gregtech:metal_casing@4"
            ]
        },
        {
            "x": -2,
            "y": 0,
            "z": 2,
            "elements": [
                "gregtech:metal_casing@4"
            ]
        },
        {
            "x": 4,
            "y": 10,
            "z": 7,
            "elements": [
                "gregtech:meta_block_frame_20@3"
            ]
        },
        {
            "x": -1,
            "y": 0,
            "z": 2,
            "elements": [
                "gregtech:metal_casing@4"
            ]
        },
        {
            "x": 0,
            "y": 0,
            "z": 2,
            "elements": [
                "gregtech:metal_casing@4"
            ]
        },
        {
            "x": 3,
            "y": 4,
            "z": 4,
            "elements": [
                "gregtech:boiler_casing@1"
            ]
        },
        {
            "x": 1,
            "y": 0,
            "z": 2,
            "elements": [
                "gregtech:metal_casing@4"
            ]
        },
        {
            "x": 2,
            "y": 0,
            "z": 2,
            "elements": [
                "gregtech:metal_casing@4"
            ]
        },
        {
            "x": 3,
            "y": 0,
            "z": 2,
            "elements": [
                "gregtech:metal_casing@4"
            ]
        },
        {
            "x": 4,
            "y": 0,
            "z": 2,
            "elements": [
                "gregtech:metal_casing@4"
            ]
        },
        {
            "x": 5,
            "y": 0,
            "z": 2,
            "elements": [
                "gregtech:metal_casing@4"
            ]
        },
        {
            "x": -4,
            "y": 11,
            "z": 7,
            "elements": [
                "gregtech:meta_block_frame_20@3"
            ]
        },
        {
            "x": 0,
            "y": 17,
            "z": 10,
            "elements": [
                "gregtech:meta_block_frame_20@3"
            ]
        },
        {
            "x": 0,
            "y": 13,
            "z": 8,
            "elements": [
                "gregtech:metal_casing@4"
            ]
        },
        {
            "x": -1,
            "y": 11,
            "z": 7,
            "elements": [
                "gregtech:metal_casing@4"
            ]
        },
        {
            "x": 0,
            "y": 11,
            "z": 7,
            "elements": [
                "gregtech:boiler_casing@1"
            ]
        },
        {
            "x": -3,
            "y": 5,
            "z": 4,
            "elements": [
                "gregtech:boiler_casing@1"
            ]
        },
        {
            "x": 1,
            "y": 11,
            "z": 7,
            "elements": [
                "gregtech:metal_casing@4"
            ]
        },
        {
            "x": 0,
            "y": 9,
            "z": 6,
            "elements": [
                "gregtech:metal_casing@4"
            ]
        },
        {
            "x": 4,
            "y": 11,
            "z": 7,
            "elements": [
                "gregtech:meta_block_frame_20@3"
            ]
        },
        {
            "x": 3,
            "y": 5,
            "z": 4,
            "elements": [
                "gregtech:boiler_casing@1"
            ]
        },
        {
            "x": -4,
            "y": 12,
            "z": 7,
            "elements": [
                "gregtech:meta_block_frame_20@3"
            ]
        },
        {
            "x": 0,
            "y": 18,
            "z": 10,
            "elements": [
                "gregtech:meta_block_frame_20@3"
            ]
        },
        {
            "x": 0,
            "y": 14,
            "z": 8,
            "elements": [
                "gregtech:metal_casing@4"
            ]
        },
        {
            "x": -1,
            "y": 12,
            "z": 7,
            "elements": [
                "gregtech:metal_casing@4"
            ]
        },
        {
            "x": 0,
            "y": 12,
            "z": 7,
            "elements": [
                "gregtech:boiler_casing@1"
            ]
        },
        {
            "x": -3,
            "y": 6,
            "z": 4,
            "elements": [
                "gregtech:boiler_casing@1"
            ]
        },
        {
            "x": 1,
            "y": 12,
            "z": 7,
            "elements": [
                "gregtech:metal_casing@4"
            ]
        },
        {
            "x": 0,
            "y": 10,
            "z": 6,
            "elements": [
                "gregtech:metal_casing@4"
            ]
        },
        {
            "x": -4,
            "y": 0,
            "z": 1,
            "elements": [
                "gregtech:metal_casing@4"
            ]
        },
        {
            "x": -3,
            "y": 0,
            "z": 1,
            "elements": [
                "gregtech:metal_casing@4"
            ]
        },
        {
            "x": 4,
            "y": 12,
            "z": 7,
            "elements": [
                "gregtech:meta_block_frame_20@3"
            ]
        },
        {
            "x": -2,
            "y": 0,
            "z": 1,
            "elements": [
                "gregtech:metal_casing@4"
            ]
        },
        {
            "x": -1,
            "y": 0,
            "z": 1,
            "elements": [
                "gregtech:metal_casing@4"
            ]
        },
        {
            "x": 0,
            "y": 0,
            "z": 1,
            "elements": [
                "gregtech:metal_casing@4"
            ]
        },
        {
            "x": 3,
            "y": 6,
            "z": 4,
            "elements": [
                "gregtech:boiler_casing@1"
            ]
        },
        {
            "x": 1,
            "y": 0,
            "z": 1,
            "elements": [
                "gregtech:metal_casing@4"
            ]
        },
        {
            "x": 2,
            "y": 0,
            "z": 1,
            "elements": [
                "gregtech:metal_casing@4"
            ]
        },
        {
            "x": 3,
            "y": 0,
            "z": 1,
            "elements": [
                "gregtech:metal_casing@4"
            ]
        },
        {
            "x": 4,
            "y": 0,
            "z": 1,
            "elements": [
                "gregtech:metal_casing@4"
            ]
        },
        {
            "x": -4,
            "y": 13,
            "z": 7,
            "elements": [
                "gregtech:meta_block_frame_20@3"
            ]
        },
        {
            "x": 0,
            "y": 19,
            "z": 10,
            "elements": [
                "gregtech:meta_block_frame_20@3"
            ]
        },
        {
            "x": 0,
            "y": 15,
            "z": 8,
            "elements": [
                "gregtech:metal_casing@4"
            ]
        },
        {
            "x": -1,
            "y": 13,
            "z": 7,
            "elements": [
                "gregtech:metal_casing@4"
            ]
        },
        {
            "x": 0,
            "y": 13,
            "z": 7,
            "elements": [
                "gregtech:boiler_casing@1"
            ]
        },
        {
            "x": 1,
            "y": 13,
            "z": 7,
            "elements": [
                "gregtech:metal_casing@4"
            ]
        },
        {
            "x": 0,
            "y": 11,
            "z": 6,
            "elements": [
                "gregtech:metal_casing@4"
            ]
        },
        {
            "x": 4,
            "y": 13,
            "z": 7,
            "elements": [
                "gregtech:meta_block_frame_20@3"
            ]
        },
        {
            "x": -4,
            "y": 14,
            "z": 7,
            "elements": [
                "gregtech:meta_block_frame_20@3"
            ]
        },
        {
            "x": 0,
            "y": 16,
            "z": 8,
            "elements": [
                "gregtech:metal_casing@4"
            ]
        },
        {
            "x": -1,
            "y": 14,
            "z": 7,
            "elements": [
                "gregtech:metal_casing@4"
            ]
        },
        {
            "x": 0,
            "y": 14,
            "z": 7,
            "elements": [
                "gregtech:boiler_casing@1"
            ]
        },
        {
            "x": 1,
            "y": 14,
            "z": 7,
            "elements": [
                "gregtech:metal_casing@4"
            ]
        },
        {
            "x": 0,
            "y": 12,
            "z": 6,
            "elements": [
                "gregtech:metal_casing@4"
            ]
        },
        {
            "x": 4,
            "y": 14,
            "z": 7,
            "elements": [
                "gregtech:meta_block_frame_20@3"
            ]
        }
    ]}