{
  "registryname": "Elite_Planetary_Drilling_Plant",
  "localizedname": "Elite Planetary Drilling Plant",
   "color": "ff0400",
    "parts": [
        {
            "x": -1,
            "y": 0,
            "z": 0,
            "elements": [
                "modularmachinery:blockinputbus"
            ]
        },
        {
            "x": 1,
            "y": 0,
            "z": 0,
            "elements": [
                "modularmachinery:blockinputbus"
            ]
        },
        {
            "x": -2,
            "y": 0,
            "z": 0,
            "elements": [
                "modularmachinery:blockfluidinputhatch"
            ]
        },
        {
            "x": -3,
            "y": 0,
            "z": 0,
            "elements": [
                "modularmachinery:blockfluidinputhatch"
            ]
        },
        {
            "x": 2,
            "y": 0,
            "z": 0,
            "elements": [
                "modularmachinery:blockfluidinputhatch"
            ]
        },
        {
            "x": 3,
            "y": 0,
            "z": 0,
            "elements": [
                "modularmachinery:blockfluidinputhatch"
            ]
        },
        {
            "x": -2,
            "y": 56,
            "z": 11,
            "elements": [
                "gregtech:meta_block_frame_188@12"
            ]
        },
        {
            "x": -1,
            "y": 25,
            "z": 12,
            "elements": [
                "gregtech:metal_casing@6"
            ]
        },
        {
            "x": -1,
            "y": 56,
            "z": 11,
            "elements": [
                "gregtech:metal_casing@6"
            ]
        },
        {
            "x": 0,
            "y": 25,
            "z": 12,
            "elements": [
                "gregtech:boiler_casing@2"
            ]
        },
        {
            "x": 0,
            "y": 56,
            "z": 11,
            "elements": [
                "gregtech:metal_casing@6"
            ]
        },
        {
            "x": -1,
            "y": 21,
            "z": 10,
            "elements": [
                "gregtech:metal_casing@6"
            ]
        },
        {
            "x": 1,
            "y": 56,
            "z": 11,
            "elements": [
                "gregtech:metal_casing@6"
            ]
        },
        {
            "x": 1,
            "y": 25,
            "z": 12,
            "elements": [
                "gregtech:metal_casing@6"
            ]
        },
        {
            "x": 0,
            "y": 21,
            "z": 10,
            "elements": [
                "gregtech:boiler_casing@2"
            ]
        },
        {
            "x": 2,
            "y": 56,
            "z": 11,
            "elements": [
                "gregtech:meta_block_frame_188@12"
            ]
        },
        {
            "x": 1,
            "y": 21,
            "z": 10,
            "elements": [
                "gregtech:metal_casing@6"
            ]
        },
        {
            "x": 0,
            "y": 48,
            "z": 7,
            "elements": [
                "gregtech:meta_block_frame_188@12"
            ]
        },
        {
            "x": 0,
            "y": 1,
            "z": 0,
            "elements": [
                "gregtech:meta_block_frame_188@12"
            ]
        },
        {
            "x": -2,
            "y": 57,
            "z": 11,
            "elements": [
                "gregtech:meta_block_frame_188@12"
            ]
        },
        {
            "x": -1,
            "y": 26,
            "z": 12,
            "elements": [
                "gregtech:metal_casing@6"
            ]
        },
        {
            "x": -1,
            "y": 57,
            "z": 11,
            "elements": [
                "gregtech:metal_casing@6"
            ]
        },
        {
            "x": 0,
            "y": 26,
            "z": 12,
            "elements": [
                "gregtech:boiler_casing@2"
            ]
        },
        {
            "x": 0,
            "y": 57,
            "z": 11,
            "elements": [
                "gregtech:metal_casing@6"
            ]
        },
        {
            "x": -1,
            "y": 22,
            "z": 10,
            "elements": [
                "gregtech:metal_casing@6"
            ]
        },
        {
            "x": 1,
            "y": 57,
            "z": 11,
            "elements": [
                "gregtech:metal_casing@6"
            ]
        },
        {
            "x": 1,
            "y": 26,
            "z": 12,
            "elements": [
                "gregtech:metal_casing@6"
            ]
        },
        {
            "x": 0,
            "y": 22,
            "z": 10,
            "elements": [
                "gregtech:boiler_casing@2"
            ]
        },
        {
            "x": 2,
            "y": 57,
            "z": 11,
            "elements": [
                "gregtech:meta_block_frame_188@12"
            ]
        },
        {
            "x": 1,
            "y": 22,
            "z": 10,
            "elements": [
                "gregtech:metal_casing@6"
            ]
        },
        {
            "x": 0,
            "y": 49,
            "z": 7,
            "elements": [
                "gregtech:meta_block_frame_188@12"
            ]
        },
        {
            "x": 0,
            "y": 2,
            "z": 0,
            "elements": [
                "gregtech:meta_block_frame_188@12"
            ]
        },
        {
            "x": -10,
            "y": 0,
            "z": 15,
            "elements": [
                "gregtech:metal_casing@6"
            ]
        },
        {
            "x": -9,
            "y": 0,
            "z": 15,
            "elements": [
                "gregtech:metal_casing@6"
            ]
        },
        {
            "x": -8,
            "y": 0,
            "z": 15,
            "elements": [
                "gregtech:metal_casing@6"
            ]
        },
        {
            "x": -7,
            "y": 0,
            "z": 15,
            "elements": [
                "gregtech:metal_casing@6"
            ]
        },
        {
            "x": -6,
            "y": 0,
            "z": 15,
            "elements": [
                "gregtech:metal_casing@6"
            ]
        },
        {
            "x": -5,
            "y": 0,
            "z": 15,
            "elements": [
                "gregtech:metal_casing@6"
            ]
        },
        {
            "x": -4,
            "y": 0,
            "z": 15,
            "elements": [
                "gregtech:metal_casing@6"
            ]
        },
        {
            "x": -3,
            "y": 0,
            "z": 15,
            "elements": [
                "gregtech:metal_casing@6"
            ]
        },
        {
            "x": 0,
            "y": 35,
            "z": 16,
            "elements": [
                "gregtech:meta_block_frame_188@12"
            ]
        },
        {
            "x": -2,
            "y": 0,
            "z": 15,
            "elements": [
                "gregtech:metal_casing@6"
            ]
        },
        {
            "x": -1,
            "y": 0,
            "z": 15,
            "elements": [
                "gregtech:metal_casing@6"
            ]
        },
        {
            "x": 0,
            "y": 0,
            "z": 15,
            "elements": [
                "gregtech:metal_casing@6"
            ]
        },
        {
            "x": -2,
            "y": 58,
            "z": 11,
            "elements": [
                "gregtech:meta_block_frame_188@12"
            ]
        },
        {
            "x": -1,
            "y": 27,
            "z": 12,
            "elements": [
                "gregtech:metal_casing@6"
            ]
        },
        {
            "x": -1,
            "y": 58,
            "z": 11,
            "elements": [
                "gregtech:metal_casing@6"
            ]
        },
        {
            "x": 1,
            "y": 0,
            "z": 15,
            "elements": [
                "gregtech:metal_casing@6"
            ]
        },
        {
            "x": 0,
            "y": 27,
            "z": 12,
            "elements": [
                "gregtech:boiler_casing@2"
            ]
        },
        {
            "x": 0,
            "y": 58,
            "z": 11,
            "elements": [
                "gregtech:metal_casing@6"
            ]
        },
        {
            "x": 2,
            "y": 0,
            "z": 15,
            "elements": [
                "gregtech:metal_casing@6"
            ]
        },
        {
            "x": -1,
            "y": 23,
            "z": 10,
            "elements": [
                "gregtech:metal_casing@6"
            ]
        },
        {
            "x": 1,
            "y": 58,
            "z": 11,
            "elements": [
                "gregtech:metal_casing@6"
            ]
        },
        {
            "x": 3,
            "y": 0,
            "z": 15,
            "elements": [
                "gregtech:metal_casing@6"
            ]
        },
        {
            "x": 1,
            "y": 27,
            "z": 12,
            "elements": [
                "gregtech:metal_casing@6"
            ]
        },
        {
            "x": 0,
            "y": 23,
            "z": 10,
            "elements": [
                "gregtech:boiler_casing@2"
            ]
        },
        {
            "x": 2,
            "y": 58,
            "z": 11,
            "elements": [
                "gregtech:meta_block_frame_188@12"
            ]
        },
        {
            "x": 4,
            "y": 0,
            "z": 15,
            "elements": [
                "gregtech:metal_casing@6"
            ]
        },
        {
            "x": 5,
            "y": 0,
            "z": 15,
            "elements": [
                "gregtech:metal_casing@6"
            ]
        },
        {
            "x": 1,
            "y": 23,
            "z": 10,
            "elements": [
                "gregtech:metal_casing@6"
            ]
        },
        {
            "x": 6,
            "y": 0,
            "z": 15,
            "elements": [
                "gregtech:metal_casing@6"
            ]
        },
        {
            "x": 7,
            "y": 0,
            "z": 15,
            "elements": [
                "gregtech:metal_casing@6"
            ]
        },
        {
            "x": 8,
            "y": 0,
            "z": 15,
            "elements": [
                "gregtech:metal_casing@6"
            ]
        },
        {
            "x": 9,
            "y": 0,
            "z": 15,
            "elements": [
                "gregtech:metal_casing@6"
            ]
        },
        {
            "x": 10,
            "y": 0,
            "z": 15,
            "elements": [
                "gregtech:metal_casing@6"
            ]
        },
        {
            "x": 0,
            "y": 3,
            "z": 0,
            "elements": [
                "gregtech:meta_block_frame_188@12"
            ]
        },
        {
            "x": 0,
            "y": 36,
            "z": 16,
            "elements": [
                "gregtech:meta_block_frame_188@12"
            ]
        },
        {
            "x": -1,
            "y": 28,
            "z": 12,
            "elements": [
                "gregtech:metal_casing@6"
            ]
        },
        {
            "x": -1,
            "y": 59,
            "z": 11,
            "elements": [
                "gregtech:meta_block_frame_188@12"
            ]
        },
        {
            "x": 0,
            "y": 28,
            "z": 12,
            "elements": [
                "gregtech:boiler_casing@2"
            ]
        },
        {
            "x": 0,
            "y": 59,
            "z": 11,
            "elements": [
                "gregtech:metal_casing@6"
            ]
        },
        {
            "x": -1,
            "y": 24,
            "z": 10,
            "elements": [
                "gregtech:metal_casing@6"
            ]
        },
        {
            "x": 1,
            "y": 59,
            "z": 11,
            "elements": [
                "gregtech:meta_block_frame_188@12"
            ]
        },
        {
            "x": 1,
            "y": 28,
            "z": 12,
            "elements": [
                "gregtech:metal_casing@6"
            ]
        },
        {
            "x": 0,
            "y": 24,
            "z": 10,
            "elements": [
                "gregtech:boiler_casing@2"
            ]
        },
        {
            "x": 0,
            "y": 55,
            "z": 9,
            "elements": [
                "gregtech:meta_block_frame_188@12"
            ]
        },
        {
            "x": 1,
            "y": 24,
            "z": 10,
            "elements": [
                "gregtech:metal_casing@6"
            ]
        },
        {
            "x": 0,
            "y": 4,
            "z": 0,
            "elements": [
                "gregtech:meta_block_frame_188@12"
            ]
        },
        {
            "x": 0,
            "y": 37,
            "z": 16,
            "elements": [
                "gregtech:meta_block_frame_188@12"
            ]
        },
        {
            "x": -1,
            "y": 29,
            "z": 12,
            "elements": [
                "gregtech:metal_casing@6"
            ]
        },
        {
            "x": -1,
            "y": 60,
            "z": 11,
            "elements": [
                "gregtech:meta_block_frame_188@12"
            ]
        },
        {
            "x": 0,
            "y": 29,
            "z": 12,
            "elements": [
                "gregtech:boiler_casing@2"
            ]
        },
        {
            "x": 0,
            "y": 60,
            "z": 11,
            "elements": [
                "gregtech:metal_casing@6"
            ]
        },
        {
            "x": -1,
            "y": 25,
            "z": 10,
            "elements": [
                "gregtech:metal_casing@6"
            ]
        },
        {
            "x": 1,
            "y": 60,
            "z": 11,
            "elements": [
                "gregtech:meta_block_frame_188@12"
            ]
        },
        {
            "x": 1,
            "y": 29,
            "z": 12,
            "elements": [
                "gregtech:metal_casing@6"
            ]
        },
        {
            "x": 0,
            "y": 25,
            "z": 10,
            "elements": [
                "gregtech:boiler_casing@2"
            ]
        },
        {
            "x": 0,
            "y": 56,
            "z": 9,
            "elements": [
                "gregtech:meta_block_frame_188@12"
            ]
        },
        {
            "x": 1,
            "y": 25,
            "z": 10,
            "elements": [
                "gregtech:metal_casing@6"
            ]
        },
        {
            "x": 0,
            "y": 9,
            "z": 2,
            "elements": [
                "gregtech:meta_block_frame_188@12"
            ]
        },
        {
            "x": 0,
            "y": 5,
            "z": 0,
            "elements": [
                "gregtech:meta_block_frame_188@12"
            ]
        },
        {
            "x": 0,
            "y": 38,
            "z": 16,
            "elements": [
                "gregtech:meta_block_frame_188@12"
            ]
        },
        {
            "x": -1,
            "y": 30,
            "z": 12,
            "elements": [
                "gregtech:metal_casing@6"
            ]
        },
        {
            "x": -1,
            "y": 61,
            "z": 11,
            "elements": [
                "gregtech:meta_block_frame_188@12"
            ]
        },
        {
            "x": 0,
            "y": 30,
            "z": 12,
            "elements": [
                "gregtech:boiler_casing@2"
            ]
        },
        {
            "x": 0,
            "y": 61,
            "z": 11,
            "elements": [
                "gregtech:metal_casing@6"
            ]
        },
        {
            "x": -1,
            "y": 26,
            "z": 10,
            "elements": [
                "gregtech:metal_casing@6"
            ]
        },
        {
            "x": 1,
            "y": 61,
            "z": 11,
            "elements": [
                "gregtech:meta_block_frame_188@12"
            ]
        },
        {
            "x": 1,
            "y": 30,
            "z": 12,
            "elements": [
                "gregtech:metal_casing@6"
            ]
        },
        {
            "x": 0,
            "y": 26,
            "z": 10,
            "elements": [
                "gregtech:boiler_casing@2"
            ]
        },
        {
            "x": 0,
            "y": 57,
            "z": 9,
            "elements": [
                "gregtech:meta_block_frame_188@12"
            ]
        },
        {
            "x": 1,
            "y": 26,
            "z": 10,
            "elements": [
                "gregtech:metal_casing@6"
            ]
        },
        {
            "x": 0,
            "y": 10,
            "z": 2,
            "elements": [
                "gregtech:meta_block_frame_188@12"
            ]
        },
        {
            "x": -11,
            "y": 0,
            "z": 13,
            "elements": [
                "modularmachinery:blockoutputbus"
            ]
        },
        {
            "x": -10,
            "y": 0,
            "z": 13,
            "elements": [
                "gregtech:metal_casing@6"
            ]
        },
        {
            "x": -9,
            "y": 0,
            "z": 13,
            "elements": [
                "gregtech:metal_casing@6"
            ]
        },
        {
            "x": -8,
            "y": 0,
            "z": 13,
            "elements": [
                "gregtech:metal_casing@6"
            ]
        },
        {
            "x": -7,
            "y": 0,
            "z": 13,
            "elements": [
                "gregtech:metal_casing@6"
            ]
        },
        {
            "x": -6,
            "y": 0,
            "z": 13,
            "elements": [
                "gregtech:metal_casing@6"
            ]
        },
        {
            "x": -5,
            "y": 0,
            "z": 13,
            "elements": [
                "gregtech:metal_casing@6"
            ]
        },
        {
            "x": 0,
            "y": 39,
            "z": 16,
            "elements": [
                "gregtech:meta_block_frame_188@12"
            ]
        },
        {
            "x": -4,
            "y": 0,
            "z": 13,
            "elements": [
                "gregtech:metal_casing@6"
            ]
        },
        {
            "x": -3,
            "y": 0,
            "z": 13,
            "elements": [
                "gregtech:metal_casing@6"
            ]
        },
        {
            "x": -2,
            "y": 0,
            "z": 13,
            "elements": [
                "gregtech:metal_casing@6"
            ]
        },
        {
            "x": -1,
            "y": 31,
            "z": 12,
            "elements": [
                "gregtech:metal_casing@6"
            ]
        },
        {
            "x": -1,
            "y": 0,
            "z": 13,
            "elements": [
                "gregtech:metal_casing@6"
            ]
        },
        {
            "x": 0,
            "y": 0,
            "z": 13,
            "elements": [
                "gregtech:metal_casing@6"
            ]
        },
        {
            "x": 0,
            "y": 31,
            "z": 12,
            "elements": [
                "gregtech:boiler_casing@2"
            ]
        },
        {
            "x": 0,
            "y": 62,
            "z": 11,
            "elements": [
                "gregtech:metal_casing@6"
            ]
        },
        {
            "x": -1,
            "y": 27,
            "z": 10,
            "elements": [
                "gregtech:metal_casing@6"
            ]
        },
        {
            "x": 1,
            "y": 0,
            "z": 13,
            "elements": [
                "gregtech:metal_casing@6"
            ]
        },
        {
            "x": 1,
            "y": 31,
            "z": 12,
            "elements": [
                "gregtech:metal_casing@6"
            ]
        },
        {
            "x": 0,
            "y": 27,
            "z": 10,
            "elements": [
                "gregtech:boiler_casing@2"
            ]
        },
        {
            "x": 0,
            "y": 58,
            "z": 9,
            "elements": [
                "gregtech:meta_block_frame_188@12"
            ]
        },
        {
            "x": 2,
            "y": 0,
            "z": 13,
            "elements": [
                "gregtech:metal_casing@6"
            ]
        },
        {
            "x": 3,
            "y": 0,
            "z": 13,
            "elements": [
                "gregtech:metal_casing@6"
            ]
        },
        {
            "x": 1,
            "y": 27,
            "z": 10,
            "elements": [
                "gregtech:metal_casing@6"
            ]
        },
        {
            "x": 4,
            "y": 0,
            "z": 13,
            "elements": [
                "gregtech:metal_casing@6"
            ]
        },
        {
            "x": 5,
            "y": 0,
            "z": 13,
            "elements": [
                "gregtech:metal_casing@6"
            ]
        },
        {
            "x": 6,
            "y": 0,
            "z": 13,
            "elements": [
                "gregtech:metal_casing@6"
            ]
        },
        {
            "x": 7,
            "y": 0,
            "z": 13,
            "elements": [
                "gregtech:metal_casing@6"
            ]
        },
        {
            "x": 8,
            "y": 0,
            "z": 13,
            "elements": [
                "gregtech:metal_casing@6"
            ]
        },
        {
            "x": 9,
            "y": 0,
            "z": 13,
            "elements": [
                "gregtech:metal_casing@6"
            ]
        },
        {
            "x": 0,
            "y": 11,
            "z": 2,
            "elements": [
                "gregtech:meta_block_frame_188@12"
            ]
        },
        {
            "x": 10,
            "y": 0,
            "z": 13,
            "elements": [
                "gregtech:metal_casing@6"
            ]
        },
        {
            "x": 11,
            "y": 0,
            "z": 13,
            "elements": [
                "modularmachinery:blockoutputbus"
            ]
        },
        {
            "x": 0,
            "y": 40,
            "z": 16,
            "elements": [
                "gregtech:meta_block_frame_188@12"
            ]
        },
        {
            "x": -1,
            "y": 32,
            "z": 12,
            "elements": [
                "gregtech:metal_casing@6"
            ]
        },
        {
            "x": 0,
            "y": 1,
            "z": 13,
            "elements": [
                "gregtech:metal_casing@6"
            ]
        },
        {
            "x": 0,
            "y": 32,
            "z": 12,
            "elements": [
                "gregtech:boiler_casing@2"
            ]
        },
        {
            "x": 0,
            "y": 63,
            "z": 11,
            "elements": [
                "gregtech:metal_casing@6"
            ]
        },
        {
            "x": -1,
            "y": 28,
            "z": 10,
            "elements": [
                "gregtech:metal_casing@6"
            ]
        },
        {
            "x": 1,
            "y": 32,
            "z": 12,
            "elements": [
                "gregtech:metal_casing@6"
            ]
        },
        {
            "x": 0,
            "y": 28,
            "z": 10,
            "elements": [
                "gregtech:boiler_casing@2"
            ]
        },
        {
            "x": 1,
            "y": 28,
            "z": 10,
            "elements": [
                "gregtech:metal_casing@6"
            ]
        },
        {
            "x": 0,
            "y": 12,
            "z": 2,
            "elements": [
                "gregtech:meta_block_frame_188@12"
            ]
        },
        {
            "x": -1,
            "y": 33,
            "z": 12,
            "elements": [
                "gregtech:metal_casing@6"
            ]
        },
        {
            "x": 0,
            "y": 2,
            "z": 13,
            "elements": [
                "gregtech:metal_casing@6"
            ]
        },
        {
            "x": 0,
            "y": 33,
            "z": 12,
            "elements": [
                "gregtech:boiler_casing@2"
            ]
        },
        {
            "x": 0,
            "y": 64,
            "z": 11,
            "elements": [
                "gregtech:metal_casing@6"
            ]
        },
        {
            "x": -1,
            "y": 29,
            "z": 10,
            "elements": [
                "gregtech:metal_casing@6"
            ]
        },
        {
            "x": 1,
            "y": 33,
            "z": 12,
            "elements": [
                "gregtech:metal_casing@6"
            ]
        },
        {
            "x": 0,
            "y": 29,
            "z": 10,
            "elements": [
                "gregtech:boiler_casing@2"
            ]
        },
        {
            "x": 1,
            "y": 29,
            "z": 10,
            "elements": [
                "gregtech:metal_casing@6"
            ]
        },
        {
            "x": 0,
            "y": 13,
            "z": 2,
            "elements": [
                "gregtech:meta_block_frame_188@12"
            ]
        },
        {
            "x": 0,
            "y": 15,
            "z": 19,
            "elements": [
                "gregtech:meta_block_frame_188@12"
            ]
        },
        {
            "x": -1,
            "y": 34,
            "z": 12,
            "elements": [
                "gregtech:metal_casing@6"
            ]
        },
        {
            "x": 0,
            "y": 3,
            "z": 13,
            "elements": [
                "gregtech:metal_casing@6"
            ]
        },
        {
            "x": 0,
            "y": 34,
            "z": 12,
            "elements": [
                "gregtech:boiler_casing@2"
            ]
        },
        {
            "x": 0,
            "y": 65,
            "z": 11,
            "elements": [
                "gregtech:metal_casing@6"
            ]
        },
        {
            "x": -1,
            "y": 30,
            "z": 10,
            "elements": [
                "gregtech:metal_casing@6"
            ]
        },
        {
            "x": 1,
            "y": 34,
            "z": 12,
            "elements": [
                "gregtech:metal_casing@6"
            ]
        },
        {
            "x": 0,
            "y": 30,
            "z": 10,
            "elements": [
                "gregtech:boiler_casing@2"
            ]
        },
        {
            "x": 1,
            "y": 30,
            "z": 10,
            "elements": [
                "gregtech:metal_casing@6"
            ]
        },
        {
            "x": 0,
            "y": 18,
            "z": 4,
            "elements": [
                "gregtech:meta_block_frame_188@12"
            ]
        },
        {
            "x": 0,
            "y": 14,
            "z": 2,
            "elements": [
                "gregtech:meta_block_frame_188@12"
            ]
        },
        {
            "x": -11,
            "y": 0,
            "z": 11,
            "elements": [
                "modularmachinery:blockoutputbus"
            ]
        },
        {
            "x": -10,
            "y": 0,
            "z": 11,
            "elements": [
                "gregtech:metal_casing@6"
            ]
        },
        {
            "x": -9,
            "y": 0,
            "z": 11,
            "elements": [
                "gregtech:metal_casing@6"
            ]
        },
        {
            "x": 0,
            "y": 16,
            "z": 19,
            "elements": [
                "gregtech:meta_block_frame_188@12"
            ]
        },
        {
            "x": -8,
            "y": 0,
            "z": 11,
            "elements": [
                "gregtech:metal_casing@6"
            ]
        },
        {
            "x": -7,
            "y": 0,
            "z": 11,
            "elements": [
                "gregtech:metal_casing@6"
            ]
        },
        {
            "x": -6,
            "y": 0,
            "z": 11,
            "elements": [
                "gregtech:metal_casing@6"
            ]
        },
        {
            "x": -5,
            "y": 0,
            "z": 11,
            "elements": [
                "gregtech:metal_casing@6"
            ]
        },
        {
            "x": -4,
            "y": 0,
            "z": 11,
            "elements": [
                "gregtech:metal_casing@6"
            ]
        },
        {
            "x": -1,
            "y": 35,
            "z": 12,
            "elements": [
                "gregtech:metal_casing@6"
            ]
        },
        {
            "x": -3,
            "y": 0,
            "z": 11,
            "elements": [
                "gregtech:metal_casing@6"
            ]
        },
        {
            "x": 0,
            "y": 4,
            "z": 13,
            "elements": [
                "gregtech:metal_casing@6"
            ]
        },
        {
            "x": 0,
            "y": 35,
            "z": 12,
            "elements": [
                "gregtech:boiler_casing@2"
            ]
        },
        {
            "x": -2,
            "y": 0,
            "z": 11,
            "elements": [
                "gregtech:metal_casing@6"
            ]
        },
        {
            "x": 0,
            "y": 66,
            "z": 11,
            "elements": [
                "gregtech:metal_casing@6"
            ]
        },
        {
            "x": -1,
            "y": 31,
            "z": 10,
            "elements": [
                "gregtech:metal_casing@6"
            ]
        },
        {
            "x": -1,
            "y": 0,
            "z": 11,
            "elements": [
                "gregtech:metal_casing@6"
            ]
        },
        {
            "x": 1,
            "y": 35,
            "z": 12,
            "elements": [
                "gregtech:metal_casing@6"
            ]
        },
        {
            "x": 0,
            "y": 0,
            "z": 11,
            "elements": [
                "modulardiversity:blockbiomedetector@0"
            ]
        },
        {
            "x": 0,
            "y": 31,
            "z": 10,
            "elements": [
                "gregtech:boiler_casing@2"
            ]
        },
        {
            "x": 1,
            "y": 0,
            "z": 11,
            "elements": [
                "gregtech:metal_casing@6"
            ]
        },
        {
            "x": 1,
            "y": 31,
            "z": 10,
            "elements": [
                "gregtech:metal_casing@6"
            ]
        },
        {
            "x": 2,
            "y": 0,
            "z": 11,
            "elements": [
                "gregtech:metal_casing@6"
            ]
        },
        {
            "x": 3,
            "y": 0,
            "z": 11,
            "elements": [
                "gregtech:metal_casing@6"
            ]
        },
        {
            "x": 4,
            "y": 0,
            "z": 11,
            "elements": [
                "gregtech:metal_casing@6"
            ]
        },
        {
            "x": 5,
            "y": 0,
            "z": 11,
            "elements": [
                "gregtech:metal_casing@6"
            ]
        },
        {
            "x": 0,
            "y": 19,
            "z": 4,
            "elements": [
                "gregtech:meta_block_frame_188@12"
            ]
        },
        {
            "x": 6,
            "y": 0,
            "z": 11,
            "elements": [
                "gregtech:metal_casing@6"
            ]
        },
        {
            "x": 7,
            "y": 0,
            "z": 11,
            "elements": [
                "gregtech:metal_casing@6"
            ]
        },
        {
            "x": 8,
            "y": 0,
            "z": 11,
            "elements": [
                "gregtech:metal_casing@6"
            ]
        },
        {
            "x": 9,
            "y": 0,
            "z": 11,
            "elements": [
                "gregtech:metal_casing@6"
            ]
        },
        {
            "x": 10,
            "y": 0,
            "z": 11,
            "elements": [
                "gregtech:metal_casing@6"
            ]
        },
        {
            "x": 11,
            "y": 0,
            "z": 11,
            "elements": [
                "modularmachinery:blockoutputbus"
            ]
        },
        {
            "x": -11,
            "y": 1,
            "z": 11,
            "elements": [
                "gregtech:meta_block_frame_188@12"
            ]
        },
        {
            "x": 0,
            "y": 17,
            "z": 19,
            "elements": [
                "gregtech:meta_block_frame_188@12"
            ]
        },
        {
            "x": -1,
            "y": 36,
            "z": 12,
            "elements": [
                "gregtech:metal_casing@6"
            ]
        },
        {
            "x": 0,
            "y": 67,
            "z": 11,
            "elements": [
                "gregtech:metal_casing@6"
            ]
        },
        {
            "x": 0,
            "y": 5,
            "z": 13,
            "elements": [
                "gregtech:metal_casing@6"
            ]
        },
        {
            "x": 0,
            "y": 36,
            "z": 12,
            "elements": [
                "gregtech:boiler_casing@2"
            ]
        },
        {
            "x": -2,
            "y": 1,
            "z": 11,
            "elements": [
                "gregtech:metal_casing@6"
            ]
        },
        {
            "x": 1,
            "y": 36,
            "z": 12,
            "elements": [
                "gregtech:metal_casing@6"
            ]
        },
        {
            "x": -1,
            "y": 32,
            "z": 10,
            "elements": [
                "gregtech:metal_casing@6"
            ]
        },
        {
            "x": -1,
            "y": 1,
            "z": 11,
            "elements": [
                "gregtech:boiler_casing@2"
            ]
        },
        {
            "x": 0,
            "y": 1,
            "z": 11,
            "elements": [
                "gregtech:boiler_casing@2"
            ]
        },
        {
            "x": 0,
            "y": 32,
            "z": 10,
            "elements": [
                "gregtech:boiler_casing@2"
            ]
        },
        {
            "x": 1,
            "y": 1,
            "z": 11,
            "elements": [
                "gregtech:boiler_casing@2"
            ]
        },
        {
            "x": 1,
            "y": 32,
            "z": 10,
            "elements": [
                "gregtech:metal_casing@6"
            ]
        },
        {
            "x": 2,
            "y": 1,
            "z": 11,
            "elements": [
                "gregtech:metal_casing@6"
            ]
        },
        {
            "x": 0,
            "y": 20,
            "z": 4,
            "elements": [
                "gregtech:meta_block_frame_188@12"
            ]
        },
        {
            "x": 11,
            "y": 1,
            "z": 11,
            "elements": [
                "gregtech:meta_block_frame_188@12"
            ]
        },
        {
            "x": -11,
            "y": 2,
            "z": 11,
            "elements": [
                "gregtech:meta_block_frame_188@12"
            ]
        },
        {
            "x": -1,
            "y": 37,
            "z": 12,
            "elements": [
                "gregtech:metal_casing@6"
            ]
        },
        {
            "x": 0,
            "y": 68,
            "z": 11,
            "elements": [
                "gregtech:metal_casing@6"
            ]
        },
        {
            "x": 0,
            "y": 6,
            "z": 13,
            "elements": [
                "gregtech:metal_casing@6"
            ]
        },
        {
            "x": 0,
            "y": 37,
            "z": 12,
            "elements": [
                "gregtech:boiler_casing@2"
            ]
        },
        {
            "x": -2,
            "y": 2,
            "z": 11,
            "elements": [
                "gregtech:metal_casing@6"
            ]
        },
        {
            "x": 1,
            "y": 37,
            "z": 12,
            "elements": [
                "gregtech:metal_casing@6"
            ]
        },
        {
            "x": -1,
            "y": 33,
            "z": 10,
            "elements": [
                "gregtech:metal_casing@6"
            ]
        },
        {
            "x": -1,
            "y": 2,
            "z": 11,
            "elements": [
                "gregtech:boiler_casing@2"
            ]
        },
        {
            "x": 0,
            "y": 2,
            "z": 11,
            "elements": [
                "gregtech:boiler_casing@2"
            ]
        },
        {
            "x": 0,
            "y": 33,
            "z": 10,
            "elements": [
                "gregtech:boiler_casing@2"
            ]
        },
        {
            "x": 1,
            "y": 2,
            "z": 11,
            "elements": [
                "gregtech:boiler_casing@2"
            ]
        },
        {
            "x": 1,
            "y": 33,
            "z": 10,
            "elements": [
                "gregtech:metal_casing@6"
            ]
        },
        {
            "x": 2,
            "y": 2,
            "z": 11,
            "elements": [
                "gregtech:metal_casing@6"
            ]
        },
        {
            "x": 0,
            "y": 21,
            "z": 4,
            "elements": [
                "gregtech:meta_block_frame_188@12"
            ]
        },
        {
            "x": 11,
            "y": 2,
            "z": 11,
            "elements": [
                "gregtech:meta_block_frame_188@12"
            ]
        },
        {
            "x": -11,
            "y": 3,
            "z": 11,
            "elements": [
                "gregtech:meta_block_frame_188@12"
            ]
        },
        {
            "x": 0,
            "y": 69,
            "z": 11,
            "elements": [
                "gregtech:metal_casing@6"
            ]
        },
        {
            "x": 0,
            "y": 7,
            "z": 13,
            "elements": [
                "gregtech:metal_casing@6"
            ]
        },
        {
            "x": 0,
            "y": 38,
            "z": 12,
            "elements": [
                "gregtech:metal_casing@6"
            ]
        },
        {
            "x": -2,
            "y": 3,
            "z": 11,
            "elements": [
                "gregtech:metal_casing@6"
            ]
        },
        {
            "x": -1,
            "y": 34,
            "z": 10,
            "elements": [
                "gregtech:metal_casing@6"
            ]
        },
        {
            "x": -1,
            "y": 3,
            "z": 11,
            "elements": [
                "gregtech:boiler_casing@2"
            ]
        },
        {
            "x": 0,
            "y": 3,
            "z": 11,
            "elements": [
                "gregtech:boiler_casing@2"
            ]
        },
        {
            "x": 0,
            "y": 34,
            "z": 10,
            "elements": [
                "gregtech:boiler_casing@2"
            ]
        },
        {
            "x": 1,
            "y": 3,
            "z": 11,
            "elements": [
                "gregtech:boiler_casing@2"
            ]
        },
        {
            "x": 1,
            "y": 34,
            "z": 10,
            "elements": [
                "gregtech:metal_casing@6"
            ]
        },
        {
            "x": 2,
            "y": 3,
            "z": 11,
            "elements": [
                "gregtech:metal_casing@6"
            ]
        },
        {
            "x": 0,
            "y": 22,
            "z": 4,
            "elements": [
                "gregtech:meta_block_frame_188@12"
            ]
        },
        {
            "x": 11,
            "y": 3,
            "z": 11,
            "elements": [
                "gregtech:meta_block_frame_188@12"
            ]
        },
        {
            "x": -11,
            "y": 4,
            "z": 11,
            "elements": [
                "gregtech:meta_block_frame_188@12"
            ]
        },
        {
            "x": -11,
            "y": 0,
            "z": 9,
            "elements": [
                "modularmachinery:blockoutputbus"
            ]
        },
        {
            "x": -10,
            "y": 0,
            "z": 9,
            "elements": [
                "gregtech:metal_casing@6"
            ]
        },
        {
            "x": -9,
            "y": 0,
            "z": 9,
            "elements": [
                "gregtech:metal_casing@6"
            ]
        },
        {
            "x": -8,
            "y": 0,
            "z": 9,
            "elements": [
                "gregtech:metal_casing@6"
            ]
        },
        {
            "x": -7,
            "y": 0,
            "z": 9,
            "elements": [
                "gregtech:metal_casing@6"
            ]
        },
        {
            "x": -6,
            "y": 0,
            "z": 9,
            "elements": [
                "gregtech:metal_casing@6"
            ]
        },
        {
            "x": -5,
            "y": 0,
            "z": 9,
            "elements": [
                "gregtech:metal_casing@6"
            ]
        },
        {
            "x": 0,
            "y": 70,
            "z": 11,
            "elements": [
                "gregtech:metal_casing@6"
            ]
        },
        {
            "x": 0,
            "y": 8,
            "z": 13,
            "elements": [
                "gregtech:metal_casing@6"
            ]
        },
        {
            "x": 0,
            "y": 39,
            "z": 12,
            "elements": [
                "gregtech:metal_casing@6"
            ]
        },
        {
            "x": -4,
            "y": 0,
            "z": 9,
            "elements": [
                "gregtech:metal_casing@6"
            ]
        },
        {
            "x": -2,
            "y": 4,
            "z": 11,
            "elements": [
                "gregtech:metal_casing@6"
            ]
        },
        {
            "x": -1,
            "y": 35,
            "z": 10,
            "elements": [
                "gregtech:metal_casing@6"
            ]
        },
        {
            "x": -3,
            "y": 0,
            "z": 9,
            "elements": [
                "gregtech:metal_casing@6"
            ]
        },
        {
            "x": -1,
            "y": 4,
            "z": 11,
            "elements": [
                "gregtech:boiler_casing@2"
            ]
        },
        {
            "x": 0,
            "y": 4,
            "z": 11,
            "elements": [
                "gregtech:boiler_casing@2"
            ]
        },
        {
            "x": 0,
            "y": 35,
            "z": 10,
            "elements": [
                "gregtech:boiler_casing@2"
            ]
        },
        {
            "x": -2,
            "y": 0,
            "z": 9,
            "elements": [
                "gregtech:metal_casing@6"
            ]
        },
        {
            "x": -1,
            "y": 0,
            "z": 9,
            "elements": [
                "gregtech:metal_casing@6"
            ]
        },
        {
            "x": 1,
            "y": 4,
            "z": 11,
            "elements": [
                "gregtech:boiler_casing@2"
            ]
        },
        {
            "x": 1,
            "y": 35,
            "z": 10,
            "elements": [
                "gregtech:metal_casing@6"
            ]
        },
        {
            "x": 0,
            "y": 0,
            "z": 9,
            "elements": [
                "gregtech:metal_casing@6"
            ]
        },
        {
            "x": 2,
            "y": 4,
            "z": 11,
            "elements": [
                "gregtech:metal_casing@6"
            ]
        },
        {
            "x": 1,
            "y": 0,
            "z": 9,
            "elements": [
                "gregtech:metal_casing@6"
            ]
        },
        {
            "x": 2,
            "y": 0,
            "z": 9,
            "elements": [
                "gregtech:metal_casing@6"
            ]
        },
        {
            "x": 3,
            "y": 0,
            "z": 9,
            "elements": [
                "gregtech:metal_casing@6"
            ]
        },
        {
            "x": 0,
            "y": 23,
            "z": 4,
            "elements": [
                "gregtech:meta_block_frame_188@12"
            ]
        },
        {
            "x": 4,
            "y": 0,
            "z": 9,
            "elements": [
                "gregtech:metal_casing@6"
            ]
        },
        {
            "x": 5,
            "y": 0,
            "z": 9,
            "elements": [
                "gregtech:metal_casing@6"
            ]
        },
        {
            "x": 6,
            "y": 0,
            "z": 9,
            "elements": [
                "gregtech:metal_casing@6"
            ]
        },
        {
            "x": 7,
            "y": 0,
            "z": 9,
            "elements": [
                "gregtech:metal_casing@6"
            ]
        },
        {
            "x": 8,
            "y": 0,
            "z": 9,
            "elements": [
                "gregtech:metal_casing@6"
            ]
        },
        {
            "x": 11,
            "y": 4,
            "z": 11,
            "elements": [
                "gregtech:meta_block_frame_188@12"
            ]
        },
        {
            "x": 9,
            "y": 0,
            "z": 9,
            "elements": [
                "gregtech:metal_casing@6"
            ]
        },
        {
            "x": 10,
            "y": 0,
            "z": 9,
            "elements": [
                "gregtech:metal_casing@6"
            ]
        },
        {
            "x": 11,
            "y": 0,
            "z": 9,
            "elements": [
                "modularmachinery:blockoutputbus"
            ]
        },
        {
            "x": -11,
            "y": 5,
            "z": 11,
            "elements": [
                "gregtech:meta_block_frame_188@12"
            ]
        },
        {
            "x": 0,
            "y": 71,
            "z": 11,
            "elements": [
                "gregtech:metal_casing@6"
            ]
        },
        {
            "x": 0,
            "y": 9,
            "z": 13,
            "elements": [
                "gregtech:metal_casing@6"
            ]
        },
        {
            "x": 0,
            "y": 40,
            "z": 12,
            "elements": [
                "gregtech:metal_casing@6"
            ]
        },
        {
            "x": -2,
            "y": 5,
            "z": 11,
            "elements": [
                "gregtech:metal_casing@6"
            ]
        },
        {
            "x": -1,
            "y": 36,
            "z": 10,
            "elements": [
                "gregtech:metal_casing@6"
            ]
        },
        {
            "x": -1,
            "y": 5,
            "z": 11,
            "elements": [
                "gregtech:boiler_casing@2"
            ]
        },
        {
            "x": 0,
            "y": 5,
            "z": 11,
            "elements": [
                "gregtech:boiler_casing@2"
            ]
        },
        {
            "x": 0,
            "y": 36,
            "z": 10,
            "elements": [
                "gregtech:boiler_casing@2"
            ]
        },
        {
            "x": 1,
            "y": 36,
            "z": 10,
            "elements": [
                "gregtech:metal_casing@6"
            ]
        },
        {
            "x": 1,
            "y": 5,
            "z": 11,
            "elements": [
                "gregtech:boiler_casing@2"
            ]
        },
        {
            "x": 2,
            "y": 5,
            "z": 11,
            "elements": [
                "gregtech:metal_casing@6"
            ]
        },
        {
            "x": 0,
            "y": 1,
            "z": 9,
            "elements": [
                "gregtech:metal_casing@6"
            ]
        },
        {
            "x": 0,
            "y": 24,
            "z": 4,
            "elements": [
                "gregtech:meta_block_frame_188@12"
            ]
        },
        {
            "x": 11,
            "y": 5,
            "z": 11,
            "elements": [
                "gregtech:meta_block_frame_188@12"
            ]
        },
        {
            "x": -10,
            "y": 6,
            "z": 11,
            "elements": [
                "gregtech:meta_block_frame_188@12"
            ]
        },
        {
            "x": 0,
            "y": 10,
            "z": 13,
            "elements": [
                "gregtech:metal_casing@6"
            ]
        },
        {
            "x": 0,
            "y": 41,
            "z": 12,
            "elements": [
                "gregtech:metal_casing@6"
            ]
        },
        {
            "x": -2,
            "y": 6,
            "z": 11,
            "elements": [
                "gregtech:metal_casing@6"
            ]
        },
        {
            "x": -1,
            "y": 37,
            "z": 10,
            "elements": [
                "gregtech:metal_casing@6"
            ]
        },
        {
            "x": -1,
            "y": 6,
            "z": 11,
            "elements": [
                "gregtech:boiler_casing@2"
            ]
        },
        {
            "x": 0,
            "y": 6,
            "z": 11,
            "elements": [
                "gregtech:boiler_casing@2"
            ]
        },
        {
            "x": 0,
            "y": 37,
            "z": 10,
            "elements": [
                "gregtech:boiler_casing@2"
            ]
        },
        {
            "x": 1,
            "y": 37,
            "z": 10,
            "elements": [
                "gregtech:metal_casing@6"
            ]
        },
        {
            "x": 1,
            "y": 6,
            "z": 11,
            "elements": [
                "gregtech:boiler_casing@2"
            ]
        },
        {
            "x": 2,
            "y": 6,
            "z": 11,
            "elements": [
                "gregtech:metal_casing@6"
            ]
        },
        {
            "x": 0,
            "y": 2,
            "z": 9,
            "elements": [
                "gregtech:metal_casing@6"
            ]
        },
        {
            "x": 0,
            "y": 25,
            "z": 4,
            "elements": [
                "gregtech:meta_block_frame_188@12"
            ]
        },
        {
            "x": 10,
            "y": 6,
            "z": 11,
            "elements": [
                "gregtech:meta_block_frame_188@12"
            ]
        },
        {
            "x": -10,
            "y": 7,
            "z": 11,
            "elements": [
                "gregtech:meta_block_frame_188@12"
            ]
        },
        {
            "x": 0,
            "y": 11,
            "z": 13,
            "elements": [
                "gregtech:metal_casing@6"
            ]
        },
        {
            "x": 0,
            "y": 42,
            "z": 12,
            "elements": [
                "gregtech:metal_casing@6"
            ]
        },
        {
            "x": -2,
            "y": 7,
            "z": 11,
            "elements": [
                "gregtech:metal_casing@6"
            ]
        },
        {
            "x": -1,
            "y": 7,
            "z": 11,
            "elements": [
                "gregtech:boiler_casing@2"
            ]
        },
        {
            "x": 0,
            "y": 7,
            "z": 11,
            "elements": [
                "gregtech:boiler_casing@2"
            ]
        },
        {
            "x": 0,
            "y": 38,
            "z": 10,
            "elements": [
                "gregtech:metal_casing@6"
            ]
        },
        {
            "x": 1,
            "y": 7,
            "z": 11,
            "elements": [
                "gregtech:boiler_casing@2"
            ]
        },
        {
            "x": 2,
            "y": 7,
            "z": 11,
            "elements": [
                "gregtech:metal_casing@6"
            ]
        },
        {
            "x": 0,
            "y": 3,
            "z": 9,
            "elements": [
                "gregtech:metal_casing@6"
            ]
        },
        {
            "x": 0,
            "y": 26,
            "z": 4,
            "elements": [
                "gregtech:meta_block_frame_188@12"
            ]
        },
        {
            "x": 10,
            "y": 7,
            "z": 11,
            "elements": [
                "gregtech:meta_block_frame_188@12"
            ]
        },
        {
            "x": -10,
            "y": 8,
            "z": 11,
            "elements": [
                "gregtech:meta_block_frame_188@12"
            ]
        },
        {
            "x": -10,
            "y": 0,
            "z": 7,
            "elements": [
                "gregtech:metal_casing@6"
            ]
        },
        {
            "x": -9,
            "y": 0,
            "z": 7,
            "elements": [
                "gregtech:metal_casing@6"
            ]
        },
        {
            "x": -8,
            "y": 0,
            "z": 7,
            "elements": [
                "gregtech:metal_casing@6"
            ]
        },
        {
            "x": -7,
            "y": 0,
            "z": 7,
            "elements": [
                "gregtech:metal_casing@6"
            ]
        },
        {
            "x": 0,
            "y": 12,
            "z": 13,
            "elements": [
                "gregtech:metal_casing@6"
            ]
        },
        {
            "x": 0,
            "y": 43,
            "z": 12,
            "elements": [
                "gregtech:metal_casing@6"
            ]
        },
        {
            "x": -6,
            "y": 0,
            "z": 7,
            "elements": [
                "gregtech:metal_casing@6"
            ]
        },
        {
            "x": -2,
            "y": 8,
            "z": 11,
            "elements": [
                "gregtech:metal_casing@6"
            ]
        },
        {
            "x": -5,
            "y": 0,
            "z": 7,
            "elements": [
                "gregtech:metal_casing@6"
            ]
        },
        {
            "x": -1,
            "y": 8,
            "z": 11,
            "elements": [
                "gregtech:boiler_casing@2"
            ]
        },
        {
            "x": 0,
            "y": 8,
            "z": 11,
            "elements": [
                "gregtech:boiler_casing@2"
            ]
        },
        {
            "x": 0,
            "y": 39,
            "z": 10,
            "elements": [
                "gregtech:metal_casing@6"
            ]
        },
        {
            "x": -4,
            "y": 0,
            "z": 7,
            "elements": [
                "gregtech:metal_casing@6"
            ]
        },
        {
            "x": -3,
            "y": 0,
            "z": 7,
            "elements": [
                "gregtech:metal_casing@6"
            ]
        },
        {
            "x": 1,
            "y": 8,
            "z": 11,
            "elements": [
                "gregtech:boiler_casing@2"
            ]
        },
        {
            "x": 2,
            "y": 8,
            "z": 11,
            "elements": [
                "gregtech:metal_casing@6"
            ]
        },
        {
            "x": 0,
            "y": 4,
            "z": 9,
            "elements": [
                "gregtech:metal_casing@6"
            ]
        },
        {
            "x": -2,
            "y": 0,
            "z": 7,
            "elements": [
                "gregtech:metal_casing@6"
            ]
        },
        {
            "x": -1,
            "y": 0,
            "z": 7,
            "elements": [
                "gregtech:metal_casing@6"
            ]
        },
        {
            "x": 0,
            "y": 0,
            "z": 7,
            "elements": [
                "gregtech:metal_casing@6"
            ]
        },
        {
            "x": 1,
            "y": 0,
            "z": 7,
            "elements": [
                "gregtech:metal_casing@6"
            ]
        },
        {
            "x": 0,
            "y": 27,
            "z": 4,
            "elements": [
                "gregtech:meta_block_frame_188@12"
            ]
        },
        {
            "x": 2,
            "y": 0,
            "z": 7,
            "elements": [
                "gregtech:metal_casing@6"
            ]
        },
        {
            "x": 3,
            "y": 0,
            "z": 7,
            "elements": [
                "gregtech:metal_casing@6"
            ]
        },
        {
            "x": 4,
            "y": 0,
            "z": 7,
            "elements": [
                "gregtech:metal_casing@6"
            ]
        },
        {
            "x": 5,
            "y": 0,
            "z": 7,
            "elements": [
                "gregtech:metal_casing@6"
            ]
        },
        {
            "x": 10,
            "y": 8,
            "z": 11,
            "elements": [
                "gregtech:meta_block_frame_188@12"
            ]
        },
        {
            "x": 6,
            "y": 0,
            "z": 7,
            "elements": [
                "gregtech:metal_casing@6"
            ]
        },
        {
            "x": 7,
            "y": 0,
            "z": 7,
            "elements": [
                "gregtech:metal_casing@6"
            ]
        },
        {
            "x": 8,
            "y": 0,
            "z": 7,
            "elements": [
                "gregtech:metal_casing@6"
            ]
        },
        {
            "x": 9,
            "y": 0,
            "z": 7,
            "elements": [
                "gregtech:metal_casing@6"
            ]
        },
        {
            "x": 10,
            "y": 0,
            "z": 7,
            "elements": [
                "gregtech:metal_casing@6"
            ]
        },
        {
            "x": -9,
            "y": 9,
            "z": 11,
            "elements": [
                "gregtech:meta_block_frame_188@12"
            ]
        },
        {
            "x": 0,
            "y": 13,
            "z": 13,
            "elements": [
                "gregtech:metal_casing@6"
            ]
        },
        {
            "x": 0,
            "y": 44,
            "z": 12,
            "elements": [
                "gregtech:metal_casing@6"
            ]
        },
        {
            "x": -2,
            "y": 9,
            "z": 11,
            "elements": [
                "gregtech:metal_casing@6"
            ]
        },
        {
            "x": -1,
            "y": 9,
            "z": 11,
            "elements": [
                "gregtech:boiler_casing@2"
            ]
        },
        {
            "x": 0,
            "y": 9,
            "z": 11,
            "elements": [
                "gregtech:boiler_casing@2"
            ]
        },
        {
            "x": 0,
            "y": 40,
            "z": 10,
            "elements": [
                "gregtech:metal_casing@6"
            ]
        },
        {
            "x": 1,
            "y": 9,
            "z": 11,
            "elements": [
                "gregtech:boiler_casing@2"
            ]
        },
        {
            "x": 2,
            "y": 9,
            "z": 11,
            "elements": [
                "gregtech:metal_casing@6"
            ]
        },
        {
            "x": 0,
            "y": 5,
            "z": 9,
            "elements": [
                "gregtech:metal_casing@6"
            ]
        },
        {
            "x": 9,
            "y": 9,
            "z": 11,
            "elements": [
                "gregtech:meta_block_frame_188@12"
            ]
        },
        {
            "x": -9,
            "y": 10,
            "z": 11,
            "elements": [
                "gregtech:meta_block_frame_188@12"
            ]
        },
        {
            "x": 0,
            "y": 14,
            "z": 13,
            "elements": [
                "gregtech:metal_casing@6"
            ]
        },
        {
            "x": 0,
            "y": 45,
            "z": 12,
            "elements": [
                "gregtech:metal_casing@6"
            ]
        },
        {
            "x": -2,
            "y": 10,
            "z": 11,
            "elements": [
                "gregtech:metal_casing@6"
            ]
        },
        {
            "x": -1,
            "y": 10,
            "z": 11,
            "elements": [
                "gregtech:boiler_casing@2"
            ]
        },
        {
            "x": 0,
            "y": 10,
            "z": 11,
            "elements": [
                "gregtech:boiler_casing@2"
            ]
        },
        {
            "x": 0,
            "y": 41,
            "z": 10,
            "elements": [
                "gregtech:metal_casing@6"
            ]
        },
        {
            "x": 1,
            "y": 10,
            "z": 11,
            "elements": [
                "gregtech:boiler_casing@2"
            ]
        },
        {
            "x": 2,
            "y": 10,
            "z": 11,
            "elements": [
                "gregtech:metal_casing@6"
            ]
        },
        {
            "x": 0,
            "y": 6,
            "z": 9,
            "elements": [
                "gregtech:metal_casing@6"
            ]
        },
        {
            "x": 9,
            "y": 10,
            "z": 11,
            "elements": [
                "gregtech:meta_block_frame_188@12"
            ]
        },
        {
            "x": -3,
            "y": 0,
            "z": 22,
            "elements": [
                "gregtech:metal_casing@6"
            ]
        },
        {
            "x": -2,
            "y": 0,
            "z": 22,
            "elements": [
                "modularmachinery:blockenergyinputhatch"
            ]
        },
        {
            "x": -1,
            "y": 0,
            "z": 22,
            "elements": [
                "modularmachinery:blockenergyinputhatch"
            ]
        },
        {
            "x": 0,
            "y": 0,
            "z": 22,
            "elements": [
                "modularmachinery:blockenergyinputhatch"
            ]
        },
        {
            "x": -9,
            "y": 11,
            "z": 11,
            "elements": [
                "gregtech:meta_block_frame_188@12"
            ]
        },
        {
            "x": 1,
            "y": 0,
            "z": 22,
            "elements": [
                "modularmachinery:blockenergyinputhatch"
            ]
        },
        {
            "x": 2,
            "y": 0,
            "z": 22,
            "elements": [
                "modularmachinery:blockenergyinputhatch"
            ]
        },
        {
            "x": 3,
            "y": 0,
            "z": 22,
            "elements": [
                "gregtech:metal_casing@6"
            ]
        },
        {
            "x": 0,
            "y": 50,
            "z": 14,
            "elements": [
                "gregtech:meta_block_frame_188@12"
            ]
        },
        {
            "x": 0,
            "y": 15,
            "z": 13,
            "elements": [
                "gregtech:metal_casing@6"
            ]
        },
        {
            "x": 0,
            "y": 46,
            "z": 12,
            "elements": [
                "gregtech:metal_casing@6"
            ]
        },
        {
            "x": -2,
            "y": 11,
            "z": 11,
            "elements": [
                "gregtech:metal_casing@6"
            ]
        },
        {
            "x": -1,
            "y": 11,
            "z": 11,
            "elements": [
                "gregtech:boiler_casing@2"
            ]
        },
        {
            "x": 0,
            "y": 11,
            "z": 11,
            "elements": [
                "gregtech:boiler_casing@2"
            ]
        },
        {
            "x": 0,
            "y": 42,
            "z": 10,
            "elements": [
                "gregtech:metal_casing@6"
            ]
        },
        {
            "x": 1,
            "y": 11,
            "z": 11,
            "elements": [
                "gregtech:boiler_casing@2"
            ]
        },
        {
            "x": 2,
            "y": 11,
            "z": 11,
            "elements": [
                "gregtech:metal_casing@6"
            ]
        },
        {
            "x": 0,
            "y": 7,
            "z": 9,
            "elements": [
                "gregtech:metal_casing@6"
            ]
        },
        {
            "x": 9,
            "y": 11,
            "z": 11,
            "elements": [
                "gregtech:meta_block_frame_188@12"
            ]
        },
        {
            "x": 0,
            "y": 1,
            "z": 22,
            "elements": [
                "gregtech:meta_block_frame_188@12"
            ]
        },
        {
            "x": -9,
            "y": 12,
            "z": 11,
            "elements": [
                "gregtech:meta_block_frame_188@12"
            ]
        },
        {
            "x": 0,
            "y": 51,
            "z": 14,
            "elements": [
                "gregtech:meta_block_frame_188@12"
            ]
        },
        {
            "x": -9,
            "y": 0,
            "z": 5,
            "elements": [
                "gregtech:metal_casing@6"
            ]
        },
        {
            "x": 0,
            "y": 16,
            "z": 13,
            "elements": [
                "gregtech:metal_casing@6"
            ]
        },
        {
            "x": 0,
            "y": 47,
            "z": 12,
            "elements": [
                "gregtech:metal_casing@6"
            ]
        },
        {
            "x": -8,
            "y": 0,
            "z": 5,
            "elements": [
                "gregtech:metal_casing@6"
            ]
        },
        {
            "x": -2,
            "y": 12,
            "z": 11,
            "elements": [
                "gregtech:metal_casing@6"
            ]
        },
        {
            "x": -7,
            "y": 0,
            "z": 5,
            "elements": [
                "gregtech:metal_casing@6"
            ]
        },
        {
            "x": -1,
            "y": 12,
            "z": 11,
            "elements": [
                "gregtech:boiler_casing@2"
            ]
        },
        {
            "x": 0,
            "y": 12,
            "z": 11,
            "elements": [
                "gregtech:boiler_casing@2"
            ]
        },
        {
            "x": 0,
            "y": 43,
            "z": 10,
            "elements": [
                "gregtech:metal_casing@6"
            ]
        },
        {
            "x": -6,
            "y": 0,
            "z": 5,
            "elements": [
                "gregtech:metal_casing@6"
            ]
        },
        {
            "x": -5,
            "y": 0,
            "z": 5,
            "elements": [
                "gregtech:metal_casing@6"
            ]
        },
        {
            "x": 1,
            "y": 12,
            "z": 11,
            "elements": [
                "gregtech:boiler_casing@2"
            ]
        },
        {
            "x": 2,
            "y": 12,
            "z": 11,
            "elements": [
                "gregtech:metal_casing@6"
            ]
        },
        {
            "x": 0,
            "y": 8,
            "z": 9,
            "elements": [
                "gregtech:metal_casing@6"
            ]
        },
        {
            "x": -4,
            "y": 0,
            "z": 5,
            "elements": [
                "gregtech:metal_casing@6"
            ]
        },
        {
            "x": -3,
            "y": 0,
            "z": 5,
            "elements": [
                "gregtech:metal_casing@6"
            ]
        },
        {
            "x": 0,
            "y": 35,
            "z": 6,
            "elements": [
                "gregtech:meta_block_frame_188@12"
            ]
        },
        {
            "x": -2,
            "y": 0,
            "z": 5,
            "elements": [
                "gregtech:metal_casing@6"
            ]
        },
        {
            "x": -1,
            "y": 0,
            "z": 5,
            "elements": [
                "gregtech:metal_casing@6"
            ]
        },
        {
            "x": 0,
            "y": 0,
            "z": 5,
            "elements": [
                "gregtech:metal_casing@6"
            ]
        },
        {
            "x": 1,
            "y": 0,
            "z": 5,
            "elements": [
                "gregtech:metal_casing@6"
            ]
        },
        {
            "x": 2,
            "y": 0,
            "z": 5,
            "elements": [
                "gregtech:metal_casing@6"
            ]
        },
        {
            "x": 9,
            "y": 12,
            "z": 11,
            "elements": [
                "gregtech:meta_block_frame_188@12"
            ]
        },
        {
            "x": 3,
            "y": 0,
            "z": 5,
            "elements": [
                "gregtech:metal_casing@6"
            ]
        },
        {
            "x": 4,
            "y": 0,
            "z": 5,
            "elements": [
                "gregtech:metal_casing@6"
            ]
        },
        {
            "x": 5,
            "y": 0,
            "z": 5,
            "elements": [
                "gregtech:metal_casing@6"
            ]
        },
        {
            "x": 6,
            "y": 0,
            "z": 5,
            "elements": [
                "gregtech:metal_casing@6"
            ]
        },
        {
            "x": 7,
            "y": 0,
            "z": 5,
            "elements": [
                "gregtech:metal_casing@6"
            ]
        },
        {
            "x": 8,
            "y": 0,
            "z": 5,
            "elements": [
                "gregtech:metal_casing@6"
            ]
        },
        {
            "x": 9,
            "y": 0,
            "z": 5,
            "elements": [
                "gregtech:metal_casing@6"
            ]
        },
        {
            "x": 0,
            "y": 2,
            "z": 22,
            "elements": [
                "gregtech:meta_block_frame_188@12"
            ]
        },
        {
            "x": -9,
            "y": 13,
            "z": 11,
            "elements": [
                "gregtech:meta_block_frame_188@12"
            ]
        },
        {
            "x": 0,
            "y": 52,
            "z": 14,
            "elements": [
                "gregtech:meta_block_frame_188@12"
            ]
        },
        {
            "x": 0,
            "y": 17,
            "z": 13,
            "elements": [
                "gregtech:metal_casing@6"
            ]
        },
        {
            "x": 0,
            "y": 48,
            "z": 12,
            "elements": [
                "gregtech:metal_casing@6"
            ]
        },
        {
            "x": -2,
            "y": 13,
            "z": 11,
            "elements": [
                "gregtech:metal_casing@6"
            ]
        },
        {
            "x": -1,
            "y": 13,
            "z": 11,
            "elements": [
                "gregtech:boiler_casing@2"
            ]
        },
        {
            "x": 0,
            "y": 13,
            "z": 11,
            "elements": [
                "gregtech:boiler_casing@2"
            ]
        },
        {
            "x": 0,
            "y": 44,
            "z": 10,
            "elements": [
                "gregtech:metal_casing@6"
            ]
        },
        {
            "x": 1,
            "y": 13,
            "z": 11,
            "elements": [
                "gregtech:boiler_casing@2"
            ]
        },
        {
            "x": 2,
            "y": 13,
            "z": 11,
            "elements": [
                "gregtech:metal_casing@6"
            ]
        },
        {
            "x": 0,
            "y": 9,
            "z": 9,
            "elements": [
                "gregtech:metal_casing@6"
            ]
        },
        {
            "x": 0,
            "y": 36,
            "z": 6,
            "elements": [
                "gregtech:meta_block_frame_188@12"
            ]
        },
        {
            "x": 9,
            "y": 13,
            "z": 11,
            "elements": [
                "gregtech:meta_block_frame_188@12"
            ]
        },
        {
            "x": 0,
            "y": 3,
            "z": 22,
            "elements": [
                "gregtech:meta_block_frame_188@12"
            ]
        },
        {
            "x": -9,
            "y": 14,
            "z": 11,
            "elements": [
                "gregtech:meta_block_frame_188@12"
            ]
        },
        {
            "x": 0,
            "y": 53,
            "z": 14,
            "elements": [
                "gregtech:meta_block_frame_188@12"
            ]
        },
        {
            "x": 0,
            "y": 18,
            "z": 13,
            "elements": [
                "gregtech:metal_casing@6"
            ]
        },
        {
            "x": -2,
            "y": 14,
            "z": 11,
            "elements": [
                "gregtech:metal_casing@6"
            ]
        },
        {
            "x": 0,
            "y": 49,
            "z": 12,
            "elements": [
                "gregtech:metal_casing@6"
            ]
        },
        {
            "x": -1,
            "y": 14,
            "z": 11,
            "elements": [
                "gregtech:boiler_casing@2"
            ]
        },
        {
            "x": 0,
            "y": 14,
            "z": 11,
            "elements": [
                "gregtech:boiler_casing@2"
            ]
        },
        {
            "x": 0,
            "y": 45,
            "z": 10,
            "elements": [
                "gregtech:metal_casing@6"
            ]
        },
        {
            "x": 1,
            "y": 14,
            "z": 11,
            "elements": [
                "gregtech:boiler_casing@2"
            ]
        },
        {
            "x": 2,
            "y": 14,
            "z": 11,
            "elements": [
                "gregtech:metal_casing@6"
            ]
        },
        {
            "x": 0,
            "y": 10,
            "z": 9,
            "elements": [
                "gregtech:metal_casing@6"
            ]
        },
        {
            "x": 0,
            "y": 37,
            "z": 6,
            "elements": [
                "gregtech:meta_block_frame_188@12"
            ]
        },
        {
            "x": 9,
            "y": 14,
            "z": 11,
            "elements": [
                "gregtech:meta_block_frame_188@12"
            ]
        },
        {
            "x": -6,
            "y": 0,
            "z": 20,
            "elements": [
                "gregtech:metal_casing@6"
            ]
        },
        {
            "x": -5,
            "y": 0,
            "z": 20,
            "elements": [
                "gregtech:metal_casing@6"
            ]
        },
        {
            "x": -4,
            "y": 0,
            "z": 20,
            "elements": [
                "gregtech:metal_casing@6"
            ]
        },
        {
            "x": -3,
            "y": 0,
            "z": 20,
            "elements": [
                "gregtech:metal_casing@6"
            ]
        },
        {
            "x": 0,
            "y": 4,
            "z": 22,
            "elements": [
                "gregtech:meta_block_frame_188@12"
            ]
        },
        {
            "x": -2,
            "y": 0,
            "z": 20,
            "elements": [
                "gregtech:metal_casing@6"
            ]
        },
        {
            "x": -1,
            "y": 0,
            "z": 20,
            "elements": [
                "gregtech:metal_casing@6"
            ]
        },
        {
            "x": 0,
            "y": 0,
            "z": 20,
            "elements": [
                "gregtech:metal_casing@6"
            ]
        },
        {
            "x": -8,
            "y": 15,
            "z": 11,
            "elements": [
                "gregtech:meta_block_frame_188@12"
            ]
        },
        {
            "x": 1,
            "y": 0,
            "z": 20,
            "elements": [
                "gregtech:metal_casing@6"
            ]
        },
        {
            "x": 2,
            "y": 0,
            "z": 20,
            "elements": [
                "gregtech:metal_casing@6"
            ]
        },
        {
            "x": 3,
            "y": 0,
            "z": 20,
            "elements": [
                "gregtech:metal_casing@6"
            ]
        },
        {
            "x": 0,
            "y": 54,
            "z": 14,
            "elements": [
                "gregtech:meta_block_frame_188@12"
            ]
        },
        {
            "x": 4,
            "y": 0,
            "z": 20,
            "elements": [
                "gregtech:metal_casing@6"
            ]
        },
        {
            "x": 5,
            "y": 0,
            "z": 20,
            "elements": [
                "gregtech:metal_casing@6"
            ]
        },
        {
            "x": 0,
            "y": 19,
            "z": 13,
            "elements": [
                "gregtech:metal_casing@6"
            ]
        },
        {
            "x": -2,
            "y": 15,
            "z": 11,
            "elements": [
                "gregtech:metal_casing@6"
            ]
        },
        {
            "x": 0,
            "y": 50,
            "z": 12,
            "elements": [
                "gregtech:metal_casing@6"
            ]
        },
        {
            "x": 6,
            "y": 0,
            "z": 20,
            "elements": [
                "gregtech:metal_casing@6"
            ]
        },
        {
            "x": -1,
            "y": 15,
            "z": 11,
            "elements": [
                "gregtech:boiler_casing@2"
            ]
        },
        {
            "x": 0,
            "y": 15,
            "z": 11,
            "elements": [
                "gregtech:boiler_casing@2"
            ]
        },
        {
            "x": 0,
            "y": 46,
            "z": 10,
            "elements": [
                "gregtech:metal_casing@6"
            ]
        },
        {
            "x": 1,
            "y": 15,
            "z": 11,
            "elements": [
                "gregtech:boiler_casing@2"
            ]
        },
        {
            "x": 2,
            "y": 15,
            "z": 11,
            "elements": [
                "gregtech:metal_casing@6"
            ]
        },
        {
            "x": 0,
            "y": 11,
            "z": 9,
            "elements": [
                "gregtech:metal_casing@6"
            ]
        },
        {
            "x": 0,
            "y": 38,
            "z": 6,
            "elements": [
                "gregtech:meta_block_frame_188@12"
            ]
        },
        {
            "x": 8,
            "y": 15,
            "z": 11,
            "elements": [
                "gregtech:meta_block_frame_188@12"
            ]
        },
        {
            "x": 0,
            "y": 5,
            "z": 22,
            "elements": [
                "gregtech:meta_block_frame_188@12"
            ]
        },
        {
            "x": -8,
            "y": 16,
            "z": 11,
            "elements": [
                "gregtech:meta_block_frame_188@12"
            ]
        },
        {
            "x": 0,
            "y": 28,
            "z": 17,
            "elements": [
                "gregtech:meta_block_frame_188@12"
            ]
        },
        {
            "x": 0,
            "y": 20,
            "z": 13,
            "elements": [
                "gregtech:metal_casing@6"
            ]
        },
        {
            "x": -2,
            "y": 16,
            "z": 11,
            "elements": [
                "gregtech:metal_casing@6"
            ]
        },
        {
            "x": 0,
            "y": 51,
            "z": 12,
            "elements": [
                "gregtech:metal_casing@6"
            ]
        },
        {
            "x": -1,
            "y": 16,
            "z": 11,
            "elements": [
                "gregtech:boiler_casing@2"
            ]
        },
        {
            "x": 0,
            "y": 16,
            "z": 11,
            "elements": [
                "gregtech:boiler_casing@2"
            ]
        },
        {
            "x": 0,
            "y": 47,
            "z": 10,
            "elements": [
                "gregtech:metal_casing@6"
            ]
        },
        {
            "x": -8,
            "y": 0,
            "z": 3,
            "elements": [
                "gregtech:metal_casing@6"
            ]
        },
        {
            "x": -7,
            "y": 0,
            "z": 3,
            "elements": [
                "gregtech:metal_casing@6"
            ]
        },
        {
            "x": 1,
            "y": 16,
            "z": 11,
            "elements": [
                "gregtech:boiler_casing@2"
            ]
        },
        {
            "x": 2,
            "y": 16,
            "z": 11,
            "elements": [
                "gregtech:metal_casing@6"
            ]
        },
        {
            "x": 0,
            "y": 12,
            "z": 9,
            "elements": [
                "gregtech:metal_casing@6"
            ]
        },
        {
            "x": -6,
            "y": 0,
            "z": 3,
            "elements": [
                "gregtech:metal_casing@6"
            ]
        },
        {
            "x": -5,
            "y": 0,
            "z": 3,
            "elements": [
                "gregtech:metal_casing@6"
            ]
        },
        {
            "x": 0,
            "y": 39,
            "z": 6,
            "elements": [
                "gregtech:meta_block_frame_188@12"
            ]
        },
        {
            "x": -4,
            "y": 0,
            "z": 3,
            "elements": [
                "gregtech:metal_casing@6"
            ]
        },
        {
            "x": -3,
            "y": 0,
            "z": 3,
            "elements": [
                "gregtech:metal_casing@6"
            ]
        },
        {
            "x": -2,
            "y": 0,
            "z": 3,
            "elements": [
                "gregtech:metal_casing@6"
            ]
        },
        {
            "x": -1,
            "y": 0,
            "z": 3,
            "elements": [
                "gregtech:metal_casing@6"
            ]
        },
        {
            "x": 0,
            "y": 0,
            "z": 3,
            "elements": [
                "gregtech:metal_casing@6"
            ]
        },
        {
            "x": 8,
            "y": 16,
            "z": 11,
            "elements": [
                "gregtech:meta_block_frame_188@12"
            ]
        },
        {
            "x": 1,
            "y": 0,
            "z": 3,
            "elements": [
                "gregtech:metal_casing@6"
            ]
        },
        {
            "x": 2,
            "y": 0,
            "z": 3,
            "elements": [
                "gregtech:metal_casing@6"
            ]
        },
        {
            "x": 3,
            "y": 0,
            "z": 3,
            "elements": [
                "gregtech:metal_casing@6"
            ]
        },
        {
            "x": 4,
            "y": 0,
            "z": 3,
            "elements": [
                "gregtech:metal_casing@6"
            ]
        },
        {
            "x": 5,
            "y": 0,
            "z": 3,
            "elements": [
                "gregtech:metal_casing@6"
            ]
        },
        {
            "x": 6,
            "y": 0,
            "z": 3,
            "elements": [
                "gregtech:metal_casing@6"
            ]
        },
        {
            "x": 7,
            "y": 0,
            "z": 3,
            "elements": [
                "gregtech:metal_casing@6"
            ]
        },
        {
            "x": 8,
            "y": 0,
            "z": 3,
            "elements": [
                "gregtech:metal_casing@6"
            ]
        },
        {
            "x": -8,
            "y": 17,
            "z": 11,
            "elements": [
                "gregtech:meta_block_frame_188@12"
            ]
        },
        {
            "x": 0,
            "y": 29,
            "z": 17,
            "elements": [
                "gregtech:meta_block_frame_188@12"
            ]
        },
        {
            "x": 0,
            "y": 21,
            "z": 13,
            "elements": [
                "gregtech:metal_casing@6"
            ]
        },
        {
            "x": -2,
            "y": 17,
            "z": 11,
            "elements": [
                "gregtech:metal_casing@6"
            ]
        },
        {
            "x": 0,
            "y": 52,
            "z": 12,
            "elements": [
                "gregtech:metal_casing@6"
            ]
        },
        {
            "x": -1,
            "y": 17,
            "z": 11,
            "elements": [
                "gregtech:boiler_casing@2"
            ]
        },
        {
            "x": 0,
            "y": 17,
            "z": 11,
            "elements": [
                "gregtech:boiler_casing@2"
            ]
        },
        {
            "x": 0,
            "y": 48,
            "z": 10,
            "elements": [
                "gregtech:metal_casing@6"
            ]
        },
        {
            "x": 1,
            "y": 17,
            "z": 11,
            "elements": [
                "gregtech:boiler_casing@2"
            ]
        },
        {
            "x": 2,
            "y": 17,
            "z": 11,
            "elements": [
                "gregtech:metal_casing@6"
            ]
        },
        {
            "x": 0,
            "y": 13,
            "z": 9,
            "elements": [
                "gregtech:metal_casing@6"
            ]
        },
        {
            "x": 0,
            "y": 40,
            "z": 6,
            "elements": [
                "gregtech:meta_block_frame_188@12"
            ]
        },
        {
            "x": 8,
            "y": 17,
            "z": 11,
            "elements": [
                "gregtech:meta_block_frame_188@12"
            ]
        },
        {
            "x": -7,
            "y": 18,
            "z": 11,
            "elements": [
                "gregtech:meta_block_frame_188@12"
            ]
        },
        {
            "x": 0,
            "y": 30,
            "z": 17,
            "elements": [
                "gregtech:meta_block_frame_188@12"
            ]
        },
        {
            "x": 0,
            "y": 22,
            "z": 13,
            "elements": [
                "gregtech:metal_casing@6"
            ]
        },
        {
            "x": -2,
            "y": 18,
            "z": 11,
            "elements": [
                "gregtech:metal_casing@6"
            ]
        },
        {
            "x": 0,
            "y": 53,
            "z": 12,
            "elements": [
                "gregtech:metal_casing@6"
            ]
        },
        {
            "x": -1,
            "y": 18,
            "z": 11,
            "elements": [
                "gregtech:boiler_casing@2"
            ]
        },
        {
            "x": 0,
            "y": 18,
            "z": 11,
            "elements": [
                "gregtech:boiler_casing@2"
            ]
        },
        {
            "x": 0,
            "y": 49,
            "z": 10,
            "elements": [
                "gregtech:metal_casing@6"
            ]
        },
        {
            "x": 1,
            "y": 18,
            "z": 11,
            "elements": [
                "gregtech:boiler_casing@2"
            ]
        },
        {
            "x": 2,
            "y": 18,
            "z": 11,
            "elements": [
                "gregtech:metal_casing@6"
            ]
        },
        {
            "x": 0,
            "y": 14,
            "z": 9,
            "elements": [
                "gregtech:metal_casing@6"
            ]
        },
        {
            "x": 7,
            "y": 18,
            "z": 11,
            "elements": [
                "gregtech:meta_block_frame_188@12"
            ]
        },
        {
            "x": -8,
            "y": 0,
            "z": 18,
            "elements": [
                "gregtech:metal_casing@6"
            ]
        },
        {
            "x": -7,
            "y": 0,
            "z": 18,
            "elements": [
                "gregtech:metal_casing@6"
            ]
        },
        {
            "x": -6,
            "y": 0,
            "z": 18,
            "elements": [
                "gregtech:metal_casing@6"
            ]
        },
        {
            "x": -5,
            "y": 0,
            "z": 18,
            "elements": [
                "gregtech:metal_casing@6"
            ]
        },
        {
            "x": -4,
            "y": 0,
            "z": 18,
            "elements": [
                "gregtech:metal_casing@6"
            ]
        },
        {
            "x": -3,
            "y": 0,
            "z": 18,
            "elements": [
                "gregtech:metal_casing@6"
            ]
        },
        {
            "x": -2,
            "y": 0,
            "z": 18,
            "elements": [
                "gregtech:metal_casing@6"
            ]
        },
        {
            "x": -7,
            "y": 19,
            "z": 11,
            "elements": [
                "gregtech:meta_block_frame_188@12"
            ]
        },
        {
            "x": -1,
            "y": 0,
            "z": 18,
            "elements": [
                "gregtech:metal_casing@6"
            ]
        },
        {
            "x": 0,
            "y": 0,
            "z": 18,
            "elements": [
                "gregtech:metal_casing@6"
            ]
        },
        {
            "x": 0,
            "y": 31,
            "z": 17,
            "elements": [
                "gregtech:meta_block_frame_188@12"
            ]
        },
        {
            "x": 1,
            "y": 0,
            "z": 18,
            "elements": [
                "gregtech:metal_casing@6"
            ]
        },
        {
            "x": 2,
            "y": 0,
            "z": 18,
            "elements": [
                "gregtech:metal_casing@6"
            ]
        },
        {
            "x": 3,
            "y": 0,
            "z": 18,
            "elements": [
                "gregtech:metal_casing@6"
            ]
        },
        {
            "x": 0,
            "y": 23,
            "z": 13,
            "elements": [
                "gregtech:metal_casing@6"
            ]
        },
        {
            "x": -2,
            "y": 19,
            "z": 11,
            "elements": [
                "gregtech:metal_casing@6"
            ]
        },
        {
            "x": 0,
            "y": 54,
            "z": 12,
            "elements": [
                "gregtech:metal_casing@6"
            ]
        },
        {
            "x": 4,
            "y": 0,
            "z": 18,
            "elements": [
                "gregtech:metal_casing@6"
            ]
        },
        {
            "x": -1,
            "y": 19,
            "z": 11,
            "elements": [
                "gregtech:boiler_casing@2"
            ]
        },
        {
            "x": 5,
            "y": 0,
            "z": 18,
            "elements": [
                "gregtech:metal_casing@6"
            ]
        },
        {
            "x": 0,
            "y": 19,
            "z": 11,
            "elements": [
                "gregtech:boiler_casing@2"
            ]
        },
        {
            "x": 0,
            "y": 50,
            "z": 10,
            "elements": [
                "gregtech:metal_casing@6"
            ]
        },
        {
            "x": 6,
            "y": 0,
            "z": 18,
            "elements": [
                "gregtech:metal_casing@6"
            ]
        },
        {
            "x": 7,
            "y": 0,
            "z": 18,
            "elements": [
                "gregtech:metal_casing@6"
            ]
        },
        {
            "x": 1,
            "y": 19,
            "z": 11,
            "elements": [
                "gregtech:boiler_casing@2"
            ]
        },
        {
            "x": 2,
            "y": 19,
            "z": 11,
            "elements": [
                "gregtech:metal_casing@6"
            ]
        },
        {
            "x": 0,
            "y": 15,
            "z": 9,
            "elements": [
                "gregtech:metal_casing@6"
            ]
        },
        {
            "x": 8,
            "y": 0,
            "z": 18,
            "elements": [
                "gregtech:metal_casing@6"
            ]
        },
        {
            "x": 7,
            "y": 19,
            "z": 11,
            "elements": [
                "gregtech:meta_block_frame_188@12"
            ]
        },
        {
            "x": -7,
            "y": 20,
            "z": 11,
            "elements": [
                "gregtech:meta_block_frame_188@12"
            ]
        },
        {
            "x": 0,
            "y": 32,
            "z": 17,
            "elements": [
                "gregtech:meta_block_frame_188@12"
            ]
        },
        {
            "x": 0,
            "y": 24,
            "z": 13,
            "elements": [
                "gregtech:metal_casing@6"
            ]
        },
        {
            "x": -2,
            "y": 20,
            "z": 11,
            "elements": [
                "gregtech:metal_casing@6"
            ]
        },
        {
            "x": 0,
            "y": 55,
            "z": 12,
            "elements": [
                "gregtech:metal_casing@6"
            ]
        },
        {
            "x": -1,
            "y": 20,
            "z": 11,
            "elements": [
                "gregtech:boiler_casing@2"
            ]
        },
        {
            "x": 0,
            "y": 20,
            "z": 11,
            "elements": [
                "gregtech:boiler_casing@2"
            ]
        },
        {
            "x": 0,
            "y": 51,
            "z": 10,
            "elements": [
                "gregtech:metal_casing@6"
            ]
        },
        {
            "x": 1,
            "y": 20,
            "z": 11,
            "elements": [
                "gregtech:boiler_casing@2"
            ]
        },
        {
            "x": 2,
            "y": 20,
            "z": 11,
            "elements": [
                "gregtech:metal_casing@6"
            ]
        },
        {
            "x": 0,
            "y": 16,
            "z": 9,
            "elements": [
                "gregtech:metal_casing@6"
            ]
        },
        {
            "x": -5,
            "y": 0,
            "z": 1,
            "elements": [
                "gregtech:metal_casing@6"
            ]
        },
        {
            "x": -4,
            "y": 0,
            "z": 1,
            "elements": [
                "gregtech:metal_casing@6"
            ]
        },
        {
            "x": -3,
            "y": 0,
            "z": 1,
            "elements": [
                "gregtech:metal_casing@6"
            ]
        },
        {
            "x": 7,
            "y": 20,
            "z": 11,
            "elements": [
                "gregtech:meta_block_frame_188@12"
            ]
        },
        {
            "x": -2,
            "y": 0,
            "z": 1,
            "elements": [
                "gregtech:metal_casing@6"
            ]
        },
        {
            "x": -1,
            "y": 0,
            "z": 1,
            "elements": [
                "gregtech:metal_casing@6"
            ]
        },
        {
            "x": 0,
            "y": 0,
            "z": 1,
            "elements": [
                "gregtech:metal_casing@6"
            ]
        },
        {
            "x": 1,
            "y": 0,
            "z": 1,
            "elements": [
                "gregtech:metal_casing@6"
            ]
        },
        {
            "x": 2,
            "y": 0,
            "z": 1,
            "elements": [
                "gregtech:metal_casing@6"
            ]
        },
        {
            "x": 3,
            "y": 0,
            "z": 1,
            "elements": [
                "gregtech:metal_casing@6"
            ]
        },
        {
            "x": 4,
            "y": 0,
            "z": 1,
            "elements": [
                "gregtech:metal_casing@6"
            ]
        },
        {
            "x": 5,
            "y": 0,
            "z": 1,
            "elements": [
                "gregtech:metal_casing@6"
            ]
        },
        {
            "x": -7,
            "y": 21,
            "z": 11,
            "elements": [
                "gregtech:meta_block_frame_188@12"
            ]
        },
        {
            "x": 0,
            "y": 33,
            "z": 17,
            "elements": [
                "gregtech:meta_block_frame_188@12"
            ]
        },
        {
            "x": 0,
            "y": 25,
            "z": 13,
            "elements": [
                "gregtech:metal_casing@6"
            ]
        },
        {
            "x": -2,
            "y": 21,
            "z": 11,
            "elements": [
                "gregtech:metal_casing@6"
            ]
        },
        {
            "x": 0,
            "y": 56,
            "z": 12,
            "elements": [
