{
    "registryname": "Large_Fusion_Reactor_Mk2",
    "localizedname": "Large Fusion Reactor Mk.2",
     "color": "ff0400",
    "parts": [
        {
            "x": -2,
            "y": -3,
            "z": -34,
            "elements": [
                "gregtech:fusion_casing@3"
            ]
        },
        {
            "x": -1,
            "y": 0,
            "z": 0,
            "elements": [
                "gregtech:fusion_casing@3"
            ]
        },
        {
            "x": -17,
            "y": -1,
            "z": -17,
            "elements": [
                "gregtech:wire_coil@6"
            ]
        },
        {
            "x": -3,
            "y": -3,
            "z": -34,
            "elements": [
                "gregtech:meta_block_frame_2@1"
            ]
        },
        {
            "x": -2,
            "y": 0,
            "z": 0,
            "elements": [
                "modularmachinery:blockfluidinputhatch@7"
            ]
        },
        {
            "x": 1,
            "y": 0,
            "z": 0,
            "elements": [
                "gregtech:fusion_casing@3"
            ]
        },
        {
            "x": -18,
            "y": -1,
            "z": -17,
            "elements": [
                "gregtech:boiler_casing@3"
            ]
        },
        {
            "x": 2,
            "y": 0,
            "z": 0,
            "elements": [
                "modularmachinery:blockfluidinputhatch@7"
            ]
        },
        {
            "x": -3,
            "y": 0,
            "z": 0,
            "elements": [
                "gregtech:meta_block_frame_2@1"
            ]
        },
        {
            "x": -19,
            "y": -1,
            "z": -17,
            "elements": [
                "gregtech:wire_coil@6"
            ]
        },
        {
            "x": 3,
            "y": 0,
            "z": 0,
            "elements": [
                "gregtech:meta_block_frame_2@1"
            ]
        },
        {
            "x": -20,
            "y": -1,
            "z": -17,
            "elements": [
                "gregtech:meta_block_frame_127@10"
            ]
        },
        {
            "x": -21,
            "y": -1,
            "z": -17,
            "elements": [
                "modularmachinery:blockfluidoutputhatch@7"
            ]
        },
        {
            "x": -5,
            "y": 0,
            "z": 0,
            "elements": [
                "gregtech:fusion_casing@3"
            ]
        },
        {
            "x": 5,
            "y": 0,
            "z": 0,
            "elements": [
                "gregtech:fusion_casing@3"
            ]
        },
        {
            "x": -6,
            "y": 0,
            "z": 0,
            "elements": [
                "gregtech:fusion_casing@3"
            ]
        },
        {
            "x": 6,
            "y": 0,
            "z": 0,
            "elements": [
                "gregtech:fusion_casing@3"
            ]
        },
        {
            "x": -10,
            "y": 0,
            "z": 0,
            "elements": [
                "gregtech:fusion_casing@1"
            ]
        },
        {
            "x": 10,
            "y": 0,
            "z": 0,
            "elements": [
                "gregtech:fusion_casing@1"
            ]
        },
        {
            "x": -13,
            "y": 0,
            "z": 0,
            "elements": [
                "gregtech:fusion_casing@3"
            ]
        },
        {
            "x": 13,
            "y": 0,
            "z": 0,
            "elements": [
                "gregtech:fusion_casing@3"
            ]
        },
        {
            "x": 13,
            "y": -1,
            "z": 0,
            "elements": [
                "gregtech:fusion_casing@3"
            ]
        },
        {
            "x": -13,
            "y": 1,
            "z": 0,
            "elements": [
                "gregtech:fusion_casing@3"
            ]
        },
        {
            "x": 6,
            "y": -1,
            "z": 0,
            "elements": [
                "gregtech:fusion_casing@3"
            ]
        },
        {
            "x": 5,
            "y": -1,
            "z": 0,
            "elements": [
                "gregtech:fusion_casing@3"
            ]
        },
        {
            "x": -6,
            "y": 1,
            "z": 0,
            "elements": [
                "gregtech:fusion_casing@3"
            ]
        },
        {
            "x": 19,
            "y": -3,
            "z": -17,
            "elements": [
                "gregtech:fusion_casing@3"
            ]
        },
        {
            "x": -5,
            "y": 1,
            "z": 0,
            "elements": [
                "gregtech:fusion_casing@3"
            ]
        },
        {
            "x": 18,
            "y": -3,
            "z": -17,
            "elements": [
                "gregtech:fusion_casing@3"
            ]
        },
        {
            "x": 3,
            "y": -1,
            "z": 0,
            "elements": [
                "gregtech:meta_block_frame_2@1"
            ]
        },
        {
            "x": 17,
            "y": -3,
            "z": -17,
            "elements": [
                "gregtech:fusion_casing@3"
            ]
        },
        {
            "x": 2,
            "y": -1,
            "z": 0,
            "elements": [
                "modularmachinery:blockfluidinputhatch@7"
            ]
        },
        {
            "x": -3,
            "y": 1,
            "z": 0,
            "elements": [
                "gregtech:meta_block_frame_2@1"
            ]
        },
        {
            "x": 1,
            "y": -1,
            "z": 0,
            "elements": [
                "gregtech:fusion_casing@3"
            ]
        },
        {
            "x": -2,
            "y": 1,
            "z": 0,
            "elements": [
                "modularmachinery:blockfluidinputhatch@7"
            ]
        },
        {
            "x": -16,
            "y": -2,
            "z": -17,
            "elements": [
                "gregtech:fusion_casing@3"
            ]
        },
        {
            "x": 0,
            "y": -1,
            "z": 0,
            "elements": [
                "gregtech:fusion_casing@3"
            ]
        },
        {
            "x": -1,
            "y": 1,
            "z": 0,
            "elements": [
                "gregtech:fusion_casing@3"
            ]
        },
        {
            "x": -1,
            "y": -1,
            "z": 0,
            "elements": [
                "gregtech:fusion_casing@3"
            ]
        },
        {
            "x": 0,
            "y": 1,
            "z": 0,
            "elements": [
                "gregtech:fusion_casing@3"
            ]
        },
        {
            "x": -17,
            "y": -2,
            "z": -17,
            "elements": [
                "gregtech:meta_block_frame_127@10"
            ]
        },
        {
            "x": -2,
            "y": -1,
            "z": 0,
            "elements": [
                "modularmachinery:blockfluidinputhatch@7"
            ]
        },
        {
            "x": 1,
            "y": 1,
            "z": 0,
            "elements": [
                "gregtech:fusion_casing@3"
            ]
        },
        {
            "x": 2,
            "y": 1,
            "z": 0,
            "elements": [
                "modularmachinery:blockfluidinputhatch@7"
            ]
        },
        {
            "x": -3,
            "y": -1,
            "z": 0,
            "elements": [
                "gregtech:meta_block_frame_2@1"
            ]
        },
        {
            "x": -19,
            "y": -2,
            "z": -17,
            "elements": [
                "gregtech:meta_block_frame_127@10"
            ]
        },
        {
            "x": -20,
            "y": -2,
            "z": -17,
            "elements": [
                "gregtech:fusion_casing@3"
            ]
        },
        {
            "x": 3,
            "y": 1,
            "z": 0,
            "elements": [
                "gregtech:meta_block_frame_2@1"
            ]
        },
        {
            "x": -5,
            "y": -1,
            "z": 0,
            "elements": [
                "gregtech:fusion_casing@3"
            ]
        },
        {
            "x": -6,
            "y": -1,
            "z": 0,
            "elements": [
                "gregtech:fusion_casing@3"
            ]
        },
        {
            "x": 5,
            "y": 1,
            "z": 0,
            "elements": [
                "gregtech:fusion_casing@3"
            ]
        },
        {
            "x": 6,
            "y": 1,
            "z": 0,
            "elements": [
                "gregtech:fusion_casing@3"
            ]
        },
        {
            "x": -13,
            "y": -1,
            "z": 0,
            "elements": [
                "gregtech:fusion_casing@3"
            ]
        },
        {
            "x": 13,
            "y": 1,
            "z": 0,
            "elements": [
                "gregtech:fusion_casing@3"
            ]
        },
        {
            "x": 12,
            "y": -2,
            "z": 0,
            "elements": [
                "gregtech:fusion_casing@3"
            ]
        },
        {
            "x": 11,
            "y": -2,
            "z": 0,
            "elements": [
                "gregtech:fusion_casing@3"
            ]
        },
        {
            "x": -12,
            "y": 2,
            "z": 0,
            "elements": [
                "gregtech:fusion_casing@3"
            ]
        },
        {
            "x": 10,
            "y": -2,
            "z": 0,
            "elements": [
                "gregtech:fusion_casing@3"
            ]
        },
        {
            "x": -11,
            "y": 2,
            "z": 0,
            "elements": [
                "gregtech:fusion_casing@3"
            ]
        },
        {
            "x": 9,
            "y": -2,
            "z": 0,
            "elements": [
                "gregtech:fusion_casing@3"
            ]
        },
        {
            "x": -10,
            "y": 2,
            "z": 0,
            "elements": [
                "gregtech:fusion_casing@3"
            ]
        },
        {
            "x": 8,
            "y": -2,
            "z": 0,
            "elements": [
                "gregtech:fusion_casing@3"
            ]
        },
        {
            "x": -9,
            "y": 2,
            "z": 0,
            "elements": [
                "gregtech:fusion_casing@3"
            ]
        },
        {
            "x": 7,
            "y": -2,
            "z": 0,
            "elements": [
                "gregtech:fusion_casing@3"
            ]
        },
        {
            "x": -8,
            "y": 2,
            "z": 0,
            "elements": [
                "gregtech:fusion_casing@3"
            ]
        },
        {
            "x": -7,
            "y": 2,
            "z": 0,
            "elements": [
                "gregtech:fusion_casing@3"
            ]
        },
        {
            "x": -17,
            "y": -3,
            "z": -17,
            "elements": [
                "gregtech:fusion_casing@3"
            ]
        },
        {
            "x": -18,
            "y": -3,
            "z": -17,
            "elements": [
                "gregtech:fusion_casing@3"
            ]
        },
        {
            "x": -19,
            "y": -3,
            "z": -17,
            "elements": [
                "gregtech:fusion_casing@3"
            ]
        },
        {
            "x": -7,
            "y": -2,
            "z": 0,
            "elements": [
                "gregtech:fusion_casing@3"
            ]
        },
        {
            "x": -8,
            "y": -2,
            "z": 0,
            "elements": [
                "gregtech:fusion_casing@3"
            ]
        },
        {
            "x": 7,
            "y": 2,
            "z": 0,
            "elements": [
                "gregtech:fusion_casing@3"
            ]
        },
        {
            "x": -9,
            "y": -2,
            "z": 0,
            "elements": [
                "gregtech:fusion_casing@3"
            ]
        },
        {
            "x": 8,
            "y": 2,
            "z": 0,
            "elements": [
                "gregtech:fusion_casing@3"
            ]
        },
        {
            "x": -10,
            "y": -2,
            "z": 0,
            "elements": [
                "gregtech:fusion_casing@3"
            ]
        },
        {
            "x": 9,
            "y": 2,
            "z": 0,
            "elements": [
                "gregtech:fusion_casing@3"
            ]
        },
        {
            "x": -11,
            "y": -2,
            "z": 0,
            "elements": [
                "gregtech:fusion_casing@3"
            ]
        },
        {
            "x": 10,
            "y": 2,
            "z": 0,
            "elements": [
                "gregtech:fusion_casing@3"
            ]
        },
        {
            "x": -12,
            "y": -2,
            "z": 0,
            "elements": [
                "gregtech:fusion_casing@3"
            ]
        },
        {
            "x": 11,
            "y": 2,
            "z": 0,
            "elements": [
                "gregtech:fusion_casing@3"
            ]
        },
        {
            "x": 12,
            "y": 2,
            "z": 0,
            "elements": [
                "gregtech:fusion_casing@3"
            ]
        },
        {
            "x": 12,
            "y": 2,
            "z": -30,
            "elements": [
                "gregtech:fusion_casing@3"
            ]
        },
        {
            "x": 11,
            "y": 2,
            "z": -30,
            "elements": [
                "gregtech:fusion_casing@3"
            ]
        },
        {
            "x": 10,
            "y": 2,
            "z": -30,
            "elements": [
                "gregtech:fusion_casing@3"
            ]
        },
        {
            "x": 9,
            "y": 2,
            "z": -30,
            "elements": [
                "gregtech:fusion_casing@3"
            ]
        },
        {
            "x": 8,
            "y": 2,
            "z": -30,
            "elements": [
                "gregtech:fusion_casing@3"
            ]
        },
        {
            "x": 7,
            "y": 2,
            "z": -30,
            "elements": [
                "gregtech:fusion_casing@3"
            ]
        },
        {
            "x": 19,
            "y": 3,
            "z": -13,
            "elements": [
                "gregtech:fusion_casing@3"
            ]
        },
        {
            "x": 18,
            "y": 3,
            "z": -13,
            "elements": [
                "gregtech:fusion_casing@3"
            ]
        },
        {
            "x": 17,
            "y": 3,
            "z": -13,
            "elements": [
                "gregtech:fusion_casing@3"
            ]
        },
        {
            "x": -7,
            "y": 2,
            "z": -30,
            "elements": [
                "gregtech:fusion_casing@3"
            ]
        },
        {
            "x": -8,
            "y": 2,
            "z": -30,
            "elements": [
                "gregtech:fusion_casing@3"
            ]
        },
        {
            "x": -9,
            "y": 2,
            "z": -30,
            "elements": [
                "gregtech:fusion_casing@3"
            ]
        },
        {
            "x": -10,
            "y": 2,
            "z": -30,
            "elements": [
                "gregtech:fusion_casing@3"
            ]
        },
        {
            "x": -11,
            "y": 2,
            "z": -30,
            "elements": [
                "gregtech:fusion_casing@3"
            ]
        },
        {
            "x": -12,
            "y": 2,
            "z": -30,
            "elements": [
                "gregtech:fusion_casing@3"
            ]
        },
        {
            "x": 13,
            "y": 1,
            "z": -30,
            "elements": [
                "gregtech:fusion_casing@3"
            ]
        },
        {
            "x": 6,
            "y": 1,
            "z": -30,
            "elements": [
                "gregtech:fusion_casing@3"
            ]
        },
        {
            "x": 5,
            "y": 1,
            "z": -30,
            "elements": [
                "gregtech:fusion_casing@3"
            ]
        },
        {
            "x": 20,
            "y": 2,
            "z": -13,
            "elements": [
                "gregtech:fusion_casing@3"
            ]
        },
        {
            "x": 3,
            "y": 1,
            "z": -30,
            "elements": [
                "gregtech:meta_block_frame_2@1"
            ]
        },
        {
            "x": 19,
            "y": 2,
            "z": -13,
            "elements": [
                "gregtech:meta_block_frame_127@10"
            ]
        },
        {
            "x": 2,
            "y": 1,
            "z": -30,
            "elements": [
                "modularmachinery:blockfluidinputhatch@7"
            ]
        },
        {
            "x": 1,
            "y": 1,
            "z": -30,
            "elements": [
                "gregtech:fusion_casing@3"
            ]
        },
        {
            "x": 17,
            "y": 2,
            "z": -13,
            "elements": [
                "gregtech:meta_block_frame_127@10"
            ]
        },
        {
            "x": 0,
            "y": 1,
            "z": -30,
            "elements": [
                "gregtech:fusion_casing@3"
            ]
        },
        {
            "x": 16,
            "y": 2,
            "z": -13,
            "elements": [
                "gregtech:fusion_casing@3"
            ]
        },
        {
            "x": -1,
            "y": 1,
            "z": -30,
            "elements": [
                "gregtech:fusion_casing@3"
            ]
        },
        {
            "x": -2,
            "y": 1,
            "z": -30,
            "elements": [
                "modularmachinery:blockfluidinputhatch@7"
            ]
        },
        {
            "x": -17,
            "y": 3,
            "z": -13,
            "elements": [
                "gregtech:fusion_casing@3"
            ]
        },
        {
            "x": -3,
            "y": 1,
            "z": -30,
            "elements": [
                "gregtech:meta_block_frame_2@1"
            ]
        },
        {
            "x": -18,
            "y": 3,
            "z": -13,
            "elements": [
                "gregtech:fusion_casing@3"
            ]
        },
        {
            "x": -19,
            "y": 3,
            "z": -13,
            "elements": [
                "gregtech:fusion_casing@3"
            ]
        },
        {
            "x": -5,
            "y": 1,
            "z": -30,
            "elements": [
                "gregtech:fusion_casing@3"
            ]
        },
        {
            "x": -6,
            "y": 1,
            "z": -30,
            "elements": [
                "gregtech:fusion_casing@3"
            ]
        },
        {
            "x": -13,
            "y": 1,
            "z": -30,
            "elements": [
                "gregtech:fusion_casing@3"
            ]
        },
        {
            "x": 13,
            "y": 0,
            "z": -30,
            "elements": [
                "gregtech:fusion_casing@3"
            ]
        },
        {
            "x": 10,
            "y": 0,
            "z": -30,
            "elements": [
                "gregtech:fusion_casing@1"
            ]
        },
        {
            "x": 6,
            "y": 0,
            "z": -30,
            "elements": [
                "gregtech:fusion_casing@3"
            ]
        },
        {
            "x": 5,
            "y": 0,
            "z": -30,
            "elements": [
                "gregtech:fusion_casing@3"
            ]
        },
        {
            "x": 21,
            "y": 1,
            "z": -13,
            "elements": [
                "modularmachinery:blockfluidoutputhatch@7"
            ]
        },
        {
            "x": 20,
            "y": 1,
            "z": -13,
            "elements": [
                "gregtech:meta_block_frame_127@10"
            ]
        },
        {
            "x": 3,
            "y": 0,
            "z": -30,
            "elements": [
                "gregtech:meta_block_frame_2@1"
            ]
        },
        {
            "x": 19,
            "y": 1,
            "z": -13,
            "elements": [
                "gregtech:wire_coil@6"
            ]
        },
        {
            "x": 2,
            "y": 0,
            "z": -30,
            "elements": [
                "modularmachinery:blockfluidinputhatch@7"
            ]
        },
        {
            "x": 18,
            "y": 1,
            "z": -13,
            "elements": [
                "gregtech:boiler_casing@3"
            ]
        },
        {
            "x": 1,
            "y": 0,
            "z": -30,
            "elements": [
                "gregtech:transparent_casing@1"
            ]
        },
        {
            "x": 17,
            "y": 1,
            "z": -13,
            "elements": [
                "gregtech:wire_coil@6"
            ]
        },
        {
            "x": 0,
            "y": 0,
            "z": -30,
            "elements": [
                "gregtech:transparent_casing@1"
            ]
        },
        {
            "x": 16,
            "y": 1,
            "z": -13,
            "elements": [
                "gregtech:meta_block_frame_127@10"
            ]
        },
        {
            "x": -1,
            "y": 0,
            "z": -30,
            "elements": [
                "gregtech:transparent_casing@1"
            ]
        },
        {
            "x": 15,
            "y": 1,
            "z": -13,
            "elements": [
                "modularmachinery:blockfluidinputhatch@7"
            ]
        },
        {
            "x": -16,
            "y": 2,
            "z": -13,
            "elements": [
                "gregtech:fusion_casing@3"
            ]
        },
        {
            "x": -2,
            "y": 0,
            "z": -30,
            "elements": [
                "modularmachinery:blockfluidinputhatch@7"
            ]
        },
        {
            "x": -17,
            "y": 2,
            "z": -13,
            "elements": [
                "gregtech:meta_block_frame_127@10"
            ]
        },
        {
            "x": -3,
            "y": 0,
            "z": -30,
            "elements": [
                "gregtech:meta_block_frame_2@1"
            ]
        },
        {
            "x": -19,
            "y": 2,
            "z": -13,
            "elements": [
                "gregtech:meta_block_frame_127@10"
            ]
        },
        {
            "x": -5,
            "y": 0,
            "z": -30,
            "elements": [
                "gregtech:fusion_casing@3"
            ]
        },
        {
            "x": -20,
            "y": 2,
            "z": -13,
            "elements": [
                "gregtech:fusion_casing@3"
            ]
        },
        {
            "x": -6,
            "y": 0,
            "z": -30,
            "elements": [
                "gregtech:fusion_casing@3"
            ]
        },
        {
            "x": -10,
            "y": 0,
            "z": -30,
            "elements": [
                "gregtech:fusion_casing@1"
            ]
        },
        {
            "x": -13,
            "y": 0,
            "z": -30,
            "elements": [
                "gregtech:fusion_casing@3"
            ]
        },
        {
            "x": 13,
            "y": -1,
            "z": -30,
            "elements": [
                "gregtech:fusion_casing@3"
            ]
        },
        {
            "x": 6,
            "y": -1,
            "z": -30,
            "elements": [
                "gregtech:fusion_casing@3"
            ]
        },
        {
            "x": 5,
            "y": -1,
            "z": -30,
            "elements": [
                "gregtech:fusion_casing@3"
            ]
        },
        {
            "x": 21,
            "y": 0,
            "z": -13,
            "elements": [
                "modularmachinery:blockfluidoutputhatch@7"
            ]
        },
        {
            "x": 3,
            "y": -1,
            "z": -30,
            "elements": [
                "gregtech:meta_block_frame_2@1"
            ]
        },
        {
            "x": 19,
            "y": 0,
            "z": -13,
            "elements": [
                "gregtech:boiler_casing@3"
            ]
        },
        {
            "x": 2,
            "y": -1,
            "z": -30,
            "elements": [
                "modularmachinery:blockfluidinputhatch@7"
            ]
        },
        {
            "x": 18,
            "y": 0,
            "z": -13,
            "elements": [
                "gregtech:fusion_casing@1"
            ]
        },
        {
            "x": 1,
            "y": -1,
            "z": -30,
            "elements": [
                "gregtech:fusion_casing@3"
            ]
        },
        {
            "x": 17,
            "y": 0,
            "z": -13,
            "elements": [
                "gregtech:boiler_casing@3"
            ]
        },
        {
            "x": 0,
            "y": -1,
            "z": -30,
            "elements": [
                "gregtech:fusion_casing@3"
            ]
        },
        {
            "x": -15,
            "y": 1,
            "z": -13,
            "elements": [
                "modularmachinery:blockfluidinputhatch@7"
            ]
        },
        {
            "x": -1,
            "y": -1,
            "z": -30,
            "elements": [
                "gregtech:fusion_casing@3"
            ]
        },
        {
            "x": 15,
            "y": 0,
            "z": -13,
            "elements": [
                "modularmachinery:blockfluidinputhatch@7"
            ]
        },
        {
            "x": -16,
            "y": 1,
            "z": -13,
            "elements": [
                "gregtech:meta_block_frame_127@10"
            ]
        },
        {
            "x": -2,
            "y": -1,
            "z": -30,
            "elements": [
                "modularmachinery:blockfluidinputhatch@7"
            ]
        },
        {
            "x": -17,
            "y": 1,
            "z": -13,
            "elements": [
                "gregtech:wire_coil@6"
            ]
        },
        {
            "x": -3,
            "y": -1,
            "z": -30,
            "elements": [
                "gregtech:meta_block_frame_2@1"
            ]
        },
        {
            "x": -18,
            "y": 1,
            "z": -13,
            "elements": [
                "gregtech:boiler_casing@3"
            ]
        },
        {
            "x": -19,
            "y": 1,
            "z": -13,
            "elements": [
                "gregtech:wire_coil@6"
            ]
        },
        {
            "x": -5,
            "y": -1,
            "z": -30,
            "elements": [
                "gregtech:fusion_casing@3"
            ]
        },
        {
            "x": -20,
            "y": 1,
            "z": -13,
            "elements": [
                "gregtech:meta_block_frame_127@10"
            ]
        },
        {
            "x": -6,
            "y": -1,
            "z": -30,
            "elements": [
                "gregtech:fusion_casing@3"
            ]
        },
        {
            "x": -21,
            "y": 1,
            "z": -13,
            "elements": [
                "modularmachinery:blockfluidoutputhatch@7"
            ]
        },
        {
            "x": -13,
            "y": -1,
            "z": -30,
            "elements": [
                "gregtech:fusion_casing@3"
            ]
        },
        {
            "x": 12,
            "y": -2,
            "z": -30,
            "elements": [
                "gregtech:fusion_casing@3"
            ]
        },
        {
            "x": 11,
            "y": -2,
            "z": -30,
            "elements": [
                "gregtech:fusion_casing@3"
            ]
        },
        {
            "x": 10,
            "y": -2,
            "z": -30,
            "elements": [
                "gregtech:fusion_casing@3"
            ]
        },
        {
            "x": 9,
            "y": -2,
            "z": -30,
            "elements": [
                "gregtech:fusion_casing@3"
            ]
        },
        {
            "x": 8,
            "y": -2,
            "z": -30,
            "elements": [
                "gregtech:fusion_casing@3"
            ]
        },
        {
            "x": 7,
            "y": -2,
            "z": -30,
            "elements": [
                "gregtech:fusion_casing@3"
            ]
        },
        {
            "x": 21,
            "y": -1,
            "z": -13,
            "elements": [
                "modularmachinery:blockfluidoutputhatch@7"
            ]
        },
        {
            "x": 20,
            "y": -1,
            "z": -13,
            "elements": [
                "gregtech:meta_block_frame_127@10"
            ]
        },
        {
            "x": 19,
            "y": -1,
            "z": -13,
            "elements": [
                "gregtech:wire_coil@6"
            ]
        },
        {
            "x": 18,
            "y": -1,
            "z": -13,
            "elements": [
                "gregtech:boiler_casing@3"
            ]
        },
        {
            "x": 17,
            "y": -1,
            "z": -13,
            "elements": [
                "gregtech:wire_coil@6"
            ]
        },
        {
            "x": -15,
            "y": 0,
            "z": -13,
            "elements": [
                "modularmachinery:blockfluidinputhatch@7"
            ]
        },
        {
            "x": 16,
            "y": -1,
            "z": -13,
            "elements": [
                "gregtech:meta_block_frame_127@10"
            ]
        },
        {
            "x": 15,
            "y": -1,
            "z": -13,
            "elements": [
                "modularmachinery:blockfluidinputhatch@7"
            ]
        },
        {
            "x": -17,
            "y": 0,
            "z": -13,
            "elements": [
                "gregtech:boiler_casing@3"
            ]
        },
        {
            "x": -18,
            "y": 0,
            "z": -13,
            "elements": [
                "gregtech:fusion_casing@1"
            ]
        },
        {
            "x": -19,
            "y": 0,
            "z": -13,
            "elements": [
                "gregtech:boiler_casing@3"
            ]
        },
        {
            "x": -21,
            "y": 0,
            "z": -13,
            "elements": [
                "modularmachinery:blockfluidoutputhatch@7"
            ]
        },
        {
            "x": -7,
            "y": -2,
            "z": -30,
            "elements": [
                "gregtech:fusion_casing@3"
            ]
        },
        {
            "x": -8,
            "y": -2,
            "z": -30,
            "elements": [
                "gregtech:fusion_casing@3"
            ]
        },
        {
            "x": -9,
            "y": -2,
            "z": -30,
            "elements": [
                "gregtech:fusion_casing@3"
            ]
        },
        {
            "x": -10,
            "y": -2,
            "z": -30,
            "elements": [
                "gregtech:fusion_casing@3"
            ]
        },
        {
            "x": -11,
            "y": -2,
            "z": -30,
            "elements": [
                "gregtech:fusion_casing@3"
            ]
        },
        {
            "x": -12,
            "y": -2,
            "z": -30,
            "elements": [
                "gregtech:fusion_casing@3"
            ]
        },
        {
            "x": 20,
            "y": -2,
            "z": -13,
            "elements": [
                "gregtech:fusion_casing@3"
            ]
        },
        {
            "x": 19,
            "y": -2,
            "z": -13,
            "elements": [
                "gregtech:meta_block_frame_127@10"
            ]
        },
        {
            "x": 17,
            "y": -2,
            "z": -13,
            "elements": [
                "gregtech:meta_block_frame_127@10"
            ]
        },
        {
            "x": 16,
            "y": -2,
            "z": -13,
            "elements": [
                "gregtech:fusion_casing@3"
            ]
        },
        {
            "x": -15,
            "y": -1,
            "z": -13,
            "elements": [
                "modularmachinery:blockfluidinputhatch@7"
            ]
        },
        {
            "x": -16,
            "y": -1,
            "z": -13,
            "elements": [
                "gregtech:meta_block_frame_127@10"
            ]
        },
        {
            "x": -17,
            "y": -1,
            "z": -13,
            "elements": [
                "gregtech:wire_coil@6"
            ]
        },
        {
            "x": -18,
            "y": -1,
            "z": -13,
            "elements": [
                "gregtech:boiler_casing@3"
            ]
        },
        {
            "x": -19,
            "y": -1,
            "z": -13,
            "elements": [
                "gregtech:wire_coil@6"
            ]
        },
        {
            "x": -20,
            "y": -1,
            "z": -13,
            "elements": [
                "gregtech:meta_block_frame_127@10"
            ]
        },
        {
            "x": -21,
            "y": -1,
            "z": -13,
            "elements": [
                "modularmachinery:blockfluidoutputhatch@7"
            ]
        },
        {
            "x": 19,
            "y": -3,
            "z": -13,
            "elements": [
                "gregtech:fusion_casing@3"
            ]
        },
        {
            "x": 18,
            "y": -3,
            "z": -13,
            "elements": [
                "gregtech:fusion_casing@3"
            ]
        },
        {
            "x": 17,
            "y": -3,
            "z": -13,
            "elements": [
                "gregtech:fusion_casing@3"
            ]
        },
        {
            "x": -16,
            "y": -2,
            "z": -13,
            "elements": [
                "gregtech:fusion_casing@3"
            ]
        },
        {
            "x": -17,
            "y": -2,
            "z": -13,
            "elements": [
                "gregtech:meta_block_frame_127@10"
            ]
        },
        {
            "x": -19,
            "y": -2,
            "z": -13,
            "elements": [
                "gregtech:meta_block_frame_127@10"
            ]
        },
        {
            "x": -20,
            "y": -2,
            "z": -13,
            "elements": [
                "gregtech:fusion_casing@3"
            ]
        },
        {
            "x": -17,
            "y": -3,
            "z": -13,
            "elements": [
                "gregtech:fusion_casing@3"
            ]
        },
        {
            "x": -18,
            "y": -3,
            "z": -13,
            "elements": [
                "gregtech:fusion_casing@3"
            ]
        },
        {
            "x": -19,
            "y": -3,
            "z": -13,
            "elements": [
                "gregtech:fusion_casing@3"
            ]
        },
        {
            "x": 15,
            "y": 2,
            "z": -26,
            "elements": [
                "gregtech:fusion_casing@3"
            ]
        },
        {
            "x": 14,
            "y": 2,
            "z": -26,
            "elements": [
                "gregtech:fusion_casing@3"
            ]
        },
        {
            "x": 13,
            "y": 2,
            "z": -26,
            "elements": [
                "gregtech:fusion_casing@3"
            ]
        },
        {
            "x": -13,
            "y": 2,
            "z": -26,
            "elements": [
                "gregtech:fusion_casing@3"
            ]
        },
        {
            "x": 17,
            "y": 1,
            "z": -26,
            "elements": [
                "modularmachinery:blockenergyinputhatch@7"
            ]
        },
        {
            "x": -14,
            "y": 2,
            "z": -26,
            "elements": [
                "gregtech:fusion_casing@3"
            ]
        },
        {
            "x": 16,
            "y": 1,
            "z": -26,
            "elements": [
                "gregtech:fusion_casing@3"
            ]
        },
        {
            "x": -15,
            "y": 2,
            "z": -26,
            "elements": [
                "gregtech:fusion_casing@3"
            ]
        },
        {
            "x": 12,
            "y": 1,
            "z": -26,
            "elements": [
                "gregtech:fusion_casing@3"
            ]
        },
        {
            "x": 18,
            "y": 2,
            "z": -9,
            "elements": [
                "gregtech:fusion_casing@3"
            ]
        },
        {
            "x": 17,
            "y": 2,
            "z": -9,
            "elements": [
                "gregtech:fusion_casing@3"
            ]
        },
        {
            "x": 16,
            "y": 2,
            "z": -9,
            "elements": [
                "gregtech:fusion_casing@3"
            ]
        },
        {
            "x": -12,
            "y": 1,
            "z": -26,
            "elements": [
                "gregtech:fusion_casing@3"
            ]
        },
        {
            "x": 17,
            "y": 0,
            "z": -26,
            "elements": [
                "gregtech:fusion_casing@3"
            ]
        },
        {
            "x": -16,
            "y": 1,
            "z": -26,
            "elements": [
                "gregtech:fusion_casing@3"
            ]
        },
        {
            "x": -17,
            "y": 1,
            "z": -26,
            "elements": [
                "modularmachinery:blockenergyinputhatch@7"
            ]
        },
        {
            "x": 14,
            "y": 0,
            "z": -26,
            "elements": [
                "gregtech:fusion_casing@1"
            ]
        },
        {
            "x": 12,
            "y": 0,
            "z": -26,
            "elements": [
                "gregtech:fusion_casing@3"
            ]
        },
        {
            "x": 19,
            "y": 1,
            "z": -9,
            "elements": [
                "gregtech:fusion_casing@3"
            ]
        },
        {
            "x": 15,
            "y": 1,
            "z": -9,
            "elements": [
                "gregtech:fusion_casing@3"
            ]
        },
        {
            "x": -16,
            "y": 2,
            "z": -9,
            "elements": [
                "gregtech:fusion_casing@3"
            ]
        },
        {
            "x": -17,
            "y": 2,
            "z": -9,
            "elements": [
                "gregtech:fusion_casing@3"
            ]
        },
        {
            "x": -18,
            "y": 2,
            "z": -9,
            "elements": [
                "gregtech:fusion_casing@3"
            ]
        },
        {
            "x": -12,
            "y": 0,
            "z": -26,
            "elements": [
                "gregtech:fusion_casing@3"
            ]
        },
        {
            "x": 17,
            "y": -1,
            "z": -26,
            "elements": [
                "modularmachinery:blockenergyinputhatch@7"
            ]
        },
        {
            "x": -14,
            "y": 0,
            "z": -26,
            "elements": [
                "gregtech:fusion_casing@1"
            ]
        },
        {
            "x": 16,
            "y": -1,
            "z": -26,
            "elements": [
                "gregtech:fusion_casing@3"
            ]
        },
        {
            "x": -17,
            "y": 0,
            "z": -26,
            "elements": [
                "gregtech:fusion_casing@3"
            ]
        },
        {
            "x": 12,
            "y": -1,
            "z": -26,
            "elements": [
                "gregtech:fusion_casing@3"
            ]
        },
        {
            "x": 19,
            "y": 0,
            "z": -9,
            "elements": [
                "gregtech:fusion_casing@3"
            ]
        },
        {
            "x": 17,
            "y": 0,
            "z": -9,
            "elements": [
                "gregtech:fusion_casing@1"
            ]
        },
        {
            "x": -15,
            "y": 1,
            "z": -9,
            "elements": [
                "gregtech:fusion_casing@3"
            ]
        },
        {
            "x": 15,
            "y": 0,
            "z": -9,
            "elements": [
                "gregtech:fusion_casing@3"
            ]
        },
        {
            "x": -19,
            "y": 1,
            "z": -9,
            "elements": [
                "gregtech:fusion_casing@3"
            ]
        },
        {
            "x": -12,
            "y": -1,
            "z": -26,
            "elements": [
                "gregtech:fusion_casing@3"
            ]
        },
        {
            "x": 15,
            "y": -2,
            "z": -26,
            "elements": [
                "gregtech:fusion_casing@3"
            ]
        },
        {
            "x": -16,
            "y": -1,
            "z": -26,
            "elements": [
                "gregtech:fusion_casing@3"
            ]
        },
        {
            "x": 14,
            "y": -2,
            "z": -26,
            "elements": [
                "gregtech:fusion_casing@3"
            ]
        },
        {
            "x": -17,
            "y": -1,
            "z": -26,
            "elements": [
                "modularmachinery:blockenergyinputhatch@7"
            ]
        },
        {
            "x": 13,
            "y": -2,
            "z": -26,
            "elements": [
                "gregtech:fusion_casing@3"
            ]
        },
        {
            "x": 19,
            "y": -1,
            "z": -9,
            "elements": [
                "gregtech:fusion_casing@3"
            ]
        },
        {
            "x": -15,
            "y": 0,
            "z": -9,
            "elements": [
                "gregtech:fusion_casing@3"
            ]
        },
        {
            "x": 15,
            "y": -1,
            "z": -9,
            "elements": [
                "gregtech:fusion_casing@3"
            ]
        },
        {
            "x": -17,
            "y": 0,
            "z": -9,
            "elements": [
                "gregtech:fusion_casing@1"
            ]
        },
        {
            "x": -19,
            "y": 0,
            "z": -9,
            "elements": [
                "gregtech:fusion_casing@3"
            ]
        },
        {
            "x": -13,
            "y": -2,
            "z": -26,
            "elements": [
                "gregtech:fusion_casing@3"
            ]
        },
        {
            "x": -14,
            "y": -2,
            "z": -26,
            "elements": [
                "gregtech:fusion_casing@3"
            ]
        },
        {
            "x": -15,
            "y": -2,
            "z": -26,
            "elements": [
                "gregtech:fusion_casing@3"
            ]
        },
        {
            "x": 18,
            "y": -2,
            "z": -9,
            "elements": [
                "gregtech:fusion_casing@3"
            ]
        },
        {
            "x": 17,
            "y": -2,
            "z": -9,
            "elements": [
                "gregtech:fusion_casing@3"
            ]
        },
        {
            "x": 16,
            "y": -2,
            "z": -9,
            "elements": [
                "gregtech:fusion_casing@3"
            ]
        },
        {
            "x": -15,
            "y": -1,
            "z": -9,
            "elements": [
                "gregtech:fusion_casing@3"
            ]
        },
        {
            "x": -19,
            "y": -1,
            "z": -9,
            "elements": [
                "gregtech:fusion_casing@3"
            ]
        },
        {
            "x": -16,
            "y": -2,
            "z": -9,
            "elements": [
                "gregtech:fusion_casing@3"
            ]
        },
        {
            "x": -17,
            "y": -2,
            "z": -9,
            "elements": [
                "gregtech:fusion_casing@3"
            ]
        },
        {
            "x": -18,
            "y": -2,
            "z": -9,
            "elements": [
                "gregtech:fusion_casing@3"
            ]
        },
        {
            "x": 18,
            "y": 2,
            "z": -22,
            "elements": [
                "gregtech:fusion_casing@3"
            ]
        },
        {
            "x": 17,
            "y": 2,
            "z": -22,
            "elements": [
                "gregtech:fusion_casing@3"
            ]
        },
        {
            "x": 16,
            "y": 2,
            "z": -22,
            "elements": [
                "gregtech:fusion_casing@3"
            ]
        },
        {
            "x": 15,
            "y": 2,
            "z": -22,
            "elements": [
                "gregtech:fusion_casing@3"
            ]
        },
        {
            "x": 19,
            "y": 1,
            "z": -22,
            "elements": [
                "gregtech:fusion_casing@3"
            ]
        },
        {
            "x": 17,
            "y": 1,
            "z": -22,
            "elements": [
                "gregtech:meta_block_frame_127@10"
            ]
        },
        {
            "x": -15,
            "y": 2,
            "z": -22,
            "elements": [
                "gregtech:fusion_casing@3"
            ]
        },
        {
            "x": -16,
            "y": 2,
            "z": -22,
            "elements": [
                "gregtech:fusion_casing@3"
            ]
        },
        {
            "x": 14,
            "y": 1,
            "z": -22,
            "elements": [
                "gregtech:fusion_casing@3"
            ]
        },
        {
            "x": -17,
            "y": 2,
            "z": -22,
            "elements": [
                "gregtech:fusion_casing@3"
            ]
        },
        {
            "x": -18,
            "y": 2,
            "z": -22,
            "elements": [
                "gregtech:fusion_casing@3"
            ]
        },
        {
            "x": 16,
            "y": 2,
            "z": -5,
            "elements": [
                "gregtech:fusion_casing@3"
            ]
        },
        {
            "x": 15,
            "y": 2,
            "z": -5,
            "elements": [
                "gregtech:fusion_casing@3"
            ]
        },
        {
            "x": 14,
            "y": 2,
            "z": -5,
            "elements": [
                "gregtech:fusion_casing@3"
            ]
        },
        {
            "x": 19,
            "y": 0,
            "z": -22,
            "elements": [
                "gregtech:fusion_casing@3"
            ]
        },
        {
            "x": -3,
            "y": -2,
            "z": 5,
            "elements": [
                "gregtech:meta_block_frame_2@1"
            ]
        },
        {
            "x": -14,
            "y": 1,
            "z": -22,
            "elements": [
                "gregtech:fusion_casing@3"
            ]
        },
        {
            "x": 17,
            "y": 0,
            "z": -22,
            "elements": [
                "gregtech:fusion_casing@1"
            ]
        },
        {
            "x": -2,
            "y": -2,
            "z": 5,
            "elements": [
                "gregtech:fusion_casing@3"
            ]
        },
        {
            "x": -1,
            "y": -2,
            "z": 5,
            "elements": [
                "gregtech:transparent_casing@1"
            ]
        },
        {
            "x": 0,
            "y": -2,
            "z": 5,
            "elements": [
                "gregtech:transparent_casing@1"
            ]
        },
        {
            "x": 14,
            "y": 0,
            "z": -22,
            "elements": [
                "gregtech:fusion_casing@3"
            ]
        },
        {
            "x": -17,
            "y": 1,
            "z": -22,
            "elements": [
                "gregtech:meta_block_frame_127@10"
            ]
        },
        {
            "x": 1,
            "y": -2,
            "z": 5,
            "elements": [
                "gregtech:transparent_casing@1"
            ]
        },
        {
            "x": 2,
            "y": -2,
            "z": 5,
            "elements": [
                "gregtech:fusion_casing@3"
            ]
        },
        {
            "x": -19,
            "y": 1,
            "z": -22,
            "elements": [
                "gregtech:fusion_casing@3"
            ]
        },
        {
            "x": 3,
            "y": -2,
            "z": 5,
            "elements": [
                "gregtech:meta_block_frame_2@1"
            ]
        },
        {
            "x": 17,
            "y": 1,
            "z": -5,
            "elements": [
                "gregtech:fusion_casing@3"
            ]
        },
        {
            "x": -14,
            "y": 2,
            "z": -5,
            "elements": [
                "gregtech:fusion_casing@3"
            ]
        },
        {
            "x": -15,
            "y": 2,
            "z": -5,
            "elements": [
                "gregtech:fusion_casing@3"
            ]
        },
        {
            "x": -16,
            "y": 2,
            "z": -5,
            "elements": [
                "gregtech:fusion_casing@3"
            ]
        },
        {
            "x": 13,
            "y": 1,
            "z": -5,
            "elements": [
                "gregtech:fusion_casing@3"
            ]
        },
        {
            "x": 12,
            "y": 1,
            "z": -5,
            "elements": [
                "gregtech:fusion_casing@3"
            ]
        },
        {
            "x": 19,
            "y": -1,
            "z": -22,
            "elements": [
                "gregtech:fusion_casing@3"
            ]
        },
        {
            "x": -4,
            "y": -1,
            "z": 5,
            "elements": [
                "gregtech:fusion_casing@3"
            ]
        },
        {
            "x": -3,
            "y": -1,
            "z": 5,
            "elements": [
                "gregtech:fusion_casing@3"
            ]
        },
        {
            "x": -14,
            "y": 0,
            "z": -22,
            "elements": [
                "gregtech:fusion_casing@3"
            ]
        },
        {
            "x": 17,
            "y": -1,
            "z": -22,
            "elements": [
                "gregtech:meta_block_frame_127@10"
            ]
        },
        {
            "x": -2,
            "y": -1,
            "z": 5,
            "elements": [
                "gregtech:meta_block_frame_127@10"
            ]
        },
        {
            "x": 14,
            "y": -1,
            "z": -22,
            "elements": [
                "gregtech:fusion_casing@3"
            ]
        },
        {
            "x": -17,
            "y": 0,
            "z": -22,
            "elements": [
                "gregtech:fusion_casing@1"
            ]
        },
        {
            "x": -19,
            "y": 0,
            "z": -22,
            "elements": [
                "gregtech:fusion_casing@3"
            ]
        },
        {
            "x": 2,
            "y": -1,
            "z": 5,
            "elements": [
                "gregtech:meta_block_frame_127@10"
            ]
        },
        {
            "x": 3,
            "y": -1,
            "z": 5,
            "elements": [
                "gregtech:fusion_casing@3"
            ]
        },
        {
            "x": 4,
            "y": -1,
            "z": 5,
            "elements": [
                "gregtech:fusion_casing@3"
            ]
        },
        {
            "x": -12,
            "y": 1,
            "z": -5,
            "elements": [
                "gregtech:fusion_casing@3"
            ]
        },
        {
            "x": -13,
            "y": 1,
            "z": -5,
            "elements": [
                "gregtech:fusion_casing@3"
            ]
        },
        {
            "x": 17,
            "y": 0,
            "z": -5,
            "elements": [
                "gregtech:fusion_casing@3"
            ]
        },
        {
            "x": 15,
            "y": 0,
            "z": -5,
            "elements": [
                "gregtech:fusion_casing@1"
            ]
        },
        {
            "x": -17,
            "y": 1,
            "z": -5,
            "elements": [
                "gregtech:fusion_casing@3"
            ]
        },
        {
            "x": 12,
            "y": 0,
            "z": -5,
            "elements": [
                "gregtech:fusion_casing@3"
            ]
        },
        {
            "x": 18,
            "y": -2,
            "z": -22,
            "elements": [
                "gregtech:fusion_casing@3"
            ]
        },
        {
            "x": -4,
            "y": 0,
            "z": 5,
            "elements": [
                "gregtech:fusion_casing@3"
            ]
        },
        {
            "x": 17,
            "y": -2,
            "z": -22,
            "elements": [
                "gregtech:fusion_casing@3"
            ]
        },
        {
            "x": -14,
            "y": -1,
            "z": -22,
            "elements": [
                "gregtech:fusion_casing@3"
            ]
        },
        {
            "x": -3,
            "y": 0,
            "z": 5,
            "elements": [
                "gregtech:fusion_casing@3"
            ]
        },
        {
            "x": 16,
            "y": -2,
            "z": -22,
            "elements": [
                "gregtech:fusion_casing@3"
            ]
        },
        {
            "x": 15,
            "y": -2,
            "z": -22,
            "elements": [
                "gregtech:fusion_casing@3"
            ]
        },
        {
            "x": -17,
            "y": -1,
            "z": -22,
            "elements": [
                "gregtech:meta_block_frame_127@10"
            ]
        },
        {
            "x": -19,
            "y": -1,
            "z": -22,
            "elements": [
                "gregtech:fusion_casing@3"
            ]
        },
        {
            "x": 3,
            "y": 0,
            "z": 5,
            "elements": [
                "gregtech:fusion_casing@3"
            ]
        },
        {
            "x": 4,
            "y": 0,
            "z": 5,
            "elements": [
                "gregtech:fusion_casing@3"
            ]
        },
        {
            "x": -12,
            "y": 0,
            "z": -5,
            "elements": [
                "gregtech:fusion_casing@3"
            ]
        },
        {
            "x": 17,
            "y": -1,
            "z": -5,
            "elements": [
                "gregtech:fusion_casing@3"
            ]
        },
        {
            "x": -15,
            "y": 0,
            "z": -5,
            "elements": [
                "gregtech:fusion_casing@1"
            ]
        },
        {
            "x": -17,
            "y": 0,
            "z": -5,
            "elements": [
                "gregtech:fusion_casing@3"
            ]
        },
        {
            "x": 13,
            "y": -1,
            "z": -5,
            "elements": [
                "gregtech:fusion_casing@3"
            ]
        },
        {
            "x": 12,
            "y": -1,
            "z": -5,
            "elements": [
                "gregtech:fusion_casing@3"
            ]
        },
        {
            "x": -4,
            "y": 1,
            "z": 5,
            "elements": [
                "gregtech:fusion_casing@3"
            ]
        },
        {
            "x": -3,
            "y": 1,
            "z": 5,
            "elements": [
                "gregtech:fusion_casing@3"
            ]
        },
        {
            "x": -15,
            "y": -2,
            "z": -22,
            "elements": [
                "gregtech:fusion_casing@3"
            ]
        },
        {
            "x": -2,
            "y": 1,
            "z": 5,
            "elements": [
                "gregtech:meta_block_frame_127@10"
            ]
        },
        {
            "x": -16,
            "y": -2,
            "z": -22,
            "elements": [
                "gregtech:fusion_casing@3"
            ]
        },
        {
            "x": -17,
            "y": -2,
            "z": -22,
            "elements": [
                "gregtech:fusion_casing@3"
            ]
        },
        {
            "x": -18,
            "y": -2,
            "z": -22,
            "elements": [
                "gregtech:fusion_casing@3"
            ]
        },
        {
            "x": 2,
            "y": 1,
            "z": 5,
            "elements": [
                "gregtech:meta_block_frame_127@10"
            ]
        },
        {
            "x": 3,
            "y": 1,
            "z": 5,
            "elements": [
                "gregtech:fusion_casing@3"
            ]
        },
        {
            "x": 4,
            "y": 1,
            "z": 5,
            "elements": [
                "gregtech:fusion_casing@3"
            ]
        },
        {
            "x": -12,
            "y": -1,
            "z": -5,
            "elements": [
                "gregtech:fusion_casing@3"
            ]
        },
        {
            "x": -13,
            "y": -1,
            "z": -5,
            "elements": [
                "gregtech:fusion_casing@3"
            ]
        },
        {
            "x": 16,
            "y": -2,
            "z": -5,
            "elements": [
                "gregtech:fusion_casing@3"
            ]
        },
        {
            "x": 15,
            "y": -2,
            "z": -5,
            "elements": [
                "gregtech:fusion_casing@3"
            ]
        },
        {
            "x": 14,
            "y": -2,
            "z": -5,
            "elements": [
                "gregtech:fusion_casing@3"
            ]
        },
        {
            "x": -17,
            "y": -1,
            "z": -5,
            "elements": [
                "gregtech:fusion_casing@3"
            ]
        },
        {
            "x": -3,
            "y": 2,
            "z": 5,
            "elements": [
                "gregtech:meta_block_frame_2@1"
            ]
        },
        {
            "x": -2,
            "y": 2,
            "z": 5,
            "elements": [
                "gregtech:fusion_casing@3"
            ]
        },
        {
            "x": -1,
            "y": 2,
            "z": 5,
            "elements": [
                "gregtech:transparent_casing@1"
            ]
        },
        {
            "x": 0,
            "y": 2,
            "z": 5,
            "elements": [
                "gregtech:transparent_casing@1"
            ]
        },
        {
            "x": 1,
            "y": 2,
            "z": 5,
            "elements": [
                "gregtech:transparent_casing@1"
            ]
        },
        {
            "x": 2,
            "y": 2,
            "z": 5,
            "elements": [
                "gregtech:fusion_casing@3"
            ]
        },
        {
            "x": 3,
            "y": 2,
            "z": 5,
            "elements": [
                "gregtech:meta_block_frame_2@1"
            ]
        },
        {
            "x": -14,
            "y": -2,
            "z": -5,
            "elements": [
                "gregtech:fusion_casing@3"
            ]
        },
        {
            "x": -15,
            "y": -2,
            "z": -5,
            "elements": [
                "gregtech:fusion_casing@3"
            ]
        },
        {
            "x": -16,
            "y": -2,
            "z": -5,
            "elements": [
                "gregtech:fusion_casing@3"
            ]
        },
        {
            "x": 3,
            "y": 2,
            "z": -35,
            "elements": [
                "gregtech:meta_block_frame_2@1"
            ]
        },
        {
            "x": 19,
            "y": 3,
            "z": -18,
            "elements": [
                "gregtech:meta_block_frame_2@1"
            ]
        },
        {
            "x": 2,
            "y": 2,
            "z": -35,
            "elements": [
                "gregtech:fusion_casing@3"
            ]
        },
        {
            "x": 18,
            "y": 3,
            "z": -18,
            "elements": [
                "gregtech:meta_block_frame_2@1"
            ]
        },
        {
            "x": 1,
            "y": 2,
            "z": -35,
            "elements": [
                "gregtech:transparent_casing@1"
            ]
        },
        {
            "x": 17,
            "y": 3,
            "z": -18,
            "elements": [
                "gregtech:meta_block_frame_2@1"
            ]
        },
        {
            "x": 0,
            "y": 2,
            "z": -35,
            "elements": [
                "gregtech:transparent_casing@1"
            ]
        },
        {
            "x": -1,
            "y": 2,
            "z": -35,
            "elements": [
                "gregtech:transparent_casing@1"
            ]
        },
        {
            "x": -2,
            "y": 2,
            "z": -35,
            "elements": [
                "gregtech:fusion_casing@3"
            ]
        },
        {
            "x": -3,
            "y": 2,
            "z": -35,
            "elements": [
                "gregtech:meta_block_frame_2@1"
            ]
        },
        {
            "x": 4,
            "y": 1,
            "z": -35,
            "elements": [
                "gregtech:fusion_casing@3"
            ]
        },
        {
            "x": 20,
            "y": 2,
            "z": -18,
            "elements": [
                "gregtech:meta_block_frame_2@1"
            ]
        },
        {
            "x": 3,
            "y": 1,
            "z": -35,
            "elements": [
                "gregtech:fusion_casing@3"
            ]
        },
        {
            "x": 19,
            "y": 2,
            "z": -18,
            "elements": [
                "gregtech:fusion_casing@3"
            ]
        },
        {
            "x": 2,
            "y": 1,
            "z": -35,
            "elements": [
                "gregtech:meta_block_frame_127@10"
            ]
        },
        {
            "x": 18,
            "y": 2,
            "z": -18,
            "elements": [
                "gregtech:fusion_casing@3"
            ]
        },
        {
            "x": 17,
            "y": 2,
            "z": -18,
            "elements": [
                "gregtech:fusion_casing@3"
            ]
        },
        {
            "x": 16,
            "y": 2,
            "z": -18,
            "elements": [
                "gregtech:meta_block_frame_2@1"
            ]
        },
        {
            "x": -2,
            "y": 1,
            "z": -35,
            "elements": [
                "gregtech:meta_block_frame_127@10"
            ]
        },
        {
            "x": -17,
            "y": 3,
            "z": -18,
            "elements": [
                "gregtech:meta_block_frame_2@1"
            ]
        },
        {
            "x": -3,
            "y": 1,
            "z": -35,
            "elements": [
                "gregtech:fusion_casing@3"
            ]
        },
        {
            "x": -18,
            "y": 3,
            "z": -18,
            "elements": [
                "gregtech:meta_block_frame_2@1"
            ]
        },
        {
            "x": -4,
            "y": 1,
            "z": -35,
            "elements": [
                "gregtech:fusion_casing@3"
            ]
        },
        {
            "x": -19,
            "y": 3,
            "z": -18,
            "elements": [
                "gregtech:meta_block_frame_2@1"
            ]
        },
        {
            "x": 21,
            "y": 1,
            "z": -18,
            "elements": [
                "gregtech:meta_block_frame_2@1"
            ]
        },
        {
            "x": 4,
            "y": 0,
            "z": -35,
            "elements": [
                "gregtech:fusion_casing@3"
            ]
        },
        {
            "x": 20,
            "y": 1,
            "z": -18,
            "elements": [
                "gregtech:fusion_casing@3"
            ]
        },
        {
            "x": 3,
            "y": 0,
            "z": -35,
            "elements": [
                "gregtech:fusion_casing@3"
            ]
        },
        {
            "x": 16,
            "y": 1,
            "z": -18,
            "elements": [
                "gregtech:fusion_casing@3"
            ]
        },
        {
            "x": 15,
            "y": 1,
            "z": -18,
            "elements": [
                "gregtech:meta_block_frame_2@1"
            ]
        },
        {
            "x": -16,
            "y": 2,
            "z": -18,
            "elements": [
                "gregtech:meta_block_frame_2@1"
            ]
        },
        {
            "x": -17,
            "y": 2,
            "z": -18,
            "elements": [
                "gregtech:fusion_casing@3"
            ]
        },
        {
            "x": -3,
            "y": 0,
            "z": -35,
            "elements": [
                "gregtech:fusion_casing@3"
            ]
        },
        {
            "x": -18,
            "y": 2,
            "z": -18,
            "elements": [
                "gregtech:fusion_casing@3"
            ]
        },
        {
            "x": -4,
            "y": 0,
            "z": -35,
            "elements": [
                "gregtech:fusion_casing@3"
            ]
        },
        {
            "x": -19,
            "y": 2,
            "z": -18,
            "elements": [
                "gregtech:fusion_casing@3"
            ]
        },
        {
            "x": -20,
            "y": 2,
            "z": -18,
            "elements": [
                "gregtech:meta_block_frame_2@1"
            ]
        },
        {
            "x": 13,
            "y": 2,
            "z": -1,
            "elements": [
                "gregtech:fusion_casing@3"
            ]
        },
        {
            "x": 12,
            "y": 2,
            "z": -1,
            "elements": [
                "gregtech:fusion_casing@3"
            ]
        },
        {
            "x": 11,
            "y": 2,
            "z": -1,
            "elements": [
                "gregtech:fusion_casing@3"
            ]
        },
        {
            "x": 10,
            "y": 2,
            "z": -1,
            "elements": [
                "gregtech:fusion_casing@3"
            ]
        },
        {
            "x": -10,
            "y": -2,
            "z": 1,
            "elements": [
                "gregtech:fusion_casing@3"
            ]
        },
        {
            "x": 9,
            "y": 2,
            "z": -1,
            "elements": [
                "gregtech:fusion_casing@3"
            ]
        },
        {
            "x": -9,
            "y": -2,
            "z": 1,
            "elements": [
                "gregtech:fusion_casing@3"
            ]
        },
        {
            "x": -8,
            "y": -2,
            "z": 1,
            "elements": [
                "gregtech:fusion_casing@3"
            ]
        },
        {
            "x": -7,
            "y": -2,
            "z": 1,
            "elements": [
                "gregtech:fusion_casing@3"
            ]
        },
        {
            "x": 21,
            "y": 0,
            "z": -18,
            "elements": [
                "gregtech:meta_block_frame_2@1"
            ]
        },
        {
            "x": -6,
            "y": -2,
            "z": 1,
            "elements": [
                "gregtech:fusion_casing@3"
            ]
        },
        {
            "x": 4,
            "y": -1,
            "z": -35,
            "elements": [
                "gregtech:fusion_casing@3"
            ]
        },
        {
            "x": 20,
            "y": 0,
            "z": -18,
            "elements": [
                "gregtech:fusion_casing@3"
            ]
        },
        {
            "x": -5,
            "y": -2,
            "z": 1,
            "elements": [
                "gregtech:fusion_casing@3"
            ]
        },
        {
            "x": 3,
            "y": -1,
            "z": -35,
            "elements": [
                "gregtech:fusion_casing@3"
            ]
        },
        {
            "x": 2,
            "y": -1,
            "z": -35,
            "elements": [
                "gregtech:meta_block_frame_127@10"
            ]
        },
        {
            "x": 18,
            "y": 0,
            "z": -18,
            "elements": [
                "gregtech:fusion_casing@1"
            ]
        },
        {
            "x": -3,
            "y": -2,
            "z": 1,
            "elements": [
                "gregtech:meta_block_frame_2@1"
            ]
        },
        {
            "x": -2,
            "y": -2,
            "z": 1,
            "elements": [
                "gregtech:fusion_casing@3"
            ]
        },
        {
            "x": 16,
            "y": 0,
            "z": -18,
            "elements": [
                "gregtech:fusion_casing@3"
            ]
        },
        {
            "x": -15,
            "y": 1,
            "z": -18,
            "elements": [
                "gregtech:meta_block_frame_2@1"
            ]
        },
        {
            "x": -1,
            "y": -2,
            "z": 1,
            "elements": [
                "gregtech:transparent_casing@1"
            ]
        },
        {
            "x": -16,
            "y": 1,
            "z": -18,
            "elements": [
                "gregtech:fusion_casing@3"
            ]
        },
        {
            "x": 15,
            "y": 0,
            "z": -18,
            "elements": [
                "gregtech:meta_block_frame_2@1"
            ]
        },
        {
            "x": 0,
            "y": -2,
            "z": 1,
            "elements": [
                "gregtech:transparent_casing@1"
            ]
        },
        {
            "x": -2,
            "y": -1,
            "z": -35,
            "elements": [
                "gregtech:meta_block_frame_127@10"
            ]
        },
        {
            "x": 1,
            "y": -2,
            "z": 1,
            "elements": [
                "gregtech:transparent_casing@1"
            ]
        },
        {
            "x": -3,
            "y": -1,
            "z": -35,
            "elements": [
                "gregtech:fusion_casing@3"
            ]
        },
        {
            "x": 2,
            "y": -2,
            "z": 1,
            "elements": [
                "gregtech:fusion_casing@3"
            ]
        },
        {
            "x": -4,
            "y": -1,
            "z": -35,
            "elements": [
                "gregtech:fusion_casing@3"
            ]
        },
        {
            "x": 3,
            "y": -2,
            "z": 1,
            "elements": [
                "gregtech:meta_block_frame_2@1"
            ]
        },
        {
            "x": -20,
            "y": 1,
            "z": -18,
            "elements": [
                "gregtech:fusion_casing@3"
            ]
        },
        {
            "x": -21,
            "y": 1,
            "z": -18,
            "elements": [
                "gregtech:meta_block_frame_2@1"
            ]
        },
        {
            "x": 5,
            "y": -2,
            "z": 1,
            "elements": [
                "gregtech:fusion_casing@3"
            ]
        },
        {
            "x": 6,
            "y": -2,
            "z": 1,
            "elements": [
                "gregtech:fusion_casing@3"
            ]
        },
        {
            "x": 7,
            "y": -2,
            "z": 1,
            "elements": [
                "gregtech:fusion_casing@3"
            ]
        },
        {
            "x": 8,
            "y": -2,
            "z": 1,
            "elements": [
                "gregtech:fusion_casing@3"
            ]
        },
        {
            "x": -9,
            "y": 2,
            "z": -1,
            "elements": [
                "gregtech:fusion_casing@3"
            ]
        },
        {
            "x": 9,
            "y": -2,
            "z": 1,
            "elements": [
                "gregtech:fusion_casing@3"
            ]
        },
        {
            "x": -10,
            "y": 2,
            "z": -1,
            "elements": [
                "gregtech:fusion_casing@3"
            ]
        },
        {
            "x": 10,
            "y": -2,
            "z": 1,
            "elements": [
                "gregtech:fusion_casing@3"
            ]
        },
        {
            "x": -11,
            "y": 2,
            "z": -1,
            "elements": [
                "gregtech:fusion_casing@3"
            ]
        },
        {
            "x": -12,
            "y": 2,
            "z": -1,
            "elements": [
                "gregtech:fusion_casing@3"
            ]
        },
        {
            "x": -13,
            "y": 2,
            "z": -1,
            "elements": [
                "gregtech:fusion_casing@3"
            ]
        },
        {
            "x": 14,
            "y": 1,
            "z": -1,
            "elements": [
                "gregtech:fusion_casing@3"
            ]
        },
        {
            "x": -12,
            "y": -1,
            "z": 1,
            "elements": [
                "gregtech:fusion_casing@3"
            ]
        },
        {
            "x": -11,
            "y": -1,
            "z": 1,
            "elements": [
                "gregtech:fusion_casing@3"
            ]
        },
        {
            "x": 8,
            "y": 1,
            "z": -1,
            "elements": [
                "gregtech:fusion_casing@3"
            ]
        },
        {
            "x": 7,
            "y": 1,
            "z": -1,
            "elements": [
                "gregtech:fusion_casing@3"
            ]
        },
        {
            "x": 21,
            "y": -1,
            "z": -18,
            "elements": [
                "gregtech:meta_block_frame_2@1"
            ]
        },
        {
            "x": 20,
            "y": -1,
            "z": -18,
            "elements": [
                "gregtech:fusion_casing@3"
            ]
        },
        {
            "x": 3,
            "y": -2,
            "z": -35,
            "elements": [
                "gregtech:meta_block_frame_2@1"
            ]
        },
        {
            "x": 2,
            "y": -2,
            "z": -35,
            "elements": [
                "gregtech:fusion_casing@3"
            ]
        },
        {
            "x": -4,
            "y": -1,
            "z": 1,
            "elements": [
                "gregtech:fusion_casing@3"
            ]
        },
        {
            "x": -3,
            "y": -1,
            "z": 1,
            "elements": [
                "gregtech:fusion_casing@3"
            ]
        },
        {
            "x": 1,
            "y": -2,
            "z": -35,
            "elements": [
                "gregtech:transparent_casing@1"
            ]
        },
        {
            "x": 0,
            "y": -2,
            "z": -35,
            "elements": [
                "gregtech:transparent_casing@1"
            ]
        },
        {
            "x": 16,
            "y": -1,
            "z": -18,
            "elements": [
                "gregtech:fusion_casing@3"
            ]
        },
        {
            "x": -15,
            "y": 0,
            "z": -18,
            "elements": [
                "gregtech:meta_block_frame_2@1"
            ]
        },
        {
            "x": -2,
            "y": -1,
            "z": 1,
            "elements": [
                "gregtech:meta_block_frame_127@10"
            ]
        },
        {
            "x": -1,
            "y": -2,
            "z": -35,
            "elements": [
                "gregtech:transparent_casing@1"
            ]
        },
        {
            "x": -16,
            "y": 0,
            "z": -18,
            "elements": [
                "gregtech:fusion_casing@3"
            ]
        },
        {
            "x": 15,
            "y": -1,
            "z": -18,
            "elements": [
                "gregtech:meta_block_frame_2@1"
            ]
        },
        {
            "x": -2,
            "y": -2,
            "z": -35,
            "elements": [
                "gregtech:fusion_casing@3"
            ]
        },
        {
            "x": -3,
            "y": -2,
            "z": -35,
            "elements": [
                "gregtech:meta_block_frame_2@1"
            ]
        },
        {
            "x": -18,
            "y": 0,
            "z": -18,
            "elements": [
                "gregtech:fusion_casing@1"
            ]
        },
        {
            "x": 2,
            "y": -1,
            "z": 1,
            "elements": [
                "gregtech:meta_block_frame_127@10"
            ]
        },
        {
            "x": 3,
            "y": -1,
            "z": 1,
            "elements": [
                "gregtech:fusion_casing@3"
            ]
        },
        {
            "x": -20,
            "y": 0,
            "z": -18,
            "elements": [
                "gregtech:fusion_casing@3"
            ]
        },
        {
            "x": 4,
            "y": -1,
            "z": 1,
            "elements": [
                "gregtech:fusion_casing@3"
            ]
        },
        {
            "x": -21,
            "y": 0,
            "z": -18,
            "elements": [
                "gregtech:meta_block_frame_2@1"
            ]
        },
        {
            "x": -7,
            "y": 1,
            "z": -1,
            "elements": [
                "gregtech:fusion_casing@3"
            ]
        },
        {
            "x": -8,
            "y": 1,
            "z": -1,
            "elements": [
                "gregtech:fusion_casing@3"
            ]
        },
        {
            "x": 11,
            "y": -1,
            "z": 1,
            "elements": [
                "gregtech:fusion_casing@3"
            ]
        },
        {
            "x": 12,
            "y": -1,
            "z": 1,
            "elements": [
                "gregtech:fusion_casing@3"
            ]
        },
        {
            "x": -14,
            "y": 1,
            "z": -1,
            "elements": [
                "gregtech:fusion_casing@3"
            ]
        },
        {
            "x": 14,
            "y": 0,
            "z": -1,
            "elements": [
                "gregtech:fusion_casing@3"
            ]
        },
        {
            "x": 12,
            "y": 0,
            "z": -1,
            "elements": [
                "gregtech:fusion_casing@1"
            ]
        },
        {
            "x": -12,
            "y": 0,
            "z": 1,
            "elements": [
                "gregtech:fusion_casing@3"
            ]
        },
        {
            "x": 11,
            "y": 0,
            "z": -1,
            "elements": [
                "gregtech:fusion_casing@1"
            ]
        },
        {
            "x": 8,
            "y": 0,
            "z": -1,
            "elements": [
                "gregtech:fusion_casing@3"
            ]
        },
        {
            "x": -9,
            "y": 0,
            "z": 1,
            "elements": [
                "gregtech:fusion_casing@1"
            ]
        },
        {
            "x": 7,
            "y": 0,
            "z": -1,
            "elements": [
                "gregtech:fusion_casing@3"
            ]
        },
        {
            "x": -8,
            "y": 0,
            "z": 1,
            "elements": [
                "gregtech:fusion_casing@1"
            ]
        },
        {
            "x": 20,
            "y": -2,
            "z": -18,
            "elements": [
                "gregtech:meta_block_frame_2@1"
            ]
        },
        {
            "x": 19,
            "y": -2,
            "z": -18,
            "elements": [
                "gregtech:fusion_casing@3"
            ]
        },
        {
            "x": 18,
            "y": -2,
            "z": -18,
            "elements": [
                "gregtech:fusion_casing@3"
            ]
        },
        {
            "x": -4,
            "y": 0,
            "z": 1,
            "elements": [
                "gregtech:fusion_casing@3"
            ]
        },
        {
            "x": 17,
            "y": -2,
            "z": -18,
            "elements": [
                "gregtech:fusion_casing@3"
            ]
        },
        {
            "x": -3,
            "y": 0,
            "z": 1,
            "elements": [
                "gregtech:fusion_casing@3"
            ]
        },
        {
            "x": 16,
            "y": -2,
            "z": -18,
            "elements": [
                "gregtech:meta_block_frame_2@1"
            ]
        },
        {
            "x": -15,
            "y": -1,
            "z": -18,
            "elements": [
                "gregtech:meta_block_frame_2@1"
            ]
        },
        {
            "x": -16,
            "y": -1,
            "z": -18,
            "elements": [
                "gregtech:fusion_casing@3"
            ]
        },
        {
            "x": -20,
            "y": -1,
            "z": -18,
            "elements": [
                "gregtech:fusion_casing@3"
            ]
        },
        {
            "x": 3,
            "y": 0,
            "z": 1,
            "elements": [
                "gregtech:fusion_casing@3"
            ]
        },
        {
            "x": 4,
            "y": 0,
            "z": 1,
            "elements": [
                "gregtech:fusion_casing@3"
            ]
        },
        {
            "x": -21,
            "y": -1,
            "z": -18,
            "elements": [
                "gregtech:meta_block_frame_2@1"
            ]
        },
        {
            "x": -7,
            "y": 0,
            "z": -1,
            "elements": [
                "gregtech:fusion_casing@3"
            ]
        },
        {
            "x": -8,
            "y": 0,
            "z": -1,
            "elements": [
                "gregtech:fusion_casing@3"
            ]
        },
        {
            "x": 8,
            "y": 0,
            "z": 1,
            "elements": [
                "gregtech:fusion_casing@1"
            ]
        },
        {
            "x": 9,
            "y": 0,
            "z": 1,
            "elements": [
                "gregtech:fusion_casing@1"
            ]
        },
        {
            "x": -11,
            "y": 0,
            "z": -1,
            "elements": [
                "gregtech:fusion_casing@1"
            ]
        },
        {
            "x": -12,
            "y": 0,
            "z": -1,
            "elements": [
                "gregtech:fusion_casing@1"
            ]
        },
        {
            "x": 12,
            "y": 0,
            "z": 1,
            "elements": [
                "gregtech:fusion_casing@3"
            ]
        },
        {
            "x": -14,
            "y": 0,
            "z": -1,
            "elements": [
                "gregtech:fusion_casing@3"
            ]
        },
        {
            "x": 14,
            "y": -1,
            "z": -1,
            "elements": [
                "gregtech:fusion_casing@3"
            ]
        },
        {
            "x": -12,
            "y": 1,
            "z": 1,
            "elements": [
                "gregtech:fusion_casing@3"
            ]
        },
        {
            "x": -11,
            "y": 1,
            "z": 1,
            "elements": [
                "gregtech:fusion_casing@3"
            ]
        },
        {
            "x": 8,
            "y": -1,
            "z": -1,
            "elements": [
                "gregtech:fusion_casing@3"
            ]
        },
        {
            "x": 7,
            "y": -1,
            "z": -1,
            "elements": [
                "gregtech:fusion_casing@3"
            ]
        },
        {
            "x": 19,
            "y": -3,
            "z": -18,
            "elements": [
                "gregtech:meta_block_frame_2@1"
            ]
        },
        {
            "x": 18,
            "y": -3,
            "z": -18,
            "elements": [
                "gregtech:meta_block_frame_2@1"
            ]
        },
        {
            "x": -4,
            "y": 1,
            "z": 1,
            "elements": [
                "gregtech:fusion_casing@3"
            ]
        },
        {
            "x": 17,
            "y": -3,
            "z": -18,
            "elements": [
                "gregtech:meta_block_frame_2@1"
            ]
        },
        {
            "x": -3,
            "y": 1,
            "z": 1,
            "elements": [
                "gregtech:fusion_casing@3"
            ]
        },
        {
            "x": -2,
            "y": 1,
            "z": 1,
            "elements": [
                "gregtech:meta_block_frame_127@10"
            ]
        },
        {
            "x": -16,
            "y": -2,
            "z": -18,
            "elements": [
                "gregtech:meta_block_frame_2@1"
            ]
        },
        {
            "x": -17,
            "y": -2,
            "z": -18,
            "elements": [
                "gregtech:fusion_casing@3"
            ]
        },
        {
            "x": -18,
            "y": -2,
            "z": -18,
            "elements": [
                "gregtech:fusion_casing@3"
            ]
        },
        {
            "x": -19,
            "y": -2,
            "z": -18,
            "elements": [
                "gregtech:fusion_casing@3"
            ]
        },
        {
            "x": 2,
            "y": 1,
            "z": 1,
            "elements": [
                "gregtech:meta_block_frame_127@10"
            ]
        },
        {
            "x": -20,
            "y": -2,
            "z": -18,
            "elements": [
                "gregtech:meta_block_frame_2@1"
            ]
        },
        {
            "x": 3,
            "y": 1,
            "z": 1,
            "elements": [
                "gregtech:fusion_casing@3"
            ]
        },
        {
            "x": 4,
            "y": 1,
            "z": 1,
            "elements": [
                "gregtech:fusion_casing@3"
            ]
        },
        {
            "x": -7,
            "y": -1,
            "z": -1,
            "elements": [
                "gregtech:fusion_casing@3"
            ]
        },
        {
            "x": -8,
            "y": -1,
            "z": -1,
            "elements": [
                "gregtech:fusion_casing@3"
            ]
        },
        {
            "x": 11,
            "y": 1,
            "z": 1,
            "elements": [
                "gregtech:fusion_casing@3"
            ]
        },
        {
            "x": 12,
            "y": 1,
            "z": 1,
            "elements": [
                "gregtech:fusion_casing@3"
            ]
        },
        {
            "x": -14,
            "y": -1,
            "z": -1,
            "elements": [
                "gregtech:fusion_casing@3"
            ]
        },
        {
            "x": 13,
            "y": -2,
            "z": -1,
            "elements": [
                "gregtech:fusion_casing@3"
            ]
        },
        {
            "x": 12,
            "y": -2,
            "z": -1,
            "elements": [
                "gregtech:fusion_casing@3"
            ]
        },
        {
            "x": 11,
            "y": -2,
            "z": -1,
            "elements": [
                "gregtech:fusion_casing@3"
            ]
        },
        {
            "x": 10,
            "y": -2,
            "z": -1,
            "elements": [
                "gregtech:fusion_casing@3"
            ]
        },
        {
            "x": 9,
            "y": -2,
            "z": -1,
            "elements": [
                "gregtech:fusion_casing@3"
            ]
        },
        {
            "x": -10,
            "y": 2,
            "z": 1,
            "elements": [
                "gregtech:fusion_casing@3"
            ]
        },
        {
            "x": -9,
            "y": 2,
            "z": 1,
            "elements": [
                "gregtech:fusion_casing@3"
            ]
        },
        {
            "x": -8,
            "y": 2,
            "z": 1,
            "elements": [
                "gregtech:fusion_casing@3"
            ]
        },
        {
            "x": -7,
            "y": 2,
            "z": 1,
            "elements": [
                "gregtech:fusion_casing@3"
            ]
        },
        {
            "x": -6,
            "y": 2,
            "z": 1,
            "elements": [
                "gregtech:fusion_casing@3"
            ]
        },
        {
            "x": -5,
            "y": 2,
            "z": 1,
            "elements": [
                "gregtech:fusion_casing@3"
            ]
        },
        {
            "x": -3,
            "y": 2,
            "z": 1,
            "elements": [
                "gregtech:meta_block_frame_2@1"
            ]
        },
        {
            "x": -2,
            "y": 2,
            "z": 1,
            "elements": [
                "gregtech:fusion_casing@3"
            ]
        },
        {
            "x": -1,
            "y": 2,
            "z": 1,
            "elements": [
                "gregtech:transparent_casing@1"
            ]
        },
        {
            "x": -17,
            "y": -3,
            "z": -18,
            "elements": [
                "gregtech:meta_block_frame_2@1"
            ]
        },
        {
            "x": 0,
            "y": 2,
            "z": 1,
            "elements": [
                "gregtech:transparent_casing@1"
            ]
        },
        {
            "x": -18,
            "y": -3,
            "z": -18,
            "elements": [
                "gregtech:meta_block_frame_2@1"
            ]
        },
        {
            "x": 1,
            "y": 2,
            "z": 1,
            "elements": [
                "gregtech:transparent_casing@1"
            ]
        },
        {
            "x": -19,
            "y": -3,
            "z": -18,
            "elements": [
                "gregtech:meta_block_frame_2@1"
            ]
        },
        {
            "x": 2,
            "y": 2,
            "z": 1,
            "elements": [
                "gregtech:fusion_casing@3"
            ]
        },
        {
            "x": 3,
            "y": 2,
            "z": 1,
            "elements": [
                "gregtech:meta_block_frame_2@1"
            ]
        },
        {
            "x": 5,
            "y": 2,
            "z": 1,
            "elements": [
                "gregtech:fusion_casing@3"
            ]
        },
        {
            "x": 6,
            "y": 2,
            "z": 1,
            "elements": [
                "gregtech:fusion_casing@3"
            ]
        },
        {
            "x": 7,
            "y": 2,
            "z": 1,
            "elements": [
                "gregtech:fusion_casing@3"
            ]
        },
        {
            "x": -9,
            "y": -2,
            "z": -1,
            "elements": [
                "gregtech:fusion_casing@3"
            ]
        },
        {
            "x": 8,
            "y": 2,
            "z": 1,
            "elements": [
                "gregtech:fusion_casing@3"
            ]
        },
        {
            "x": -10,
            "y": -2,
            "z": -1,
            "elements": [
                "gregtech:fusion_casing@3"
            ]
        },
        {
            "x": 9,
            "y": 2,
            "z": 1,
            "elements": [
                "gregtech:fusion_casing@3"
            ]
        },
        {
            "x": -11,
            "y": -2,
            "z": -1,
            "elements": [
                "gregtech:fusion_casing@3"
            ]
        },
        {
            "x": 10,
            "y": 2,
            "z": 1,
            "elements": [
                "gregtech:fusion_casing@3"
            ]
        },
        {
            "x": -12,
            "y": -2,
            "z": -1,
            "elements": [
                "gregtech:fusion_casing@3"
            ]
        },
        {
            "x": -13,
            "y": -2,
            "z": -1,
            "elements": [
                "gregtech:fusion_casing@3"
            ]
        },
        {
            "x": 10,
            "y": 2,
            "z": -31,
            "elements": [
                "gregtech:fusion_casing@3"
            ]
        },
        {
            "x": 9,
            "y": 2,
            "z": -31,
            "elements": [
                "gregtech:fusion_casing@3"
            ]
        },
        {
            "x": 8,
            "y": 2,
            "z": -31,
            "elements": [
                "gregtech:fusion_casing@3"
            ]
        },
        {
            "x": 7,
            "y": 2,
            "z": -31,
            "elements": [
                "gregtech:fusion_casing@3"
            ]
        },
        {
            "x": 6,
            "y": 2,
            "z": -31,
            "elements": [
                "gregtech:fusion_casing@3"
            ]
        },
        {
            "x": 5,
            "y": 2,
            "z": -31,
            "elements": [
                "gregtech:fusion_casing@3"
            ]
        },
        {
            "x": 19,
            "y": 3,
            "z": -14,
            "elements": [
                "gregtech:fusion_casing@3"
            ]
        },
        {
            "x": 3,
            "y": 2,
            "z": -31,
            "elements": [
                "gregtech:meta_block_frame_2@1"
            ]
        },
        {
            "x": 2,
            "y": 2,
            "z": -31,
            "elements": [
                "gregtech:fusion_casing@3"
            ]
        },
        {
            "x": 18,
            "y": 3,
            "z": -14,
            "elements": [
                "gregtech:fusion_casing@3"
            ]
        },
        {
            "x": 1,
            "y": 2,
            "z": -31,
            "elements": [
                "gregtech:transparent_casing@1"
            ]
        },
        {
            "x": 17,
            "y": 3,
            "z": -14,
            "elements": [
                "gregtech:fusion_casing@3"
            ]
        },
        {
            "x": 0,
            "y": 2,
            "z": -31,
            "elements": [
                "gregtech:transparent_casing@1"
            ]
        },
        {
            "x": -1,
            "y": 2,
            "z": -31,
            "elements": [
                "gregtech:transparent_casing@1"
            ]
        },
        {
            "x": -2,
            "y": 2,
            "z": -31,
            "elements": [
                "gregtech:fusion_casing@3"
            ]
        },
        {
            "x": -3,
            "y": 2,
            "z": -31,
            "elements": [
                "gregtech:meta_block_frame_2@1"
            ]
        },
        {
            "x": -5,
            "y": 2,
            "z": -31,
            "elements": [
                "gregtech:fusion_casing@3"
            ]
        },
        {
            "x": -6,
            "y": 2,
            "z": -31,
            "elements": [
                "gregtech:fusion_casing@3"
            ]
        },
        {
            "x": -7,
            "y": 2,
            "z": -31,
            "elements": [
                "gregtech:fusion_casing@3"
            ]
        },
        {
            "x": -8,
            "y": 2,
            "z": -31,
            "elements": [
                "gregtech:fusion_casing@3"
            ]
        },
        {
            "x": -9,
            "y": 2,
            "z": -31,
            "elements": [
                "gregtech:fusion_casing@3"
            ]
        },
        {
            "x": -10,
            "y": 2,
            "z": -31,
            "elements": [
                "gregtech:fusion_casing@3"
            ]
        },
        {
            "x": 12,
            "y": 1,
            "z": -31,
            "elements": [
                "gregtech:fusion_casing@3"
            ]
        },
        {
            "x": 11,
            "y": 1,
            "z": -31,
            "elements": [
                "gregtech:fusion_casing@3"
            ]
        },
        {
            "x": 4,
            "y": 1,
            "z": -31,
            "elements": [
                "gregtech:fusion_casing@3"
            ]
        },
        {
            "x": 20,
            "y": 2,
            "z": -14,
            "elements": [
                "gregtech:transparent_casing@1"
            ]
        },
        {
            "x": 3,
            "y": 1,
            "z": -31,
            "elements": [
                "gregtech:fusion_casing@3"
            ]
        },
        {
            "x": 2,
            "y": 1,
            "z": -31,
            "elements": [
                "gregtech:meta_block_frame_127@10"
            ]
        },
        {
            "x": 16,
            "y": 2,
            "z": -14,
            "elements": [
                "gregtech:transparent_casing@1"
            ]
        },
        {
            "x": -2,
            "y": 1,
            "z": -31,
            "elements": [
                "gregtech:meta_block_frame_127@10"
            ]
        },
        {
            "x": -17,
            "y": 3,
            "z": -14,
            "elements": [
                "gregtech:fusion_casing@3"
            ]
        },
        {
            "x": -3,
            "y": 1,
            "z": -31,
            "elements": [
                "gregtech:fusion_casing@3"
            ]
        },
