{
    "registryname": "Large_Assembly_Line",
    "localizedname": "Large Assembly Line(LHL)",
     "color": "c9caca",
    "parts": [
        {
            "x": -1,
            "y": 0,
            "z": 0,
            "elements": [
                "modularmachinery:blockfluidinputhatch"
            ]
        },
        {
            "x": 1,
            "y": 2,
            "z": 1,
            "elements": [
                "modularmachinery:blockcasing@3"
            ]
        },
        {
            "x": -2,
            "y": 0,
            "z": 0,
            "elements": [
                "modularmachinery:blockfluidinputhatch"
            ]
        },
        {
            "x": 2,
            "y": 2,
            "z": 1,
            "elements": [
                "gcym:large_multiblock_casing@2"
            ]
        },
        {
            "x": 1,
            "y": 0,
            "z": 0,
            "elements": [
                "gcym:large_multiblock_casing@2"
            ]
        },
        {
            "x": -3,
            "y": 0,
            "z": 0,
            "elements": [
                "modularmachinery:blockfluidinputhatch"
            ]
        },
        {
            "x": 2,
            "y": 0,
            "z": 0,
            "elements": [
                "gcym:large_multiblock_casing@2"
            ]
        },
        {
            "x": -4,
            "y": 0,
            "z": 0,
            "elements": [
                "modularmachinery:blockfluidinputhatch"
            ]
        },
        {
            "x": -5,
            "y": 0,
            "z": 0,
            "elements": [
                "modularmachinery:blockfluidinputhatch"
            ]
        },
        {
            "x": -6,
            "y": 0,
            "z": 0,
            "elements": [
                "modularmachinery:blockfluidinputhatch"
            ]
        },
        {
            "x": -7,
            "y": 0,
            "z": 0,
            "elements": [
                "modularmachinery:blockfluidinputhatch"
            ]
        },
        {
            "x": -8,
            "y": 0,
            "z": 0,
            "elements": [
                "modularmachinery:blockfluidinputhatch"
            ]
        },
        {
            "x": -9,
            "y": 0,
            "z": 0,
            "elements": [
                "gcym:large_multiblock_casing@2"
            ]
        },
        {
            "x": -10,
            "y": 0,
            "z": 0,
            "elements": [
                "gcym:large_multiblock_casing@2"
            ]
        },
        {
            "x": -11,
            "y": 0,
            "z": 0,
            "elements": [
                "gcym:large_multiblock_casing@2"
            ]
        },
        {
            "x": -12,
            "y": 0,
            "z": 0,
            "elements": [
                "gcym:large_multiblock_casing@2"
            ]
        },
        {
            "x": -13,
            "y": 0,
            "z": 0,
            "elements": [
                "gcym:large_multiblock_casing@2"
            ]
        },
        {
            "x": -14,
            "y": 0,
            "z": 0,
            "elements": [
                "gcym:large_multiblock_casing@2"
            ]
        },
        {
            "x": -15,
            "y": 0,
            "z": 0,
            "elements": [
                "gcym:large_multiblock_casing@2"
            ]
        },
        {
            "x": -16,
            "y": 3,
            "z": 1,
            "elements": [
                "gregtech:metal_casing@4"
            ]
        },
        {
            "x": -16,
            "y": 0,
            "z": 0,
            "elements": [
                "gcym:large_multiblock_casing@2"
            ]
        },
        {
            "x": -16,
            "y": 1,
            "z": 0,
            "elements": [
                "gcym:large_multiblock_casing@2"
            ]
        },
        {
            "x": -15,
            "y": 3,
            "z": 1,
            "elements": [
                "gregtech:multiblock_casing@2"
            ]
        },
        {
            "x": -15,
            "y": 1,
            "z": 0,
            "elements": [
                "gregtech:transparent_casing@2"
            ]
        },
        {
            "x": -14,
            "y": 3,
            "z": 1,
            "elements": [
                "gregtech:multiblock_casing@2"
            ]
        },
        {
            "x": -14,
            "y": 1,
            "z": 0,
            "elements": [
                "gregtech:transparent_casing@2"
            ]
        },
        {
            "x": -13,
            "y": 3,
            "z": 1,
            "elements": [
                "gregtech:multiblock_casing@2"
            ]
        },
        {
            "x": -13,
            "y": 1,
            "z": 0,
            "elements": [
                "gregtech:transparent_casing@2"
            ]
        },
        {
            "x": -12,
            "y": 3,
            "z": 1,
            "elements": [
                "gregtech:multiblock_casing@2"
            ]
        },
        {
            "x": -12,
            "y": 1,
            "z": 0,
            "elements": [
                "gregtech:transparent_casing@2"
            ]
        },
        {
            "x": -11,
            "y": 3,
            "z": 1,
            "elements": [
                "gregtech:multiblock_casing@2"
            ]
        },
        {
            "x": -11,
            "y": 1,
            "z": 0,
            "elements": [
                "gregtech:transparent_casing@2"
            ]
        },
        {
            "x": -10,
            "y": 3,
            "z": 1,
            "elements": [
                "gregtech:multiblock_casing@2"
            ]
        },
        {
            "x": -10,
            "y": 1,
            "z": 0,
            "elements": [
                "gregtech:transparent_casing@2"
            ]
        },
        {
            "x": -9,
            "y": 3,
            "z": 1,
            "elements": [
                "gregtech:multiblock_casing@2"
            ]
        },
        {
            "x": -9,
            "y": 1,
            "z": 0,
            "elements": [
                "gregtech:transparent_casing@2"
            ]
        },
        {
            "x": -8,
            "y": 3,
            "z": 1,
            "elements": [
                "gregtech:multiblock_casing@2"
            ]
        },
        {
            "x": -8,
            "y": 1,
            "z": 0,
            "elements": [
                "gregtech:transparent_casing@2"
            ]
        },
        {
            "x": -7,
            "y": 3,
            "z": 1,
            "elements": [
                "gregtech:multiblock_casing@2"
            ]
        },
        {
            "x": -7,
            "y": 1,
            "z": 0,
            "elements": [
                "gregtech:transparent_casing@2"
            ]
        },
        {
            "x": -6,
            "y": 3,
            "z": 1,
            "elements": [
                "gregtech:multiblock_casing@2"
            ]
        },
        {
            "x": -6,
            "y": 1,
            "z": 0,
            "elements": [
                "gregtech:transparent_casing@2"
            ]
        },
        {
            "x": -5,
            "y": 3,
            "z": 1,
            "elements": [
                "gregtech:multiblock_casing@2"
            ]
        },
        {
            "x": -5,
            "y": 1,
            "z": 0,
            "elements": [
                "gregtech:transparent_casing@2"
            ]
        },
        {
            "x": -4,
            "y": 3,
            "z": 1,
            "elements": [
                "gregtech:multiblock_casing@2"
            ]
        },
        {
            "x": -4,
            "y": 1,
            "z": 0,
            "elements": [
                "gregtech:transparent_casing@2"
            ]
        },
        {
            "x": -3,
            "y": 3,
            "z": 1,
            "elements": [
                "gregtech:multiblock_casing@2"
            ]
        },
        {
            "x": -3,
            "y": 1,
            "z": 0,
            "elements": [
                "gregtech:transparent_casing@2"
            ]
        },
        {
            "x": -2,
            "y": 3,
            "z": 1,
            "elements": [
                "gregtech:multiblock_casing@2"
            ]
        },
        {
            "x": 2,
            "y": -1,
            "z": 0,
            "elements": [
                "gregtech:multiblock_casing@3"
            ]
        },
        {
            "x": -2,
            "y": 1,
            "z": 0,
            "elements": [
                "gregtech:transparent_casing@2"
            ]
        },
        {
            "x": -1,
            "y": 3,
            "z": 1,
            "elements": [
                "gregtech:multiblock_casing@2"
            ]
        },
        {
            "x": 1,
            "y": -1,
            "z": 0,
            "elements": [
                "gregtech:multiblock_casing@3"
            ]
        },
        {
            "x": 0,
            "y": -1,
            "z": 0,
            "elements": [
                "gregtech:multiblock_casing@3"
            ]
        },
        {
            "x": 0,
            "y": 3,
            "z": 1,
            "elements": [
                "gregtech:multiblock_casing@2"
            ]
        },
        {
            "x": -1,
            "y": 1,
            "z": 0,
            "elements": [
                "gregtech:transparent_casing@2"
            ]
        },
        {
            "x": 1,
            "y": 3,
            "z": 1,
            "elements": [
                "gregtech:multiblock_casing@2"
            ]
        },
        {
            "x": 0,
            "y": 1,
            "z": 0,
            "elements": [
                "gregtech:transparent_casing@2"
            ]
        },
        {
            "x": -1,
            "y": -1,
            "z": 0,
            "elements": [
                "gregtech:multiblock_casing@3"
            ]
        },
        {
            "x": -2,
            "y": -1,
            "z": 0,
            "elements": [
                "gregtech:multiblock_casing@3"
            ]
        },
        {
            "x": 2,
            "y": 3,
            "z": 1,
            "elements": [
                "gregtech:metal_casing@4"
            ]
        },
        {
            "x": 1,
            "y": 1,
            "z": 0,
            "elements": [
                "gregtech:transparent_casing@2"
            ]
        },
        {
            "x": -3,
            "y": -1,
            "z": 0,
            "elements": [
                "gregtech:multiblock_casing@3"
            ]
        },
        {
            "x": 2,
            "y": 1,
            "z": 0,
            "elements": [
                "gcym:large_multiblock_casing@2"
            ]
        },
        {
            "x": -4,
            "y": -1,
            "z": 0,
            "elements": [
                "gregtech:multiblock_casing@3"
            ]
        },
        {
            "x": -5,
            "y": -1,
            "z": 0,
            "elements": [
                "gregtech:multiblock_casing@3"
            ]
        },
        {
            "x": -6,
            "y": -1,
            "z": 0,
            "elements": [
                "gregtech:multiblock_casing@3"
            ]
        },
        {
            "x": -7,
            "y": -1,
            "z": 0,
            "elements": [
                "gregtech:multiblock_casing@3"
            ]
        },
        {
            "x": -8,
            "y": -1,
            "z": 0,
            "elements": [
                "gregtech:multiblock_casing@3"
            ]
        },
        {
            "x": -9,
            "y": -1,
            "z": 0,
            "elements": [
                "gregtech:multiblock_casing@3"
            ]
        },
        {
            "x": -10,
            "y": -1,
            "z": 0,
            "elements": [
                "gregtech:multiblock_casing@3"
            ]
        },
        {
            "x": -11,
            "y": -1,
            "z": 0,
            "elements": [
                "gregtech:multiblock_casing@3"
            ]
        },
        {
            "x": -12,
            "y": -1,
            "z": 0,
            "elements": [
                "gregtech:multiblock_casing@3"
            ]
        },
        {
            "x": -13,
            "y": -1,
            "z": 0,
            "elements": [
                "gregtech:multiblock_casing@3"
            ]
        },
        {
            "x": -14,
            "y": -1,
            "z": 0,
            "elements": [
                "gregtech:multiblock_casing@3"
            ]
        },
        {
            "x": -15,
            "y": -1,
            "z": 0,
            "elements": [
                "gregtech:multiblock_casing@3"
            ]
        },
        {
            "x": -16,
            "y": -1,
            "z": 0,
            "elements": [
                "gregtech:multiblock_casing@3"
            ]
        },
        {
            "x": -16,
            "y": 2,
            "z": 0,
            "elements": [
                "gcym:large_multiblock_casing@2"
            ]
        },
        {
            "x": -15,
            "y": 2,
            "z": 0,
            "elements": [
                "gcym:large_multiblock_casing@2"
            ]
        },
        {
            "x": -14,
            "y": 2,
            "z": 0,
            "elements": [
                "gcym:large_multiblock_casing@2"
            ]
        },
        {
            "x": -13,
            "y": 2,
            "z": 0,
            "elements": [
                "gcym:large_multiblock_casing@2"
            ]
        },
        {
            "x": -12,
            "y": 2,
            "z": 0,
            "elements": [
                "gcym:large_multiblock_casing@2"
            ]
        },
        {
            "x": -11,
            "y": 2,
            "z": 0,
            "elements": [
                "gcym:large_multiblock_casing@2"
            ]
        },
        {
            "x": -10,
            "y": 2,
            "z": 0,
            "elements": [
                "gcym:large_multiblock_casing@2"
            ]
        },
        {
            "x": -9,
            "y": 2,
            "z": 0,
            "elements": [
                "gcym:large_multiblock_casing@2"
            ]
        },
        {
            "x": -8,
            "y": 2,
            "z": 0,
            "elements": [
                "gcym:large_multiblock_casing@2"
            ]
        },
        {
            "x": -7,
            "y": 2,
            "z": 0,
            "elements": [
                "gcym:large_multiblock_casing@2"
            ]
        },
        {
            "x": -6,
            "y": 2,
            "z": 0,
            "elements": [
                "gcym:large_multiblock_casing@2"
            ]
        },
        {
            "x": -5,
            "y": 2,
            "z": 0,
            "elements": [
                "gcym:large_multiblock_casing@2"
            ]
        },
        {
            "x": -4,
            "y": 2,
            "z": 0,
            "elements": [
                "gcym:large_multiblock_casing@2"
            ]
        },
        {
            "x": -3,
            "y": 2,
            "z": 0,
            "elements": [
                "gcym:large_multiblock_casing@2"
            ]
        },
        {
            "x": -2,
            "y": 2,
            "z": 0,
            "elements": [
                "gcym:large_multiblock_casing@2"
            ]
        },
        {
            "x": -1,
            "y": 2,
            "z": 0,
            "elements": [
                "gcym:large_multiblock_casing@2"
            ]
        },
        {
            "x": 0,
            "y": 2,
            "z": 0,
            "elements": [
                "gcym:large_multiblock_casing@2"
            ]
        },
        {
            "x": 1,
            "y": 2,
            "z": 0,
            "elements": [
                "gcym:large_multiblock_casing@2"
            ]
        },
        {
            "x": 2,
            "y": 2,
            "z": 0,
            "elements": [
                "gcym:large_multiblock_casing@2"
            ]
        },
        {
            "x": -16,
            "y": 3,
            "z": 0,
            "elements": [
                "gregtech:multiblock_casing@3"
            ]
        },
        {
            "x": -15,
            "y": 3,
            "z": 0,
            "elements": [
                "gregtech:multiblock_casing@3"
            ]
        },
        {
            "x": -14,
            "y": 3,
            "z": 0,
            "elements": [
                "gregtech:multiblock_casing@3"
            ]
        },
        {
            "x": -13,
            "y": 3,
            "z": 0,
            "elements": [
                "gregtech:multiblock_casing@3"
            ]
        },
        {
            "x": -12,
            "y": 3,
            "z": 0,
            "elements": [
                "gregtech:multiblock_casing@3"
            ]
        },
        {
            "x": -11,
            "y": 3,
            "z": 0,
            "elements": [
                "gregtech:multiblock_casing@3"
            ]
        },
        {
            "x": -10,
            "y": 3,
            "z": 0,
            "elements": [
                "gregtech:multiblock_casing@3"
            ]
        },
        {
            "x": -9,
            "y": 3,
            "z": 0,
            "elements": [
                "gregtech:multiblock_casing@3"
            ]
        },
        {
            "x": -8,
            "y": 3,
            "z": 0,
            "elements": [
                "gregtech:multiblock_casing@3"
            ]
        },
        {
            "x": -7,
            "y": 3,
            "z": 0,
            "elements": [
                "gregtech:multiblock_casing@3"
            ]
        },
        {
            "x": -6,
            "y": 3,
            "z": 0,
            "elements": [
                "gregtech:multiblock_casing@3"
            ]
        },
        {
            "x": -5,
            "y": 3,
            "z": 0,
            "elements": [
                "gregtech:multiblock_casing@3"
            ]
        },
        {
            "x": -4,
            "y": 3,
            "z": 0,
            "elements": [
                "gregtech:multiblock_casing@3"
            ]
        },
        {
            "x": -3,
            "y": 3,
            "z": 0,
            "elements": [
                "gregtech:multiblock_casing@3"
            ]
        },
        {
            "x": -2,
            "y": 3,
            "z": 0,
            "elements": [
                "gregtech:multiblock_casing@3"
            ]
        },
        {
            "x": -1,
            "y": 3,
            "z": 0,
            "elements": [
                "gregtech:multiblock_casing@3"
            ]
        },
        {
            "x": 0,
            "y": 3,
            "z": 0,
            "elements": [
                "gregtech:multiblock_casing@3"
            ]
        },
        {
            "x": 1,
            "y": 3,
            "z": 0,
            "elements": [
                "gregtech:multiblock_casing@3"
            ]
        },
        {
            "x": 2,
            "y": 3,
            "z": 0,
            "elements": [
                "gregtech:metal_casing@4"
            ]
        },
        {
            "x": -16,
            "y": -1,
            "z": 4,
            "elements": [
                "gregtech:multiblock_casing@3"
            ]
        },
        {
            "x": -15,
            "y": -1,
            "z": 4,
            "elements": [
                "gregtech:multiblock_casing@3"
            ]
        },
        {
            "x": -14,
            "y": -1,
            "z": 4,
            "elements": [
                "gregtech:multiblock_casing@3"
            ]
        },
        {
            "x": -13,
            "y": -1,
            "z": 4,
            "elements": [
                "gregtech:multiblock_casing@3"
            ]
        },
        {
            "x": -12,
            "y": -1,
            "z": 4,
            "elements": [
                "gregtech:multiblock_casing@3"
            ]
        },
        {
            "x": -11,
            "y": -1,
            "z": 4,
            "elements": [
                "gregtech:multiblock_casing@3"
            ]
        },
        {
            "x": -10,
            "y": -1,
            "z": 4,
            "elements": [
                "gregtech:multiblock_casing@3"
            ]
        },
        {
            "x": -9,
            "y": -1,
            "z": 4,
            "elements": [
                "gregtech:multiblock_casing@3"
            ]
        },
        {
            "x": -8,
            "y": -1,
            "z": 4,
            "elements": [
                "gregtech:multiblock_casing@3"
            ]
        },
        {
            "x": -7,
            "y": -1,
            "z": 4,
            "elements": [
                "gregtech:multiblock_casing@3"
            ]
        },
        {
            "x": -6,
            "y": -1,
            "z": 4,
            "elements": [
                "gregtech:multiblock_casing@3"
            ]
        },
        {
            "x": -5,
            "y": -1,
            "z": 4,
            "elements": [
                "gregtech:multiblock_casing@3"
            ]
        },
        {
            "x": -4,
            "y": -1,
            "z": 4,
            "elements": [
                "gregtech:multiblock_casing@3"
            ]
        },
        {
            "x": -3,
            "y": -1,
            "z": 4,
            "elements": [
                "gregtech:multiblock_casing@3"
            ]
        },
        {
            "x": -2,
            "y": -1,
            "z": 4,
            "elements": [
                "gregtech:multiblock_casing@3"
            ]
        },
        {
            "x": -1,
            "y": -1,
            "z": 4,
            "elements": [
                "gregtech:multiblock_casing@3"
            ]
        },
        {
            "x": 0,
            "y": -1,
            "z": 4,
            "elements": [
                "gregtech:multiblock_casing@3"
            ]
        },
        {
            "x": 1,
            "y": -1,
            "z": 4,
            "elements": [
                "gregtech:multiblock_casing@3"
            ]
        },
        {
            "x": 2,
            "y": -1,
            "z": 4,
            "elements": [
                "gregtech:multiblock_casing@3"
            ]
        },
        {
            "x": -16,
            "y": 0,
            "z": 4,
            "elements": [
                "gcym:large_multiblock_casing@2"
            ]
        },
        {
            "x": -15,
            "y": 0,
            "z": 4,
            "elements": [
                "gcym:large_multiblock_casing@2"
            ]
        },
        {
            "x": -14,
            "y": 0,
            "z": 4,
            "elements": [
                "gcym:large_multiblock_casing@2"
            ]
        },
        {
            "x": -13,
            "y": 0,
            "z": 4,
            "elements": [
                "gcym:large_multiblock_casing@2"
            ]
        },
        {
            "x": -12,
            "y": 0,
            "z": 4,
            "elements": [
                "gcym:large_multiblock_casing@2"
            ]
        },
        {
            "x": -11,
            "y": 0,
            "z": 4,
            "elements": [
                "gcym:large_multiblock_casing@2"
            ]
        },
        {
            "x": -10,
            "y": 0,
            "z": 4,
            "elements": [
                "gcym:large_multiblock_casing@2"
            ]
        },
        {
            "x": -9,
            "y": 0,
            "z": 4,
            "elements": [
                "gcym:large_multiblock_casing@2"
            ]
        },
        {
            "x": -8,
            "y": 0,
            "z": 4,
            "elements": [
                "gcym:large_multiblock_casing@2"
            ]
        },
        {
            "x": -7,
            "y": 0,
            "z": 4,
            "elements": [
                "gcym:large_multiblock_casing@2"
            ]
        },
        {
            "x": -6,
            "y": 0,
            "z": 4,
            "elements": [
                "gcym:large_multiblock_casing@2"
            ]
        },
        {
            "x": -5,
            "y": 0,
            "z": 4,
            "elements": [
                "gcym:large_multiblock_casing@2"
            ]
        },
        {
            "x": -4,
            "y": 0,
            "z": 4,
            "elements": [
                "gcym:large_multiblock_casing@2"
            ]
        },
        {
            "x": -3,
            "y": 0,
            "z": 4,
            "elements": [
                "gcym:large_multiblock_casing@2"
            ]
        },
        {
            "x": -2,
            "y": 0,
            "z": 4,
            "elements": [
                "gcym:large_multiblock_casing@2"
            ]
        },
        {
            "x": -1,
            "y": 0,
            "z": 4,
            "elements": [
                "gcym:large_multiblock_casing@2"
            ]
        },
        {
            "x": 0,
            "y": 0,
            "z": 4,
            "elements": [
                "gcym:large_multiblock_casing@2"
            ]
        },
        {
            "x": 1,
            "y": 0,
            "z": 4,
            "elements": [
                "modularmachinery:blockfluidoutputhatch"
            ]
        },
        {
            "x": 2,
            "y": 0,
            "z": 4,
            "elements": [
                "gcym:large_multiblock_casing@2"
            ]
        },
        {
            "x": -16,
            "y": 1,
            "z": 4,
            "elements": [
                "gcym:large_multiblock_casing@2"
            ]
        },
        {
            "x": -16,
            "y": -1,
            "z": 3,
            "elements": [
                "gregtech:metal_casing@4"
            ]
        },
        {
            "x": -15,
            "y": 1,
            "z": 4,
            "elements": [
                "gregtech:transparent_casing@2"
            ]
        },
        {
            "x": -15,
            "y": -1,
            "z": 3,
            "elements": [
                "gregtech:multiblock_casing@3"
            ]
        },
        {
            "x": -14,
            "y": 1,
            "z": 4,
            "elements": [
                "gregtech:transparent_casing@2"
            ]
        },
        {
            "x": -14,
            "y": -1,
            "z": 3,
            "elements": [
                "gregtech:multiblock_casing@3"
            ]
        },
        {
            "x": -13,
            "y": 1,
            "z": 4,
            "elements": [
                "gregtech:transparent_casing@2"
            ]
        },
        {
            "x": -13,
            "y": -1,
            "z": 3,
            "elements": [
                "gregtech:multiblock_casing@3"
            ]
        },
        {
            "x": -12,
            "y": 1,
            "z": 4,
            "elements": [
                "gregtech:transparent_casing@2"
            ]
        },
        {
            "x": -12,
            "y": -1,
            "z": 3,
            "elements": [
                "gregtech:multiblock_casing@3"
            ]
        },
        {
            "x": -11,
            "y": 1,
            "z": 4,
            "elements": [
                "gregtech:transparent_casing@2"
            ]
        },
        {
            "x": -11,
            "y": -1,
            "z": 3,
            "elements": [
                "gregtech:multiblock_casing@3"
            ]
        },
        {
            "x": -10,
            "y": 1,
            "z": 4,
            "elements": [
                "gregtech:transparent_casing@2"
            ]
        },
        {
            "x": -10,
            "y": -1,
            "z": 3,
            "elements": [
                "gregtech:multiblock_casing@3"
            ]
        },
        {
            "x": -9,
            "y": 1,
            "z": 4,
            "elements": [
                "gregtech:transparent_casing@2"
            ]
        },
        {
            "x": -9,
            "y": -1,
            "z": 3,
            "elements": [
                "gregtech:multiblock_casing@3"
            ]
        },
        {
            "x": -8,
            "y": 1,
            "z": 4,
            "elements": [
                "gregtech:transparent_casing@2"
            ]
        },
        {
            "x": -8,
            "y": -1,
            "z": 3,
            "elements": [
                "gregtech:multiblock_casing@3"
            ]
        },
        {
            "x": -7,
            "y": 1,
            "z": 4,
            "elements": [
                "gregtech:transparent_casing@2"
            ]
        },
        {
            "x": -7,
            "y": -1,
            "z": 3,
            "elements": [
                "gregtech:multiblock_casing@3"
            ]
        },
        {
            "x": -6,
            "y": 1,
            "z": 4,
            "elements": [
                "gregtech:transparent_casing@2"
            ]
        },
        {
            "x": -6,
            "y": -1,
            "z": 3,
            "elements": [
                "gregtech:multiblock_casing@3"
            ]
        },
        {
            "x": -5,
            "y": 1,
            "z": 4,
            "elements": [
                "gregtech:transparent_casing@2"
            ]
        },
        {
            "x": -5,
            "y": -1,
            "z": 3,
            "elements": [
                "gregtech:multiblock_casing@3"
            ]
        },
        {
            "x": -4,
            "y": 1,
            "z": 4,
            "elements": [
                "gregtech:transparent_casing@2"
            ]
        },
        {
            "x": -4,
            "y": -1,
            "z": 3,
            "elements": [
                "gregtech:multiblock_casing@3"
            ]
        },
        {
            "x": -3,
            "y": 1,
            "z": 4,
            "elements": [
                "gregtech:transparent_casing@2"
            ]
        },
        {
            "x": -3,
            "y": -1,
            "z": 3,
            "elements": [
                "gregtech:multiblock_casing@3"
            ]
        },
        {
            "x": -2,
            "y": 1,
            "z": 4,
            "elements": [
                "gregtech:transparent_casing@2"
            ]
        },
        {
            "x": -2,
            "y": -1,
            "z": 3,
            "elements": [
                "gregtech:multiblock_casing@3"
            ]
        },
        {
            "x": -1,
            "y": 1,
            "z": 4,
            "elements": [
                "gregtech:transparent_casing@2"
            ]
        },
        {
            "x": 0,
            "y": 1,
            "z": 4,
            "elements": [
                "gregtech:transparent_casing@2"
            ]
        },
        {
            "x": -1,
            "y": -1,
            "z": 3,
            "elements": [
                "gregtech:multiblock_casing@3"
            ]
        },
        {
            "x": 0,
            "y": -1,
            "z": 3,
            "elements": [
                "gregtech:multiblock_casing@3"
            ]
        },
        {
            "x": 1,
            "y": 1,
            "z": 4,
            "elements": [
                "gregtech:transparent_casing@2"
            ]
        },
        {
            "x": 2,
            "y": 1,
            "z": 4,
            "elements": [
                "gcym:large_multiblock_casing@2"
            ]
        },
        {
            "x": 1,
            "y": -1,
            "z": 3,
            "elements": [
                "gregtech:multiblock_casing@3"
            ]
        },
        {
            "x": 2,
            "y": -1,
            "z": 3,
            "elements": [
                "gregtech:multiblock_casing@3"
            ]
        },
        {
            "x": -16,
            "y": 2,
            "z": 4,
            "elements": [
                "gcym:large_multiblock_casing@2"
            ]
        },
        {
            "x": -16,
            "y": 0,
            "z": 3,
            "elements": [
                "modularmachinery:blockenergyinputhatch"
            ]
        },
        {
            "x": -15,
            "y": 2,
            "z": 4,
            "elements": [
                "gcym:large_multiblock_casing@2"
            ]
        },
        {
            "x": -15,
            "y": 0,
            "z": 3,
            "elements": [
                "modularmachinery:blockcasing@3"
            ]
        },
        {
            "x": -14,
            "y": 2,
            "z": 4,
            "elements": [
                "gcym:large_multiblock_casing@2"
            ]
        },
        {
            "x": -14,
            "y": 0,
            "z": 3,
            "elements": [
                "modularmachinery:blockcasing@3"
            ]
        },
        {
            "x": -13,
            "y": 2,
            "z": 4,
            "elements": [
                "gcym:large_multiblock_casing@2"
            ]
        },
        {
            "x": -13,
            "y": 0,
            "z": 3,
            "elements": [
                "modularmachinery:blockcasing@3"
            ]
        },
        {
            "x": -12,
            "y": 2,
            "z": 4,
            "elements": [
                "gcym:large_multiblock_casing@2"
            ]
        },
        {
            "x": -12,
            "y": 0,
            "z": 3,
            "elements": [
                "modularmachinery:blockcasing@3"
            ]
        },
        {
            "x": -11,
            "y": 2,
            "z": 4,
            "elements": [
                "gcym:large_multiblock_casing@2"
            ]
        },
        {
            "x": -11,
            "y": 0,
            "z": 3,
            "elements": [
                "modularmachinery:blockcasing@3"
            ]
        },
        {
            "x": -10,
            "y": 2,
            "z": 4,
            "elements": [
                "gcym:large_multiblock_casing@2"
            ]
        },
        {
            "x": -10,
            "y": 0,
            "z": 3,
            "elements": [
                "modularmachinery:blockcasing@3"
            ]
        },
        {
            "x": -9,
            "y": 2,
            "z": 4,
            "elements": [
                "gcym:large_multiblock_casing@2"
            ]
        },
        {
            "x": -9,
            "y": 0,
            "z": 3,
            "elements": [
                "modularmachinery:blockcasing@3"
            ]
        },
        {
            "x": -8,
            "y": 2,
            "z": 4,
            "elements": [
                "gcym:large_multiblock_casing@2"
            ]
        },
        {
            "x": -8,
            "y": 0,
            "z": 3,
            "elements": [
                "modularmachinery:blockcasing@3"
            ]
        },
        {
            "x": -7,
            "y": 2,
            "z": 4,
            "elements": [
                "gcym:large_multiblock_casing@2"
            ]
        },
        {
            "x": -7,
            "y": 0,
            "z": 3,
            "elements": [
                "modularmachinery:blockcasing@3"
            ]
        },
        {
            "x": -6,
            "y": 2,
            "z": 4,
            "elements": [
                "gcym:large_multiblock_casing@2"
            ]
        },
        {
            "x": -6,
            "y": 0,
            "z": 3,
            "elements": [
                "modularmachinery:blockcasing@3"
            ]
        },
        {
            "x": -5,
            "y": 2,
            "z": 4,
            "elements": [
                "gcym:large_multiblock_casing@2"
            ]
        },
        {
            "x": -5,
            "y": 0,
            "z": 3,
            "elements": [
                "modularmachinery:blockcasing@3"
            ]
        },
        {
            "x": -4,
            "y": 2,
            "z": 4,
            "elements": [
                "gcym:large_multiblock_casing@2"
            ]
        },
        {
            "x": -4,
            "y": 0,
            "z": 3,

            "elements": [
                "modularmachinery:blockcasing@3"
            ]
        },
        {
            "x": -3,
            "y": 2,
            "z": 4,
            "elements": [
                "gcym:large_multiblock_casing@2"
            ]
        },
        {
            "x": -3,
            "y": 0,
            "z": 3,

            "elements": [
                "modularmachinery:blockcasing@3"
            ]
        },
        {
            "x": -2,
            "y": 2,
            "z": 4,
            "elements": [
                "gcym:large_multiblock_casing@2"
            ]
        },
        {
            "x": -2,
            "y": 0,
            "z": 3,

            "elements": [
                "modularmachinery:blockcasing@3"
            ]
        },
        {
            "x": -1,
            "y": 2,
            "z": 4,
            "elements": [
                "gcym:large_multiblock_casing@2"
            ]
        },
        {
            "x": 0,
            "y": 2,
            "z": 4,
            "elements": [
                "gcym:large_multiblock_casing@2"
            ]
        },
        {
            "x": -1,
            "y": 0,
            "z": 3,

            "elements": [
                "modularmachinery:blockcasing@3"
            ]
        },
        {
            "x": 0,
            "y": 0,
            "z": 3,

            "elements": [
                "modularmachinery:blockcasing@3"
            ]
        },
        {
            "x": 1,
            "y": 2,
            "z": 4,
            "elements": [
                "gcym:large_multiblock_casing@2"
            ]
        },
        {
            "x": 2,
            "y": 2,
            "z": 4,
            "elements": [
                "gcym:large_multiblock_casing@2"
            ]
        },
        {
            "x": 1,
            "y": 0,
            "z": 3,

            "elements": [
                "modularmachinery:blockcasing@3"
            ]
        },
        {
            "x": 2,
            "y": 0,
            "z": 3,
            "elements": [
                "gcym:large_multiblock_casing@2"
            ]
        },
        {
            "x": -16,
            "y": 3,
            "z": 4,
            "elements": [
                "gregtech:multiblock_casing@3"
            ]
        },
        {
            "x": -16,
            "y": 1,
            "z": 3,
            "elements": [
                "gregtech:multiblock_casing@3"
            ]
        },
        {
            "x": -15,
            "y": 3,
            "z": 4,
            "elements": [
                "gregtech:multiblock_casing@3"
            ]
        },
        {
            "x": -16,
            "y": -1,
            "z": 2,
            "elements": [
                "gregtech:metal_casing@4"
            ]
        },
        {
            "x": -15,
            "y": 1,
            "z": 3,
            "elements": [
                "gregtech:multiblock_casing@4"
            ]
        },
        {
            "x": -14,
            "y": 3,
            "z": 4,
            "elements": [
                "gregtech:multiblock_casing@3"
            ]
        },
        {
            "x": -15,
            "y": -1,
            "z": 2,

            "elements": [
                "modularmachinery:blockinputbus@0"
            ]
        },
        {
            "x": -14,
            "y": 1,
            "z": 3,
            "elements": [
                "gregtech:multiblock_casing@4"
            ]
        },
        {
            "x": -13,
            "y": 3,
            "z": 4,
            "elements": [
                "gregtech:multiblock_casing@3"
            ]
        },
        {
            "x": -14,
            "y": -1,
            "z": 2,

            "elements": [
                "modularmachinery:blockinputbus@0"
            ]
        },
        {
            "x": -13,
            "y": 1,
            "z": 3,
            "elements": [
                "gregtech:multiblock_casing@4"
            ]
        },
        {
            "x": -12,
            "y": 3,
            "z": 4,
            "elements": [
                "gregtech:multiblock_casing@3"
            ]
        },
        {
            "x": -13,
            "y": -1,
            "z": 2,

            "elements": [
                "modularmachinery:blockinputbus@0"
            ]
        },
        {
            "x": -12,
            "y": 1,
            "z": 3,
            "elements": [
                "gregtech:multiblock_casing@4"
            ]
        },
        {
            "x": -11,
            "y": 3,
            "z": 4,
            "elements": [
                "gregtech:multiblock_casing@3"
            ]
        },
        {
            "x": -12,
            "y": -1,
            "z": 2,

            "elements": [
                "modularmachinery:blockinputbus@0"
            ]
        },
        {
            "x": -11,
            "y": 1,
            "z": 3,
            "elements": [
                "gregtech:multiblock_casing@4"
            ]
        },
        {
            "x": -10,
            "y": 3,
            "z": 4,
            "elements": [
                "gregtech:multiblock_casing@3"
            ]
        },
        {
            "x": -11,
            "y": -1,
            "z": 2,

            "elements": [
                "modularmachinery:blockinputbus@0"
            ]
        },
        {
            "x": -10,
            "y": 1,
            "z": 3,
            "elements": [
                "gregtech:multiblock_casing@4"
            ]
        },
        {
            "x": -9,
            "y": 3,
            "z": 4,
            "elements": [
                "gregtech:multiblock_casing@3"
            ]
        },
        {
            "x": -10,
            "y": -1,
            "z": 2,

            "elements": [
                "modularmachinery:blockinputbus@0"
            ]
        },
        {
            "x": -9,
            "y": 1,
            "z": 3,
            "elements": [
                "gregtech:multiblock_casing@4"
            ]
        },
        {
            "x": -8,
            "y": 3,
            "z": 4,
            "elements": [
                "gregtech:multiblock_casing@3"
            ]
        },
        {
            "x": -9,
            "y": -1,
            "z": 2,

            "elements": [
                "modularmachinery:blockinputbus@0"
            ]
        },
        {
            "x": -8,
            "y": 1,
            "z": 3,
            "elements": [
                "gregtech:multiblock_casing@4"
            ]
        },
        {
            "x": -7,
            "y": 3,
            "z": 4,
            "elements": [
                "gregtech:multiblock_casing@3"
            ]
        },
        {
            "x": -8,
            "y": -1,
            "z": 2,

            "elements": [
                "modularmachinery:blockinputbus@0"
            ]
        },
        {
            "x": -7,
            "y": 1,
            "z": 3,
            "elements": [
                "gregtech:multiblock_casing@4"
            ]
        },
        {
            "x": -6,
            "y": 3,
            "z": 4,
            "elements": [
                "gregtech:multiblock_casing@3"
            ]
        },
        {
            "x": -7,
            "y": -1,
            "z": 2,

            "elements": [
                "modularmachinery:blockinputbus@0"
            ]
        },
        {
            "x": -6,
            "y": 1,
            "z": 3,
            "elements": [
                "gregtech:multiblock_casing@4"
            ]
        },
        {
            "x": -5,
            "y": 3,
            "z": 4,
            "elements": [
                "gregtech:multiblock_casing@3"
            ]
        },
        {
            "x": -6,
            "y": -1,
            "z": 2,

            "elements": [
                "modularmachinery:blockinputbus@0"
            ]
        },
        {
            "x": -5,
            "y": 1,
            "z": 3,
            "elements": [
                "gregtech:multiblock_casing@4"
            ]
        },
        {
            "x": -4,
            "y": 3,
            "z": 4,
            "elements": [
                "gregtech:multiblock_casing@3"
            ]
        },
        {
            "x": -5,
            "y": -1,
            "z": 2,

            "elements": [
                "modularmachinery:blockinputbus@0"
            ]
        },
        {
            "x": -4,
            "y": 1,
            "z": 3,
            "elements": [
                "gregtech:multiblock_casing@4"
            ]
        },
        {
            "x": -3,
            "y": 3,
            "z": 4,
            "elements": [
                "gregtech:multiblock_casing@3"
            ]
        },
        {
            "x": -4,
            "y": -1,
            "z": 2,

            "elements": [
                "modularmachinery:blockinputbus@0"
            ]
        },
        {
            "x": -3,
            "y": 1,
            "z": 3,
            "elements": [
                "gregtech:multiblock_casing@4"
            ]
        },
        {
            "x": -2,
            "y": 3,
            "z": 4,
            "elements": [
                "gregtech:multiblock_casing@3"
            ]
        },
        {
            "x": -3,
            "y": -1,
            "z": 2,

            "elements": [
                "modularmachinery:blockinputbus@0"
            ]
        },
        {
            "x": -2,
            "y": 1,
            "z": 3,
            "elements": [
                "gregtech:multiblock_casing@4"
            ]
        },
        {
            "x": -1,
            "y": 3,
            "z": 4,
            "elements": [
                "gregtech:multiblock_casing@3"
            ]
        },
        {
            "x": 0,
            "y": 3,
            "z": 4,
            "elements": [
                "gregtech:multiblock_casing@3"
            ]
        },
        {
            "x": -2,
            "y": -1,
            "z": 2,

            "elements": [
                "modularmachinery:blockinputbus@0"
            ]
        },
        {
            "x": -1,
            "y": 1,
            "z": 3,
            "elements": [
                "gregtech:multiblock_casing@4"
            ]
        },
        {
            "x": 1,
            "y": 3,
            "z": 4,
            "elements": [
                "gregtech:multiblock_casing@3"
            ]
        },
        {
            "x": 0,
            "y": 1,
            "z": 3,
            "elements": [
                "gregtech:multiblock_casing@4"
            ]
        },
        {
            "x": -1,
            "y": -1,
            "z": 2,

            "elements": [
                "modularmachinery:blockinputbus@0"
            ]
        },
        {
            "x": 0,
            "y": -1,
            "z": 2,

            "elements": [
                "modularmachinery:blockinputbus@0"
            ]
        },
        {
            "x": 2,
            "y": 3,
            "z": 4,
            "elements": [
                "gregtech:metal_casing@4"
            ]
        },
        {
            "x": 1,
            "y": 1,
            "z": 3,
            "elements": [
                "gregtech:multiblock_casing@4"
            ]
        },
        {
            "x": 2,
            "y": 1,
            "z": 3,
            "elements": [
                "gcym:large_multiblock_casing@2"
            ]
        },
        {
            "x": 1,
            "y": -1,
            "z": 2,

            "elements": [
                "modularmachinery:blockinputbus@0"
            ]
        },
        {
            "x": 2,
            "y": -1,
            "z": 2,
            "elements": [
                "gregtech:multiblock_casing@3"
            ]
        },
        {
            "x": -16,
            "y": 2,
            "z": 3,

            "elements": [
                "modularmachinery:blockenergyinputhatch"
            ]
        },
        {
            "x": -16,
            "y": 0,
            "z": 2,
            "elements": [
                "gregtech:multiblock_casing@3"
            ]
        },
        {
            "x": -15,
            "y": 2,
            "z": 3,

            "elements": [
                "modularmachinery:blockcasing@3"
            ]
        },
        {
            "x": -15,
            "y": 0,
            "z": 2,
            "elements": [
                "gregtech:multiblock_casing@4"
            ]
        },
        {
            "x": -14,
            "y": 2,
            "z": 3,

            "elements": [
                "modularmachinery:blockcasing@3"
            ]
        },
        {
            "x": -14,
            "y": 0,
            "z": 2,
            "elements": [
                "gregtech:multiblock_casing@4"
            ]
        },
        {
            "x": -13,
            "y": 2,
            "z": 3,

            "elements": [
                "modularmachinery:blockcasing@3"
            ]
        },
        {
            "x": -13,
            "y": 0,
            "z": 2,
            "elements": [
                "gregtech:multiblock_casing@4"
            ]
        },
        {
            "x": -12,
            "y": 2,
            "z": 3,

            "elements": [
                "modularmachinery:blockcasing@3"
            ]
        },
        {
            "x": -12,
            "y": 0,
            "z": 2,
            "elements": [
                "gregtech:multiblock_casing@4"
            ]
        },
        {
            "x": -11,
            "y": 2,
            "z": 3,

            "elements": [
                "modularmachinery:blockcasing@3"
            ]
        },
        {
            "x": -11,
            "y": 0,
            "z": 2,
            "elements": [
                "gregtech:multiblock_casing@4"
            ]
        },
        {
            "x": -10,
            "y": 2,
            "z": 3,

            "elements": [
                "modularmachinery:blockcasing@3"
            ]
        },
        {
            "x": -10,
            "y": 0,
            "z": 2,
            "elements": [
                "gregtech:multiblock_casing@4"
            ]
        },
        {
            "x": -9,
            "y": 2,
            "z": 3,

            "elements": [
                "modularmachinery:blockcasing@3"
            ]
        },
        {
            "x": -9,
            "y": 0,
            "z": 2,
            "elements": [
                "gregtech:multiblock_casing@4"
            ]
        },
        {
            "x": -8,
            "y": 2,
            "z": 3,

            "elements": [
                "modularmachinery:blockcasing@3"
            ]
        },
        {
            "x": -8,
            "y": 0,
            "z": 2,
            "elements": [
                "gregtech:multiblock_casing@4"
            ]
        },
        {
            "x": -7,
            "y": 2,
            "z": 3,

            "elements": [
                "modularmachinery:blockcasing@3"
            ]
        },
        {
            "x": -7,
            "y": 0,
            "z": 2,
            "elements": [
                "gregtech:multiblock_casing@4"
            ]
        },
        {
            "x": -6,
            "y": 2,
            "z": 3,

            "elements": [
                "modularmachinery:blockcasing@3"
            ]
        },
        {
            "x": -6,
            "y": 0,
            "z": 2,
            "elements": [
                "gregtech:multiblock_casing@4"
            ]
        },
        {
            "x": -5,
            "y": 2,
            "z": 3,

            "elements": [
                "modularmachinery:blockcasing@3"
            ]
        },
        {
            "x": -5,
            "y": 0,
            "z": 2,
            "elements": [
                "gregtech:multiblock_casing@4"
            ]
        },
        {
            "x": -4,
            "y": 2,
            "z": 3,

            "elements": [
                "modularmachinery:blockcasing@3"
            ]
        },
        {
            "x": -4,
            "y": 0,
            "z": 2,
            "elements": [
                "gregtech:multiblock_casing@4"
            ]
        },
        {
            "x": -3,
            "y": 2,
            "z": 3,

            "elements": [
                "modularmachinery:blockcasing@3"
            ]
        },
        {
            "x": -3,
            "y": 0,
            "z": 2,
            "elements": [
                "gregtech:multiblock_casing@4"
            ]
        },
        {
            "x": -2,
            "y": 2,
            "z": 3,

            "elements": [
                "modularmachinery:blockcasing@3"
            ]
        },
        {
            "x": -2,
            "y": 0,
            "z": 2,
            "elements": [
                "gregtech:multiblock_casing@4"
            ]
        },
        {
            "x": -1,
            "y": 2,
            "z": 3,

            "elements": [
                "modularmachinery:blockcasing@3"
            ]
        },
        {
            "x": 0,
            "y": 2,
            "z": 3,

            "elements": [
                "modularmachinery:blockcasing@3"
            ]
        },
        {
            "x": -1,
            "y": 0,
            "z": 2,
            "elements": [
                "gregtech:multiblock_casing@4"
            ]
        },
        {
            "x": 0,
            "y": 0,
            "z": 2,
            "elements": [
                "gregtech:multiblock_casing@4"
            ]
        },
        {
            "x": 1,
            "y": 2,
            "z": 3,

            "elements": [
                "modularmachinery:blockcasing@3"
            ]
        },
        {
            "x": 2,
            "y": 2,
            "z": 3,
            "elements": [
                "gcym:large_multiblock_casing@2"
            ]
        },
        {
            "x": 1,
            "y": 0,
            "z": 2,
            "elements": [
                "gregtech:multiblock_casing@4"
            ]
        },
        {
            "x": 2,
            "y": 0,
            "z": 2,
            "elements": [
                "gcym:large_multiblock_casing@2"
            ]
        },
        {
            "x": -16,
            "y": 3,
            "z": 3,
            "elements": [
                "gregtech:metal_casing@4"
            ]
        },
        {
            "x": -16,
            "y": 1,
            "z": 2,

            "elements": [
                "modularmachinery:blockenergyinputhatch"
            ]
        },
        {
            "x": -15,
            "y": 3,
            "z": 3,
            "elements": [
                "gregtech:multiblock_casing@2"
            ]
        },
        {
            "x": -16,
            "y": -1,
            "z": 1,
            "elements": [
                "gregtech:metal_casing@4"
            ]
        },
        {
            "x": -15,
            "y": 1,
            "z": 2,
            "elements": [
                "gregtech:multiblock_casing@3"
            ]
        },
        {
            "x": -14,
            "y": 3,
            "z": 3,
            "elements": [
                "gregtech:multiblock_casing@2"
            ]
        },
        {
            "x": -15,
            "y": -1,
            "z": 1,
            "elements": [
                "gregtech:multiblock_casing@3"
            ]
        },
        {
            "x": -14,
            "y": 1,
            "z": 2,
            "elements": [
                "gregtech:multiblock_casing@3"
            ]
        },
        {
            "x": -13,
            "y": 3,
            "z": 3,
            "elements": [
                "gregtech:multiblock_casing@2"
            ]
        },
        {
            "x": -14,
            "y": -1,
            "z": 1,
            "elements": [
                "gregtech:multiblock_casing@3"
            ]
        },
        {
            "x": -13,
            "y": 1,
            "z": 2,
            "elements": [
                "gregtech:multiblock_casing@3"
            ]
        },
        {
            "x": -12,
            "y": 3,
            "z": 3,
            "elements": [
                "gregtech:multiblock_casing@2"
            ]
        },
        {
            "x": -13,
            "y": -1,
            "z": 1,
            "elements": [
                "gregtech:multiblock_casing@3"
            ]
        },
        {
            "x": -12,
            "y": 1,
            "z": 2,
            "elements": [
                "gregtech:multiblock_casing@3"
            ]
        },
        {
            "x": -11,
            "y": 3,
            "z": 3,
            "elements": [
                "gregtech:multiblock_casing@2"
            ]
        },
        {
            "x": -12,
            "y": -1,
            "z": 1,
            "elements": [
                "gregtech:multiblock_casing@3"
            ]
        },
        {
            "x": -11,
            "y": 1,
            "z": 2,
            "elements": [
                "gregtech:multiblock_casing@3"
            ]
        },
        {
            "x": -10,
            "y": 3,
            "z": 3,
            "elements": [
                "gregtech:multiblock_casing@2"
            ]
        },
        {
            "x": -11,
            "y": -1,
            "z": 1,
            "elements": [
                "gregtech:multiblock_casing@3"
            ]
        },
        {
            "x": -10,
            "y": 1,
            "z": 2,
            "elements": [
                "gregtech:multiblock_casing@3"
            ]
        },
        {
            "x": -9,
            "y": 3,
            "z": 3,
            "elements": [
                "gregtech:multiblock_casing@2"
            ]
        },
        {
            "x": -10,
            "y": -1,
            "z": 1,
            "elements": [
                "gregtech:multiblock_casing@3"
            ]
        },
        {
            "x": -9,
            "y": 1,
            "z": 2,
            "elements": [
                "gregtech:multiblock_casing@3"
            ]
        },
        {
            "x": -8,
            "y": 3,
            "z": 3,
            "elements": [
                "gregtech:multiblock_casing@2"
            ]
        },
        {
            "x": -9,
            "y": -1,
            "z": 1,
            "elements": [
                "gregtech:multiblock_casing@3"
            ]
        },
        {
            "x": -8,
            "y": 1,
            "z": 2,
            "elements": [
                "gregtech:multiblock_casing@3"
            ]
        },
        {
            "x": -7,
            "y": 3,
            "z": 3,
            "elements": [
                "gregtech:multiblock_casing@2"
            ]
        },
        {
            "x": -8,
            "y": -1,
            "z": 1,
            "elements": [
                "gregtech:multiblock_casing@3"
            ]
        },
        {
            "x": -7,
            "y": 1,
            "z": 2,
            "elements": [
                "gregtech:multiblock_casing@3"
            ]
        },
        {
            "x": -6,
            "y": 3,
            "z": 3,
            "elements": [
                "gregtech:multiblock_casing@2"
            ]
        },
        {
            "x": -7,
            "y": -1,
            "z": 1,
            "elements": [
                "gregtech:multiblock_casing@3"
            ]
        },
        {
            "x": -6,
            "y": 1,
            "z": 2,
            "elements": [
                "gregtech:multiblock_casing@3"
            ]
        },
        {
            "x": -5,
            "y": 3,
            "z": 3,
            "elements": [
                "gregtech:multiblock_casing@2"
            ]
        },
        {
            "x": -6,
            "y": -1,
            "z": 1,
            "elements": [
                "gregtech:multiblock_casing@3"
            ]
        },
        {
            "x": -5,
            "y": 1,
            "z": 2,
            "elements": [
                "gregtech:multiblock_casing@3"
            ]
        },
        {
            "x": -4,
            "y": 3,
            "z": 3,
            "elements": [
                "gregtech:multiblock_casing@2"
            ]
        },
        {
            "x": -5,
            "y": -1,
            "z": 1,
            "elements": [
                "gregtech:multiblock_casing@3"
            ]
        },
        {
            "x": -4,
            "y": 1,
            "z": 2,
            "elements": [
                "gregtech:multiblock_casing@3"
            ]
        },
        {
            "x": -3,
            "y": 3,
            "z": 3,
            "elements": [
                "gregtech:multiblock_casing@2"
            ]
        },
        {
            "x": -4,
            "y": -1,
            "z": 1,
            "elements": [
                "gregtech:multiblock_casing@3"
            ]
        },
        {
            "x": -3,
            "y": 1,
            "z": 2,
            "elements": [
                "gregtech:multiblock_casing@3"
            ]
        },
        {
            "x": -2,
            "y": 3,
            "z": 3,
            "elements": [
                "gregtech:multiblock_casing@2"
            ]
        },
        {
            "x": -3,
            "y": -1,
            "z": 1,
            "elements": [
                "gregtech:multiblock_casing@3"
            ]
        },
        {
            "x": -2,
            "y": 1,
            "z": 2,
            "elements": [
                "gregtech:multiblock_casing@3"
            ]
        },
        {
            "x": -1,
            "y": 3,
            "z": 3,
            "elements": [
                "gregtech:multiblock_casing@2"
            ]
        },
        {
            "x": 0,
            "y": 3,
            "z": 3,
            "elements": [
                "gregtech:multiblock_casing@2"
            ]
        },
        {
            "x": -2,
            "y": -1,
            "z": 1,
            "elements": [
                "gregtech:multiblock_casing@3"
            ]
        },
        {
            "x": -1,
            "y": 1,
            "z": 2,
            "elements": [
                "gregtech:multiblock_casing@3"
            ]
        },
        {
            "x": 1,
            "y": 3,
            "z": 3,
            "elements": [
                "gregtech:multiblock_casing@2"
            ]
        },
        {
            "x": 0,
            "y": 1,
            "z": 2,
            "elements": [
                "gregtech:multiblock_casing@3"
            ]
        },
        {
            "x": -1,
            "y": -1,
            "z": 1,
            "elements": [
                "gregtech:multiblock_casing@3"
            ]
        },
        {
            "x": 0,
            "y": -1,
            "z": 1,
            "elements": [
                "gregtech:multiblock_casing@3"
            ]
        },
        {
            "x": 2,
            "y": 3,
            "z": 3,
            "elements": [
                "gregtech:metal_casing@4"
            ]
        },
        {
            "x": 1,
            "y": 1,
            "z": 2,
            "elements": [
                "gregtech:multiblock_casing@3"
            ]
        },
        {
            "x": 2,
            "y": 1,
            "z": 2,
            "elements": [
                "modularmachinery:blockoutputbus"
            ]
        },
        {
            "x": 1,
            "y": -1,
            "z": 1,
            "elements": [
                "gregtech:multiblock_casing@3"
            ]
        },
        {
            "x": 2,
            "y": -1,
            "z": 1,
            "elements": [
                "gregtech:multiblock_casing@3"
            ]
        },
        {
            "x": -16,
            "y": 2,
            "z": 2,
            "elements": [
                "gregtech:multiblock_casing@3"
            ]
        },
        {
            "x": -16,
            "y": 0,
            "z": 1,

            "elements": [
                "modularmachinery:blockenergyinputhatch"
            ]
        },
        {
            "x": -15,
            "y": 2,
            "z": 2,
            "elements": [
                "gregtech:multiblock_casing@4"
            ]
        },
        {
            "x": -15,
            "y": 0,
            "z": 1,

            "elements": [
                "modularmachinery:blockcasing@3"
            ]
        },
        {
            "x": -14,
            "y": 2,
            "z": 2,
            "elements": [
                "gregtech:multiblock_casing@4"
            ]
        },
        {
            "x": -14,
            "y": 0,
            "z": 1,

            "elements": [
                "modularmachinery:blockcasing@3"
            ]
        },
        {
            "x": -13,
            "y": 2,
            "z": 2,
            "elements": [
                "gregtech:multiblock_casing@4"
            ]
        },
        {
            "x": -13,
            "y": 0,
            "z": 1,

            "elements": [
                "modularmachinery:blockcasing@3"
            ]
        },
        {
            "x": -12,
            "y": 2,
            "z": 2,
            "elements": [
                "gregtech:multiblock_casing@4"
            ]
        },
        {
            "x": -12,
            "y": 0,
            "z": 1,

            "elements": [
                "modularmachinery:blockcasing@3"
            ]
        },
        {
            "x": -11,
            "y": 2,
            "z": 2,
            "elements": [
                "gregtech:multiblock_casing@4"
            ]
        },
        {
            "x": -11,
            "y": 0,
            "z": 1,

            "elements": [
                "modularmachinery:blockcasing@3"
            ]
        },
        {
            "x": -10,
            "y": 2,
            "z": 2,
            "elements": [
                "gregtech:multiblock_casing@4"
            ]
        },
        {
            "x": -10,
            "y": 0,
            "z": 1,

            "elements": [
                "modularmachinery:blockcasing@3"
            ]
        },
        {
            "x": -9,
            "y": 2,
            "z": 2,
            "elements": [
                "gregtech:multiblock_casing@4"
            ]
        },
        {
            "x": -9,
            "y": 0,
            "z": 1,

            "elements": [
                "modularmachinery:blockcasing@3"
            ]
        },
        {
            "x": -8,
            "y": 2,
            "z": 2,
            "elements": [
                "gregtech:multiblock_casing@4"
            ]
        },
        {
            "x": -8,
            "y": 0,
            "z": 1,

            "elements": [
                "modularmachinery:blockcasing@3"
            ]
        },
        {
            "x": -7,
            "y": 2,
            "z": 2,
            "elements": [
                "gregtech:multiblock_casing@4"
            ]
        },
        {
            "x": -7,
            "y": 0,
            "z": 1,

            "elements": [
                "modularmachinery:blockcasing@3"
            ]
        },
        {
            "x": -6,
            "y": 2,
            "z": 2,
            "elements": [
                "gregtech:multiblock_casing@4"
            ]
        },
        {
            "x": -6,
            "y": 0,
            "z": 1,

            "elements": [
                "modularmachinery:blockcasing@3"
            ]
        },
        {
            "x": -5,
            "y": 2,
            "z": 2,
            "elements": [
                "gregtech:multiblock_casing@4"
            ]
        },
        {
            "x": -5,
            "y": 0,
            "z": 1,

            "elements": [
                "modularmachinery:blockcasing@3"
            ]
        },
        {
            "x": -4,
            "y": 2,
            "z": 2,
            "elements": [
                "gregtech:multiblock_casing@4"
            ]
        },
        {
            "x": -4,
            "y": 0,
            "z": 1,

            "elements": [
                "modularmachinery:blockcasing@3"
            ]
        },
        {
            "x": -3,
            "y": 2,
            "z": 2,
            "elements": [
                "gregtech:multiblock_casing@4"
            ]
        },
        {
            "x": -3,
            "y": 0,
            "z": 1,

            "elements": [
                "modularmachinery:blockcasing@3"
            ]
        },
        {
            "x": -2,
            "y": 2,
            "z": 2,
            "elements": [
                "gregtech:multiblock_casing@4"
            ]
        },
        {
            "x": -2,
            "y": 0,
            "z": 1,

            "elements": [
                "modularmachinery:blockcasing@3"
            ]
        },
        {
            "x": -1,
            "y": 2,
            "z": 2,
            "elements": [
                "gregtech:multiblock_casing@4"
            ]
        },
        {
            "x": 0,
            "y": 2,
            "z": 2,
            "elements": [
                "gregtech:multiblock_casing@4"
            ]
        },
        {
            "x": -1,
            "y": 0,
            "z": 1,

            "elements": [
                "modularmachinery:blockcasing@3"
            ]
        },
        {
            "x": 0,
            "y": 0,
            "z": 1,

            "elements": [
                "modularmachinery:blockcasing@3"
            ]
        },
        {
            "x": 1,
            "y": 2,
            "z": 2,
            "elements": [
                "gregtech:multiblock_casing@4"
            ]
        },
        {
            "x": 2,
            "y": 2,
            "z": 2,
            "elements": [
                "gcym:large_multiblock_casing@2"
            ]
        },
        {
            "x": 1,
            "y": 0,
            "z": 1,

            "elements": [
                "modularmachinery:blockcasing@3"
            ]
        },
        {
            "x": 2,
            "y": 0,
            "z": 1,
            "elements": [
                "gcym:large_multiblock_casing@2"
            ]
        },
        {
            "x": -16,
            "y": 3,
            "z": 2,
            "elements": [
                "gregtech:metal_casing@4"
            ]
        },
        {
            "x": -16,
            "y": 1,
            "z": 1,
            "elements": [
                "gregtech:multiblock_casing@3"
            ]
        },
        {
            "x": -15,
            "y": 3,
            "z": 2,
            "elements": [
                "gregtech:multiblock_casing@2"
            ]
        },
        {
            "x": -15,
            "y": 1,
            "z": 1,
            "elements": [
                "gregtech:multiblock_casing@4"
            ]
        },
        {
            "x": -14,
            "y": 3,
            "z": 2,
            "elements": [
                "gregtech:multiblock_casing@2"
            ]
        },
        {
            "x": -14,
            "y": 1,
            "z": 1,
            "elements": [
                "gregtech:multiblock_casing@4"
            ]
        },
        {
            "x": -13,
            "y": 3,
            "z": 2,
            "elements": [
                "gregtech:multiblock_casing@2"
            ]
        },
        {
            "x": -13,
            "y": 1,
            "z": 1,
            "elements": [
                "gregtech:multiblock_casing@4"
            ]
        },
        {
            "x": -12,
            "y": 3,
            "z": 2,
            "elements": [
                "gregtech:multiblock_casing@2"
            ]
        },
        {
            "x": -12,
            "y": 1,
            "z": 1,
            "elements": [
                "gregtech:multiblock_casing@4"
            ]
        },
        {
            "x": -11,
            "y": 3,
            "z": 2,
            "elements": [
                "gregtech:multiblock_casing@2"
            ]
        },
        {
            "x": -11,
            "y": 1,
            "z": 1,
            "elements": [
                "gregtech:multiblock_casing@4"
            ]
        },
        {
            "x": -10,
            "y": 3,
            "z": 2,
            "elements": [
                "gregtech:multiblock_casing@2"
            ]
        },
        {
            "x": -10,
            "y": 1,
            "z": 1,
            "elements": [
                "gregtech:multiblock_casing@4"
            ]
        },
        {
            "x": -9,
            "y": 3,
            "z": 2,
            "elements": [
                "gregtech:multiblock_casing@2"
            ]
        },
        {
            "x": -9,
            "y": 1,
            "z": 1,
            "elements": [
                "gregtech:multiblock_casing@4"
            ]
        },
        {
            "x": -8,
            "y": 3,
            "z": 2,
            "elements": [
                "gregtech:multiblock_casing@2"
            ]
        },
        {
            "x": -8,
            "y": 1,
            "z": 1,
            "elements": [
                "gregtech:multiblock_casing@4"
            ]
        },
        {
            "x": -7,
            "y": 3,
            "z": 2,
            "elements": [
                "gregtech:multiblock_casing@2"
            ]
        },
        {
            "x": -7,
            "y": 1,
            "z": 1,
            "elements": [
                "gregtech:multiblock_casing@4"
            ]
        },
        {
            "x": -6,
            "y": 3,
            "z": 2,
            "elements": [
                "gregtech:multiblock_casing@2"
            ]
        },
        {
            "x": -6,
            "y": 1,
            "z": 1,
            "elements": [
                "gregtech:multiblock_casing@4"
            ]
        },
        {
            "x": -5,
            "y": 3,
            "z": 2,
            "elements": [
                "gregtech:multiblock_casing@2"
            ]
        },
        {
            "x": -5,
            "y": 1,
            "z": 1,
            "elements": [
                "gregtech:multiblock_casing@4"
            ]
        },
        {
            "x": -4,
            "y": 3,
            "z": 2,
            "elements": [
                "gregtech:multiblock_casing@2"
            ]
        },
        {
            "x": -4,
            "y": 1,
            "z": 1,
            "elements": [
                "gregtech:multiblock_casing@4"
            ]
        },
        {
            "x": -3,
            "y": 3,
            "z": 2,
            "elements": [
                "gregtech:multiblock_casing@2"
            ]
        },
        {
            "x": -3,
            "y": 1,
            "z": 1,
            "elements": [
                "gregtech:multiblock_casing@4"
            ]
        },
        {
            "x": -2,
            "y": 3,
            "z": 2,
            "elements": [
                "gregtech:multiblock_casing@2"
            ]
        },
        {
            "x": -2,
            "y": 1,
            "z": 1,
            "elements": [
                "gregtech:multiblock_casing@4"
            ]
        },
        {
            "x": -1,
            "y": 3,
            "z": 2,
            "elements": [
                "gregtech:multiblock_casing@2"
            ]
        },
        {
            "x": 0,
            "y": 3,
            "z": 2,
            "elements": [
                "gregtech:multiblock_casing@2"
            ]
        },
        {
            "x": -1,
            "y": 1,
            "z": 1,
            "elements": [
                "gregtech:multiblock_casing@4"
            ]
        },
        {
            "x": 1,
            "y": 3,
            "z": 2,
            "elements": [
                "gregtech:multiblock_casing@2"
            ]
        },
        {
            "x": 0,
            "y": 1,
            "z": 1,
            "elements": [
                "gregtech:multiblock_casing@4"
            ]
        },
        {
            "x": 2,
            "y": 3,
            "z": 2,
            "elements": [
                "gregtech:metal_casing@4"
            ]
        },
        {
            "x": 1,
            "y": 1,
            "z": 1,
            "elements": [
                "gregtech:multiblock_casing@4"
            ]
        },
        {
            "x": 2,
            "y": 1,
            "z": 1,
            "elements": [
                "gcym:large_multiblock_casing@2"
            ]
        },
        {
            "x": -16,
            "y": 2,
            "z": 1,

            "elements": [
                "modularmachinery:blockenergyinputhatch"
            ]
        },
        {
            "x": -15,
            "y": 2,
            "z": 1,

            "elements": [
                "modularmachinery:blockcasing@3"
            ]
        },
        {
            "x": -14,
            "y": 2,
            "z": 1,

            "elements": [
                "modularmachinery:blockcasing@3"
            ]
        },
        {
            "x": -13,
            "y": 2,
            "z": 1,

            "elements": [
                "modularmachinery:blockcasing@3"
            ]
        },
        {
            "x": -12,
            "y": 2,
            "z": 1,

            "elements": [
                "modularmachinery:blockcasing@3"
            ]
        },
        {
            "x": -11,
            "y": 2,
            "z": 1,

            "elements": [
                "modularmachinery:blockcasing@3"
            ]
        },
        {
            "x": -10,
            "y": 2,
            "z": 1,

            "elements": [
                "modularmachinery:blockcasing@3"
            ]
        },
        {
            "x": -9,
            "y": 2,
            "z": 1,

            "elements": [
                "modularmachinery:blockcasing@3"
            ]
        },
        {
            "x": -8,
            "y": 2,
            "z": 1,

            "elements": [
                "modularmachinery:blockcasing@3"
            ]
        },
        {
            "x": -7,
            "y": 2,
            "z": 1,

            "elements": [
                "modularmachinery:blockcasing@3"
            ]
        },
        {
            "x": -6,
            "y": 2,
            "z": 1,

            "elements": [
                "modularmachinery:blockcasing@3"
            ]
        },
        {
            "x": -5,
            "y": 2,
            "z": 1,

            "elements": [
                "modularmachinery:blockcasing@3"
            ]
        },
        {
            "x": -4,
            "y": 2,
            "z": 1,

            "elements": [
                "modularmachinery:blockcasing@3"
            ]
        },
        {
            "x": -3,
            "y": 2,
            "z": 1,

            "elements": [
                "modularmachinery:blockcasing@3"
            ]
        },
        {
            "x": -2,
            "y": 2,
            "z": 1,

            "elements": [
                "modularmachinery:blockcasing@3"
            ]
        },
        {
            "x": -1,
            "y": 2,
            "z": 1,

            "elements": [
                "modularmachinery:blockcasing@3"
            ]
        },
        {
            "x": 0,
            "y": 2,
            "z": 1,

            "elements": [
                "modularmachinery:blockcasing@3"
            ]
        }
    ]}