{
    "registryname": "Large_High-Precision_Assembly_Line",
    "localizedname": "Large High-Precision Assembly Line(LH-PAL)",
     "color": "c9caca",
    "parts": [
        {
            "x": -1,
            "y": 0,
            "z": 0,
            "elements": [
                "opencomputers:keyboard"
            ]
        },
        {
            "x": -2,
            "y": 0,
            "z": 0,
            "elements": [
                "gregtech:multiblock_casing@3"
            ]
        },
        {
            "x": 1,
            "y": 0,
            "z": 0,
            "elements": [
                "gregtech:multiblock_casing@3"
            ]
        },
        {
            "x": -7,
            "y": 2,
            "z": 17,
            "elements": [
                "gregtech:transparent_casing@1"
            ]
        },
        {
            "x": -6,
            "y": 2,
            "z": 17,
            "elements": [
                "gregtech:multiblock_casing@4"
            ]
        },
        {
            "x": -5,
            "y": 2,
            "z": 17,
            "elements": [
                "gregtech:boiler_casing@3"
            ]
        },
        {
            "x": -4,
            "y": 2,
            "z": 17,
            "elements": [
                "gregtech:multiblock_casing@4"
            ]
        },
        {
            "x": -3,
            "y": 2,
            "z": 17,
            "elements": [
                "gregtech:boiler_casing@3"
            ]
        },
        {
            "x": -2,
            "y": 2,
            "z": 17,
            "elements": [
                "gregtech:multiblock_casing@4"
            ]
        },
        {
            "x": -1,
            "y": 2,
            "z": 17,
            "elements": [
                "gregtech:transparent_casing@1"
            ]
        },
        {
            "x": -7,
            "y": 4,
            "z": 34,
            "elements": [
                "gregtech:transparent_casing@1"
            ]
        },
        {
            "x": -6,
            "y": 4,
            "z": 34,
            "elements": [
                "gregtech:multiblock_casing@4"
            ]
        },
        {
            "x": -5,
            "y": 4,
            "z": 34,
            "elements": [
                "gregtech:boiler_casing@3"
            ]
        },
        {
            "x": -4,
            "y": 4,
            "z": 34,
            "elements": [
                "gregtech:multiblock_casing@4"
            ]
        },
        {
            "x": -3,
            "y": 4,
            "z": 34,
            "elements": [
                "gregtech:boiler_casing@3"
            ]
        },
        {
            "x": -2,
            "y": 4,
            "z": 34,
            "elements": [
                "gregtech:multiblock_casing@4"
            ]
        },
        {
            "x": -1,
            "y": 4,
            "z": 34,
            "elements": [
                "gregtech:transparent_casing@1"
            ]
        },
        {
            "x": 1,
            "y": -1,
            "z": 0,
            "elements": [
                "gregtech:multiblock_casing@3"
            ]
        },
        {
            "x": 0,
            "y": -1,
            "z": 0,
            "elements": [
                "gregtech:multiblock_casing@3"
            ]
        },
        {
            "x": -1,
            "y": -1,
            "z": 0,
            "elements": [
                "gregtech:multiblock_casing@3"
            ]
        },
        {
            "x": -2,
            "y": -1,
            "z": 0,
            "elements": [
                "gregtech:multiblock_casing@3"
            ]
        },
        {
            "x": -7,
            "y": 3,
            "z": 17,
            "elements": [
                "gregtech:transparent_casing@1"
            ]
        },
        {
            "x": -6,
            "y": 3,
            "z": 17,
            "elements": [
                "gregtech:multiblock_casing@3"
            ]
        },
        {
            "x": -5,
            "y": 3,
            "z": 17,
            "elements": [
                "gregtech:multiblock_casing@4"
            ]
        },
        {
            "x": -4,
            "y": 3,
            "z": 17,
            "elements": [
                "gregtech:boiler_casing@3"
            ]
        },
        {
            "x": -3,
            "y": 3,
            "z": 17,
            "elements": [
                "gregtech:multiblock_casing@4"
            ]
        },
        {
            "x": -2,
            "y": 3,
            "z": 17,
            "elements": [
                "gregtech:multiblock_casing@3"
            ]
        },
        {
            "x": -1,
            "y": 3,
            "z": 17,
            "elements": [
                "gregtech:transparent_casing@1"
            ]
        },
        {
            "x": -7,
            "y": 5,
            "z": 34,
            "elements": [
                "gregtech:multiblock_casing@2"
            ]
        },
        {
            "x": -6,
            "y": 5,
            "z": 34,
            "elements": [
                "gregtech:multiblock_casing@3"
            ]
        },
        {
            "x": -5,
            "y": 5,
            "z": 34,
            "elements": [
                "gregtech:multiblock_casing@4"
            ]
        },
        {
            "x": -4,
            "y": 5,
            "z": 34,
            "elements": [
                "gregtech:multiblock_casing@3"
            ]
        },
        {
            "x": -3,
            "y": 5,
            "z": 34,
            "elements": [
                "gregtech:multiblock_casing@4"
            ]
        },
        {
            "x": -2,
            "y": 5,
            "z": 34,
            "elements": [
                "gregtech:multiblock_casing@3"
            ]
        },
        {
            "x": -1,
            "y": 5,
            "z": 34,
            "elements": [
                "gregtech:multiblock_casing@2"
            ]
        },
        {
            "x": -7,
            "y": 4,
            "z": 17,
            "elements": [
                "gregtech:transparent_casing@1"
            ]
        },
        {
            "x": -6,
            "y": 4,
            "z": 17,
            "elements": [
                "gregtech:multiblock_casing@4"
            ]
        },
        {
            "x": -5,
            "y": 4,
            "z": 17,
            "elements": [
                "gregtech:boiler_casing@3"
            ]
        },
        {
            "x": -4,
            "y": 4,
            "z": 17,
            "elements": [
                "gregtech:multiblock_casing@4"
            ]
        },
        {
            "x": -3,
            "y": 4,
            "z": 17,
            "elements": [
                "gregtech:boiler_casing@3"
            ]
        },
        {
            "x": -2,
            "y": 4,
            "z": 17,
            "elements": [
                "gregtech:multiblock_casing@4"
            ]
        },
        {
            "x": -1,
            "y": 4,
            "z": 17,
            "elements": [
                "gregtech:transparent_casing@1"
            ]
        },
        {
            "x": -7,
            "y": 6,
            "z": 34,
            "elements": [
                "gcym:large_multiblock_casing@2"
            ]
        },
        {
            "x": -6,
            "y": 6,
            "z": 34,
            "elements": [
                "gregtech:boiler_casing@4"
            ]
        },
        {
            "x": -5,
            "y": 6,
            "z": 34,
            "elements": [
                "gregtech:hermetic_casing@8"
            ]
        },
        {
            "x": -4,
            "y": 6,
            "z": 34,
            "elements": [
                "gregtech:fusion_casing@1"
            ]
        },
        {
            "x": -3,
            "y": 6,
            "z": 34,
            "elements": [
                "gregtech:hermetic_casing@8"
            ]
        },
        {
            "x": -2,
            "y": 6,
            "z": 34,
            "elements": [
                "gregtech:boiler_casing@4"
            ]
        },
        {
            "x": -1,
            "y": 6,
            "z": 34,
            "elements": [
                "gcym:large_multiblock_casing@2"
            ]
        },
        {
            "x": -7,
            "y": 5,
            "z": 17,
            "elements": [
                "gregtech:multiblock_casing@2"
            ]
        },
        {
            "x": -6,
            "y": 5,
            "z": 17,
            "elements": [
                "gregtech:multiblock_casing@3"
            ]
        },
        {
            "x": -5,
            "y": 5,
            "z": 17,
            "elements": [
                "gregtech:multiblock_casing@4"
            ]
        },
        {
            "x": -4,
            "y": 5,
            "z": 17,
            "elements": [
                "gregtech:multiblock_casing@3"
            ]
        },
        {
            "x": -3,
            "y": 5,
            "z": 17,
            "elements": [
                "gregtech:multiblock_casing@4"
            ]
        },
        {
            "x": -2,
            "y": 5,
            "z": 17,
            "elements": [
                "gregtech:multiblock_casing@3"
            ]
        },
        {
            "x": -1,
            "y": 5,
            "z": 17,
            "elements": [
                "gregtech:multiblock_casing@2"
            ]
        },
        {
            "x": -7,
            "y": 7,
            "z": 34,
            "elements": [
                "gregtech:metal_casing@4"
            ]
        },
        {
            "x": -6,
            "y": 7,
            "z": 34,
            "elements": [
                "gregtech:metal_casing@4"
            ]
        },
        {
            "x": -5,
            "y": 7,
            "z": 34,
            "elements": [
                "gregtech:metal_casing@4"
            ]
        },
        {
            "x": -4,
            "y": 7,
            "z": 34,
            "elements": [
                "gregtech:metal_casing@4"
            ]
        },
        {
            "x": -7,
            "y": -1,
            "z": 30,
            "elements": [
                "gregtech:metal_casing@4"
            ]
        },
        {
            "x": -3,
            "y": 7,
            "z": 34,
            "elements": [
                "gregtech:metal_casing@4"
            ]
        },
        {
            "x": -6,
            "y": -1,
            "z": 30,
            "elements": [
                "gregtech:metal_casing@4"
            ]
        },
        {
            "x": -2,
            "y": 7,
            "z": 34,
            "elements": [
                "gregtech:metal_casing@4"
            ]
        },
        {
            "x": -5,
            "y": -1,
            "z": 30,
            "elements": [
                "gregtech:metal_casing@4"
            ]
        },
        {
            "x": -1,
            "y": 7,
            "z": 34,
            "elements": [
                "gregtech:metal_casing@4"
            ]
        },
        {
            "x": -4,
            "y": -1,
            "z": 30,
            "elements": [
                "gregtech:metal_casing@4"
            ]
        },
        {
            "x": -3,
            "y": -1,
            "z": 30,
            "elements": [
                "gregtech:metal_casing@4"
            ]
        },
        {
            "x": -2,
            "y": -1,
            "z": 30,
            "elements": [
                "gregtech:metal_casing@4"
            ]
        },
        {
            "x": -1,
            "y": -1,
            "z": 30,
            "elements": [
                "gregtech:metal_casing@4"
            ]
        },
        {
            "x": -7,
            "y": 6,
            "z": 17,
            "elements": [
                "gcym:large_multiblock_casing@2"
            ]
        },
        {
            "x": -6,
            "y": 6,
            "z": 17,
            "elements": [
                "gregtech:boiler_casing@4"
            ]
        },
        {
            "x": -5,
            "y": 6,
            "z": 17,
            "elements": [
                "gregtech:hermetic_casing@8"
            ]
        },
        {
            "x": -4,
            "y": 6,
            "z": 17,
            "elements": [
                "gregtech:fusion_casing@1"
            ]
        },
        {
            "x": -3,
            "y": 6,
            "z": 17,
            "elements": [
                "gregtech:hermetic_casing@8"
            ]
        },
        {
            "x": -2,
            "y": 6,
            "z": 17,
            "elements": [
                "gregtech:boiler_casing@4"
            ]
        },
        {
            "x": -1,
            "y": 6,
            "z": 17,
            "elements": [
                "gcym:large_multiblock_casing@2"
            ]
        },
        {
            "x": -7,
            "y": 0,
            "z": 30,
            "elements": [
                "gcym:large_multiblock_casing@2"
            ]
        },
        {
            "x": -6,
            "y": 0,
            "z": 30,
            "elements": [
                "gregtech:boiler_casing@4"
            ]
        },
        {
            "x": -5,
            "y": 0,
            "z": 30,
            "elements": [
                "gregtech:hermetic_casing@8"
            ]
        },
        {
            "x": -4,
            "y": 0,
            "z": 30,
            "elements": [
                "gregtech:fusion_casing@1"
            ]
        },
        {
            "x": -3,
            "y": 0,
            "z": 30,
            "elements": [
                "gregtech:hermetic_casing@8"
            ]
        },
        {
            "x": -2,
            "y": 0,
            "z": 30,
            "elements": [
                "gregtech:boiler_casing@4"
            ]
        },
        {
            "x": -1,
            "y": 0,
            "z": 30,
            "elements": [
                "modularmachinery:blockinputbus@0"
            ]
        },
        {
            "x": -7,
            "y": 7,
            "z": 17,
            "elements": [
                "modularmachinery:blockenergyinputhatch@7"
            ]
        },
        {
            "x": -6,
            "y": 7,
            "z": 17,
            "elements": [
                "gregtech:metal_casing@4"
            ]
        },
        {
            "x": -5,
            "y": 7,
            "z": 17,
            "elements": [
                "gregtech:metal_casing@4"
            ]
        },
        {
            "x": -4,
            "y": 7,
            "z": 17,
            "elements": [
                "gregtech:metal_casing@4"
            ]
        },
        {
            "x": -7,
            "y": -1,
            "z": 13,
            "elements": [
                "gregtech:metal_casing@4"
            ]
        },
        {
            "x": -3,
            "y": 7,
            "z": 17,
            "elements": [
                "gregtech:metal_casing@4"
            ]
        },
        {
            "x": -6,
            "y": -1,
            "z": 13,
            "elements": [
                "gregtech:metal_casing@4"
            ]
        },
        {
            "x": -2,
            "y": 7,
            "z": 17,
            "elements": [
                "gregtech:metal_casing@4"
            ]
        },
        {
            "x": -5,
            "y": -1,
            "z": 13,
            "elements": [
                "gregtech:metal_casing@4"
            ]
        },
        {
            "x": -1,
            "y": 7,
            "z": 17,
            "elements": [
                "gregtech:metal_casing@4"
            ]
        },
        {
            "x": -4,
            "y": -1,
            "z": 13,
            "elements": [
                "gregtech:metal_casing@4"
            ]
        },
        {
            "x": -3,
            "y": -1,
            "z": 13,
            "elements": [
                "gregtech:metal_casing@4"
            ]
        },
        {
            "x": -2,
            "y": -1,
            "z": 13,
            "elements": [
                "gregtech:metal_casing@4"
            ]
        },
        {
            "x": -1,
            "y": -1,
            "z": 13,
            "elements": [
                "gregtech:metal_casing@4"
            ]
        },
        {
            "x": -7,
            "y": 1,
            "z": 30,
            "elements": [
                "gregtech:multiblock_casing@2"
            ]
        },
        {
            "x": -6,
            "y": 1,
            "z": 30,
            "elements": [
                "gregtech:multiblock_casing@3"
            ]
        },
        {
            "x": -5,
            "y": 1,
            "z": 30,
            "elements": [
                "gregtech:multiblock_casing@4"
            ]
        },
        {
            "x": -4,
            "y": 1,
            "z": 30,
            "elements": [
                "gregtech:multiblock_casing@3"
            ]
        },
        {
            "x": -3,
            "y": 1,
            "z": 30,
            "elements": [
                "gregtech:multiblock_casing@4"
            ]
        },
        {
            "x": -2,
            "y": 1,
            "z": 30,
            "elements": [
                "gregtech:multiblock_casing@3"
            ]
        },
        {
            "x": -1,
            "y": 1,
            "z": 30,
            "elements": [
                "gregtech:multiblock_casing@2"
            ]
        },
        {
            "x": -7,
            "y": 0,
            "z": 13,
            "elements": [
                "modularmachinery:blockfluidinputhatch@7"
            ]
        },
        {
            "x": -6,
            "y": 0,
            "z": 13,
            "elements": [
                "gregtech:boiler_casing@4"
            ]
        },
        {
            "x": -5,
            "y": 0,
            "z": 13,
            "elements": [
                "gregtech:hermetic_casing@8"
            ]
        },
        {
            "x": -4,
            "y": 0,
            "z": 13,
            "elements": [
                "gregtech:fusion_casing@1"
            ]
        },
        {
            "x": -3,
            "y": 0,
            "z": 13,
            "elements": [
                "gregtech:hermetic_casing@8"
            ]
        },
        {
            "x": -2,
            "y": 0,
            "z": 13,
            "elements": [
                "gregtech:boiler_casing@4"
            ]
        },
        {
            "x": -1,
            "y": 0,
            "z": 13,
            "elements": [
                "modularmachinery:blockinputbus@0"
            ]
        },
        {
            "x": -7,
            "y": 2,
            "z": 30,
            "elements": [
                "gregtech:transparent_casing@1"
            ]
        },
        {
            "x": -6,
            "y": 2,
            "z": 30,
            "elements": [
                "gregtech:multiblock_casing@4"
            ]
        },
        {
            "x": -5,
            "y": 2,
            "z": 30,
            "elements": [
                "gregtech:boiler_casing@3"
            ]
        },
        {
            "x": -4,
            "y": 2,
            "z": 30,
            "elements": [
                "gregtech:multiblock_casing@4"
            ]
        },
        {
            "x": -3,
            "y": 2,
            "z": 30,
            "elements": [
                "gregtech:boiler_casing@3"
            ]
        },
        {
            "x": -2,
            "y": 2,
            "z": 30,
            "elements": [
                "gregtech:multiblock_casing@4"
            ]
        },
        {
            "x": -1,
            "y": 2,
            "z": 30,
            "elements": [
                "gregtech:transparent_casing@1"
            ]
        },
        {
            "x": -7,
            "y": 1,
            "z": 13,
            "elements": [
                "gregtech:multiblock_casing@2"
            ]
        },
        {
            "x": -6,
            "y": 1,
            "z": 13,
            "elements": [
                "gregtech:multiblock_casing@3"
            ]
        },
        {
            "x": -5,
            "y": 1,
            "z": 13,
            "elements": [
                "gregtech:multiblock_casing@4"
            ]
        },
        {
            "x": -4,
            "y": 1,
            "z": 13,
            "elements": [
                "gregtech:multiblock_casing@3"
            ]
        },
        {
            "x": -3,
            "y": 1,
            "z": 13,
            "elements": [
                "gregtech:multiblock_casing@4"
            ]
        },
        {
            "x": -2,
            "y": 1,
            "z": 13,
            "elements": [
                "gregtech:multiblock_casing@3"
            ]
        },
        {
            "x": -1,
            "y": 1,
            "z": 13,
            "elements": [
                "gregtech:multiblock_casing@2"
            ]
        },
        {
            "x": -7,
            "y": 3,
            "z": 30,
            "elements": [
                "gregtech:transparent_casing@1"
            ]
        },
        {
            "x": -6,
            "y": 3,
            "z": 30,
            "elements": [
                "gregtech:multiblock_casing@3"
            ]
        },
        {
            "x": -5,
            "y": 3,
            "z": 30,
            "elements": [
                "gregtech:multiblock_casing@4"
            ]
        },
        {
            "x": -4,
            "y": 3,
            "z": 30,
            "elements": [
                "gregtech:boiler_casing@3"
            ]
        },
        {
            "x": -3,
            "y": 3,
            "z": 30,
            "elements": [
                "gregtech:multiblock_casing@4"
            ]
        },
        {
            "x": -2,
            "y": 3,
            "z": 30,
            "elements": [
                "gregtech:multiblock_casing@3"
            ]
        },
        {
            "x": -1,
            "y": 3,
            "z": 30,
            "elements": [
                "gregtech:transparent_casing@1"
            ]
        },
        {
            "x": -7,
            "y": 2,
            "z": 13,
            "elements": [
                "gregtech:transparent_casing@1"
            ]
        },
        {
            "x": -6,
            "y": 2,
            "z": 13,
            "elements": [
                "gregtech:multiblock_casing@4"
            ]
        },
        {
            "x": -5,
            "y": 2,
            "z": 13,
            "elements": [
                "gregtech:boiler_casing@3"
            ]
        },
        {
            "x": -4,
            "y": 2,
            "z": 13,
            "elements": [
                "gregtech:multiblock_casing@4"
            ]
        },
        {
            "x": -3,
            "y": 2,
            "z": 13,
            "elements": [
                "gregtech:boiler_casing@3"
            ]
        },
        {
            "x": -2,
            "y": 2,
            "z": 13,
            "elements": [
                "gregtech:multiblock_casing@4"
            ]
        },
        {
            "x": -1,
            "y": 2,
            "z": 13,
            "elements": [
                "gregtech:transparent_casing@1"
            ]
        },
        {
            "x": -7,
            "y": 4,
            "z": 30,
            "elements": [
                "gregtech:transparent_casing@1"
            ]
        },
        {
            "x": -6,
            "y": 4,
            "z": 30,
            "elements": [
                "gregtech:multiblock_casing@4"
            ]
        },
        {
            "x": -5,
            "y": 4,
            "z": 30,
            "elements": [
                "gregtech:boiler_casing@3"
            ]
        },
        {
            "x": -4,
            "y": 4,
            "z": 30,
            "elements": [
                "gregtech:multiblock_casing@4"
            ]
        },
        {
            "x": -3,
            "y": 4,
            "z": 30,
            "elements": [
                "gregtech:boiler_casing@3"
            ]
        },
        {
            "x": -2,
            "y": 4,
            "z": 30,
            "elements": [
                "gregtech:multiblock_casing@4"
            ]
        },
        {
            "x": -1,
            "y": 4,
            "z": 30,
            "elements": [
                "gregtech:transparent_casing@1"
            ]
        },
        {
            "x": -7,
            "y": 3,
            "z": 13,
            "elements": [
                "gregtech:transparent_casing@1"
            ]
        },
        {
            "x": -6,
            "y": 3,
            "z": 13,
            "elements": [
                "gregtech:multiblock_casing@3"
            ]
        },
        {
            "x": -5,
            "y": 3,
            "z": 13,
            "elements": [
                "gregtech:multiblock_casing@4"
            ]
        },
        {
            "x": -4,
            "y": 3,
            "z": 13,
            "elements": [
                "gregtech:boiler_casing@3"
            ]
        },
        {
            "x": -3,
            "y": 3,
            "z": 13,
            "elements": [
                "gregtech:multiblock_casing@4"
            ]
        },
        {
            "x": -2,
            "y": 3,
            "z": 13,
            "elements": [
                "gregtech:multiblock_casing@3"
            ]
        },
        {
            "x": -1,
            "y": 3,
            "z": 13,
            "elements": [
                "gregtech:transparent_casing@1"
            ]
        },
        {
            "x": -7,
            "y": 5,
            "z": 30,
            "elements": [
                "gregtech:multiblock_casing@2"
            ]
        },
        {
            "x": -6,
            "y": 5,
            "z": 30,
            "elements": [
                "gregtech:multiblock_casing@3"
            ]
        },
        {
            "x": -5,
            "y": 5,
            "z": 30,
            "elements": [
                "gregtech:multiblock_casing@4"
            ]
        },
        {
            "x": -4,
            "y": 5,
            "z": 30,
            "elements": [
                "gregtech:multiblock_casing@3"
            ]
        },
        {
            "x": -3,
            "y": 5,
            "z": 30,
            "elements": [
                "gregtech:multiblock_casing@4"
            ]
        },
        {
            "x": -2,
            "y": 5,
            "z": 30,
            "elements": [
                "gregtech:multiblock_casing@3"
            ]
        },
        {
            "x": -1,
            "y": 5,
            "z": 30,
            "elements": [
                "gregtech:multiblock_casing@2"
            ]
        },
        {
            "x": -7,
            "y": 4,
            "z": 13,
            "elements": [
                "gregtech:transparent_casing@1"
            ]
        },
        {
            "x": -6,
            "y": 4,
            "z": 13,
            "elements": [
                "gregtech:multiblock_casing@4"
            ]
        },
        {
            "x": -5,
            "y": 4,
            "z": 13,
            "elements": [
                "gregtech:boiler_casing@3"
            ]
        },
        {
            "x": -4,
            "y": 4,
            "z": 13,
            "elements": [
                "gregtech:multiblock_casing@4"
            ]
        },
        {
            "x": -3,
            "y": 4,
            "z": 13,
            "elements": [
                "gregtech:boiler_casing@3"
            ]
        },
        {
            "x": -2,
            "y": 4,
            "z": 13,
            "elements": [
                "gregtech:multiblock_casing@4"
            ]
        },
        {
            "x": -1,
            "y": 4,
            "z": 13,
            "elements": [
                "gregtech:transparent_casing@1"
            ]
        },
        {
            "x": -7,
            "y": 6,
            "z": 30,
            "elements": [
                "gcym:large_multiblock_casing@2"
            ]
        },
        {
            "x": -6,
            "y": 6,
            "z": 30,
            "elements": [
                "gregtech:boiler_casing@4"
            ]
        },
        {
            "x": -5,
            "y": 6,
            "z": 30,
            "elements": [
                "gregtech:hermetic_casing@8"
            ]
        },
        {
            "x": -4,
            "y": 6,
            "z": 30,
            "elements": [
                "gregtech:fusion_casing@1"
            ]
        },
        {
            "x": -3,
            "y": 6,
            "z": 30,
            "elements": [
                "gregtech:hermetic_casing@8"
            ]
        },
        {
            "x": -2,
            "y": 6,
            "z": 30,
            "elements": [
                "gregtech:boiler_casing@4"
            ]
        },
        {
            "x": -1,
            "y": 6,
            "z": 30,
            "elements": [
                "gcym:large_multiblock_casing@2"
            ]
        },
        {
            "x": -7,
            "y": 5,
            "z": 13,
            "elements": [
                "gregtech:multiblock_casing@2"
            ]
        },
        {
            "x": -6,
            "y": 5,
            "z": 13,
            "elements": [
                "gregtech:multiblock_casing@3"
            ]
        },
        {
            "x": -5,
            "y": 5,
            "z": 13,
            "elements": [
                "gregtech:multiblock_casing@4"
            ]
        },
        {
            "x": -4,
            "y": 5,
            "z": 13,
            "elements": [
                "gregtech:multiblock_casing@3"
            ]
        },
        {
            "x": -3,
            "y": 5,
            "z": 13,
            "elements": [
                "gregtech:multiblock_casing@4"
            ]
        },
        {
            "x": -2,
            "y": 5,
            "z": 13,
            "elements": [
                "gregtech:multiblock_casing@3"
            ]
        },
        {
            "x": -1,
            "y": 5,
            "z": 13,
            "elements": [
                "gregtech:multiblock_casing@2"
            ]
        },
        {
            "x": -7,
            "y": 7,
            "z": 30,
            "elements": [
                "gregtech:metal_casing@4"
            ]
        },
        {
            "x": -6,
            "y": 7,
            "z": 30,
            "elements": [
                "gregtech:metal_casing@4"
            ]
        },
        {
            "x": -5,
            "y": 7,
            "z": 30,
            "elements": [
                "gregtech:metal_casing@4"
            ]
        },
        {
            "x": -4,
            "y": 7,
            "z": 30,
            "elements": [
                "gregtech:metal_casing@4"
            ]
        },
        {
            "x": -7,
            "y": -1,
            "z": 26,
            "elements": [
                "gregtech:metal_casing@4"
            ]
        },
        {
            "x": -3,
            "y": 7,
            "z": 30,
            "elements": [
                "gregtech:metal_casing@4"
            ]
        },
        {
            "x": -6,
            "y": -1,
            "z": 26,
            "elements": [
                "gregtech:metal_casing@4"
            ]
        },
        {
            "x": -2,
            "y": 7,
            "z": 30,
            "elements": [
                "gregtech:metal_casing@4"
            ]
        },
        {
            "x": -5,
            "y": -1,
            "z": 26,
            "elements": [
                "gregtech:metal_casing@4"
            ]
        },
        {
            "x": -1,
            "y": 7,
            "z": 30,
            "elements": [
                "gregtech:metal_casing@4"
            ]
        },
        {
            "x": -4,
            "y": -1,
            "z": 26,
            "elements": [
                "gregtech:metal_casing@4"
            ]
        },
        {
            "x": -3,
            "y": -1,
            "z": 26,
            "elements": [
                "gregtech:metal_casing@4"
            ]
        },
        {
            "x": -2,
            "y": -1,
            "z": 26,
            "elements": [
                "gregtech:metal_casing@4"
            ]
        },
        {
            "x": -1,
            "y": -1,
            "z": 26,
            "elements": [
                "gregtech:metal_casing@4"
            ]
        },
        {
            "x": -7,
            "y": 6,
            "z": 13,
            "elements": [
                "gcym:large_multiblock_casing@2"
            ]
        },
        {
            "x": -6,
            "y": 6,
            "z": 13,
            "elements": [
                "gregtech:boiler_casing@4"
            ]
        },
        {
            "x": -5,
            "y": 6,
            "z": 13,
            "elements": [
                "gregtech:hermetic_casing@8"
            ]
        },
        {
            "x": -4,
            "y": 6,
            "z": 13,
            "elements": [
                "gregtech:fusion_casing@1"
            ]
        },
        {
            "x": -3,
            "y": 6,
            "z": 13,
            "elements": [
                "gregtech:hermetic_casing@8"
            ]
        },
        {
            "x": -2,
            "y": 6,
            "z": 13,
            "elements": [
                "gregtech:boiler_casing@4"
            ]
        },
        {
            "x": -1,
            "y": 6,
            "z": 13,
            "elements": [
                "gcym:large_multiblock_casing@2"
            ]
        },
        {
            "x": -7,
            "y": 0,
            "z": 26,
            "elements": [
                "gcym:large_multiblock_casing@2"
            ]
        },
        {
            "x": -6,
            "y": 0,
            "z": 26,
            "elements": [
                "gregtech:boiler_casing@4"
            ]
        },
        {
            "x": -5,
            "y": 0,
            "z": 26,
            "elements": [
                "gregtech:hermetic_casing@8"
            ]
        },
        {
            "x": -4,
            "y": 0,
            "z": 26,
            "elements": [
                "gregtech:fusion_casing@1"
            ]
        },
        {
            "x": -3,
            "y": 0,
            "z": 26,
            "elements": [
                "gregtech:hermetic_casing@8"
            ]
        },
        {
            "x": -2,
            "y": 0,
            "z": 26,
            "elements": [
                "gregtech:boiler_casing@4"
            ]
        },
        {
            "x": -1,
            "y": 0,
            "z": 26,
            "elements": [
                "modularmachinery:blockinputbus@0"
            ]
        },
        {
            "x": -7,
            "y": 7,
            "z": 13,
            "elements": [
                "modularmachinery:blockenergyinputhatch@7"
            ]
        },
        {
            "x": -6,
            "y": 7,
            "z": 13,
            "elements": [
                "gregtech:metal_casing@4"
            ]
        },
        {
            "x": -5,
            "y": 7,
            "z": 13,
            "elements": [
                "gregtech:metal_casing@4"
            ]
        },
        {
            "x": -4,
            "y": 7,
            "z": 13,
            "elements": [
                "gregtech:metal_casing@4"
            ]
        },
        {
            "x": -7,
            "y": -1,
            "z": 9,
            "elements": [
                "gregtech:metal_casing@4"
            ]
        },
        {
            "x": -3,
            "y": 7,
            "z": 13,
            "elements": [
                "gregtech:metal_casing@4"
            ]
        },
        {
            "x": -6,
            "y": -1,
            "z": 9,
            "elements": [
                "gregtech:metal_casing@4"
            ]
        },
        {
            "x": -2,
            "y": 7,
            "z": 13,
            "elements": [
                "gregtech:metal_casing@4"
            ]
        },
        {
            "x": -5,
            "y": -1,
            "z": 9,
            "elements": [
                "gregtech:metal_casing@4"
            ]
        },
        {
            "x": -1,
            "y": 7,
            "z": 13,
            "elements": [
                "gregtech:metal_casing@4"
            ]
        },
        {
            "x": -4,
            "y": -1,
            "z": 9,
            "elements": [
                "gregtech:metal_casing@4"
            ]
        },
        {
            "x": -3,
            "y": -1,
            "z": 9,
            "elements": [
                "gregtech:metal_casing@4"
            ]
        },
        {
            "x": -2,
            "y": -1,
            "z": 9,
            "elements": [
                "gregtech:metal_casing@4"
            ]
        },
        {
            "x": -1,
            "y": -1,
            "z": 9,
            "elements": [
                "gregtech:metal_casing@4"
            ]
        },
        {
            "x": -7,
            "y": 1,
            "z": 26,
            "elements": [
                "gregtech:multiblock_casing@2"
            ]
        },
        {
            "x": -6,
            "y": 1,
            "z": 26,
            "elements": [
                "gregtech:multiblock_casing@3"
            ]
        },
        {
            "x": -5,
            "y": 1,
            "z": 26,
            "elements": [
                "gregtech:multiblock_casing@4"
            ]
        },
        {
            "x": -4,
            "y": 1,
            "z": 26,
            "elements": [
                "gregtech:multiblock_casing@3"
            ]
        },
        {
            "x": -3,
            "y": 1,
            "z": 26,
            "elements": [
                "gregtech:multiblock_casing@4"
            ]
        },
        {
            "x": -2,
            "y": 1,
            "z": 26,
            "elements": [
                "gregtech:multiblock_casing@3"
            ]
        },
        {
            "x": -1,
            "y": 1,
            "z": 26,
            "elements": [
                "gregtech:multiblock_casing@2"
            ]
        },
        {
            "x": -7,
            "y": 0,
            "z": 9,
            "elements": [
                "modularmachinery:blockfluidinputhatch@7"
            ]
        },
        {
            "x": -6,
            "y": 0,
            "z": 9,
            "elements": [
                "gregtech:boiler_casing@4"
            ]
        },
        {
            "x": -5,
            "y": 0,
            "z": 9,
            "elements": [
                "gregtech:hermetic_casing@8"
            ]
        },
        {
            "x": -4,
            "y": 0,
            "z": 9,
            "elements": [
                "gregtech:fusion_casing@1"
            ]
        },
        {
            "x": -3,
            "y": 0,
            "z": 9,
            "elements": [
                "gregtech:hermetic_casing@8"
            ]
        },
        {
            "x": -2,
            "y": 0,
            "z": 9,
            "elements": [
                "gregtech:boiler_casing@4"
            ]
        },
        {
            "x": -1,
            "y": 0,
            "z": 9,
            "elements": [
                "modularmachinery:blockinputbus@0"
            ]
        },
        {
            "x": -7,
            "y": 2,
            "z": 26,
            "elements": [
                "gregtech:transparent_casing@1"
            ]
        },
        {
            "x": -6,
            "y": 2,
            "z": 26,
            "elements": [
                "gregtech:multiblock_casing@4"
            ]
        },
        {
            "x": -5,
            "y": 2,
            "z": 26,
            "elements": [
                "gregtech:boiler_casing@3"
            ]
        },
        {
            "x": -4,
            "y": 2,
            "z": 26,
            "elements": [
                "gregtech:multiblock_casing@4"
            ]
        },
        {
            "x": -3,
            "y": 2,
            "z": 26,
            "elements": [
                "gregtech:boiler_casing@3"
            ]
        },
        {
            "x": -2,
            "y": 2,
            "z": 26,
            "elements": [
                "gregtech:multiblock_casing@4"
            ]
        },
        {
            "x": -1,
            "y": 2,
            "z": 26,
            "elements": [
                "gregtech:transparent_casing@1"
            ]
        },
        {
            "x": -7,
            "y": 1,
            "z": 9,
            "elements": [
                "gregtech:multiblock_casing@2"
            ]
        },
        {
            "x": -6,
            "y": 1,
            "z": 9,
            "elements": [
                "gregtech:multiblock_casing@3"
            ]
        },
        {
            "x": -5,
            "y": 1,
            "z": 9,
            "elements": [
                "gregtech:multiblock_casing@4"
            ]
        },
        {
            "x": -4,
            "y": 1,
            "z": 9,
            "elements": [
                "gregtech:multiblock_casing@3"
            ]
        },
        {
            "x": -3,
            "y": 1,
            "z": 9,
            "elements": [
                "gregtech:multiblock_casing@4"
            ]
        },
        {
            "x": -2,
            "y": 1,
            "z": 9,
            "elements": [
                "gregtech:multiblock_casing@3"
            ]
        },
        {
            "x": -1,
            "y": 1,
            "z": 9,
            "elements": [
                "gregtech:multiblock_casing@2"
            ]
        },
        {
            "x": -7,
            "y": 3,
            "z": 26,
            "elements": [
                "gregtech:transparent_casing@1"
            ]
        },
        {
            "x": -6,
            "y": 3,
            "z": 26,
            "elements": [
                "gregtech:multiblock_casing@3"
            ]
        },
        {
            "x": -5,
            "y": 3,
            "z": 26,
            "elements": [
                "gregtech:multiblock_casing@4"
            ]
        },
        {
            "x": -4,
            "y": 3,
            "z": 26,
            "elements": [
                "gregtech:boiler_casing@3"
            ]
        },
        {
            "x": -3,
            "y": 3,
            "z": 26,
            "elements": [
                "gregtech:multiblock_casing@4"
            ]
        },
        {
            "x": -2,
            "y": 3,
            "z": 26,
            "elements": [
                "gregtech:multiblock_casing@3"
            ]
        },
        {
            "x": -1,
            "y": 3,
            "z": 26,
            "elements": [
                "gregtech:transparent_casing@1"
            ]
        },
        {
            "x": -7,
            "y": 2,
            "z": 9,
            "elements": [
                "gregtech:transparent_casing@1"
            ]
        },
        {
            "x": -6,
            "y": 2,
            "z": 9,
            "elements": [
                "gregtech:multiblock_casing@4"
            ]
        },
        {
            "x": -5,
            "y": 2,
            "z": 9,
            "elements": [
                "gregtech:boiler_casing@3"
            ]
        },
        {
            "x": -4,
            "y": 2,
            "z": 9,
            "elements": [
                "gregtech:multiblock_casing@4"
            ]
        },
        {
            "x": -3,
            "y": 2,
            "z": 9,
            "elements": [
                "gregtech:boiler_casing@3"
            ]
        },
        {
            "x": -2,
            "y": 2,
            "z": 9,
            "elements": [
                "gregtech:multiblock_casing@4"
            ]
        },
        {
            "x": -1,
            "y": 2,
            "z": 9,
            "elements": [
                "gregtech:transparent_casing@1"
            ]
        },
        {
            "x": -7,
            "y": 4,
            "z": 26,
            "elements": [
                "gregtech:transparent_casing@1"
            ]
        },
        {
            "x": -6,
            "y": 4,
            "z": 26,
            "elements": [
                "gregtech:multiblock_casing@4"
            ]
        },
        {
            "x": -5,
            "y": 4,
            "z": 26,
            "elements": [
                "gregtech:boiler_casing@3"
            ]
        },
        {
            "x": -4,
            "y": 4,
            "z": 26,
            "elements": [
                "gregtech:multiblock_casing@4"
            ]
        },
        {
            "x": -3,
            "y": 4,
            "z": 26,
            "elements": [
                "gregtech:boiler_casing@3"
            ]
        },
        {
            "x": -2,
            "y": 4,
            "z": 26,
            "elements": [
                "gregtech:multiblock_casing@4"
            ]
        },
        {
            "x": -1,
            "y": 4,
            "z": 26,
            "elements": [
                "gregtech:transparent_casing@1"
            ]
        },
        {
            "x": -7,
            "y": 3,
            "z": 9,
            "elements": [
                "gregtech:transparent_casing@1"
            ]
        },
        {
            "x": -6,
            "y": 3,
            "z": 9,
            "elements": [
                "gregtech:multiblock_casing@3"
            ]
        },
        {
            "x": -5,
            "y": 3,
            "z": 9,
            "elements": [
                "gregtech:multiblock_casing@4"
            ]
        },
        {
            "x": -4,
            "y": 3,
            "z": 9,
            "elements": [
                "gregtech:boiler_casing@3"
            ]
        },
        {
            "x": -3,
            "y": 3,
            "z": 9,
            "elements": [
                "gregtech:multiblock_casing@4"
            ]
        },
        {
            "x": -2,
            "y": 3,
            "z": 9,
            "elements": [
                "gregtech:multiblock_casing@3"
            ]
        },
        {
            "x": -1,
            "y": 3,
            "z": 9,
            "elements": [
                "gregtech:transparent_casing@1"
            ]
        },
        {
            "x": -7,
            "y": 5,
            "z": 26,
            "elements": [
                "gregtech:multiblock_casing@2"
            ]
        },
        {
            "x": -6,
            "y": 5,
            "z": 26,
            "elements": [
                "gregtech:multiblock_casing@3"
            ]
        },
        {
            "x": -5,
            "y": 5,
            "z": 26,
            "elements": [
                "gregtech:multiblock_casing@4"
            ]
        },
        {
            "x": -4,
            "y": 5,
            "z": 26,
            "elements": [
                "gregtech:multiblock_casing@3"
            ]
        },
        {
            "x": -3,
            "y": 5,
            "z": 26,
            "elements": [
                "gregtech:multiblock_casing@4"
            ]
        },
        {
            "x": -2,
            "y": 5,
            "z": 26,
            "elements": [
                "gregtech:multiblock_casing@3"
            ]
        },
        {
            "x": -1,
            "y": 5,
            "z": 26,
            "elements": [
                "gregtech:multiblock_casing@2"
            ]
        },
        {
            "x": -7,
            "y": 4,
            "z": 9,
            "elements": [
                "gregtech:transparent_casing@1"
            ]
        },
        {
            "x": -6,
            "y": 4,
            "z": 9,
            "elements": [
                "gregtech:multiblock_casing@4"
            ]
        },
        {
            "x": -5,
            "y": 4,
            "z": 9,
            "elements": [
                "gregtech:boiler_casing@3"
            ]
        },
        {
            "x": -4,
            "y": 4,
            "z": 9,
            "elements": [
                "gregtech:multiblock_casing@4"
            ]
        },
        {
            "x": -3,
            "y": 4,
            "z": 9,
            "elements": [
                "gregtech:boiler_casing@3"
            ]
        },
        {
            "x": -2,
            "y": 4,
            "z": 9,
            "elements": [
                "gregtech:multiblock_casing@4"
            ]
        },
        {
            "x": -1,
            "y": 4,
            "z": 9,
            "elements": [
                "gregtech:transparent_casing@1"
            ]
        },
        {
            "x": -7,
            "y": 6,
            "z": 26,
            "elements": [
                "gcym:large_multiblock_casing@2"
            ]
        },
        {
            "x": -6,
            "y": 6,
            "z": 26,
            "elements": [
                "gregtech:boiler_casing@4"
            ]
        },
        {
            "x": -5,
            "y": 6,
            "z": 26,
            "elements": [
                "gregtech:hermetic_casing@8"
            ]
        },
        {
            "x": -4,
            "y": 6,
            "z": 26,
            "elements": [
                "gregtech:fusion_casing@1"
            ]
        },
        {
            "x": -3,
            "y": 6,
            "z": 26,
            "elements": [
                "gregtech:hermetic_casing@8"
            ]
        },
        {
            "x": -2,
            "y": 6,
            "z": 26,
            "elements": [
                "gregtech:boiler_casing@4"
            ]
        },
        {
            "x": -1,
            "y": 6,
            "z": 26,
            "elements": [
                "gcym:large_multiblock_casing@2"
            ]
        },
        {
            "x": -7,
            "y": 5,
            "z": 9,
            "elements": [
                "gregtech:multiblock_casing@2"
            ]
        },
        {
            "x": -6,
            "y": 5,
            "z": 9,
            "elements": [
                "gregtech:multiblock_casing@3"
            ]
        },
        {
            "x": -5,
            "y": 5,
            "z": 9,
            "elements": [
                "gregtech:multiblock_casing@4"
            ]
        },
        {
            "x": -4,
            "y": 5,
            "z": 9,
            "elements": [
                "gregtech:multiblock_casing@3"
            ]
        },
        {
            "x": -3,
            "y": 5,
            "z": 9,
            "elements": [
                "gregtech:multiblock_casing@4"
            ]
        },
        {
            "x": -2,
            "y": 5,
            "z": 9,
            "elements": [
                "gregtech:multiblock_casing@3"
            ]
        },
        {
            "x": -1,
            "y": 5,
            "z": 9,
            "elements": [
                "gregtech:multiblock_casing@2"
            ]
        },
        {
            "x": -7,
            "y": 7,
            "z": 26,
            "elements": [
                "modularmachinery:blockenergyinputhatch@7"
            ]
        },
        {
            "x": -6,
            "y": 7,
            "z": 26,
            "elements": [
                "gregtech:metal_casing@4"
            ]
        },
        {
            "x": -5,
            "y": 7,
            "z": 26,
            "elements": [
                "gregtech:metal_casing@4"
            ]
        },
        {
            "x": -4,
            "y": 7,
            "z": 26,
            "elements": [
                "gregtech:metal_casing@4"
            ]
        },
        {
            "x": -7,
            "y": -1,
            "z": 22,
            "elements": [
                "gregtech:metal_casing@4"
            ]
        },
        {
            "x": -3,
            "y": 7,
            "z": 26,
            "elements": [
                "gregtech:metal_casing@4"
            ]
        },
        {
            "x": -6,
            "y": -1,
            "z": 22,
            "elements": [
                "gregtech:metal_casing@4"
            ]
        },
        {
            "x": -2,
            "y": 7,
            "z": 26,
            "elements": [
                "gregtech:metal_casing@4"
            ]
        },
        {
            "x": -5,
            "y": -1,
            "z": 22,
            "elements": [
                "gregtech:metal_casing@4"
            ]
        },
        {
            "x": -1,
            "y": 7,
            "z": 26,
            "elements": [
                "gregtech:metal_casing@4"
            ]
        },
        {
            "x": -4,
            "y": -1,
            "z": 22,
            "elements": [
                "gregtech:metal_casing@4"
            ]
        },
        {
            "x": -3,
            "y": -1,
            "z": 22,
            "elements": [
                "gregtech:metal_casing@4"
            ]
        },
        {
            "x": -2,
            "y": -1,
            "z": 22,
            "elements": [
                "gregtech:metal_casing@4"
            ]
        },
        {
            "x": -1,
            "y": -1,
            "z": 22,
            "elements": [
                "gregtech:metal_casing@4"
            ]
        },
        {
            "x": -7,
            "y": 6,
            "z": 9,
            "elements": [
                "gcym:large_multiblock_casing@2"
            ]
        },
        {
            "x": -6,
            "y": 6,
            "z": 9,
            "elements": [
                "gregtech:boiler_casing@4"
            ]
        },
        {
            "x": -5,
            "y": 6,
            "z": 9,
            "elements": [
                "gregtech:hermetic_casing@8"
            ]
        },
        {
            "x": -4,
            "y": 6,
            "z": 9,
            "elements": [
                "gregtech:fusion_casing@1"
            ]
        },
        {
            "x": -3,
            "y": 6,
            "z": 9,
            "elements": [
                "gregtech:hermetic_casing@8"
            ]
        },
        {
            "x": -2,
            "y": 6,
            "z": 9,
            "elements": [
                "gregtech:boiler_casing@4"
            ]
        },
        {
            "x": -1,
            "y": 6,
            "z": 9,
            "elements": [
                "gcym:large_multiblock_casing@2"
            ]
        },
        {
            "x": -7,
            "y": 0,
            "z": 22,
            "elements": [
                "gcym:large_multiblock_casing@2"
            ]
        },
        {
            "x": -6,
            "y": 0,
            "z": 22,
            "elements": [
                "gregtech:boiler_casing@4"
            ]
        },
        {
            "x": -5,
            "y": 0,
            "z": 22,
            "elements": [
                "gregtech:hermetic_casing@8"
            ]
        },
        {
            "x": -4,
            "y": 0,
            "z": 22,
            "elements": [
                "gregtech:fusion_casing@1"
            ]
        },
        {
            "x": -3,
            "y": 0,
            "z": 22,
            "elements": [
                "gregtech:hermetic_casing@8"
            ]
        },
        {
            "x": -2,
            "y": 0,
            "z": 22,
            "elements": [
                "gregtech:boiler_casing@4"
            ]
        },
        {
            "x": -1,
            "y": 0,
            "z": 22,
            "elements": [
                "modularmachinery:blockinputbus@0"
            ]
        },
        {
            "x": -7,
            "y": 7,
            "z": 9,
            "elements": [
                "modularmachinery:blockenergyinputhatch@7"
            ]
        },
        {
            "x": -6,
            "y": 7,
            "z": 9,
            "elements": [
                "gregtech:metal_casing@4"
            ]
        },
        {
            "x": -9,
            "y": -1,
            "z": 5,
            "elements": [
                "htmltech:casing@0"
            ]
        },
        {
            "x": -5,
            "y": 7,
            "z": 9,
            "elements": [
                "gregtech:metal_casing@4"
            ]
        },
        {
            "x": -8,
            "y": -1,
            "z": 5,
            "elements": [
                "htmltech:casing@0"
            ]
        },
        {
            "x": -4,
            "y": 7,
            "z": 9,
            "elements": [
                "gregtech:metal_casing@4"
            ]
        },
        {
            "x": -7,
            "y": -1,
            "z": 5,
            "elements": [
                "htmltech:casing@0"
            ]
        },
        {
            "x": -3,
            "y": 7,
            "z": 9,
            "elements": [
                "gregtech:metal_casing@4"
            ]
        },
        {
            "x": -6,
            "y": -1,
            "z": 5,
            "elements": [
                "htmltech:casing@0"
            ]
        },
        {
            "x": -2,
            "y": 7,
            "z": 9,
            "elements": [
                "gregtech:metal_casing@4"
            ]
        },
        {
            "x": -5,
            "y": -1,
            "z": 5,
            "elements": [
                "htmltech:casing@0"
            ]
        },
        {
            "x": -1,
            "y": 7,
            "z": 9,
            "elements": [
                "gregtech:metal_casing@4"
            ]
        },
        {
            "x": -4,
            "y": -1,
            "z": 5,
            "elements": [
                "htmltech:casing@0"
            ]
        },
        {
            "x": -3,
            "y": -1,
            "z": 5,
            "elements": [
                "htmltech:casing@0"
            ]
        },
        {
            "x": -2,
            "y": -1,
            "z": 5,
            "elements": [
                "htmltech:casing@0"
            ]
        },
        {
            "x": -1,
            "y": -1,
            "z": 5,
            "elements": [
                "htmltech:casing@0"
            ]
        },
        {
            "x": 0,
            "y": -1,
            "z": 5,
            "elements": [
                "htmltech:casing@0"
            ]
        },
        {
            "x": -7,
            "y": 1,
            "z": 22,
            "elements": [
                "gregtech:multiblock_casing@2"
            ]
        },
        {
            "x": -6,
            "y": 1,
            "z": 22,
            "elements": [
                "gregtech:multiblock_casing@3"
            ]
        },
        {
            "x": -5,
            "y": 1,
            "z": 22,
            "elements": [
                "gregtech:multiblock_casing@4"
            ]
        },
        {
            "x": -4,
            "y": 1,
            "z": 22,
            "elements": [
                "gregtech:multiblock_casing@3"
            ]
        },
        {
            "x": -3,
            "y": 1,
            "z": 22,
            "elements": [
                "gregtech:multiblock_casing@4"
            ]
        },
        {
            "x": -2,
            "y": 1,
            "z": 22,
            "elements": [
                "gregtech:multiblock_casing@3"
            ]
        },
        {
            "x": -1,
            "y": 1,
            "z": 22,
            "elements": [
                "gregtech:multiblock_casing@2"
            ]
        },
        {
            "x": -9,
            "y": 0,
            "z": 5,
            "elements": [
                "htmltech:casing@0"
            ]
        },
        {
            "x": -8,
            "y": 0,
            "z": 5,
            "elements": [
                "htmltech:casing@0"
            ]
        },
        {
            "x": -7,
            "y": 0,
            "z": 5,
            "elements": [
                "htmltech:casing@0"
            ]
        },
        {
            "x": -6,
            "y": 0,
            "z": 5,
            "elements": [
                "htmltech:casing@0"
            ]
        },
        {
            "x": -5,
            "y": 0,
            "z": 5,
            "elements": [
                "htmltech:casing@0"
            ]
        },
        {
            "x": -4,
            "y": 0,
            "z": 5,
            "elements": [
                "htmltech:casing@0"
            ]
        },
        {
            "x": -3,
            "y": 0,
            "z": 5,
            "elements": [
                "htmltech:casing@0"
            ]
        },
        {
            "x": -2,
            "y": 0,
            "z": 5,
            "elements": [
                "htmltech:casing@0"
            ]
        },
        {
            "x": -1,
            "y": 0,
            "z": 5,
            "elements": [
                "htmltech:casing@0"
            ]
        },
        {
            "x": 0,
            "y": 0,
            "z": 5,
            "elements": [
                "opencomputers:adapter@0"
            ]
        },
        {
            "x": -7,
            "y": 2,
            "z": 22,
            "elements": [
                "gregtech:transparent_casing@1"
            ]
        },
        {
            "x": -6,
            "y": 2,
            "z": 22,
            "elements": [
                "gregtech:multiblock_casing@4"
            ]
        },
        {
            "x": -5,
            "y": 2,
            "z": 22,
            "elements": [
                "gregtech:boiler_casing@3"
            ]
        },
        {
            "x": -4,
            "y": 2,
            "z": 22,
            "elements": [
                "gregtech:multiblock_casing@4"
            ]
        },
        {
            "x": -3,
            "y": 2,
            "z": 22,
            "elements": [
                "gregtech:boiler_casing@3"
            ]
        },
        {
            "x": -2,
            "y": 2,
            "z": 22,
            "elements": [
                "gregtech:multiblock_casing@4"
            ]
        },
        {
            "x": -1,
            "y": 2,
            "z": 22,
            "elements": [
                "gregtech:transparent_casing@1"
            ]
        },
        {
            "x": -9,
            "y": 1,
            "z": 5,
            "elements": [
                "htmltech:casing@0"
            ]
        },
        {
            "x": -8,
            "y": 1,
            "z": 5,
            "elements": [
                "htmltech:casing@0"
            ]
        },
        {
            "x": -7,
            "y": 1,
            "z": 5,
            "elements": [
                "htmltech:casing@0"
            ]
        },
        {
            "x": -6,
            "y": 1,
            "z": 5,
            "elements": [
                "htmltech:casing@0"
            ]
        },
        {
            "x": -5,
            "y": 1,
            "z": 5,
            "elements": [
                "htmltech:casing@0"
            ]
        },
        {
            "x": -4,
            "y": 1,
            "z": 5,
            "elements": [
                "htmltech:casing@0"
            ]
        },
        {
            "x": -3,
            "y": 1,
            "z": 5,
            "elements": [
                "mekanismgenerators:reactorglass@1"
            ]
        },
        {
            "x": -2,
            "y": 1,
            "z": 5,
            "elements": [
                "htmltech:casing@0"
            ]
        },
        {
            "x": -1,
            "y": 1,
            "z": 5,
            "elements": [
                "htmltech:casing@0"
            ]
        },
        {
            "x": 0,
            "y": 1,
            "z": 5,
            "elements": [
                "htmltech:casing@0"
            ]
        },
        {
            "x": -7,
            "y": 3,
            "z": 22,
            "elements": [
                "gregtech:transparent_casing@1"
            ]
        },
        {
            "x": -6,
            "y": 3,
            "z": 22,
            "elements": [
                "gregtech:multiblock_casing@3"
            ]
        },
        {
            "x": -5,
            "y": 3,
            "z": 22,
            "elements": [
                "gregtech:multiblock_casing@4"
            ]
        },
        {
            "x": -4,
            "y": 3,
            "z": 22,
            "elements": [
                "gregtech:boiler_casing@3"
            ]
        },
        {
            "x": -3,
            "y": 3,
            "z": 22,
            "elements": [
                "gregtech:multiblock_casing@4"
            ]
        },
        {
            "x": -2,
            "y": 3,
            "z": 22,
            "elements": [
                "gregtech:multiblock_casing@3"
            ]
        },
        {
            "x": -1,
            "y": 3,
            "z": 22,
            "elements": [
                "gregtech:transparent_casing@1"
            ]
        },
        {
            "x": -9,
            "y": 2,
            "z": 5,
            "elements": [
                "htmltech:casing@0"
            ]
        },
        {
            "x": -8,
            "y": 2,
            "z": 5,
            "elements": [
                "htmltech:casing@0"
            ]
        },
        {
            "x": -7,
            "y": 2,
            "z": 5,
            "elements": [
                "htmltech:casing@0"
            ]
        },
        {
            "x": -6,
            "y": 2,
            "z": 5,
            "elements": [
                "htmltech:casing@0"
            ]
        },
        {
            "x": -5,
            "y": 2,
            "z": 5,
            "elements": [
                "htmltech:casing@0"
            ]
        },
        {
            "x": -4,
            "y": 2,
            "z": 5,
            "elements": [
                "htmltech:casing@0"
            ]
        },
        {
            "x": -3,
            "y": 2,
            "z": 5,
            "elements": [
                "htmltech:casing@0"
            ]
        },
        {
            "x": -2,
            "y": 2,
            "z": 5,
            "elements": [
                "htmltech:casing@0"
            ]
        },
        {
            "x": -1,
            "y": 2,
            "z": 5,
            "elements": [
                "htmltech:casing@0"
            ]
        },
        {
            "x": 0,
            "y": 2,
            "z": 5,
            "elements": [
                "htmltech:casing@0"
            ]
        },
        {
            "x": -7,
            "y": 4,
            "z": 22,
            "elements": [
                "gregtech:transparent_casing@1"
            ]
        },
        {
            "x": -6,
            "y": 4,
            "z": 22,
            "elements": [
                "gregtech:multiblock_casing@4"
            ]
        },
        {
            "x": -5,
            "y": 4,
            "z": 22,
            "elements": [
                "gregtech:boiler_casing@3"
            ]
        },
        {
            "x": -4,
            "y": 4,
            "z": 22,
            "elements": [
                "gregtech:multiblock_casing@4"
            ]
        },
        {
            "x": -3,
            "y": 4,
            "z": 22,
            "elements": [
                "gregtech:boiler_casing@3"
            ]
        },
        {
            "x": -2,
            "y": 4,
            "z": 22,
            "elements": [
                "gregtech:multiblock_casing@4"
            ]
        },
        {
            "x": -1,
            "y": 4,
            "z": 22,
            "elements": [
                "gregtech:transparent_casing@1"
            ]
        },
        {
            "x": -9,
            "y": 3,
            "z": 5,
            "elements": [
                "gregtech:meta_block_frame_2000@8"
            ]
        },
        {
            "x": -6,
            "y": 3,
            "z": 5,
            "elements": [
                "gregtech:meta_block_frame_2000@8"
            ]
        },
        {
            "x": -3,
            "y": 3,
            "z": 5,
            "elements": [
                "gregtech:meta_block_frame_2000@8"
            ]
        },
        {
            "x": 0,
            "y": 3,
            "z": 5,
            "elements": [
                "gregtech:meta_block_frame_2000@8"
            ]
        },
        {
            "x": -7,
            "y": 5,
            "z": 22,
            "elements": [
                "gregtech:multiblock_casing@2"
            ]
        },
        {
            "x": -6,
            "y": 5,
            "z": 22,
            "elements": [
                "gregtech:multiblock_casing@3"
            ]
        },
        {
            "x": -5,
            "y": 5,
            "z": 22,
            "elements": [
                "gregtech:multiblock_casing@4"
            ]
        },
        {
            "x": -4,
            "y": 5,
            "z": 22,
            "elements": [
                "gregtech:multiblock_casing@3"
            ]
        },
        {
            "x": -3,
            "y": 5,
            "z": 22,
            "elements": [
                "gregtech:multiblock_casing@4"
            ]
        },
        {
            "x": -2,
            "y": 5,
            "z": 22,
            "elements": [
                "gregtech:multiblock_casing@3"
            ]
        },
        {
            "x": -1,
            "y": 5,
            "z": 22,
            "elements": [
                "gregtech:multiblock_casing@2"
            ]
        },
        {
            "x": -9,
            "y": 4,
            "z": 5,
            "elements": [
                "gregtech:metal_casing@10"
            ]
        },
        {
            "x": -8,
            "y": 4,
            "z": 5,
            "elements": [
                "gregtech:metal_casing@10"
            ]
        },
        {
            "x": -7,
            "y": 4,
            "z": 5,
            "elements": [
                "gregtech:metal_casing@10"
            ]
        },
        {
            "x": -6,
            "y": 4,
            "z": 5,
            "elements": [
                "gregtech:metal_casing@10"
            ]
        },
        {
            "x": -5,
            "y": 4,
            "z": 5,
            "elements": [
                "gregtech:metal_casing@10"
            ]
        },
        {
            "x": -7,
            "y": -1,
            "z": 35,
            "elements": [
                "gregtech:metal_casing@4"
            ]
        },
        {
            "x": -4,
            "y": 4,
            "z": 5,
            "elements": [
                "gregtech:metal_casing@10"
            ]
        },
        {
            "x": -6,
            "y": -1,
            "z": 35,
            "elements": [
                "gregtech:metal_casing@4"
            ]
        },
        {
            "x": -3,
            "y": 4,
            "z": 5,
            "elements": [
                "gregtech:metal_casing@10"
            ]
        },
        {
            "x": -5,
            "y": -1,
            "z": 35,
            "elements": [
                "gregtech:metal_casing@4"
            ]
        },
        {
            "x": -2,
            "y": 4,
            "z": 5,
            "elements": [
                "gregtech:metal_casing@10"
            ]
        },
        {
            "x": -4,
            "y": -1,
            "z": 35,
            "elements": [
                "gregtech:metal_casing@4"
            ]
        },
        {
            "x": -1,
            "y": 4,
            "z": 5,
            "elements": [
                "gregtech:metal_casing@10"
            ]
        },
        {
            "x": -3,
            "y": -1,
            "z": 35,
            "elements": [
                "gregtech:metal_casing@4"
            ]
        },
        {
            "x": 0,
            "y": 4,
            "z": 5,
            "elements": [
                "gregtech:metal_casing@10"
            ]
        },
        {
            "x": -2,
            "y": -1,
            "z": 35,
            "elements": [
                "gregtech:metal_casing@4"
            ]
        },
        {
            "x": -1,
            "y": -1,
            "z": 35,
            "elements": [
                "gregtech:metal_casing@4"
            ]
        },
        {
            "x": -7,
            "y": 6,
            "z": 22,
            "elements": [
                "gcym:large_multiblock_casing@2"
            ]
        },
        {
            "x": -6,
            "y": 6,
            "z": 22,
            "elements": [
                "gregtech:boiler_casing@4"
            ]
        },
        {
            "x": -5,
            "y": 6,
            "z": 22,
            "elements": [
                "gregtech:hermetic_casing@8"
            ]
        },
        {
            "x": -4,
            "y": 6,
            "z": 22,
            "elements": [
                "gregtech:fusion_casing@1"
            ]
        },
        {
            "x": -3,
            "y": 6,
            "z": 22,
            "elements": [
                "gregtech:hermetic_casing@8"
            ]
        },
        {
            "x": -2,
            "y": 6,
            "z": 22,
            "elements": [
                "gregtech:boiler_casing@4"
            ]
        },
        {
            "x": -1,
            "y": 6,
            "z": 22,
            "elements": [
                "gcym:large_multiblock_casing@2"
            ]
        },
        {
            "x": -9,
            "y": 5,
            "z": 5,
            "elements": [
                "gregtech:metal_casing@10"
            ]
        },
        {
            "x": -8,
            "y": 5,
            "z": 5,
            "elements": [
                "gregtech:metal_casing@10"
            ]
        },
        {
            "x": -7,
            "y": 5,
            "z": 5,
            "elements": [
                "gregtech:metal_casing@10"
            ]
        },
        {
            "x": -6,
            "y": 5,
            "z": 5,
            "elements": [
                "gregtech:metal_casing@10"
            ]
        },
        {
            "x": -5,
            "y": 5,
            "z": 5,
            "elements": [
                "gregtech:multiblock_casing@1"
            ]
        },
        {
            "x": -7,
            "y": 0,
            "z": 35,
            "elements": [
                "gcym:large_multiblock_casing@2"
            ]
        },
        {
            "x": -4,
            "y": 5,
            "z": 5,
            "elements": [
                "gregtech:multiblock_casing@1"
            ]
        },
        {
            "x": -3,
            "y": 5,
            "z": 5,
            "elements": [
                "gregtech:metal_casing@10"
            ]
        },
        {
            "x": -6,
            "y": 0,
            "z": 35,
            "elements": [
                "gregtech:boiler_casing@4"
            ]
        },
        {
            "x": -2,
            "y": 5,
            "z": 5,
            "elements": [
                "gregtech:metal_casing@10"
            ]
        },
        {
            "x": -5,
            "y": 0,
            "z": 35,
            "elements": [
                "gregtech:hermetic_casing@8"
            ]
        },
        {
            "x": -1,
            "y": 5,
            "z": 5,
            "elements": [
                "gregtech:metal_casing@10"
            ]
        },
        {
            "x": -4,
            "y": 0,
            "z": 35,
            "elements": [
                "gregtech:fusion_casing@1"
            ]
        },
        {
            "x": 0,
            "y": 5,
            "z": 5,
            "elements": [
                "opencomputers:adapter@0"
            ]
        },
        {
            "x": -3,
            "y": 0,
            "z": 35,
            "elements": [
                "gregtech:hermetic_casing@8"
            ]
        },
        {
            "x": -2,
            "y": 0,
            "z": 35,
            "elements": [
                "gregtech:boiler_casing@4"
            ]
        },
        {
            "x": -1,
            "y": 0,
            "z": 35,
            "elements": [
                "modularmachinery:blockinputbus@0"
            ]
        },
        {
            "x": -7,
            "y": 7,
            "z": 22,
            "elements": [
                "modularmachinery:blockenergyinputhatch@7"
            ]
        },
        {
            "x": -6,
            "y": 7,
            "z": 22,
            "elements": [
                "gregtech:metal_casing@4"
            ]
        },
        {
            "x": -5,
            "y": 7,
            "z": 22,
            "elements": [
                "gregtech:metal_casing@4"
            ]
        },
        {
            "x": -4,
            "y": 7,
            "z": 22,
            "elements": [
                "gregtech:metal_casing@4"
            ]
        },
        {
            "x": -7,
            "y": -1,
            "z": 18,
            "elements": [
                "gregtech:metal_casing@4"
            ]
        },
        {
            "x": -3,
            "y": 7,
            "z": 22,
            "elements": [
                "gregtech:metal_casing@4"
            ]
        },
        {
            "x": -6,
            "y": -1,
            "z": 18,
            "elements": [
                "gregtech:metal_casing@4"
            ]
        },
        {
            "x": -2,
            "y": 7,
            "z": 22,
            "elements": [
                "gregtech:metal_casing@4"
            ]
        },
        {
            "x": -5,
            "y": -1,
            "z": 18,
            "elements": [
                "gregtech:metal_casing@4"
            ]
        },
        {
            "x": -1,
            "y": 7,
            "z": 22,
            "elements": [
                "gregtech:metal_casing@4"
            ]
        },
        {
            "x": -4,
            "y": -1,
            "z": 18,
            "elements": [
                "gregtech:metal_casing@4"
            ]
        },
        {
            "x": -3,
            "y": -1,
            "z": 18,
            "elements": [
                "gregtech:metal_casing@4"
            ]
        },
        {
            "x": -2,
            "y": -1,
            "z": 18,
            "elements": [
                "gregtech:metal_casing@4"
            ]
        },
        {
            "x": -1,
            "y": -1,
            "z": 18,
            "elements": [
                "gregtech:metal_casing@4"
            ]
        },
        {
            "x": -9,
            "y": 6,
            "z": 5,
            "elements": [
                "gregtech:metal_casing@10"
            ]
        },
        {
            "x": -8,
            "y": 6,
            "z": 5,
            "elements": [
                "gregtech:metal_casing@10"
            ]
        },
        {
            "x": -7,
            "y": 6,
            "z": 5,
            "elements": [
                "gregtech:metal_casing@10"
            ]
        },
        {
            "x": -6,
            "y": 6,
            "z": 5,
            "elements": [
                "gregtech:metal_casing@10"
            ]
        },
        {
            "x": -5,
            "y": 6,
            "z": 5,
            "elements": [
                "gregtech:multiblock_casing@1"
            ]
        },
        {
            "x": -4,
            "y": 6,
            "z": 5,
            "elements": [
                "gregtech:multiblock_casing@1"
            ]
        },
        {
            "x": -7,
            "y": 1,
            "z": 35,
            "elements": [
                "gregtech:multiblock_casing@2"
            ]
        },
        {
            "x": -3,
            "y": 6,
            "z": 5,
            "elements": [
                "gregtech:metal_casing@10"
            ]
        },
        {
            "x": -6,
            "y": 1,
            "z": 35,
            "elements": [
                "gregtech:multiblock_casing@3"
            ]
        },
        {
            "x": -2,
            "y": 6,
            "z": 5,
            "elements": [
                "gregtech:metal_casing@10"
            ]
        },
        {
            "x": -5,
            "y": 1,
            "z": 35,
            "elements": [
                "gregtech:multiblock_casing@4"
            ]
        },
        {
            "x": -1,
            "y": 6,
            "z": 5,
            "elements": [
                "gregtech:metal_casing@10"
            ]
        },
        {
            "x": -4,
            "y": 1,
            "z": 35,
            "elements": [
                "gregtech:multiblock_casing@3"
            ]
        },
        {
            "x": 0,
            "y": 6,
            "z": 5,
            "elements": [
                "gregtech:metal_casing@10"
            ]
        },
        {
            "x": -3,
            "y": 1,
            "z": 35,
            "elements": [
                "gregtech:multiblock_casing@4"
            ]
        },
        {
            "x": -2,
            "y": 1,
            "z": 35,
            "elements": [
                "gregtech:multiblock_casing@3"
            ]
        },
        {
            "x": -1,
            "y": 1,
            "z": 35,
            "elements": [
                "gregtech:multiblock_casing@2"
            ]
        },
        {
            "x": -7,
            "y": 0,
            "z": 18,
            "elements": [
                "modularmachinery:blockfluidinputhatch@7"
            ]
        },
        {
            "x": -6,
            "y": 0,
            "z": 18,
            "elements": [
                "gregtech:boiler_casing@4"
            ]
        },
        {
            "x": -5,
            "y": 0,
            "z": 18,
            "elements": [
                "gregtech:hermetic_casing@8"
            ]
        },
        {
            "x": -4,
            "y": 0,
            "z": 18,
            "elements": [
                "gregtech:fusion_casing@1"
            ]
        },
        {
            "x": -3,
            "y": 0,
            "z": 18,
            "elements": [
                "gregtech:hermetic_casing@8"
            ]
        },
        {
            "x": -2,
            "y": 0,
            "z": 18,
            "elements": [
                "gregtech:boiler_casing@4"
            ]
        },
        {
            "x": -1,
            "y": 0,
            "z": 18,
            "elements": [
                "modularmachinery:blockinputbus@0"
            ]
        },
        {
            "x": -9,
            "y": 7,
            "z": 5,
            "elements": [
                "gregtech:metal_casing@10"
            ]
        },
        {
            "x": -8,
            "y": 7,
            "z": 5,
            "elements": [
                "gregtech:metal_casing@10"
            ]
        },
        {
            "x": -7,
            "y": 7,
            "z": 5,
            "elements": [
                "gregtech:metal_casing@10"
            ]
        },
        {
            "x": -6,
            "y": 7,
            "z": 5,
            "elements": [
                "gregtech:metal_casing@10"
            ]
        },
        {
            "x": -5,
            "y": 7,
            "z": 5,
            "elements": [
                "gregtech:metal_casing@10"
            ]
        },
        {
            "x": -4,
            "y": 7,
            "z": 5,
            "elements": [
                "gregtech:metal_casing@10"
            ]
        },
        {
            "x": -7,
            "y": 2,
            "z": 35,
            "elements": [
                "gregtech:transparent_casing@1"
            ]
        },
        {
            "x": -3,
            "y": 7,
            "z": 5,
            "elements": [
                "gregtech:metal_casing@10"
            ]
        },
        {
            "x": -6,
            "y": 2,
            "z": 35,
            "elements": [
                "gregtech:multiblock_casing@4"
            ]
        },
        {
            "x": -2,
            "y": 7,
            "z": 5,
            "elements": [
                "gregtech:metal_casing@10"
            ]
        },
        {
            "x": -5,
            "y": 2,
            "z": 35,
            "elements": [
                "gregtech:boiler_casing@3"
            ]
        },
        {
            "x": -1,
            "y": 7,
            "z": 5,
            "elements": [
                "gregtech:metal_casing@10"
            ]
        },
        {
            "x": -4,
            "y": 2,
            "z": 35,
            "elements": [
                "gregtech:multiblock_casing@4"
            ]
        },
        {
            "x": 0,
            "y": 7,
            "z": 5,
            "elements": [
                "gregtech:metal_casing@10"
            ]
        },
        {
            "x": -3,
            "y": 2,
            "z": 35,
            "elements": [
                "gregtech:boiler_casing@3"
            ]
        },
        {
            "x": -2,
            "y": 2,
            "z": 35,
            "elements": [
                "gregtech:multiblock_casing@4"
            ]
        },
        {
            "x": -1,
            "y": 2,
            "z": 35,
            "elements": [
                "gregtech:transparent_casing@1"
            ]
        },
        {
            "x": -2,
            "y": -1,
            "z": 1,
            "elements": [
                "gregtech:multiblock_casing@3"
            ]
        },
        {
            "x": -1,
            "y": -1,
            "z": 1,
            "elements": [
                "gregtech:multiblock_casing@3"
            ]
        },
        {
            "x": 0,
            "y": -1,
            "z": 1,
            "elements": [
                "gregtech:multiblock_casing@3"
            ]
        },
        {
            "x": 1,
            "y": -1,
            "z": 1,
            "elements": [
                "opencomputers:adapter@0"
            ]
        },
        {
            "x": -7,
            "y": 1,
            "z": 18,
            "elements": [
                "gregtech:multiblock_casing@2"
            ]
        },
        {
            "x": -6,
            "y": 1,
            "z": 18,
            "elements": [
                "gregtech:multiblock_casing@3"
            ]
        },
        {
            "x": -5,
            "y": 1,
            "z": 18,
            "elements": [
                "gregtech:multiblock_casing@4"
            ]
        },
        {
            "x": -4,
            "y": 1,
            "z": 18,
            "elements": [
                "gregtech:multiblock_casing@3"
            ]
        },
        {
            "x": -3,
            "y": 1,
            "z": 18,
            "elements": [
                "gregtech:multiblock_casing@4"
            ]
        },
        {
            "x": -2,
            "y": 1,
            "z": 18,
            "elements": [
                "gregtech:multiblock_casing@3"
            ]
        },
        {
            "x": -1,
            "y": 1,
            "z": 18,
            "elements": [
                "gregtech:multiblock_casing@2"
            ]
        },
        {
            "x": -7,
            "y": 3,
            "z": 35,
            "elements": [
                "gregtech:transparent_casing@1"
            ]
        },
        {
            "x": -6,
            "y": 3,
            "z": 35,
            "elements": [
                "gregtech:multiblock_casing@3"
            ]
        },
        {
            "x": -5,
            "y": 3,
            "z": 35,
            "elements": [
                "gregtech:multiblock_casing@4"
            ]
        },
        {
            "x": -4,
            "y": 3,
            "z": 35,
            "elements": [
                "gregtech:boiler_casing@3"
            ]
        },
        {
            "x": -3,
            "y": 3,
            "z": 35,
            "elements": [
                "gregtech:multiblock_casing@4"
            ]
        },
        {
            "x": -2,
            "y": 3,
            "z": 35,
            "elements": [
                "gregtech:multiblock_casing@3"
            ]
        },
        {
            "x": -1,
            "y": 3,
            "z": 35,
            "elements": [
                "gregtech:transparent_casing@1"
            ]
        },
        {
            "x": -2,
            "y": 0,
            "z": 1,
            "elements": [
                "gregtech:multiblock_casing@3"
            ]
        },
        {
            "x": -1,
            "y": 0,
            "z": 1,
            "elements": [
                "opencomputers:screen3"
            ]
        },
        {
            "x": 0,
            "y": 0,
            "z": 1,
            "elements": [
                "gregtech:multiblock_casing@3"
            ]
        },
        {
            "x": 1,
            "y": 0,
            "z": 1,
            "elements": [
                "gregtech:multiblock_casing@3"
            ]
        },
        {
            "x": -7,
            "y": 2,
            "z": 18,
            "elements": [
                "gregtech:transparent_casing@1"
            ]
        },
        {
            "x": -6,
            "y": 2,
            "z": 18,
            "elements": [
                "gregtech:multiblock_casing@4"
            ]
        },
        {
            "x": -5,
            "y": 2,
            "z": 18,
            "elements": [
                "gregtech:boiler_casing@3"
            ]
        },
        {
            "x": -4,
            "y": 2,
            "z": 18,
            "elements": [
                "gregtech:multiblock_casing@4"
            ]
        },
        {
            "x": -3,
            "y": 2,
            "z": 18,
            "elements": [
                "gregtech:boiler_casing@3"
            ]
        },
        {
            "x": -2,
            "y": 2,
            "z": 18,
            "elements": [
                "gregtech:multiblock_casing@4"
            ]
        },
        {
            "x": -1,
            "y": 2,
            "z": 18,
            "elements": [
                "gregtech:transparent_casing@1"
            ]
        },
        {
            "x": -7,
            "y": 4,
            "z": 35,
            "elements": [
                "gregtech:transparent_casing@1"
            ]
        },
        {
            "x": -6,
            "y": 4,
            "z": 35,
            "elements": [
                "gregtech:multiblock_casing@4"
            ]
        },
        {
            "x": -5,
            "y": 4,
            "z": 35,
            "elements": [
                "gregtech:boiler_casing@3"
            ]
        },
        {
            "x": -4,
            "y": 4,
            "z": 35,
            "elements": [
                "gregtech:multiblock_casing@4"
            ]
        },
        {
            "x": -3,
            "y": 4,
            "z": 35,
            "elements": [
                "gregtech:boiler_casing@3"
            ]
        },
        {
            "x": -2,
            "y": 4,
            "z": 35,
            "elements": [
                "gregtech:multiblock_casing@4"
            ]
        },
        {
            "x": -1,
            "y": 4,
            "z": 35,
            "elements": [
                "gregtech:transparent_casing@1"
            ]
        },
        {
            "x": -7,
            "y": 3,
            "z": 18,
            "elements": [
                "gregtech:transparent_casing@1"
            ]
        },
        {
            "x": -6,
            "y": 3,
            "z": 18,
            "elements": [
                "gregtech:multiblock_casing@3"
            ]
        },
        {
            "x": -5,
            "y": 3,
            "z": 18,
            "elements": [
                "gregtech:multiblock_casing@4"
            ]
        },
        {
            "x": -4,
            "y": 3,
            "z": 18,
            "elements": [
                "gregtech:boiler_casing@3"
            ]
        },
        {
            "x": -3,
            "y": 3,
            "z": 18,
            "elements": [
                "gregtech:multiblock_casing@4"
            ]
        },
        {
            "x": -2,
            "y": 3,
            "z": 18,
            "elements": [
                "gregtech:multiblock_casing@3"
            ]
        },
        {
            "x": -1,
            "y": 3,
            "z": 18,
            "elements": [
                "gregtech:transparent_casing@1"
            ]
        },
        {
            "x": -7,
            "y": 5,
            "z": 35,
            "elements": [
                "gregtech:multiblock_casing@2"
            ]
        },
        {
            "x": -6,
            "y": 5,
            "z": 35,
            "elements": [
                "gregtech:multiblock_casing@3"
            ]
        },
        {
            "x": -5,
            "y": 5,
            "z": 35,
            "elements": [
                "gregtech:multiblock_casing@4"
            ]
        },
        {
            "x": -4,
            "y": 5,
            "z": 35,
            "elements": [
                "gregtech:multiblock_casing@3"
            ]
        },
        {
            "x": -3,
            "y": 5,
            "z": 35,
            "elements": [
                "gregtech:multiblock_casing@4"
            ]
        },
        {
            "x": -2,
            "y": 5,
            "z": 35,
            "elements": [
                "gregtech:multiblock_casing@3"
            ]
        },
        {
            "x": -1,
            "y": 5,
            "z": 35,
            "elements": [
                "gregtech:multiblock_casing@2"
            ]
        },
        {
            "x": -7,
            "y": 4,
            "z": 18,
            "elements": [
                "gregtech:transparent_casing@1"
            ]
        },
        {
            "x": -6,
            "y": 4,
            "z": 18,
            "elements": [
                "gregtech:multiblock_casing@4"
            ]
        },
        {
            "x": -5,
            "y": 4,
            "z": 18,
            "elements": [
                "gregtech:boiler_casing@3"
            ]
        },
        {
            "x": -4,
            "y": 4,
            "z": 18,
            "elements": [
                "gregtech:multiblock_casing@4"
            ]
        },
        {
            "x": -3,
            "y": 4,
            "z": 18,
            "elements": [
                "gregtech:boiler_casing@3"
            ]
        },
        {
            "x": -2,
            "y": 4,
            "z": 18,
            "elements": [
                "gregtech:multiblock_casing@4"
            ]
        },
        {
            "x": -1,
            "y": 4,
            "z": 18,
            "elements": [
                "gregtech:transparent_casing@1"
            ]
        },
        {
            "x": -7,
            "y": 6,
            "z": 35,
            "elements": [
                "gcym:large_multiblock_casing@2"
            ]
        },
        {
            "x": -6,
            "y": 6,
            "z": 35,
            "elements": [
                "gregtech:boiler_casing@4"
            ]
        },
        {
            "x": -5,
            "y": 6,
            "z": 35,
            "elements": [
                "gregtech:hermetic_casing@8"
            ]
        },
        {
            "x": -4,
            "y": 6,
            "z": 35,
            "elements": [
                "gregtech:fusion_casing@1"
            ]
        },
        {
            "x": -3,
            "y": 6,
            "z": 35,
            "elements": [
                "gregtech:hermetic_casing@8"
            ]
        },
        {
            "x": -2,
            "y": 6,
            "z": 35,
            "elements": [
                "gregtech:boiler_casing@4"
            ]
        },
        {
            "x": -1,
            "y": 6,
            "z": 35,
            "elements": [
                "gcym:large_multiblock_casing@2"
            ]
        },
        {
            "x": -7,
            "y": 5,
            "z": 18,
            "elements": [
                "gregtech:multiblock_casing@2"
            ]
        },
        {
            "x": -6,
            "y": 5,
            "z": 18,
            "elements": [
                "gregtech:multiblock_casing@3"
            ]
        },
        {
            "x": -5,
            "y": 5,
            "z": 18,
            "elements": [
                "gregtech:multiblock_casing@4"
            ]
        },
        {
            "x": -4,
            "y": 5,
            "z": 18,
            "elements": [
                "gregtech:multiblock_casing@3"
            ]
        },
        {
            "x": -3,
            "y": 5,
            "z": 18,
            "elements": [
                "gregtech:multiblock_casing@4"
            ]
        },
        {
            "x": -2,
            "y": 5,
            "z": 18,
            "elements": [
                "gregtech:multiblock_casing@3"
            ]
        },
        {
            "x": -1,
            "y": 5,
            "z": 18,
            "elements": [
                "gregtech:multiblock_casing@2"
            ]
        },
        {
            "x": -7,
            "y": 7,
            "z": 35,
            "elements": [
                "gregtech:metal_casing@4"
            ]
        },
        {
            "x": -6,
            "y": 7,
            "z": 35,
            "elements": [
                "gregtech:metal_casing@4"
            ]
        },
        {
            "x": -5,
            "y": 7,
            "z": 35,
            "elements": [
                "gregtech:metal_casing@4"
            ]
        },
        {
            "x": -4,
            "y": 7,
            "z": 35,
            "elements": [
                "gregtech:metal_casing@4"
            ]
        },
        {
            "x": -7,
            "y": -1,
            "z": 31,
            "elements": [
                "gregtech:metal_casing@4"
            ]
        },
        {
            "x": -3,
            "y": 7,
            "z": 35,
            "elements": [
                "gregtech:metal_casing@4"
            ]
        },
        {
            "x": -6,
