{
    "registryname": "Material_Phase_Transition_Devices",
    "localizedname": "Material Phase_Transition Devices",
     "color": "c9caca",
    "parts": [
        {
            "x": -1,
            "y": 0,
            "z": 0,
            "elements": [
                "modularmachinery:blockinputbus@6"
            ]
        },
        {
            "x": 4,
            "y": 8,
            "z": 4,
            "elements": [
                "modularmachinery:blockenergyinputhatch@7"
            ]
        },
        {
            "x": 4,
            "y": 6,
            "z": 3,
            "elements": [
                "gregtech:transparent_casing@1"
            ]
        },
        {
            "x": 3,
            "y": 4,
            "z": 2,
            "elements": [
                "gregtech:transparent_casing@1"
            ]
        },
        {
            "x": 2,
            "y": 2,
            "z": 1,
            "elements": [
                "gregtech:transparent_casing@1"
            ]
        },
        {
            "x": 1,
            "y": 0,
            "z": 0,
            "elements": [
                "modularmachinery:blockinputbus@6"
            ]
        },
        {
            "x": 9,
            "y": 4,
            "z": 2,
            "elements": [
                "gregtech:fusion_casing@1"
            ]
        },
        {
            "x": 11,
            "y": 6,
            "z": 3,
            "elements": [
                "contenttweaker:machine_coil_neutonium@0"
            ]
        },
        {
            "x": 11,
            "y": 2,
            "z": 1,
            "elements": [
                "contenttweaker:machine_coil_neutonium@0"
            ]
        },
        {
            "x": 13,
            "y": 4,
            "z": 2,
            "elements": [
                "gregtech:fusion_casing@1"
            ]
        },
        {
            "x": -4,
            "y": 7,
            "z": 3,
            "elements": [
                "gregtech:transparent_casing@1"
            ]
        },
        {
            "x": -3,
            "y": 9,
            "z": 4,
            "elements": [
                "contenttweaker:chaosproofmachinecasing@0"
            ]
        },
        {
            "x": -2,
            "y": 9,
            "z": 4,
            "elements": [
                "contenttweaker:chaosproofmachinecasing@0"
            ]
        },
        {
            "x": -3,
            "y": 5,
            "z": 2,
            "elements": [
                "gregtech:transparent_casing@1"
            ]
        },
        {
            "x": -2,
            "y": 7,
            "z": 3,
            "elements": [
                "gregtech:meta_block_compressed_7@15"
            ]
        },
        {
            "x": -1,
            "y": 9,
            "z": 4,
            "elements": [
                "contenttweaker:chaosproofmachinecasing@0"
            ]
        },
        {
            "x": 0,
            "y": 9,
            "z": 4,
            "elements": [
                "contenttweaker:chaosproofmachinecasing@0"
            ]
        },
        {
            "x": 1,
            "y": 9,
            "z": 4,
            "elements": [
                "contenttweaker:chaosproofmachinecasing@0"
            ]
        },
        {
            "x": -2,
            "y": 3,
            "z": 1,
            "elements": [
                "gregtech:transparent_casing@1"
            ]
        },
        {
            "x": 2,
            "y": 9,
            "z": 4,
            "elements": [
                "contenttweaker:chaosproofmachinecasing@0"
            ]
        },
        {
            "x": 0,
            "y": 5,
            "z": 2,
            "elements": [
                "gregtech:meta_block_compressed_7@15"
            ]
        },
        {
            "x": 3,
            "y": 9,
            "z": 4,
            "elements": [
                "contenttweaker:chaosproofmachinecasing@0"
            ]
        },
        {
            "x": -1,
            "y": 1,
            "z": 0,
            "elements": [
                "gregtech:transparent_casing@1"
            ]
        },
        {
            "x": 0,
            "y": 1,
            "z": 0,
            "elements": [
                "gregtech:transparent_casing@1"
            ]
        },
        {
            "x": 4,
            "y": 7,
            "z": 3,
            "elements": [
                "gregtech:transparent_casing@1"
            ]
        },
        {
            "x": 3,
            "y": 5,
            "z": 2,
            "elements": [
                "gregtech:transparent_casing@1"
            ]
        },
        {
            "x": 2,
            "y": 3,
            "z": 1,
            "elements": [
                "gregtech:transparent_casing@1"
            ]
        },
        {
            "x": 1,
            "y": 1,
            "z": 0,
            "elements": [
                "gregtech:transparent_casing@1"
            ]
        },
        {
            "x": -13,
            "y": 4,
            "z": 1,
            "elements": [
                "gregtech:fusion_casing@1"
            ]
        },
        {
            "x": -11,
            "y": 6,
            "z": 2,
            "elements": [
                "contenttweaker:machine_coil_neutonium@0"
            ]
        },
        {
            "x": -10,
            "y": 2,
            "z": 0,
            "elements": [
                "contenttweaker:machine_coil_neutonium@0"
            ]
        },
        {
            "x": -8,
            "y": 4,
            "z": 1,
            "elements": [
                "gregtech:fusion_casing@1"
            ]
        },
        {
            "x": -4,
            "y": 8,
            "z": 3,
            "elements": [
                "modularmachinery:blockenergyinputhatch@7"
            ]
        },
        {
            "x": -3,
            "y": 6,
            "z": 2,
            "elements": [
                "gregtech:transparent_casing@1"
            ]
        },
        {
            "x": -1,
            "y": 8,
            "z": 3,
            "elements": [
                "gregtech:meta_block_compressed_7@15"
            ]
        },
        {
            "x": -2,
            "y": 4,
            "z": 1,
            "elements": [
                "gregtech:transparent_casing@1"
            ]
        },
        {
            "x": -1,
            "y": 6,
            "z": 2,
            "elements": [
                "gregtech:meta_block_compressed_7@15"
            ]
        },
        {
            "x": -1,
            "y": 2,
            "z": 0,
            "elements": [
                "gregtech:transparent_casing@1"
            ]
        },
        {
            "x": 0,
            "y": 2,
            "z": 0,
            "elements": [
                "gregtech:transparent_casing@1"
            ]
        },
        {
            "x": 4,
            "y": 8,
            "z": 3,
            "elements": [
                "modularmachinery:blockenergyinputhatch@7"
            ]
        },
        {
            "x": 3,
            "y": 6,
            "z": 2,
            "elements": [
                "gregtech:transparent_casing@1"
            ]
        },
        {
            "x": 2,
            "y": 4,
            "z": 1,
            "elements": [
                "gregtech:transparent_casing@1"
            ]
        },
        {
            "x": 1,
            "y": 2,
            "z": 0,
            "elements": [
                "gregtech:transparent_casing@1"
            ]
        },
        {
            "x": 8,
            "y": 4,
            "z": 1,
            "elements": [
                "gregtech:fusion_casing@1"
            ]
        },
        {
            "x": 11,
            "y": 6,
            "z": 2,
            "elements": [
                "contenttweaker:machine_coil_neutonium@0"
            ]
        },
        {
            "x": 10,
            "y": 2,
            "z": 0,
            "elements": [
                "contenttweaker:machine_coil_neutonium@0"
            ]
        },
        {
            "x": 13,
            "y": 4,
            "z": 1,
            "elements": [
                "gregtech:fusion_casing@1"
            ]
        },
        {
            "x": -3,
            "y": 4,
            "z": 17,
            "elements": [
                "gregtech:fusion_casing@1"
            ]
        },
        {
            "x": -2,
            "y": 4,
            "z": 17,
            "elements": [
                "gregtech:fusion_casing@1"
            ]
        },
        {
            "x": -1,
            "y": 4,
            "z": 17,
            "elements": [
                "gregtech:fusion_casing@1"
            ]
        },
        {
            "x": 0,
            "y": 4,
            "z": 17,
            "elements": [
                "gregtech:fusion_casing@1"
            ]
        },
        {
            "x": 1,
            "y": 4,
            "z": 17,
            "elements": [
                "gregtech:fusion_casing@1"
            ]
        },
        {
            "x": 2,
            "y": 4,
            "z": 17,
            "elements": [
                "gregtech:fusion_casing@1"
            ]
        },
        {
            "x": 3,
            "y": 4,
            "z": 17,
            "elements": [
                "gregtech:fusion_casing@1"
            ]
        },
        {
            "x": -3,
            "y": 9,
            "z": 3,
            "elements": [
                "contenttweaker:chaosproofmachinecasing@0"
            ]
        },
        {
            "x": -3,
            "y": 7,
            "z": 2,
            "elements": [
                "gregtech:transparent_casing@1"
            ]
        },
        {
            "x": -2,
            "y": 9,
            "z": 3,
            "elements": [
                "contenttweaker:chaosproofmachinecasing@0"
            ]
        },
        {
            "x": -1,
            "y": 9,
            "z": 3,
            "elements": [
                "contenttweaker:chaosproofmachinecasing@0"
            ]
        },
        {
            "x": 0,
            "y": 9,
            "z": 3,
            "elements": [
                "contenttweaker:chaosproofmachinecasing@0"
            ]
        },
        {
            "x": -2,
            "y": 5,
            "z": 1,
            "elements": [
                "gregtech:transparent_casing@1"
            ]
        },
        {
            "x": 1,
            "y": 9,
            "z": 3,
            "elements": [
                "contenttweaker:chaosproofmachinecasing@0"
            ]
        },
        {
            "x": 2,
            "y": 9,
            "z": 3,
            "elements": [
                "contenttweaker:chaosproofmachinecasing@0"
            ]
        },
        {
            "x": -1,
            "y": 3,
            "z": 0,
            "elements": [
                "gregtech:transparent_casing@1"
            ]
        },
        {
            "x": 3,
            "y": 9,
            "z": 3,
            "elements": [
                "contenttweaker:chaosproofmachinecasing@0"
            ]
        },
        {
            "x": 0,
            "y": 3,
            "z": 0,
            "elements": [
                "gregtech:transparent_casing@1"
            ]
        },
        {
            "x": 3,
            "y": 7,
            "z": 2,
            "elements": [
                "gregtech:transparent_casing@1"
            ]
        },
        {
            "x": 2,
            "y": 5,
            "z": 1,
            "elements": [
                "gregtech:transparent_casing@1"
            ]
        },
        {
            "x": 1,
            "y": 3,
            "z": 0,
            "elements": [
                "gregtech:transparent_casing@1"
            ]
        },
        {
            "x": -12,
            "y": 4,
            "z": 0,
            "elements": [
                "gregtech:fusion_casing@1"
            ]
        },
        {
            "x": -11,
            "y": 6,
            "z": 1,
            "elements": [
                "contenttweaker:machine_coil_neutonium@0"
            ]
        },
        {
            "x": -8,
            "y": 4,
            "z": 0,
            "elements": [
                "gregtech:fusion_casing@1"
            ]
        },
        {
            "x": -3,
            "y": 8,
            "z": 2,
            "elements": [
                "contenttweaker:chaosproofmachinecasing@0"
            ]
        },
        {
            "x": -2,
            "y": 6,
            "z": 1,
            "elements": [
                "gregtech:transparent_casing@1"
            ]
        },
        {
            "x": -1,
            "y": 4,
            "z": 0,
            "elements": [
                "gregtech:transparent_casing@1"
            ]
        },
        {
            "x": 0,
            "y": 4,
            "z": 0,
            "elements": [
                "gregtech:transparent_casing@1"
            ]
        },
        {
            "x": 3,
            "y": 8,
            "z": 2,
            "elements": [
                "contenttweaker:chaosproofmachinecasing@0"
            ]
        },
        {
            "x": 2,
            "y": 6,
            "z": 1,
            "elements": [
                "gregtech:transparent_casing@1"
            ]
        },
        {
            "x": 1,
            "y": 4,
            "z": 0,
            "elements": [
                "gregtech:transparent_casing@1"
            ]
        },
        {
            "x": 8,
            "y": 4,
            "z": 0,
            "elements": [
                "gregtech:fusion_casing@1"
            ]
        },
        {
            "x": 11,
            "y": 6,
            "z": 1,
            "elements": [
                "contenttweaker:machine_coil_neutonium@0"
            ]
        },
        {
            "x": -6,
            "y": 4,
            "z": 16,
            "elements": [
                "gregtech:fusion_casing@1"
            ]
        },
        {
            "x": -5,
            "y": 4,
            "z": 16,
            "elements": [
                "gregtech:fusion_casing@1"
            ]
        },
        {
            "x": 12,
            "y": 4,
            "z": 0,
            "elements": [
                "gregtech:fusion_casing@1"
            ]
        },
        {
            "x": -4,
            "y": 4,
            "z": 16,
            "elements": [
                "gregtech:fusion_casing@1"
            ]
        },
        {
            "x": -3,
            "y": 2,
            "z": 15,
            "elements": [
                "contenttweaker:machine_coil_neutonium@0"
            ]
        },
        {
            "x": -2,
            "y": 2,
            "z": 15,
            "elements": [
                "contenttweaker:machine_coil_neutonium@0"
            ]
        },
        {
            "x": -1,
            "y": 2,
            "z": 15,
            "elements": [
                "contenttweaker:machine_coil_neutonium@0"
            ]
        },
        {
            "x": 0,
            "y": 2,
            "z": 15,
            "elements": [
                "contenttweaker:machine_coil_neutonium@0"
            ]
        },
        {
            "x": 1,
            "y": 2,
            "z": 15,
            "elements": [
                "contenttweaker:machine_coil_neutonium@0"
            ]
        },
        {
            "x": 2,
            "y": 2,
            "z": 15,
            "elements": [
                "contenttweaker:machine_coil_neutonium@0"
            ]
        },
        {
            "x": 4,
            "y": 4,
            "z": 16,
            "elements": [
                "gregtech:fusion_casing@1"
            ]
        },
        {
            "x": 3,
            "y": 2,
            "z": 15,
            "elements": [
                "contenttweaker:machine_coil_neutonium@0"
            ]
        },
        {
            "x": 5,
            "y": 4,
            "z": 16,
            "elements": [
                "gregtech:fusion_casing@1"
            ]
        },
        {
            "x": 6,
            "y": 4,
            "z": 16,
            "elements": [
                "gregtech:fusion_casing@1"
            ]
        },
        {
            "x": -2,
            "y": 9,
            "z": 2,
            "elements": [
                "contenttweaker:chaosproofmachinecasing@0"
            ]
        },
        {
            "x": -2,
            "y": 7,
            "z": 1,
            "elements": [
                "gregtech:transparent_casing@1"
            ]
        },
        {
            "x": -1,
            "y": 9,
            "z": 2,
            "elements": [
                "contenttweaker:chaosproofmachinecasing@0"
            ]
        },
        {
            "x": 0,
            "y": 9,
            "z": 2,
            "elements": [
                "contenttweaker:chaosproofmachinecasing@0"
            ]
        },
        {
            "x": 1,
            "y": 9,
            "z": 2,
            "elements": [
                "contenttweaker:chaosproofmachinecasing@0"
            ]
        },
        {
            "x": -1,
            "y": 5,
            "z": 0,
            "elements": [
                "gregtech:transparent_casing@1"
            ]
        },
        {
            "x": 2,
            "y": 9,
            "z": 2,
            "elements": [
                "contenttweaker:chaosproofmachinecasing@0"
            ]
        },
        {
            "x": 0,
            "y": 5,
            "z": 0,
            "elements": [
                "gregtech:transparent_casing@1"
            ]
        },
        {
            "x": 2,
            "y": 7,
            "z": 1,
            "elements": [
                "gregtech:transparent_casing@1"
            ]
        },
        {
            "x": 1,
            "y": 5,
            "z": 0,
            "elements": [
                "gregtech:transparent_casing@1"
            ]
        },
        {
            "x": -10,
            "y": 6,
            "z": 0,
            "elements": [
                "contenttweaker:machine_coil_neutonium@0"
            ]
        },
        {
            "x": -2,
            "y": 8,
            "z": 1,
            "elements": [
                "contenttweaker:chaosproofmachinecasing@0"
            ]
        },
        {
            "x": -1,
            "y": 6,
            "z": 0,
            "elements": [
                "gregtech:transparent_casing@1"
            ]
        },
        {
            "x": 0,
            "y": 6,
            "z": 0,
            "elements": [
                "gregtech:transparent_casing@1"
            ]
        },
        {
            "x": 2,
            "y": 8,
            "z": 1,
            "elements": [
                "contenttweaker:chaosproofmachinecasing@0"
            ]
        },
        {
            "x": 1,
            "y": 6,
            "z": 0,
            "elements": [
                "gregtech:transparent_casing@1"
            ]
        },
        {
            "x": -7,
            "y": 4,
            "z": 15,
            "elements": [
                "gregtech:fusion_casing@1"
            ]
        },
        {
            "x": 10,
            "y": 6,
            "z": 0,
            "elements": [
                "contenttweaker:machine_coil_neutonium@0"
            ]
        },
        {
            "x": -5,
            "y": 2,
            "z": 14,
            "elements": [
                "contenttweaker:machine_coil_neutonium@0"
            ]
        },
        {
            "x": -4,
            "y": 2,
            "z": 14,
            "elements": [
                "contenttweaker:machine_coil_neutonium@0"
            ]
        },
        {
            "x": 4,
            "y": 2,
            "z": 14,
            "elements": [
                "contenttweaker:machine_coil_neutonium@0"
            ]
        },
        {
            "x": 5,
            "y": 2,
            "z": 14,
            "elements": [
                "contenttweaker:machine_coil_neutonium@0"
            ]
        },
        {
            "x": 7,
            "y": 4,
            "z": 15,
            "elements": [
                "gregtech:fusion_casing@1"
            ]
        },
        {
            "x": -1,
            "y": 9,
            "z": 1,
            "elements": [
                "contenttweaker:chaosproofmachinecasing@0"
            ]
        },
        {
            "x": 0,
            "y": 9,
            "z": 1,
            "elements": [
                "contenttweaker:chaosproofmachinecasing@0"
            ]
        },
        {
            "x": -1,
            "y": 7,
            "z": 0,
            "elements": [
                "gregtech:transparent_casing@1"
            ]
        },
        {
            "x": 1,
            "y": 9,
            "z": 1,
            "elements": [
                "contenttweaker:chaosproofmachinecasing@0"
            ]
        },
        {
            "x": 0,
            "y": 7,
            "z": 0,
            "elements": [
                "gregtech:transparent_casing@1"
            ]
        },
        {
            "x": 1,
            "y": 7,
            "z": 0,
            "elements": [
                "gregtech:transparent_casing@1"
            ]
        },
        {
            "x": -1,
            "y": 8,
            "z": 0,
            "elements": [
                "modularmachinery:blockenergyinputhatch@7"
            ]
        },
        {
            "x": 0,
            "y": 8,
            "z": 0,
            "elements": [
                "modularmachinery:blockenergyinputhatch@7"
            ]
        },
        {
            "x": 1,
            "y": 8,
            "z": 0,
            "elements": [
                "modularmachinery:blockenergyinputhatch@7"
            ]
        },
        {
            "x": -8,
            "y": 4,
            "z": 14,
            "elements": [
                "gregtech:fusion_casing@1"
            ]
        },
        {
            "x": -6,
            "y": 2,
            "z": 13,
            "elements": [
                "contenttweaker:machine_coil_neutonium@0"
            ]
        },
        {
            "x": -3,
            "y": 6,
            "z": 15,
            "elements": [
                "contenttweaker:machine_coil_neutonium@0"
            ]
        },
        {
            "x": -2,
            "y": 6,
            "z": 15,
            "elements": [
                "contenttweaker:machine_coil_neutonium@0"
            ]
        },
        {
            "x": -1,
            "y": 6,
            "z": 15,
            "elements": [
                "contenttweaker:machine_coil_neutonium@0"
            ]
        },
        {
            "x": 0,
            "y": 6,
            "z": 15,
            "elements": [
                "contenttweaker:machine_coil_neutonium@0"
            ]
        },
        {
            "x": 1,
            "y": 6,
            "z": 15,
            "elements": [
                "contenttweaker:machine_coil_neutonium@0"
            ]
        },
        {
            "x": 2,
            "y": 6,
            "z": 15,
            "elements": [
                "contenttweaker:machine_coil_neutonium@0"
            ]
        },
        {
            "x": 3,
            "y": 6,
            "z": 15,
            "elements": [
                "contenttweaker:machine_coil_neutonium@0"
            ]
        },
        {
            "x": 6,
            "y": 2,
            "z": 13,
            "elements": [
                "contenttweaker:machine_coil_neutonium@0"
            ]
        },
        {
            "x": 8,
            "y": 4,
            "z": 14,
            "elements": [
                "gregtech:fusion_casing@1"
            ]
        },
        {
            "x": -9,
            "y": 4,
            "z": 13,
            "elements": [
                "gregtech:fusion_casing@1"
            ]
        },
        {
            "x": -8,
            "y": 2,
            "z": 12,
            "elements": [
                "contenttweaker:machine_coil_neutonium@0"
            ]
        },
        {
            "x": -7,
            "y": 2,
            "z": 12,
            "elements": [
                "contenttweaker:machine_coil_neutonium@0"
            ]
        },
        {
            "x": -5,
            "y": 6,
            "z": 14,
            "elements": [
                "contenttweaker:machine_coil_neutonium@0"
            ]
        },
        {
            "x": -4,
            "y": 6,
            "z": 14,
            "elements": [
                "contenttweaker:machine_coil_neutonium@0"
            ]
        },
        {
            "x": -2,
            "y": 4,
            "z": 13,
            "elements": [
                "gregtech:fusion_casing@1"
            ]
        },
        {
            "x": -1,
            "y": 4,
            "z": 13,
            "elements": [
                "gregtech:fusion_casing@1"
            ]
        },
        {
            "x": 0,
            "y": 4,
            "z": 13,
            "elements": [
                "gregtech:fusion_casing@1"
            ]
        },
        {
            "x": 3,
            "y": 4,
            "z": -9,
            "elements": [
                "gregtech:fusion_casing@1"
            ]
        },
        {
            "x": 2,
            "y": 4,
            "z": -9,
            "elements": [
                "gregtech:fusion_casing@1"
            ]
        },
        {
            "x": 1,
            "y": 4,
            "z": 13,
            "elements": [
                "gregtech:fusion_casing@1"
            ]
        },
        {
            "x": 1,
            "y": 4,
            "z": -9,
            "elements": [
                "gregtech:fusion_casing@1"
            ]
        },
        {
            "x": 2,
            "y": 4,
            "z": 13,
            "elements": [
                "gregtech:fusion_casing@1"
            ]
        },
        {
            "x": 0,
            "y": 4,
            "z": -9,
            "elements": [
                "gregtech:fusion_casing@1"
            ]
        },
        {
            "x": 4,
            "y": 6,
            "z": 14,
            "elements": [
                "contenttweaker:machine_coil_neutonium@0"
            ]
        },
        {
            "x": -1,
            "y": 4,
            "z": -9,
            "elements": [
                "gregtech:fusion_casing@1"
            ]
        },
        {
            "x": 5,
            "y": 6,
            "z": 14,
            "elements": [
                "contenttweaker:machine_coil_neutonium@0"
            ]
        },
        {
            "x": -2,
            "y": 4,
            "z": -9,
            "elements": [
                "gregtech:fusion_casing@1"
            ]
        },
        {
            "x": -3,
            "y": 4,
            "z": -9,
            "elements": [
                "gregtech:fusion_casing@1"
            ]
        },
        {
            "x": 7,
            "y": 2,
            "z": 12,
            "elements": [
                "contenttweaker:machine_coil_neutonium@0"
            ]
        },
        {
            "x": 9,
            "y": 4,
            "z": 13,
            "elements": [
                "gregtech:fusion_casing@1"
            ]
        },
        {
            "x": 8,
            "y": 2,
            "z": 12,
            "elements": [
                "contenttweaker:machine_coil_neutonium@0"
            ]
        },
        {
            "x": -10,
            "y": 4,
            "z": 12,
            "elements": [
                "gregtech:fusion_casing@1"
            ]
        },
        {
            "x": -8,
            "y": 2,
            "z": 11,
            "elements": [
                "contenttweaker:machine_coil_neutonium@0"
            ]
        },
        {
            "x": -6,
            "y": 6,
            "z": 13,
            "elements": [
                "contenttweaker:machine_coil_neutonium@0"
            ]
        },
        {
            "x": -4,
            "y": 4,
            "z": 12,
            "elements": [
                "gregtech:fusion_casing@1"
            ]
        },
        {
            "x": -3,
            "y": 4,
            "z": 12,
            "elements": [
                "gregtech:fusion_casing@1"
            ]
        },
        {
            "x": 6,
            "y": 4,
            "z": -8,
            "elements": [
                "gregtech:fusion_casing@1"
            ]
        },
        {
            "x": 5,
            "y": 4,
            "z": -8,
            "elements": [
                "gregtech:fusion_casing@1"
            ]
        },
        {
            "x": 4,
            "y": 4,
            "z": -8,
            "elements": [
                "gregtech:fusion_casing@1"
            ]
        },
        {
            "x": 3,
            "y": 6,
            "z": -7,
            "elements": [
                "contenttweaker:machine_coil_neutonium@0"
            ]
        },
        {
            "x": 2,
            "y": 6,
            "z": -7,
            "elements": [
                "contenttweaker:machine_coil_neutonium@0"
            ]
        },
        {
            "x": 1,
            "y": 6,
            "z": -7,
            "elements": [
                "contenttweaker:machine_coil_neutonium@0"
            ]
        },
        {
            "x": 3,
            "y": 4,
            "z": 12,
            "elements": [
                "gregtech:fusion_casing@1"
            ]
        },
        {
            "x": 0,
            "y": 6,
            "z": -7,
            "elements": [
                "contenttweaker:machine_coil_neutonium@0"
            ]
        },
        {
            "x": 4,
            "y": 4,
            "z": 12,
            "elements": [
                "gregtech:fusion_casing@1"
            ]
        },
        {
            "x": -1,
            "y": 6,
            "z": -7,
            "elements": [
                "contenttweaker:machine_coil_neutonium@0"
            ]
        },
        {
            "x": 6,
            "y": 6,
            "z": 13,
            "elements": [
                "contenttweaker:machine_coil_neutonium@0"
            ]
        },
        {
            "x": -2,
            "y": 6,
            "z": -7,
            "elements": [
                "contenttweaker:machine_coil_neutonium@0"
            ]
        },
        {
            "x": -4,
            "y": 4,
            "z": -8,
            "elements": [
                "gregtech:fusion_casing@1"
            ]
        },
        {
            "x": -3,
            "y": 6,
            "z": -7,
            "elements": [
                "contenttweaker:machine_coil_neutonium@0"
            ]
        },
        {
            "x": -5,
            "y": 4,
            "z": -8,
            "elements": [
                "gregtech:fusion_casing@1"
            ]
        },
        {
            "x": -6,
            "y": 4,
            "z": -8,
            "elements": [
                "gregtech:fusion_casing@1"
            ]
        },
        {
            "x": 8,
            "y": 2,
            "z": 11,
            "elements": [
                "contenttweaker:machine_coil_neutonium@0"
            ]
        },
        {
            "x": 10,
            "y": 4,
            "z": 12,
            "elements": [
                "gregtech:fusion_casing@1"
            ]
        },
        {
            "x": -11,
            "y": 4,
            "z": 11,
            "elements": [
                "gregtech:fusion_casing@1"
            ]
        },
        {
            "x": -8,
            "y": 6,
            "z": 12,
            "elements": [
                "contenttweaker:machine_coil_neutonium@0"
            ]
        },
        {
            "x": -9,
            "y": 2,
            "z": 10,
            "elements": [
                "contenttweaker:machine_coil_neutonium@0"
            ]
        },
        {
            "x": -7,
            "y": 6,
            "z": 12,
            "elements": [
                "contenttweaker:machine_coil_neutonium@0"
            ]
        },
        {
            "x": -6,
            "y": 4,
            "z": 11,
            "elements": [
                "gregtech:fusion_casing@1"
            ]
        },
        {
            "x": -5,
            "y": 4,
            "z": 11,
            "elements": [
                "gregtech:fusion_casing@1"
            ]
        },
        {
            "x": 7,
            "y": 4,
            "z": -7,
            "elements": [
                "gregtech:fusion_casing@1"
            ]
        },
        {
            "x": 5,
            "y": 6,
            "z": -6,
            "elements": [
                "contenttweaker:machine_coil_neutonium@0"
            ]
        },
        {
            "x": 4,
            "y": 6,
            "z": -6,
            "elements": [
                "contenttweaker:machine_coil_neutonium@0"
            ]
        },
        {
            "x": 5,
            "y": 4,
            "z": 11,
            "elements": [
                "gregtech:fusion_casing@1"
            ]
        },
        {
            "x": 7,
            "y": 6,
            "z": 12,
            "elements": [
                "contenttweaker:machine_coil_neutonium@0"
            ]
        },
        {
            "x": 6,
            "y": 4,
            "z": 11,
            "elements": [
                "gregtech:fusion_casing@1"
            ]
        },
        {
            "x": 8,
            "y": 6,
            "z": 12,
            "elements": [
                "contenttweaker:machine_coil_neutonium@0"
            ]
        },
        {
            "x": -4,
            "y": 6,
            "z": -6,
            "elements": [
                "contenttweaker:machine_coil_neutonium@0"
            ]
        },
        {
            "x": -5,
            "y": 6,
            "z": -6,
            "elements": [
                "contenttweaker:machine_coil_neutonium@0"
            ]
        },
        {
            "x": -7,
            "y": 4,
            "z": -7,
            "elements": [
                "gregtech:fusion_casing@1"
            ]
        },
        {
            "x": 9,
            "y": 2,
            "z": 10,
            "elements": [
                "contenttweaker:machine_coil_neutonium@0"
            ]
        },
        {
            "x": 11,
            "y": 4,
            "z": 11,
            "elements": [
                "gregtech:fusion_casing@1"
            ]
        },
        {
            "x": -12,
            "y": 4,
            "z": 10,
            "elements": [
                "gregtech:fusion_casing@1"
            ]
        },
        {
            "x": -10,
            "y": 2,
            "z": 9,
            "elements": [
                "contenttweaker:machine_coil_neutonium@0"
            ]
        },
        {
            "x": -8,
            "y": 6,
            "z": 11,
            "elements": [
                "contenttweaker:machine_coil_neutonium@0"
            ]
        },
        {
            "x": -7,
            "y": 4,
            "z": 10,
            "elements": [
                "gregtech:fusion_casing@1"
            ]
        },
        {
            "x": 8,
            "y": 4,
            "z": -6,
            "elements": [
                "gregtech:fusion_casing@1"
            ]
        },
        {
            "x": 6,
            "y": 6,
            "z": -5,
            "elements": [
                "contenttweaker:machine_coil_neutonium@0"
            ]
        },
        {
            "x": 3,
            "y": 2,
            "z": -7,
            "elements": [
                "contenttweaker:machine_coil_neutonium@0"
            ]
        },
        {
            "x": 2,
            "y": 2,
            "z": -7,
            "elements": [
                "contenttweaker:machine_coil_neutonium@0"
            ]
        },
        {
            "x": 1,
            "y": 2,
            "z": -7,
            "elements": [
                "contenttweaker:machine_coil_neutonium@0"
            ]
        },
        {
            "x": -1,
            "y": 0,
            "z": 8,
            "elements": [
                "modularmachinery:blockoutputbus@6"
            ]
        },
        {
            "x": 0,
            "y": 0,
            "z": 8,
            "elements": [
                "contenttweaker:chaosproofmachinecasing@0"
            ]
        },
        {
            "x": 0,
            "y": 2,
            "z": -7,
            "elements": [
                "contenttweaker:machine_coil_neutonium@0"
            ]
        },
        {
            "x": -1,
            "y": 2,
            "z": -7,
            "elements": [
                "contenttweaker:machine_coil_neutonium@0"
            ]
        },
        {
            "x": 1,
            "y": 0,
            "z": 8,
            "elements": [
                "modularmachinery:blockoutputbus@6"
            ]
        },
        {
            "x": -2,
            "y": 2,
            "z": -7,
            "elements": [
                "contenttweaker:machine_coil_neutonium@0"
            ]
        },
        {
            "x": -3,
            "y": 2,
            "z": -7,
            "elements": [
                "contenttweaker:machine_coil_neutonium@0"
            ]
        },
        {
            "x": 8,
            "y": 6,
            "z": 11,
            "elements": [
                "contenttweaker:machine_coil_neutonium@0"
            ]
        },
        {
            "x": 7,
            "y": 4,
            "z": 10,
            "elements": [
                "gregtech:fusion_casing@1"
            ]
        },
        {
            "x": -6,
            "y": 6,
            "z": -5,
            "elements": [
                "contenttweaker:machine_coil_neutonium@0"
            ]
        },
        {
            "x": -8,
            "y": 4,
            "z": -6,
            "elements": [
                "gregtech:fusion_casing@1"
            ]
        },
        {
            "x": 10,
            "y": 2,
            "z": 9,
            "elements": [
                "contenttweaker:machine_coil_neutonium@0"
            ]
        },
        {
            "x": 12,
            "y": 4,
            "z": 10,
            "elements": [
                "gregtech:fusion_casing@1"
            ]
        },
        {
            "x": -1,
            "y": 1,
            "z": 8,
            "elements": [
                "gregtech:transparent_casing@1"
            ]
        },
        {
            "x": 0,
            "y": 1,
            "z": 8,
            "elements": [
                "gregtech:transparent_casing@1"
            ]
        },
        {
            "x": -1,
            "y": -1,
            "z": 7,
            "elements": [
                "contenttweaker:chaosproofmachinecasing@0"
            ]
        },
        {
            "x": 0,
            "y": -1,
            "z": 7,
            "elements": [
                "contenttweaker:chaosproofmachinecasing@0"
            ]
        },
        {
            "x": 1,
            "y": 1,
            "z": 8,
            "elements": [
                "gregtech:transparent_casing@1"
            ]
        },
        {
            "x": 1,
            "y": -1,
            "z": 7,
            "elements": [
                "contenttweaker:chaosproofmachinecasing@0"
            ]
        },
        {
            "x": -12,
            "y": 4,
            "z": 9,
            "elements": [
                "gregtech:fusion_casing@1"
            ]
        },
        {
            "x": -9,
            "y": 6,
            "z": 10,
            "elements": [
                "contenttweaker:machine_coil_neutonium@0"
            ]
        },
        {
            "x": -10,
            "y": 2,
            "z": 8,
            "elements": [
                "contenttweaker:machine_coil_neutonium@0"
            ]
        },
        {
            "x": -7,
            "y": 4,
            "z": 9,
            "elements": [
                "gregtech:fusion_casing@1"
            ]
        },
        {
            "x": 9,
            "y": 4,
            "z": -5,
            "elements": [
                "gregtech:fusion_casing@1"
            ]
        },
        {
            "x": 8,
            "y": 6,
            "z": -4,
            "elements": [
                "contenttweaker:machine_coil_neutonium@0"
            ]
        },
        {
            "x": 7,
            "y": 6,
            "z": -4,
            "elements": [
                "contenttweaker:machine_coil_neutonium@0"
            ]
        },
        {
            "x": 5,
            "y": 2,
            "z": -6,
            "elements": [
                "contenttweaker:machine_coil_neutonium@0"
            ]
        },
        {
            "x": 4,
            "y": 2,
            "z": -6,
            "elements": [
                "contenttweaker:machine_coil_neutonium@0"
            ]
        },
        {
            "x": -2,
            "y": 0,
            "z": 7,
            "elements": [
                "contenttweaker:chaosproofmachinecasing@0"
            ]
        },
        {
            "x": -1,
            "y": 2,
            "z": 8,
            "elements": [
                "gregtech:transparent_casing@1"
            ]
        },
        {
            "x": 2,
            "y": 4,
            "z": -5,
            "elements": [
                "gregtech:fusion_casing@1"
            ]
        },
        {
            "x": 0,
            "y": 2,
            "z": 8,
            "elements": [
                "gregtech:transparent_casing@1"
            ]
        },
        {
            "x": 1,
            "y": 4,
            "z": -5,
            "elements": [
                "gregtech:fusion_casing@1"
            ]
        },
        {
            "x": 1,
            "y": 2,
            "z": 8,
            "elements": [
                "gregtech:transparent_casing@1"
            ]
        },
        {
            "x": 0,
            "y": 4,
            "z": -5,
            "elements": [
                "gregtech:fusion_casing@1"
            ]
        },
        {
            "x": -1,
            "y": 4,
            "z": -5,
            "elements": [
                "gregtech:fusion_casing@1"
            ]
        },
        {
            "x": 2,
            "y": 0,
            "z": 7,
            "elements": [
                "contenttweaker:chaosproofmachinecasing@0"
            ]
        },
        {
            "x": -2,
            "y": 4,
            "z": -5,
            "elements": [
                "gregtech:fusion_casing@1"
            ]
        },
        {
            "x": -4,
            "y": 2,
            "z": -6,
            "elements": [
                "contenttweaker:machine_coil_neutonium@0"
            ]
        },
        {
            "x": -5,
            "y": 2,
            "z": -6,
            "elements": [
                "contenttweaker:machine_coil_neutonium@0"
            ]
        },
        {
            "x": 7,
            "y": 4,
            "z": 9,
            "elements": [
                "gregtech:fusion_casing@1"
            ]
        },
        {
            "x": 9,
            "y": 6,
            "z": 10,
            "elements": [
                "contenttweaker:machine_coil_neutonium@0"
            ]
        },
        {
            "x": -7,
            "y": 6,
            "z": -4,
            "elements": [
                "contenttweaker:machine_coil_neutonium@0"
            ]
        },
        {
            "x": 10,
            "y": 2,
            "z": 8,
            "elements": [
                "contenttweaker:machine_coil_neutonium@0"
            ]
        },
        {
            "x": -9,
            "y": 4,
            "z": -5,
            "elements": [
                "gregtech:fusion_casing@1"
            ]
        },
        {
            "x": -8,
            "y": 6,
            "z": -4,
            "elements": [
                "contenttweaker:machine_coil_neutonium@0"
            ]
        },
        {
            "x": 12,
            "y": 4,
            "z": 9,
            "elements": [
                "gregtech:fusion_casing@1"
            ]
        },
        {
            "x": -2,
            "y": 1,
            "z": 7,
            "elements": [
                "gregtech:transparent_casing@1"
            ]
        },
        {
            "x": -1,
            "y": 3,
            "z": 8,
            "elements": [
                "gregtech:transparent_casing@1"
            ]
        },
        {
            "x": 0,
            "y": 3,
            "z": 8,
            "elements": [
                "gregtech:transparent_casing@1"
            ]
        },
        {
            "x": -2,
            "y": -1,
            "z": 6,
            "elements": [
                "contenttweaker:chaosproofmachinecasing@0"
            ]
        },
        {
            "x": 1,
            "y": 3,
            "z": 8,
            "elements": [
                "gregtech:transparent_casing@1"
            ]
        },
        {
            "x": -1,
            "y": -1,
            "z": 6,
            "elements": [
                "contenttweaker:chaosproofmachinecasing@0"
            ]
        },
        {
            "x": 0,
            "y": -1,
            "z": 6,
            "elements": [
                "contenttweaker:chaosproofmachinecasing@0"
            ]
        },
        {
            "x": 2,
            "y": 1,
            "z": 7,
            "elements": [
                "gregtech:transparent_casing@1"
            ]
        },
        {
            "x": 1,
            "y": -1,
            "z": 6,
            "elements": [
                "contenttweaker:chaosproofmachinecasing@0"
            ]
        },
        {
            "x": 2,
            "y": -1,
            "z": 6,
            "elements": [
                "contenttweaker:chaosproofmachinecasing@0"
            ]
        },
        {
            "x": -12,
            "y": 4,
            "z": 8,
            "elements": [
                "gregtech:fusion_casing@1"
            ]
        },
        {
            "x": -10,
            "y": 6,
            "z": 9,
            "elements": [
                "contenttweaker:machine_coil_neutonium@0"
            ]
        },
        {
            "x": -11,
            "y": 2,
            "z": 7,
            "elements": [
                "contenttweaker:machine_coil_neutonium@0"
            ]
        },
        {
            "x": -8,
            "y": 4,
            "z": 8,
            "elements": [
                "gregtech:fusion_casing@1"
            ]
        },
        {
            "x": 10,
            "y": 4,
            "z": -4,
            "elements": [
                "gregtech:fusion_casing@1"
            ]
        },
        {
            "x": 8,
            "y": 6,
            "z": -3,
            "elements": [
                "contenttweaker:machine_coil_neutonium@0"
            ]
        },
        {
            "x": 6,
            "y": 2,
            "z": -5,
            "elements": [
                "contenttweaker:machine_coil_neutonium@0"
            ]
        },
        {
            "x": -3,
            "y": 0,
            "z": 6,
            "elements": [
                "contenttweaker:chaosproofmachinecasing@0"
            ]
        },
        {
            "x": -2,
            "y": 2,
            "z": 7,
            "elements": [
                "gregtech:transparent_casing@1"
            ]
        },
        {
            "x": -1,
            "y": 4,
            "z": 8,
            "elements": [
                "gregtech:transparent_casing@1"
            ]
        },
        {
            "x": 4,
            "y": 4,
            "z": -4,
            "elements": [
                "gregtech:fusion_casing@1"
            ]
        },
        {
            "x": 0,
            "y": 4,
            "z": 8,
            "elements": [
                "gregtech:transparent_casing@1"
            ]
        },
        {
            "x": 3,
            "y": 4,
            "z": -4,
            "elements": [
                "gregtech:fusion_casing@1"
            ]
        },
        {
            "x": 1,
            "y": 4,
            "z": 8,
            "elements": [
                "gregtech:transparent_casing@1"
            ]
        },
        {
            "x": 2,
            "y": 2,
            "z": 7,
            "elements": [
                "gregtech:transparent_casing@1"
            ]
        },
        {
            "x": 3,
            "y": 0,
            "z": 6,
            "elements": [
                "contenttweaker:chaosproofmachinecasing@0"
            ]
        },
        {
            "x": -3,
            "y": 4,
            "z": -4,
            "elements": [
                "gregtech:fusion_casing@1"
            ]
        },
        {
            "x": -4,
            "y": 4,
            "z": -4,
            "elements": [
                "gregtech:fusion_casing@1"
            ]
        },
        {
            "x": -6,
            "y": 2,
            "z": -5,
            "elements": [
                "contenttweaker:machine_coil_neutonium@0"
            ]
        },
        {
            "x": 8,
            "y": 4,
            "z": 8,
            "elements": [
                "gregtech:fusion_casing@1"
            ]
        },
        {
            "x": 10,
            "y": 6,
            "z": 9,
            "elements": [
                "contenttweaker:machine_coil_neutonium@0"
            ]
        },
        {
            "x": -8,
            "y": 6,
            "z": -3,
            "elements": [
                "contenttweaker:machine_coil_neutonium@0"
            ]
        },
        {
            "x": 12,
            "y": 4,
            "z": 8,
            "elements": [
                "gregtech:fusion_casing@1"
            ]
        },
        {
            "x": 11,
            "y": 2,
            "z": 7,
            "elements": [
                "contenttweaker:machine_coil_neutonium@0"
            ]
        },
        {
            "x": -10,
            "y": 4,
            "z": -4,
            "elements": [
                "gregtech:fusion_casing@1"
            ]
        },
        {
            "x": -3,
            "y": 1,
            "z": 6,
            "elements": [
                "gregtech:transparent_casing@1"
            ]
        },
        {
            "x": -2,
            "y": 3,
            "z": 7,
            "elements": [
                "gregtech:transparent_casing@1"
            ]
        },
        {
            "x": -1,
            "y": 5,
            "z": 8,
            "elements": [
                "gregtech:transparent_casing@1"
            ]
        },
        {
            "x": 0,
            "y": 5,
            "z": 8,
            "elements": [
                "gregtech:transparent_casing@1"
            ]
        },
        {
            "x": -3,
            "y": -1,
            "z": 5,
            "elements": [
                "contenttweaker:chaosproofmachinecasing@0"
            ]
        },
        {
            "x": 1,
            "y": 5,
            "z": 8,
            "elements": [
                "gregtech:transparent_casing@1"
            ]
        },
        {
            "x": -2,
            "y": -1,
            "z": 5,
            "elements": [
                "contenttweaker:chaosproofmachinecasing@0"
            ]
        },
        {
            "x": 0,
            "y": 1,
            "z": 6,
            "elements": [
                "gregtech:meta_block_compressed_7@15"
            ]
        },
        {
            "x": -1,
            "y": -1,
            "z": 5,
            "elements": [
                "contenttweaker:chaosproofmachinecasing@0"
            ]
        },
        {
            "x": 0,
            "y": -1,
            "z": 5,
            "elements": [
                "contenttweaker:chaosproofmachinecasing@0"
            ]
        },
        {
            "x": 2,
            "y": 3,
            "z": 7,
            "elements": [
                "gregtech:transparent_casing@1"
            ]
        },
        {
            "x": 1,
            "y": -1,
            "z": 5,
            "elements": [
                "contenttweaker:chaosproofmachinecasing@0"
            ]
        },
        {
            "x": 3,
            "y": 1,
            "z": 6,
            "elements": [
                "gregtech:transparent_casing@1"
            ]
        },
        {
            "x": 2,
            "y": -1,
            "z": 5,
            "elements": [
                "contenttweaker:chaosproofmachinecasing@0"
            ]
        },
        {
            "x": 3,
            "y": -1,
            "z": 5,
            "elements": [
                "contenttweaker:chaosproofmachinecasing@0"
            ]
        },
        {
            "x": -13,
            "y": 4,
            "z": 7,
            "elements": [
                "gregtech:fusion_casing@1"
            ]
        },
        {
            "x": -10,
            "y": 6,
            "z": 8,
            "elements": [
                "contenttweaker:machine_coil_neutonium@0"
            ]
        },
        {
            "x": -11,
            "y": 2,
            "z": 6,
            "elements": [
                "contenttweaker:machine_coil_neutonium@0"
            ]
        },
        {
            "x": -8,
            "y": 4,
            "z": 7,
            "elements": [
                "gregtech:fusion_casing@1"
            ]
        },
        {
            "x": 11,
            "y": 4,
            "z": -3,
            "elements": [
                "gregtech:fusion_casing@1"
            ]
        },
        {
            "x": 8,
            "y": 2,
            "z": -4,
            "elements": [
                "contenttweaker:machine_coil_neutonium@0"
            ]
        },
        {
            "x": 9,
            "y": 6,
            "z": -2,
            "elements": [
                "contenttweaker:machine_coil_neutonium@0"
            ]
        },
        {
            "x": 7,
            "y": 2,
            "z": -4,
            "elements": [
                "contenttweaker:machine_coil_neutonium@0"
            ]
        },
        {
            "x": 6,
            "y": 4,
            "z": -3,
            "elements": [
                "gregtech:fusion_casing@1"
            ]
        },
        {
            "x": -4,
            "y": 0,
            "z": 5,
            "elements": [
                "modularmachinery:blockfluidoutputhatch@7"
            ]
        },
        {
            "x": -3,
            "y": 2,
            "z": 6,
            "elements": [
                "gregtech:transparent_casing@1"
            ]
        },
        {
            "x": -2,
            "y": 4,
            "z": 7,
            "elements": [
                "gregtech:transparent_casing@1"
            ]
        },
        {
            "x": -1,
            "y": 6,
            "z": 8,
            "elements": [
                "gregtech:transparent_casing@1"
            ]
        },
        {
            "x": 5,
            "y": 4,
            "z": -3,
            "elements": [
                "gregtech:fusion_casing@1"
            ]
        },
        {
            "x": 0,
            "y": 6,
            "z": 8,
            "elements": [
                "gregtech:transparent_casing@1"
            ]
        },
        {
            "x": 1,
            "y": 6,
            "z": 8,
            "elements": [
                "gregtech:transparent_casing@1"
            ]
        },
        {
            "x": -1,
            "y": 0,
            "z": 5,
            "elements": [
                "gregtech:meta_block_compressed_7@15"
            ]
        },
        {
            "x": 2,
            "y": 4,
            "z": 7,
            "elements": [
                "gregtech:transparent_casing@1"
            ]
        },
        {
            "x": 3,
            "y": 2,
            "z": 6,
            "elements": [
                "gregtech:transparent_casing@1"
            ]
        },
        {
            "x": 4,
            "y": 0,
            "z": 5,
            "elements": [
                "modularmachinery:blockfluidoutputhatch@7"
            ]
        },
        {
            "x": -5,
            "y": 4,
            "z": -3,
            "elements": [
                "gregtech:fusion_casing@1"
            ]
        },
        {
            "x": 8,
            "y": 4,
            "z": 7,
            "elements": [
                "gregtech:fusion_casing@1"
            ]
        },
        {
            "x": -7,
            "y": 2,
            "z": -4,
            "elements": [
                "contenttweaker:machine_coil_neutonium@0"
            ]
        },
        {
            "x": -6,
            "y": 4,
            "z": -3,
            "elements": [
                "gregtech:fusion_casing@1"
            ]
        },
        {
            "x": 10,
            "y": 6,
            "z": 8,
            "elements": [
                "contenttweaker:machine_coil_neutonium@0"
            ]
        },
        {
            "x": -8,
            "y": 2,
            "z": -4,
            "elements": [
                "contenttweaker:machine_coil_neutonium@0"
            ]
        },
        {
            "x": 11,
            "y": 2,
            "z": 6,
            "elements": [
                "contenttweaker:machine_coil_neutonium@0"
            ]
        },
        {
            "x": -9,
            "y": 6,
            "z": -2,
            "elements": [
                "contenttweaker:machine_coil_neutonium@0"
            ]
        },
        {
            "x": 13,
            "y": 4,
            "z": 7,
            "elements": [
                "gregtech:fusion_casing@1"
            ]
        },
        {
            "x": -11,
            "y": 4,
            "z": -3,
            "elements": [
                "gregtech:fusion_casing@1"
            ]
        },
        {
            "x": -4,
            "y": 1,
            "z": 5,
            "elements": [
                "gregtech:transparent_casing@1"
            ]
        },
        {
            "x": -3,
            "y": 3,
            "z": 6,
            "elements": [
                "gregtech:transparent_casing@1"
            ]
        },
        {
            "x": -2,
            "y": 5,
            "z": 7,
            "elements": [
                "gregtech:transparent_casing@1"
            ]
        },
        {
            "x": -1,
            "y": 7,
            "z": 8,
            "elements": [
                "gregtech:transparent_casing@1"
            ]
        },
        {
            "x": 0,
            "y": 7,
            "z": 8,
            "elements": [
                "gregtech:transparent_casing@1"
            ]
        },
        {
            "x": 1,
            "y": 7,
            "z": 8,
            "elements": [
                "gregtech:transparent_casing@1"
            ]
        },
        {
            "x": -3,
            "y": -1,
            "z": 4,
            "elements": [
                "contenttweaker:chaosproofmachinecasing@0"
            ]
        },
        {
            "x": -2,
            "y": -1,
            "z": 4,
            "elements": [
                "contenttweaker:chaosproofmachinecasing@0"
            ]
        },
        {
            "x": 2,
            "y": 5,
            "z": 7,
            "elements": [
                "gregtech:transparent_casing@1"
            ]
        },
        {
            "x": -1,
            "y": -1,
            "z": 4,
            "elements": [
                "contenttweaker:chaosproofmachinecasing@0"
            ]
        },
        {
            "x": 0,
            "y": -1,
            "z": 4,
            "elements": [
                "contenttweaker:chaosproofmachinecasing@0"
            ]
        },
        {
            "x": 3,
            "y": 3,
            "z": 6,
            "elements": [
                "gregtech:transparent_casing@1"
            ]
        },
        {
            "x": 1,
            "y": -1,
            "z": 4,
            "elements": [
                "contenttweaker:chaosproofmachinecasing@0"
            ]
        },
        {
            "x": 2,
            "y": -1,
            "z": 4,
            "elements": [
                "contenttweaker:chaosproofmachinecasing@0"
            ]
        },
        {
            "x": 4,
            "y": 1,
            "z": 5,
            "elements": [
                "gregtech:transparent_casing@1"
            ]
        },
        {
            "x": 3,
            "y": -1,
            "z": 4,
            "elements": [
                "contenttweaker:chaosproofmachinecasing@0"
            ]
        },
        {
            "x": -13,
            "y": 4,
            "z": 6,
            "elements": [
                "gregtech:fusion_casing@1"
            ]
        },
        {
            "x": -11,
            "y": 6,
            "z": 7,
            "elements": [
                "contenttweaker:machine_coil_neutonium@0"
            ]
        },
        {
            "x": -11,
            "y": 2,
            "z": 5,
            "elements": [
                "contenttweaker:machine_coil_neutonium@0"
            ]
        },
        {
            "x": -9,
            "y": 4,
            "z": 6,
            "elements": [
                "gregtech:fusion_casing@1"
            ]
        },
        {
            "x": 12,
            "y": 4,
            "z": -2,
            "elements": [
                "gregtech:fusion_casing@1"
            ]
        },
        {
            "x": 10,
            "y": 6,
            "z": -1,
            "elements": [
                "contenttweaker:machine_coil_neutonium@0"
            ]
        },
        {
            "x": 8,
            "y": 2,
            "z": -3,
            "elements": [
                "contenttweaker:machine_coil_neutonium@0"
            ]
        },
        {
            "x": 7,
            "y": 4,
            "z": -2,
            "elements": [
                "gregtech:fusion_casing@1"
            ]
        },
        {
            "x": -4,
            "y": 2,
            "z": 5,
            "elements": [
                "gregtech:transparent_casing@1"
            ]
        },
        {
            "x": -3,
            "y": 4,
            "z": 6,
            "elements": [
                "gregtech:transparent_casing@1"
            ]
        },
        {
            "x": -2,
            "y": 6,
            "z": 7,
            "elements": [
                "gregtech:transparent_casing@1"
            ]
        },
        {
            "x": -1,
            "y": 8,
            "z": 8,
            "elements": [
                "modularmachinery:blockenergyinputhatch@7"
            ]
        },
        {
            "x": 0,
            "y": 8,
            "z": 8,
            "elements": [
                "modularmachinery:blockenergyinputhatch@7"
            ]
        },
        {
            "x": -4,
            "y": 0,
            "z": 4,
            "elements": [
                "contenttweaker:chaosproofmachinecasing@0"
            ]
        },
        {
            "x": 1,
            "y": 8,
            "z": 8,
            "elements": [
                "modularmachinery:blockenergyinputhatch@7"
            ]
        },
        {
            "x": 2,
            "y": 6,
            "z": 7,
            "elements": [
                "gregtech:transparent_casing@1"
            ]
        },
        {
            "x": 1,
            "y": 2,
            "z": 5,
            "elements": [
                "gregtech:meta_block_compressed_7@15"
            ]
        },
        {
            "x": 3,
            "y": 4,
            "z": 6,
            "elements": [
                "gregtech:transparent_casing@1"
            ]
        },
        {
            "x": 4,
            "y": 2,
            "z": 5,
            "elements": [
                "gregtech:transparent_casing@1"
            ]
        },
        {
            "x": 4,
            "y": 0,
            "z": 4,
            "elements": [
                "contenttweaker:chaosproofmachinecasing@0"
            ]
        },
        {
            "x": 9,
            "y": 4,
            "z": 6,
            "elements": [
                "gregtech:fusion_casing@1"
            ]
        },
        {
            "x": -8,
            "y": 2,
            "z": -3,
            "elements": [
                "contenttweaker:machine_coil_neutonium@0"
            ]
        },
        {
            "x": -7,
            "y": 4,
            "z": -2,
            "elements": [
                "gregtech:fusion_casing@1"
            ]
        },
        {
            "x": 11,
            "y": 6,
            "z": 7,
            "elements": [
                "contenttweaker:machine_coil_neutonium@0"
            ]
        },
        {
            "x": 11,
            "y": 2,
            "z": 5,
            "elements": [
                "contenttweaker:machine_coil_neutonium@0"
            ]
        },
        {
            "x": 13,
            "y": 4,
            "z": 6,
            "elements": [
                "gregtech:fusion_casing@1"
            ]
        },
        {
            "x": -10,
            "y": 6,
            "z": -1,
            "elements": [
                "contenttweaker:machine_coil_neutonium@0"
            ]
        },
        {
            "x": -12,
            "y": 4,
            "z": -2,
            "elements": [
                "gregtech:fusion_casing@1"
            ]
        },
        {
            "x": -4,
            "y": 3,
            "z": 5,
            "elements": [
                "gregtech:transparent_casing@1"
            ]
        },
        {
            "x": -3,
            "y": 5,
            "z": 6,
            "elements": [
                "gregtech:transparent_casing@1"
            ]
        },
        {
            "x": -2,
            "y": 7,
            "z": 7,
            "elements": [
                "gregtech:transparent_casing@1"
            ]
        },
        {
            "x": -4,
            "y": 1,
            "z": 4,
            "elements": [
                "gregtech:transparent_casing@1"
            ]
        },
        {
            "x": 0,
            "y": 5,
            "z": 6,
            "elements": [
                "gregtech:meta_block_compressed_7@15"
            ]
        },
        {
            "x": -3,
            "y": -1,
            "z": 3,
            "elements": [
                "contenttweaker:chaosproofmachinecasing@0"
            ]
        },
        {
            "x": 2,
            "y": 7,
            "z": 7,
            "elements": [
                "gregtech:transparent_casing@1"
            ]
        },
        {
            "x": -2,
            "y": -1,
            "z": 3,
            "elements": [
                "contenttweaker:chaosproofmachinecasing@0"
            ]
        },
        {
            "x": -1,
            "y": -1,
            "z": 3,
            "elements": [
                "contenttweaker:chaosproofmachinecasing@0"
            ]
        },
        {
            "x": 0,
            "y": -1,
            "z": 3,
            "elements": [
                "contenttweaker:chaosproofmachinecasing@0"
            ]
        },
        {
            "x": 3,
            "y": 5,
            "z": 6,
            "elements": [
                "gregtech:transparent_casing@1"
            ]
        },
        {
            "x": 1,
            "y": -1,
            "z": 3,
            "elements": [
                "contenttweaker:chaosproofmachinecasing@0"
            ]
        },
        {
            "x": 4,
            "y": 3,
            "z": 5,
            "elements": [
                "gregtech:transparent_casing@1"
            ]
        },
        {
            "x": 2,
            "y": -1,
            "z": 3,
            "elements": [
                "contenttweaker:chaosproofmachinecasing@0"
            ]
        },
        {
            "x": 4,
            "y": 1,
            "z": 4,
            "elements": [
                "gregtech:transparent_casing@1"
            ]
        },
        {
            "x": 3,
            "y": -1,
            "z": 3,
            "elements": [
                "contenttweaker:chaosproofmachinecasing@0"
            ]
        },
        {
            "x": -13,
            "y": 4,
            "z": 5,
            "elements": [
                "gregtech:fusion_casing@1"
            ]
        },
        {
            "x": -11,
            "y": 6,
            "z": 6,
            "elements": [
                "contenttweaker:machine_coil_neutonium@0"
            ]
        },
        {
            "x": -11,
            "y": 2,
            "z": 4,
            "elements": [
                "contenttweaker:machine_coil_neutonium@0"
            ]
        },
        {
            "x": -9,
            "y": 4,
            "z": 5,
            "elements": [
                "gregtech:fusion_casing@1"
            ]
        },
        {
            "x": 12,
            "y": 4,
            "z": -1,
            "elements": [
                "gregtech:fusion_casing@1"
            ]
        },
        {
            "x": 9,
            "y": 2,
            "z": -2,
            "elements": [
                "contenttweaker:machine_coil_neutonium@0"
            ]
        },
        {
            "x": -4,
            "y": 4,
            "z": 5,
            "elements": [
                "gregtech:transparent_casing@1"
            ]
        },
        {
            "x": -3,
            "y": 6,
            "z": 6,
            "elements": [
                "gregtech:transparent_casing@1"
            ]
        },
        {
            "x": -2,
            "y": 8,
            "z": 7,
            "elements": [
                "contenttweaker:chaosproofmachinecasing@0"
            ]
        },
        {
            "x": 7,
            "y": 4,
            "z": -1,
            "elements": [
                "gregtech:fusion_casing@1"
            ]
        },
        {
            "x": -4,
            "y": 2,
            "z": 4,
            "elements": [
                "gregtech:transparent_casing@1"
            ]
        },
        {
            "x": -4,
            "y": 0,
            "z": 3,
            "elements": [
                "modularmachinery:blockfluidinputhatch@7"
            ]
        },
        {
            "x": -1,
            "y": 4,
            "z": 5,
            "elements": [
                "gregtech:meta_block_compressed_7@15"
            ]
        },
        {
            "x": 2,
            "y": 8,
            "z": 7,
            "elements": [
                "contenttweaker:chaosproofmachinecasing@0"
            ]
        },
        {
            "x": 1,
            "y": 6,
            "z": 6,
            "elements": [
                "gregtech:meta_block_compressed_7@15"
            ]
        },
        {
            "x": 3,
            "y": 6,
            "z": 6,
            "elements": [
                "gregtech:transparent_casing@1"
            ]
        },
        {
            "x": 1,
            "y": 0,
            "z": 3,
            "elements": [
                "gregtech:meta_block_compressed_7@15"
            ]
        },
        {
            "x": 4,
            "y": 4,
            "z": 5,
            "elements": [
                "gregtech:transparent_casing@1"
            ]
        },
        {
            "x": 4,
            "y": 2,
            "z": 4,
            "elements": [
                "gregtech:transparent_casing@1"
            ]
        },
        {
            "x": 4,
            "y": 0,
            "z": 3,
            "elements": [
                "modularmachinery:blockfluidinputhatch@7"
            ]
        },
        {
            "x": 9,
            "y": 4,
            "z": 5,
            "elements": [
                "gregtech:fusion_casing@1"
            ]
        },
        {
            "x": -7,
            "y": 4,
            "z": -1,
            "elements": [
                "gregtech:fusion_casing@1"
            ]
        },
        {
            "x": 11,
            "y": 6,
            "z": 6,
            "elements": [
                "contenttweaker:machine_coil_neutonium@0"
            ]
        },
        {
            "x": -9,
            "y": 2,
            "z": -2,
            "elements": [
                "contenttweaker:machine_coil_neutonium@0"
            ]
        },
        {
            "x": 11,
            "y": 2,
            "z": 4,
            "elements": [
                "contenttweaker:machine_coil_neutonium@0"
            ]
        },
        {
            "x": 13,
            "y": 4,
            "z": 5,
            "elements": [
                "gregtech:fusion_casing@1"
            ]
        },
        {
            "x": -12,
            "y": 4,
            "z": -1,
            "elements": [
                "gregtech:fusion_casing@1"
            ]
        },
        {
            "x": -4,
            "y": 5,
            "z": 5,
            "elements": [
                "gregtech:transparent_casing@1"
            ]
        },
        {
            "x": -3,
            "y": 7,
            "z": 6,
            "elements": [
                "gregtech:transparent_casing@1"
            ]
        },
        {
            "x": -4,
            "y": 3,
            "z": 4,
            "elements": [
                "gregtech:transparent_casing@1"
            ]
        },
        {
            "x": -1,
            "y": 9,
            "z": 7,
            "elements": [
                "contenttweaker:chaosproofmachinecasing@0"
            ]
        },
        {
            "x": 0,
            "y": 9,
            "z": 7,
            "elements": [
                "contenttweaker:chaosproofmachinecasing@0"
            ]
        },
        {
            "x": -4,
            "y": 1,
            "z": 3,
            "elements": [
                "gregtech:transparent_casing@1"
            ]
        },
        {
            "x": 1,
            "y": 9,
            "z": 7,
            "elements": [
                "contenttweaker:chaosproofmachinecasing@0"
            ]
        },
        {
            "x": -2,
            "y": 3,
            "z": 4,
            "elements": [
                "gregtech:meta_block_compressed_7@15"
            ]
        },
        {
            "x": -2,
            "y": -1,
            "z": 2,
            "elements": [
                "contenttweaker:chaosproofmachinecasing@0"
            ]
        },
        {
            "x": 3,
            "y": 7,
            "z": 6,
            "elements": [
                "gregtech:transparent_casing@1"
            ]
        },
        {
            "x": -1,
            "y": -1,
            "z": 2,
            "elements": [
                "contenttweaker:chaosproofmachinecasing@0"
            ]
        },
        {
            "x": 0,
            "y": -1,
            "z": 2,
            "elements": [
                "contenttweaker:chaosproofmachinecasing@0"
            ]
        },
        {
            "x": 2,
            "y": 3,
            "z": 4,
            "elements": [
                "gregtech:meta_block_compressed_7@15"
            ]
        },
        {
            "x": 4,
            "y": 5,
            "z": 5,
            "elements": [
                "gregtech:transparent_casing@1"
            ]
        },
        {
            "x": 1,
            "y": -1,
            "z": 2,
            "elements": [
                "contenttweaker:chaosproofmachinecasing@0"
            ]
        },
        {
            "x": 4,
            "y": 3,
            "z": 4,
            "elements": [
                "gregtech:transparent_casing@1"
            ]
        },
        {
            "x": 2,
            "y": -1,
            "z": 2,
            "elements": [
                "contenttweaker:chaosproofmachinecasing@0"
            ]
        },
        {
            "x": 4,
            "y": 1,
            "z": 3,
            "elements": [
                "gregtech:transparent_casing@1"
            ]
        },
        {
            "x": -13,
            "y": 4,
            "z": 4,
            "elements": [
                "gregtech:fusion_casing@1"
            ]
        },
        {
            "x": -11,
            "y": 6,
            "z": 5,
            "elements": [
                "contenttweaker:machine_coil_neutonium@0"
            ]
        },
        {
            "x": -11,
            "y": 2,
            "z": 3,
            "elements": [
                "contenttweaker:machine_coil_neutonium@0"
            ]
        },
        {
            "x": -9,
            "y": 4,
            "z": 4,
            "elements": [
                "gregtech:fusion_casing@1"
            ]
        },
        {
            "x": 10,
            "y": 2,
            "z": -1,
            "elements": [
                "contenttweaker:machine_coil_neutonium@0"
            ]
        },
        {
            "x": -4,
            "y": 6,
            "z": 5,
            "elements": [
                "gregtech:transparent_casing@1"
            ]
        },
        {
            "x": -3,
            "y": 8,
            "z": 6,
            "elements": [
                "contenttweaker:chaosproofmachinecasing@0"
            ]
        },
        {
            "x": -4,
            "y": 4,
            "z": 4,
            "elements": [
                "gregtech:transparent_casing@1"
            ]
        },
        {
            "x": -4,
            "y": 2,
            "z": 3,
            "elements": [
                "gregtech:transparent_casing@1"
            ]
        },
        {
            "x": -3,
            "y": 0,
            "z": 2,
            "elements": [
                "contenttweaker:chaosproofmachinecasing@0"
            ]
        },
        {
            "x": 0,
            "y": 4,
            "z": 4,
            "elements": [
                "gregtech:meta_block_compressed_2000@11"
            ]
        },
        {
            "x": -1,
            "y": 2,
            "z": 3,
            "elements": [
                "gregtech:meta_block_compressed_7@15"
            ]
        },
        {
            "x": 3,
            "y": 8,
            "z": 6,
            "elements": [
                "contenttweaker:chaosproofmachinecasing@0"
            ]
        },
        {
            "x": 4,
            "y": 6,
            "z": 5,
            "elements": [
                "gregtech:transparent_casing@1"
            ]
        },
        {
            "x": 4,
            "y": 4,
            "z": 4,
            "elements": [
                "gregtech:transparent_casing@1"
            ]
        },
        {
            "x": 4,
            "y": 2,
            "z": 3,
            "elements": [
                "gregtech:transparent_casing@1"
            ]
        },
        {
            "x": 3,
            "y": 0,
            "z": 2,
            "elements": [
                "contenttweaker:chaosproofmachinecasing@0"
            ]
        },
        {
            "x": 9,
            "y": 4,
            "z": 4,
            "elements": [
                "gregtech:fusion_casing@1"
            ]
        },
        {
            "x": 11,
            "y": 6,
            "z": 5,
            "elements": [
                "contenttweaker:machine_coil_neutonium@0"
            ]
        },
        {
            "x": -10,
            "y": 2,
            "z": -1,
            "elements": [
                "contenttweaker:machine_coil_neutonium@0"
            ]
        },
        {
            "x": 11,
            "y": 2,
            "z": 3,
            "elements": [
                "contenttweaker:machine_coil_neutonium@0"
            ]
        },
        {
            "x": 13,
            "y": 4,
            "z": 4,
            "elements": [
                "gregtech:fusion_casing@1"
            ]
        },
        {
            "x": -4,
            "y": 7,
            "z": 5,
            "elements": [
                "gregtech:transparent_casing@1"
            ]
        },
        {
            "x": -4,
            "y": 5,
            "z": 4,
            "elements": [
                "gregtech:transparent_casing@1"
            ]
        },
        {
            "x": -2,
            "y": 9,
            "z": 6,
            "elements": [
                "contenttweaker:chaosproofmachinecasing@0"
            ]
        },
        {
            "x": -4,
            "y": 3,
            "z": 3,
            "elements": [
                "gregtech:transparent_casing@1"
            ]
        },
        {
            "x": -1,
            "y": 9,
            "z": 6,
            "elements": [
                "contenttweaker:chaosproofmachinecasing@0"
            ]
        },
        {
            "x": 0,
            "y": 9,
            "z": 6,
            "elements": [
                "contenttweaker:chaosproofmachinecasing@0"
            ]
        },
        {
            "x": 1,
            "y": 9,
            "z": 6,
            "elements": [
                "contenttweaker:chaosproofmachinecasing@0"
            ]
        },
        {
            "x": -3,
            "y": 1,
            "z": 2,
            "elements": [
                "gregtech:transparent_casing@1"
            ]
        },
        {
            "x": 2,
            "y": 9,
            "z": 6,
            "elements": [
                "contenttweaker:chaosproofmachinecasing@0"
            ]
        },
        {
            "x": 2,
            "y": 7,
            "z": 5,
            "elements": [
                "gregtech:meta_block_compressed_7@15"
            ]
        },
        {
            "x": 0,
            "y": 1,
            "z": 2,
            "elements": [
                "gregtech:meta_block_compressed_7@15"
            ]
        },
        {
            "x": -1,
            "y": -1,
            "z": 1,
            "elements": [
                "contenttweaker:chaosproofmachinecasing@0"
            ]
        },
        {
            "x": 0,
            "y": -1,
            "z": 1,
            "elements": [
                "contenttweaker:chaosproofmachinecasing@0"
            ]
        },
        {
            "x": 4,
            "y": 7,
            "z": 5,
            "elements": [
                "gregtech:transparent_casing@1"
            ]
        },
        {
            "x": 4,
            "y": 5,
            "z": 4,
            "elements": [
                "gregtech:transparent_casing@1"
            ]
        },
        {
            "x": 1,
            "y": -1,
            "z": 1,
            "elements": [
                "contenttweaker:chaosproofmachinecasing@0"
            ]
        },
        {
            "x": 4,
            "y": 3,
            "z": 3,
            "elements": [
                "gregtech:transparent_casing@1"
            ]
        },
        {
            "x": 3,
            "y": 1,
            "z": 2,
            "elements": [
                "gregtech:transparent_casing@1"
            ]
        },
        {
            "x": -13,
            "y": 4,
            "z": 3,
            "elements": [
                "gregtech:fusion_casing@1"
            ]
        },
        {
            "x": -11,
            "y": 6,
            "z": 4,
            "elements": [
                "contenttweaker:machine_coil_neutonium@0"
            ]
        },
        {
            "x": -11,
            "y": 2,
            "z": 2,
            "elements": [
                "contenttweaker:machine_coil_neutonium@0"
            ]
        },
        {
            "x": -9,
            "y": 4,
            "z": 3,
            "elements": [
                "gregtech:fusion_casing@1"
            ]
        },
        {
            "x": -4,
            "y": 8,
            "z": 5,
            "elements": [
                "modularmachinery:blockenergyinputhatch@7"
            ]
        },
        {
            "x": -4,
            "y": 6,
            "z": 4,
            "elements": [
                "gregtech:transparent_casing@1"
            ]
        },
        {
            "x": -4,
            "y": 4,
            "z": 3,
            "elements": [
                "gregtech:transparent_casing@1"
            ]
        },
        {
            "x": -3,
            "y": 2,
            "z": 2,
            "elements": [
                "gregtech:transparent_casing@1"
            ]
        },
        {
            "x": 1,
            "y": 8,
            "z": 5,
            "elements": [
                "gregtech:meta_block_compressed_7@15"
            ]
        },
        {
            "x": -2,
            "y": 0,
            "z": 1,
            "elements": [
                "contenttweaker:chaosproofmachinecasing@0"
            ]
        },
        {
            "x": 1,
            "y": 4,
            "z": 3,
            "elements": [
                "gregtech:meta_block_compressed_7@15"
            ]
        },
        {
            "x": 4,
            "y": 8,
            "z": 5,
            "elements": [
                "modularmachinery:blockenergyinputhatch@7"
            ]
        },
        {
            "x": 4,
            "y": 6,
            "z": 4,
            "elements": [
                "gregtech:transparent_casing@1"
            ]
        },
        {
            "x": 4,
            "y": 4,
            "z": 3,
            "elements": [
                "gregtech:transparent_casing@1"
            ]
        },
        {
            "x": 3,
            "y": 2,
            "z": 2,
            "elements": [
                "gregtech:transparent_casing@1"
            ]
        },
        {
            "x": 2,
            "y": 0,
            "z": 1,
            "elements": [
                "contenttweaker:chaosproofmachinecasing@0"
            ]
        },
        {
            "x": 9,
            "y": 4,
            "z": 3,
            "elements": [
                "gregtech:fusion_casing@1"
            ]
        },
        {
            "x": 11,
            "y": 6,
            "z": 4,
            "elements": [
                "contenttweaker:machine_coil_neutonium@0"
            ]
        },
        {
            "x": 11,
            "y": 2,
            "z": 2,
            "elements": [
                "contenttweaker:machine_coil_neutonium@0"
            ]
        },
        {
            "x": 13,
            "y": 4,
            "z": 3,
            "elements": [
                "gregtech:fusion_casing@1"
            ]
        },
        {
            "x": -4,
            "y": 7,
            "z": 4,
            "elements": [
                "gregtech:transparent_casing@1"
            ]
        },
        {
            "x": -3,
            "y": 9,
            "z": 5,
            "elements": [
                "contenttweaker:chaosproofmachinecasing@0"
            ]
        },
        {
            "x": -4,
            "y": 5,
            "z": 3,
            "elements": [
                "gregtech:transparent_casing@1"
            ]
        },
        {
            "x": -2,
            "y": 9,
            "z": 5,
            "elements": [
                "contenttweaker:chaosproofmachinecasing@0"
            ]
        },
        {
            "x": -1,
            "y": 9,
            "z": 5,
            "elements": [
                "contenttweaker:chaosproofmachinecasing@0"
            ]
        },
        {
            "x": 0,
            "y": 9,
            "z": 5,
            "elements": [
                "contenttweaker:chaosproofmachinecasing@0"
            ]
        },
        {
            "x": -3,
            "y": 3,
            "z": 2,
            "elements": [
                "gregtech:transparent_casing@1"
            ]
        },
        {
            "x": 1,
            "y": 9,
            "z": 5,
            "elements": [
                "contenttweaker:chaosproofmachinecasing@0"
            ]
        },
        {
            "x": 2,
            "y": 9,
            "z": 5,
            "elements": [
                "contenttweaker:chaosproofmachinecasing@0"
            ]
        },
        {
            "x": -2,
            "y": 1,
            "z": 1,
            "elements": [
                "gregtech:transparent_casing@1"
            ]
        },
        {
            "x": 3,
            "y": 9,
            "z": 5,
            "elements": [
                "contenttweaker:chaosproofmachinecasing@0"
            ]
        },
        {
            "x": 4,
            "y": 7,
            "z": 4,
            "elements": [
                "gregtech:transparent_casing@1"
            ]
        },
        {
            "x": 4,
            "y": 5,
            "z": 3,
            "elements": [
                "gregtech:transparent_casing@1"
            ]
        },
        {
            "x": 3,
            "y": 3,
            "z": 2,
            "elements": [
                "gregtech:transparent_casing@1"
            ]
        },
        {
            "x": 2,
            "y": 1,
            "z": 1,
            "elements": [
                "gregtech:transparent_casing@1"
            ]
        },
        {
            "x": -13,
            "y": 4,
            "z": 2,
            "elements": [
                "gregtech:fusion_casing@1"
            ]
        },
        {
            "x": -11,
            "y": 6,
            "z": 3,
            "elements": [
                "contenttweaker:machine_coil_neutonium@0"
            ]
        },
        {
            "x": -11,
            "y": 2,
            "z": 1,
            "elements": [
                "contenttweaker:machine_coil_neutonium@0"
            ]
        },
        {
            "x": -9,
            "y": 4,
            "z": 2,
            "elements": [
                "gregtech:fusion_casing@1"
            ]
        },
        {
            "x": -4,
            "y": 8,
            "z": 4,
            "elements": [
                "modularmachinery:blockenergyinputhatch@7"
            ]
        },
        {
            "x": -4,
            "y": 6,
            "z": 3,
            "elements": [
                "gregtech:transparent_casing@1"
            ]
        },
        {
            "x": -3,
            "y": 4,
            "z": 2,
            "elements": [
                "gregtech:transparent_casing@1"
            ]
        },
        {
            "x": -2,
            "y": 2,
            "z": 1,
            "elements": [
                "gregtech:transparent_casing@1"
            ]
        }
    ]}