{
    "registryname": "Pair_Annihilation_Reaction_Controller",
    "localizedname": "Pair Annihilation Reaction Controller",
     "color": "ff0400",
    "parts": [
        {
            "x": -1,
            "y": 0,
            "z": 0,
            "elements": [
                "modularmachinery:blockinputbus@0"
            ]
        },
        {
            "x": 12,
            "y": -7,
            "z": 13,
            "elements": [
                "avaritia:block_resource@2"
            ]
        },
        {
            "x": 1,
            "y": 0,
            "z": 0,
            "elements": [
                "modularmachinery:blockinputbus@0"
            ]
        },
        {
            "x": -2,
            "y": 0,
            "z": 0,
            "elements": [
                "deepmoblearning:infused_ingot_block@0"
            ]
        },
        {
            "x": 2,
            "y": 0,
            "z": 0,
            "elements": [
                "deepmoblearning:infused_ingot_block@0"
            ]
        },
        {
            "x": -3,
            "y": 0,
            "z": 0,
            "elements": [
                "enderio:block_end_iron_bars@0"
            ]
        },
        {
            "x": 3,
            "y": 0,
            "z": 0,
            "elements": [
                "enderio:block_end_iron_bars@0"
            ]
        },
        {
            "x": -12,
            "y": 2,
            "z": 17,
            "elements": [
                "gregtech:transparent_casing@1"
            ]
        },
        {
            "x": -12,
            "y": -6,
            "z": 13,
            "elements": [
                "gregtech:transparent_casing@1"
            ]
        },
        {
            "x": -19,
            "y": 9,
            "z": 4,
            "elements": [
                "draconicevolution:infused_obsidian@0"
            ]
        },
        {
            "x": 1,
            "y": -2,
            "z": -17,
            "elements": [
                "botania:storage@1"
            ]
        },
        {
            "x": 0,
            "y": -2,
            "z": -17,
            "elements": [
                "enderio:block_alloy_endergy@3"
            ]
        },
        {
            "x": 18,
            "y": 8,
            "z": 4,
            "elements": [
                "avaritia:block_resource@2"
            ]
        },
        {
            "x": -1,
            "y": -2,
            "z": -17,
            "elements": [
                "botania:storage@1"
            ]
        },
        {
            "x": 19,
            "y": 8,
            "z": 4,
            "elements": [
                "draconicevolution:infused_obsidian@0"
            ]
        },
        {
            "x": 20,
            "y": 8,
            "z": 4,
            "elements": [
                "avaritia:block_resource@2"
            ]
        },
        {
            "x": -19,
            "y": 0,
            "z": 0,
            "elements": [
                "gregtech:meta_block_compressed_7@15"
            ]
        },
        {
            "x": 19,
            "y": 0,
            "z": 0,
            "elements": [
                "gregtech:meta_block_compressed_7@15"
            ]
        },
        {
            "x": -2,
            "y": 9,
            "z": 4,
            "elements": [
                "botania:storage@1"
            ]
        },
        {
            "x": -1,
            "y": 9,
            "z": 4,
            "elements": [
                "avaritia:block_resource@1"
            ]
        },
        {
            "x": 0,
            "y": 9,
            "z": 4,
            "elements": [
                "thaumadditions:mithminite_block@0"
            ]
        },
        {
            "x": 3,
            "y": -1,
            "z": 0,
            "elements": [
                "enderio:block_end_iron_bars@0"
            ]
        },
        {
            "x": 12,
            "y": 2,
            "z": 17,
            "elements": [
                "gregtech:transparent_casing@1"
            ]
        },
        {
            "x": 1,
            "y": 9,
            "z": 4,
            "elements": [
                "avaritia:block_resource@1"
            ]
        },
        {
            "x": 2,
            "y": -1,
            "z": 0,
            "elements": [
                "deepmoblearning:infused_ingot_block@0"
            ]
        },
        {
            "x": -3,
            "y": 1,
            "z": 0,
            "elements": [
                "enderio:block_end_iron_bars@0"
            ]
        },
        {
            "x": 1,
            "y": -1,
            "z": 0,
            "elements": [
                "deepmoblearning:infused_ingot_block@0"
            ]
        },
        {
            "x": -2,
            "y": 1,
            "z": 0,
            "elements": [
                "deepmoblearning:infused_ingot_block@0"
            ]
        },
        {
            "x": 2,
            "y": 9,
            "z": 4,
            "elements": [
                "botania:storage@1"
            ]
        },
        {
            "x": 0,
            "y": -1,
            "z": 0,
            "elements": [
                "gregtech:transparent_casing@1"
            ]
        },
        {
            "x": -1,
            "y": 1,
            "z": 0,
            "elements": [
                "deepmoblearning:infused_ingot_block@0"
            ]
        },
        {
            "x": 0,
            "y": 1,
            "z": 0,
            "elements": [
                "gregtech:transparent_casing@1"
            ]
        },
        {
            "x": -1,
            "y": -1,
            "z": 0,
            "elements": [
                "deepmoblearning:infused_ingot_block@0"
            ]
        },
        {
            "x": 12,
            "y": -6,
            "z": 13,
            "elements": [
                "gregtech:transparent_casing@1"
            ]
        },
        {
            "x": 1,
            "y": 1,
            "z": 0,
            "elements": [
                "deepmoblearning:infused_ingot_block@0"
            ]
        },
        {
            "x": -2,
            "y": -1,
            "z": 0,
            "elements": [
                "deepmoblearning:infused_ingot_block@0"
            ]
        },
        {
            "x": 2,
            "y": 1,
            "z": 0,
            "elements": [
                "deepmoblearning:infused_ingot_block@0"
            ]
        },
        {
            "x": -3,
            "y": -1,
            "z": 0,
            "elements": [
                "enderio:block_end_iron_bars@0"
            ]
        },
        {
            "x": 3,
            "y": 1,
            "z": 0,
            "elements": [
                "enderio:block_end_iron_bars@0"
            ]
        },
        {
            "x": -12,
            "y": 3,
            "z": 17,
            "elements": [
                "gregtech:transparent_casing@1"
            ]
        },
        {
            "x": -12,
            "y": -5,
            "z": 13,
            "elements": [
                "gregtech:transparent_casing@1"
            ]
        },
        {
            "x": 1,
            "y": -3,
            "z": -17,
            "elements": [
                "deepmoblearning:infused_ingot_block@0"
            ]
        },
        {
            "x": 0,
            "y": -3,
            "z": -17,
            "elements": [
                "enderio:block_alloy_endergy@3"
            ]
        },
        {
            "x": -1,
            "y": -3,
            "z": -17,
            "elements": [
                "deepmoblearning:infused_ingot_block@0"
            ]
        },
        {
            "x": 19,
            "y": 9,
            "z": 4,
            "elements": [
                "draconicevolution:infused_obsidian@0"
            ]
        },
        {
            "x": -2,
            "y": 10,
            "z": 4,
            "elements": [
                "botania:storage@1"
            ]
        },
        {
            "x": -1,
            "y": 10,
            "z": 4,
            "elements": [
                "deepmoblearning:infused_ingot_block@0"
            ]
        },
        {
            "x": 0,
            "y": 10,
            "z": 4,
            "elements": [
                "avaritia:block_resource@2"
            ]
        },
        {
            "x": 3,
            "y": -2,
            "z": 0,
            "elements": [
                "enderio:block_end_iron_bars@0"
            ]
        },
        {
            "x": 12,
            "y": 3,
            "z": 17,
            "elements": [
                "gregtech:transparent_casing@1"
            ]
        },
        {
            "x": 1,
            "y": 10,
            "z": 4,
            "elements": [
                "deepmoblearning:infused_ingot_block@0"
            ]
        },
        {
            "x": 2,
            "y": -2,
            "z": 0,
            "elements": [
                "gregtech:wire_coil@7"
            ]
        },
        {
            "x": -3,
            "y": 2,
            "z": 0,
            "elements": [
                "enderio:block_end_iron_bars@0"
            ]
        },
        {
            "x": 1,
            "y": -2,
            "z": 0,
            "elements": [
                "gregtech:wire_coil@7"
            ]
        },
        {
            "x": -2,
            "y": 2,
            "z": 0,
            "elements": [
                "gregtech:wire_coil@7"
            ]
        },
        {
            "x": 2,
            "y": 10,
            "z": 4,
            "elements": [
                "botania:storage@1"
            ]
        },
        {
            "x": 0,
            "y": -2,
            "z": 0,
            "elements": [
                "avaritia:block_resource@0"
            ]
        },
        {
            "x": -1,
            "y": 2,
            "z": 0,
            "elements": [
                "gregtech:wire_coil@7"
            ]
        },
        {
            "x": 0,
            "y": 2,
            "z": 0,
            "elements": [
                "avaritia:block_resource@0"
            ]
        },
        {
            "x": -1,
            "y": -2,
            "z": 0,
            "elements": [
                "gregtech:wire_coil@7"
            ]
        },
        {
            "x": 12,
            "y": -5,
            "z": 13,
            "elements": [
                "gregtech:transparent_casing@1"
            ]
        },
        {
            "x": 1,
            "y": 2,
            "z": 0,
            "elements": [
                "gregtech:wire_coil@7"
            ]
        },
        {
            "x": -2,
            "y": -2,
            "z": 0,
            "elements": [
                "gregtech:wire_coil@7"
            ]
        },
        {
            "x": 2,
            "y": 2,
            "z": 0,
            "elements": [
                "gregtech:wire_coil@7"
            ]
        },
        {
            "x": -3,
            "y": -2,
            "z": 0,
            "elements": [
                "enderio:block_end_iron_bars@0"
            ]
        },
        {
            "x": 3,
            "y": 2,
            "z": 0,
            "elements": [
                "enderio:block_end_iron_bars@0"
            ]
        },
        {
            "x": -12,
            "y": 4,
            "z": 17,
            "elements": [
                "gregtech:transparent_casing@1"
            ]
        },
        {
            "x": -12,
            "y": -4,
            "z": 13,
            "elements": [
                "gregtech:transparent_casing@1"
            ]
        },
        {
            "x": 12,
            "y": 12,
            "z": -9,
            "elements": [
                "modularmachinery:blockenergyoutputhatch@7"
            ]
        },
        {
            "x": 1,
            "y": -4,
            "z": -17,
            "elements": [
                "deepmoblearning:infused_ingot_block@0"
            ]
        },
        {
            "x": 0,
            "y": -4,
            "z": -17,
            "elements": [
                "enderio:block_alloy_endergy@3"
            ]
        },
        {
            "x": -1,
            "y": -4,
            "z": -17,
            "elements": [
                "deepmoblearning:infused_ingot_block@0"
            ]
        },
        {
            "x": -2,
            "y": 11,
            "z": 4,
            "elements": [
                "avaritia:block_resource@2"
            ]
        },
        {
            "x": -1,
            "y": 11,
            "z": 4,
            "elements": [
                "deepmoblearning:infused_ingot_block@0"
            ]
        },
        {
            "x": 0,
            "y": 11,
            "z": 4,
            "elements": [
                "avaritia:block_resource@2"
            ]
        },
        {
            "x": 12,
            "y": 4,
            "z": 17,
            "elements": [
                "gregtech:transparent_casing@1"
            ]
        },
        {
            "x": 1,
            "y": 11,
            "z": 4,
            "elements": [
                "deepmoblearning:infused_ingot_block@0"
            ]
        },
        {
            "x": 2,
            "y": -3,
            "z": 0,
            "elements": [
                "gregtech:wire_coil@7"
            ]
        },
        {
            "x": 1,
            "y": -3,
            "z": 0,
            "elements": [
                "gregtech:wire_coil@7"
            ]
        },
        {
            "x": -2,
            "y": 3,
            "z": 0,
            "elements": [
                "gregtech:wire_coil@7"
            ]
        },
        {
            "x": 2,
            "y": 11,
            "z": 4,
            "elements": [
                "avaritia:block_resource@2"
            ]
        },
        {
            "x": 0,
            "y": -3,
            "z": 0,
            "elements": [
                "avaritia:block_resource@0"
            ]
        },
        {
            "x": -1,
            "y": 3,
            "z": 0,
            "elements": [
                "gregtech:wire_coil@7"
            ]
        },
        {
            "x": 0,
            "y": 3,
            "z": 0,
            "elements": [
                "avaritia:block_resource@0"
            ]
        },
        {
            "x": -1,
            "y": -3,
            "z": 0,
            "elements": [
                "gregtech:wire_coil@7"
            ]
        },
        {
            "x": 12,
            "y": -4,
            "z": 13,
            "elements": [
                "gregtech:transparent_casing@1"
            ]
        },
        {
            "x": 1,
            "y": 3,
            "z": 0,
            "elements": [
                "gregtech:wire_coil@7"
            ]
        },
        {
            "x": -2,
            "y": -3,
            "z": 0,
            "elements": [
                "gregtech:wire_coil@7"
            ]
        },
        {
            "x": 2,
            "y": 3,
            "z": 0,
            "elements": [
                "gregtech:wire_coil@7"
            ]
        },
        {
            "x": -12,
            "y": 12,
            "z": -9,
            "elements": [
                "modularmachinery:blockenergyoutputhatch@7"
            ]
        },
        {
            "x": -12,
            "y": 5,
            "z": 17,
            "elements": [
                "gregtech:transparent_casing@1"
            ]
        },
        {
            "x": -12,
            "y": -3,
            "z": 13,
            "elements": [
                "gregtech:transparent_casing@1"
            ]
        },
        {
            "x": 12,
            "y": 11,
            "z": -9,
            "elements": [
                "minecraft:bedrock@0"
            ]
        },
        {
            "x": 1,
            "y": -5,
            "z": -17,
            "elements": [
                "deepmoblearning:infused_ingot_block@0"
            ]
        },
        {
            "x": 0,
            "y": -5,
            "z": -17,
            "elements": [
                "enderio:block_alloy_endergy@3"
            ]
        },
        {
            "x": -1,
            "y": -5,
            "z": -17,
            "elements": [
                "deepmoblearning:infused_ingot_block@0"
            ]
        },
        {
            "x": -2,
            "y": 12,
            "z": 4,
            "elements": [
                "avaritia:block_resource@2"
            ]
        },
        {
            "x": -1,
            "y": 12,
            "z": 4,
            "elements": [
                "avaritia:block_resource@0"
            ]
        },
        {
            "x": 0,
            "y": 12,
            "z": 4,
            "elements": [
                "avaritia:block_resource@2"
            ]
        },
        {
            "x": 12,
            "y": 5,
            "z": 17,
            "elements": [
                "gregtech:transparent_casing@1"
            ]
        },
        {
            "x": 1,
            "y": 12,
            "z": 4,
            "elements": [
                "avaritia:block_resource@0"
            ]
        },
        {
            "x": 2,
            "y": -4,
            "z": 0,
            "elements": [
                "contenttweaker:machine_coil_neutonium@0"
            ]
        },
        {
            "x": 1,
            "y": -4,
            "z": 0,
            "elements": [
                "contenttweaker:machine_coil_neutonium@0"
            ]
        },
        {
            "x": -2,
            "y": 4,
            "z": 0,
            "elements": [
                "contenttweaker:machine_coil_neutonium@0"
            ]
        },
        {
            "x": 2,
            "y": 12,
            "z": 4,
            "elements": [
                "avaritia:block_resource@2"
            ]
        },
        {
            "x": 0,
            "y": -4,
            "z": 0,
            "elements": [
                "avaritia:block_resource@0"
            ]
        },
        {
            "x": -1,
            "y": 4,
            "z": 0,
            "elements": [
                "contenttweaker:machine_coil_neutonium@0"
            ]
        },
        {
            "x": 0,
            "y": 4,
            "z": 0,
            "elements": [
                "avaritia:block_resource@0"
            ]
        },
        {
            "x": -1,
            "y": -4,
            "z": 0,
            "elements": [
                "contenttweaker:machine_coil_neutonium@0"
            ]
        },
        {
            "x": 12,
            "y": -3,
            "z": 13,
            "elements": [
                "gregtech:transparent_casing@1"
            ]
        },
        {
            "x": 1,
            "y": 4,
            "z": 0,
            "elements": [
                "contenttweaker:machine_coil_neutonium@0"
            ]
        },
        {
            "x": -2,
            "y": -4,
            "z": 0,
            "elements": [
                "contenttweaker:machine_coil_neutonium@0"
            ]
        },
        {
            "x": 2,
            "y": 4,
            "z": 0,
            "elements": [
                "contenttweaker:machine_coil_neutonium@0"
            ]
        },
        {
            "x": -12,
            "y": 11,
            "z": -9,
            "elements": [
                "minecraft:bedrock@0"
            ]
        },
        {
            "x": -12,
            "y": 6,
            "z": 17,
            "elements": [
                "gregtech:transparent_casing@1"
            ]
        },
        {
            "x": -12,
            "y": -2,
            "z": 13,
            "elements": [
                "gregtech:transparent_casing@1"
            ]
        },
        {
            "x": 12,
            "y": 10,
            "z": -9,
            "elements": [
                "minecraft:bedrock@0"
            ]
        },
        {
            "x": 1,
            "y": -6,
            "z": -17,
            "elements": [
                "deepmoblearning:infused_ingot_block@0"
            ]
        },
        {
            "x": 0,
            "y": -6,
            "z": -17,
            "elements": [
                "enderio:block_alloy_endergy@3"
            ]
        },
        {
            "x": -1,
            "y": -6,
            "z": -17,
            "elements": [
                "deepmoblearning:infused_ingot_block@0"
            ]
        },
        {
            "x": -2,
            "y": 13,
            "z": 4,
            "elements": [
                "enderio:block_alloy_endergy@3"
            ]
        },
        {
            "x": -1,
            "y": 13,
            "z": 4,
            "elements": [
                "minecraft:bedrock@0"
            ]
        },
        {
            "x": 0,
            "y": 13,
            "z": 4,
            "elements": [
                "draconicevolution:infused_obsidian@0"
            ]
        },
        {
            "x": 12,
            "y": 6,
            "z": 17,
            "elements": [
                "gregtech:transparent_casing@1"
            ]
        },
        {
            "x": 1,
            "y": 13,
            "z": 4,
            "elements": [
                "minecraft:bedrock@0"
            ]
        },
        {
            "x": 2,
            "y": -5,
            "z": 0,
            "elements": [
                "minecraft:bedrock@0"
            ]
        },
        {
            "x": 1,
            "y": -5,
            "z": 0,
            "elements": [
                "minecraft:bedrock@0"
            ]
        },
        {
            "x": -2,
            "y": 5,
            "z": 0,
            "elements": [
                "minecraft:bedrock@0"
            ]
        },
        {
            "x": 2,
            "y": 13,
            "z": 4,
            "elements": [
                "enderio:block_alloy_endergy@3"
            ]
        },
        {
            "x": 0,
            "y": -5,
            "z": 0,
            "elements": [
                "gregtech:transparent_casing@1"
            ]
        },
        {
            "x": -1,
            "y": 5,
            "z": 0,
            "elements": [
                "minecraft:bedrock@0"
            ]
        },
        {
            "x": 0,
            "y": 5,
            "z": 0,
            "elements": [
                "gregtech:transparent_casing@1"
            ]
        },
        {
            "x": -1,
            "y": -5,
            "z": 0,
            "elements": [
                "minecraft:bedrock@0"
            ]
        },
        {
            "x": 12,
            "y": -2,
            "z": 13,
            "elements": [
                "gregtech:transparent_casing@1"
            ]
        },
        {
            "x": 1,
            "y": 5,
            "z": 0,
            "elements": [
                "minecraft:bedrock@0"
            ]
        },
        {
            "x": -2,
            "y": -5,
            "z": 0,
            "elements": [
                "minecraft:bedrock@0"
            ]
        },
        {
            "x": 2,
            "y": 5,
            "z": 0,
            "elements": [
                "minecraft:bedrock@0"
            ]
        },
        {
            "x": -12,
            "y": 10,
            "z": -9,
            "elements": [
                "minecraft:bedrock@0"
            ]
        },
        {
            "x": -12,
            "y": 7,
            "z": 17,
            "elements": [
                "avaritia:block_resource@2"
            ]
        },
        {
            "x": -12,
            "y": -1,
            "z": 13,
            "elements": [
                "botania:storage@1"
            ]
        },
        {
            "x": 13,
            "y": 9,
            "z": -9,
            "elements": [
                "draconicevolution:infused_obsidian@0"
            ]
        },
        {
            "x": 12,
            "y": 9,
            "z": -9,
            "elements": [
                "minecraft:bedrock@0"
            ]
        },
        {
            "x": 11,
            "y": 9,
            "z": -9,
            "elements": [
                "draconicevolution:infused_obsidian@0"
            ]
        },
        {
            "x": 1,
            "y": -7,
            "z": -17,
            "elements": [
                "draconicevolution:infused_obsidian@0"
            ]
        },
        {
            "x": 0,
            "y": -7,
            "z": -17,
            "elements": [
                "avaritia:block_resource@0"
            ]
        },
        {
            "x": -1,
            "y": -7,
            "z": -17,
            "elements": [
                "draconicevolution:infused_obsidian@0"
            ]
        },
        {
            "x": -2,
            "y": 14,
            "z": 4,
            "elements": [
                "draconicevolution:infused_obsidian@0"
            ]
        },
        {
            "x": -1,
            "y": 14,
            "z": 4,
            "elements": [
                "minecraft:bedrock@0"
            ]
        },
        {
            "x": 0,
            "y": 14,
            "z": 4,
            "elements": [
                "draconicevolution:infused_obsidian@0"
            ]
        },
        {
            "x": 12,
            "y": 7,
            "z": 17,
            "elements": [
                "avaritia:block_resource@2"
            ]
        },
        {
            "x": 1,
            "y": 14,
            "z": 4,
            "elements": [
                "minecraft:bedrock@0"
            ]
        },
        {
            "x": 2,
            "y": 14,
            "z": 4,
            "elements": [
                "draconicevolution:infused_obsidian@0"
            ]
        },
        {
            "x": 0,
            "y": -6,
            "z": 0,
            "elements": [
                "gregtech:transparent_casing@1"
            ]
        },
        {
            "x": 0,
            "y": 6,
            "z": 0,
            "elements": [
                "gregtech:transparent_casing@1"
            ]
        },
        {
            "x": 12,
            "y": -1,
            "z": 13,
            "elements": [
                "botania:storage@1"
            ]
        },
        {
            "x": -11,
            "y": 9,
            "z": -9,
            "elements": [
                "draconicevolution:infused_obsidian@0"
            ]
        },
        {
            "x": -12,
            "y": 9,
            "z": -9,
            "elements": [
                "minecraft:bedrock@0"
            ]
        },
        {
            "x": -12,
            "y": 8,
            "z": 17,
            "elements": [
                "draconicevolution:infused_obsidian@0"
            ]
        },
        {
            "x": -13,
            "y": 9,
            "z": -9,
            "elements": [
                "draconicevolution:infused_obsidian@0"
            ]
        },
        {
            "x": -13,
            "y": 0,
            "z": 13,
            "elements": [
                "deepmoblearning:infused_ingot_block@0"
            ]
        },
        {
            "x": -12,
            "y": 0,
            "z": 13,
            "elements": [
                "avaritia:block_resource@0"
            ]
        },
        {
            "x": 14,
            "y": 8,
            "z": -9,
            "elements": [
                "draconicevolution:infused_obsidian@0"
            ]
        },
        {
            "x": -11,
            "y": 0,
            "z": 13,
            "elements": [
                "deepmoblearning:infused_ingot_block@0"
            ]
        },
        {
            "x": 13,
            "y": 8,
            "z": -9,
            "elements": [
                "draconicevolution:infused_obsidian@0"
            ]
        },
        {
            "x": 12,
            "y": 8,
            "z": -9,
            "elements": [
                "avaritia:block_resource@0"
            ]
        },
        {
            "x": 11,
            "y": 8,
            "z": -9,
            "elements": [
                "draconicevolution:infused_obsidian@0"
            ]
        },
        {
            "x": 10,
            "y": 8,
            "z": -9,
            "elements": [
                "draconicevolution:infused_obsidian@0"
            ]
        },
        {
            "x": 1,
            "y": -8,
            "z": -17,
            "elements": [
                "avaritia:block_resource@2"
            ]
        },
        {
            "x": 0,
            "y": -8,
            "z": -17,
            "elements": [
                "draconicevolution:infused_obsidian@0"
            ]
        },
        {
            "x": -1,
            "y": -8,
            "z": -17,
            "elements": [
                "avaritia:block_resource@2"
            ]
        },
        {
            "x": 0,
            "y": 0,
            "z": -13,
            "elements": [
                "gregtech:meta_block_compressed_7@15"
            ]
        },
        {
            "x": -1,
            "y": 15,
            "z": 4,
            "elements": [
                "minecraft:bedrock@0"
            ]
        },
        {
            "x": 0,
            "y": 15,
            "z": 4,
            "elements": [
                "draconicevolution:infused_obsidian@0"
            ]
        },
        {
            "x": 12,
            "y": 8,
            "z": 17,
            "elements": [
                "draconicevolution:infused_obsidian@0"
            ]
        },
        {
            "x": 1,
            "y": 15,
            "z": 4,
            "elements": [
                "minecraft:bedrock@0"
            ]
        },
        {
            "x": 0,
            "y": -7,
            "z": 0,
            "elements": [
                "gregtech:transparent_casing@1"
            ]
        },
        {
            "x": 11,
            "y": 0,
            "z": 13,
            "elements": [
                "deepmoblearning:infused_ingot_block@0"
            ]
        },
        {
            "x": 0,
            "y": 7,
            "z": 0,
            "elements": [
                "gregtech:transparent_casing@1"
            ]
        },
        {
            "x": 12,
            "y": 0,
            "z": 13,
            "elements": [
                "avaritia:block_resource@0"
            ]
        },
        {
            "x": 13,
            "y": 0,
            "z": 13,
            "elements": [
                "deepmoblearning:infused_ingot_block@0"
            ]
        },
        {
            "x": -10,
            "y": 8,
            "z": -9,
            "elements": [
                "draconicevolution:infused_obsidian@0"
            ]
        },
        {
            "x": -11,
            "y": 8,
            "z": -9,
            "elements": [
                "draconicevolution:infused_obsidian@0"
            ]
        },
        {
            "x": -12,
            "y": 8,
            "z": -9,
            "elements": [
                "avaritia:block_resource@0"
            ]
        },
        {
            "x": -13,
            "y": 8,
            "z": -9,
            "elements": [
                "draconicevolution:infused_obsidian@0"
            ]
        },
        {
            "x": -14,
            "y": 8,
            "z": -9,
            "elements": [
                "draconicevolution:infused_obsidian@0"
            ]
        },
        {
            "x": -12,
            "y": 1,
            "z": 13,
            "elements": [
                "botania:storage@1"
            ]
        },
        {
            "x": 14,
            "y": 7,
            "z": -9,
            "elements": [
                "avaritia:block_resource@2"
            ]
        },
        {
            "x": 13,
            "y": 7,
            "z": -9,
            "elements": [
                "avaritia:block_resource@0"
            ]
        },
        {
            "x": 12,
            "y": 7,
            "z": -9,
            "elements": [
                "draconicevolution:energy_storage_core@0"
            ]
        },
        {
            "x": 11,
            "y": 7,
            "z": -9,
            "elements": [
                "avaritia:block_resource@0"
            ]
        },
        {
            "x": 10,
            "y": 7,
            "z": -9,
            "elements": [
                "avaritia:block_resource@2"
            ]
        },
        {
            "x": 0,
            "y": -9,
            "z": -17,
            "elements": [
                "draconicevolution:infused_obsidian@0"
            ]
        },
        {
            "x": -1,
            "y": 16,
            "z": 4,
            "elements": [
                "minecraft:bedrock@0"
            ]
        },
        {
            "x": 0,
            "y": -15,
            "z": 5,
            "elements": [
                "draconicevolution:infused_obsidian@0"
            ]
        },
        {
            "x": 0,
            "y": 16,
            "z": 4,
            "elements": [
                "draconicevolution:infused_obsidian@0"
            ]
        },
        {
            "x": 1,
            "y": 16,
            "z": 4,
            "elements": [
                "minecraft:bedrock@0"
            ]
        },
        {
            "x": 0,
            "y": -8,
            "z": 0,
            "elements": [
                "gregtech:transparent_casing@1"
            ]
        },
        {
            "x": 0,
            "y": 8,
            "z": 0,
            "elements": [
                "gregtech:transparent_casing@1"
            ]
        },
        {
            "x": 12,
            "y": 1,
            "z": 13,
            "elements": [
                "botania:storage@1"
            ]
        },
        {
            "x": -10,
            "y": 7,
            "z": -9,
            "elements": [
                "avaritia:block_resource@2"
            ]
        },
        {
            "x": -11,
            "y": 7,
            "z": -9,
            "elements": [
                "avaritia:block_resource@0"
            ]
        },
        {
            "x": -12,
            "y": 7,
            "z": -9,
            "elements": [
                "draconicevolution:energy_storage_core@0"
            ]
        },
        {
            "x": -13,
            "y": 7,
            "z": -9,
            "elements": [
                "avaritia:block_resource@0"
            ]
        },
        {
            "x": -14,
            "y": 7,
            "z": -9,
            "elements": [
                "avaritia:block_resource@2"
            ]
        },
        {
            "x": -12,
            "y": 2,
            "z": 13,
            "elements": [
                "gregtech:transparent_casing@1"
            ]
        },
        {
            "x": 14,
            "y": 6,
            "z": -9,
            "elements": [
                "gregtech:transparent_casing@1"
            ]
        },
        {
            "x": 13,
            "y": 6,
            "z": -9,
            "elements": [
                "enderio:block_alloy_endergy@3"
            ]
        },
        {
            "x": 12,
            "y": 6,
            "z": -9,
            "elements": [
                "avaritia:block_resource@1"
            ]
        },
        {
            "x": 11,
            "y": 6,
            "z": -9,
            "elements": [
                "enderio:block_alloy_endergy@3"
            ]
        },
        {
            "x": 10,
            "y": 6,
            "z": -9,
            "elements": [
                "gregtech:transparent_casing@1"
            ]
        },
        {
            "x": -1,
            "y": 17,
            "z": 4,
            "elements": [
                "minecraft:bedrock@0"
            ]
        },
        {
            "x": -1,
            "y": -14,
            "z": 5,
            "elements": [
                "draconicevolution:infused_obsidian@0"
            ]
        },
        {
            "x": 0,
            "y": -14,
            "z": 5,
            "elements": [
                "draconicevolution:infused_obsidian@0"
            ]
        },
        {
            "x": 0,
            "y": 17,
            "z": 4,
            "elements": [
                "draconicevolution:infused_obsidian@0"
            ]
        },
        {
            "x": 1,
            "y": -14,
            "z": 5,
            "elements": [
                "draconicevolution:infused_obsidian@0"
            ]
        },
        {
            "x": 1,
            "y": 17,
            "z": 4,
            "elements": [
                "minecraft:bedrock@0"
            ]
        },
        {
            "x": 0,
            "y": -9,
            "z": 0,
            "elements": [
                "gregtech:transparent_casing@1"
            ]
        },
        {
            "x": 0,
            "y": 9,
            "z": 0,
            "elements": [
                "gregtech:transparent_casing@1"
            ]
        },
        {
            "x": 12,
            "y": 2,
            "z": 13,
            "elements": [
                "gregtech:transparent_casing@1"
            ]
        },
        {
            "x": -10,
            "y": 6,
            "z": -9,
            "elements": [
                "gregtech:transparent_casing@1"
            ]
        },
        {
            "x": -11,
            "y": 6,
            "z": -9,
            "elements": [
                "enderio:block_alloy_endergy@3"
            ]
        },
        {
            "x": -12,
            "y": 6,
            "z": -9,
            "elements": [
                "avaritia:block_resource@1"
            ]
        },
        {
            "x": -13,
            "y": 6,
            "z": -9,
            "elements": [
                "enderio:block_alloy_endergy@3"
            ]
        },
        {
            "x": -14,
            "y": 6,
            "z": -9,
            "elements": [
                "gregtech:transparent_casing@1"
            ]
        },
        {
            "x": -12,
            "y": 3,
            "z": 13,
            "elements": [
                "gregtech:transparent_casing@1"
            ]
        },
        {
            "x": 14,
            "y": 5,
            "z": -9,
            "elements": [
                "gregtech:transparent_casing@1"
            ]
        },
        {
            "x": 13,
            "y": 5,
            "z": -9,
            "elements": [
                "enderio:block_alloy_endergy@3"
            ]
        },
        {
            "x": 12,
            "y": 5,
            "z": -9,
            "elements": [
                "avaritia:block_resource@1"
            ]
        },
        {
            "x": 0,
            "y": -12,
            "z": 22,
            "elements": [
                "modularmachinery:blockenergyoutputhatch@7"
            ]
        },
        {
            "x": 11,
            "y": 5,
            "z": -9,
            "elements": [
                "enderio:block_alloy_endergy@3"
            ]
        },
        {
            "x": 10,
            "y": 5,
            "z": -9,
            "elements": [
                "gregtech:transparent_casing@1"
            ]
        },
        {
            "x": -1,
            "y": 18,
            "z": 4,
            "elements": [
                "avaritia:block_resource@0"
            ]
        },
        {
            "x": -1,
            "y": -13,
            "z": 5,
            "elements": [
                "enderio:block_alloy_endergy@3"
            ]
        },
        {
            "x": 0,
            "y": -13,
            "z": 5,
            "elements": [
                "draconicevolution:infused_obsidian@0"
            ]
        },
        {
            "x": 1,
            "y": -13,
            "z": 5,
            "elements": [
                "enderio:block_alloy_endergy@3"
            ]
        },
        {
            "x": 1,
            "y": 18,
            "z": 4,
            "elements": [
                "avaritia:block_resource@0"
            ]
        },
        {
            "x": 0,
            "y": -10,
            "z": 0,
            "elements": [
                "gregtech:transparent_casing@1"
            ]
        },
        {
            "x": 0,
            "y": 10,
            "z": 0,
            "elements": [
                "gregtech:transparent_casing@1"
            ]
        },
        {
            "x": 12,
            "y": 3,
            "z": 13,
            "elements": [
                "gregtech:transparent_casing@1"
            ]
        },
        {
            "x": -10,
            "y": 5,
            "z": -9,
            "elements": [
                "gregtech:transparent_casing@1"
            ]
        },
        {
            "x": -11,
            "y": 5,
            "z": -9,
            "elements": [
                "enderio:block_alloy_endergy@3"
            ]
        },
        {
            "x": -12,
            "y": 5,
            "z": -9,
            "elements": [
                "avaritia:block_resource@1"
            ]
        },
        {
            "x": -13,
            "y": 5,
            "z": -9,
            "elements": [
                "enderio:block_alloy_endergy@3"
            ]
        },
        {
            "x": -14,
            "y": 5,
            "z": -9,
            "elements": [
                "gregtech:transparent_casing@1"
            ]
        },
        {
            "x": -12,
            "y": 4,
            "z": 13,
            "elements": [
                "gregtech:transparent_casing@1"
            ]
        },
        {
            "x": 14,
            "y": 4,
            "z": -9,
            "elements": [
                "gregtech:transparent_casing@1"
            ]
        },
        {
            "x": 13,
            "y": 4,
            "z": -9,
            "elements": [
                "enderio:block_alloy_endergy@3"
            ]
        },
        {
            "x": 12,
            "y": 4,
            "z": -9,
            "elements": [
                "avaritia:block_resource@1"
            ]
        },
        {
            "x": 0,
            "y": -11,
            "z": 22,
            "elements": [
                "minecraft:bedrock@0"
            ]
        },
        {
            "x": 11,
            "y": 4,
            "z": -9,
            "elements": [
                "enderio:block_alloy_endergy@3"
            ]
        },
        {
            "x": 10,
            "y": 4,
            "z": -9,
            "elements": [
                "gregtech:transparent_casing@1"
            ]
        },
        {
            "x": -1,
            "y": -12,
            "z": 5,
            "elements": [
                "avaritia:block_resource@2"
            ]
        },
        {
            "x": 0,
            "y": -12,
            "z": 5,
            "elements": [
                "enderio:block_alloy_endergy@3"
            ]
        },
        {
            "x": 1,
            "y": -12,
            "z": 5,
            "elements": [
                "avaritia:block_resource@2"
            ]
        },
        {
            "x": 0,
            "y": -11,
            "z": 0,
            "elements": [
                "gregtech:transparent_casing@1"
            ]
        },
        {
            "x": 0,
            "y": 11,
            "z": 0,
            "elements": [
                "gregtech:transparent_casing@1"
            ]
        },
        {
            "x": 12,
            "y": 4,
            "z": 13,
            "elements": [
                "gregtech:transparent_casing@1"
            ]
        },
        {
            "x": -10,
            "y": 4,
            "z": -9,
            "elements": [
                "gregtech:transparent_casing@1"
            ]
        },
        {
            "x": -11,
            "y": 4,
            "z": -9,
            "elements": [
                "enderio:block_alloy_endergy@3"
            ]
        },
        {
            "x": -12,
            "y": 4,
            "z": -9,
            "elements": [
                "avaritia:block_resource@1"
            ]
        },
        {
            "x": -13,
            "y": 4,
            "z": -9,
            "elements": [
                "enderio:block_alloy_endergy@3"
            ]
        },
        {
            "x": -14,
            "y": 4,
            "z": -9,
            "elements": [
                "gregtech:transparent_casing@1"
            ]
        },
        {
            "x": -12,
            "y": 5,
            "z": 13,
            "elements": [
                "gregtech:transparent_casing@1"
            ]
        },
        {
            "x": 14,
            "y": 3,
            "z": -9,
            "elements": [
                "gregtech:transparent_casing@1"
            ]
        },
        {
            "x": 13,
            "y": 3,
            "z": -9,
            "elements": [
                "enderio:block_alloy_endergy@3"
            ]
        },
        {
            "x": 12,
            "y": 3,
            "z": -9,
            "elements": [
                "avaritia:block_resource@1"
            ]
        },
        {
            "x": 0,
            "y": -10,
            "z": 22,
            "elements": [
                "minecraft:bedrock@0"
            ]
        },
        {
            "x": 11,
            "y": 3,
            "z": -9,
            "elements": [
                "enderio:block_alloy_endergy@3"
            ]
        },
        {
            "x": 10,
            "y": 3,
            "z": -9,
            "elements": [
                "gregtech:transparent_casing@1"
            ]
        },
        {
            "x": -1,
            "y": -11,
            "z": 5,
            "elements": [
                "avaritia:block_resource@2"
            ]
        },
        {
            "x": 0,
            "y": -11,
            "z": 5,
            "elements": [
                "enderio:block_alloy_endergy@3"
            ]
        },
        {
            "x": 1,
            "y": -11,
            "z": 5,
            "elements": [
                "avaritia:block_resource@2"
            ]
        },
        {
            "x": 0,
            "y": -12,
            "z": 0,
            "elements": [
                "gregtech:transparent_casing@1"
            ]
        },
        {
            "x": 0,
            "y": 12,
            "z": 0,
            "elements": [
                "gregtech:transparent_casing@1"
            ]
        },
        {
            "x": 12,
            "y": 5,
            "z": 13,
            "elements": [
                "gregtech:transparent_casing@1"
            ]
        },
        {
            "x": -10,
            "y": 3,
            "z": -9,
            "elements": [
                "gregtech:transparent_casing@1"
            ]
        },
        {
            "x": -11,
            "y": 3,
            "z": -9,
            "elements": [
                "enderio:block_alloy_endergy@3"
            ]
        },
        {
            "x": -12,
            "y": 3,
            "z": -9,
            "elements": [
                "avaritia:block_resource@1"
            ]
        },
        {
            "x": -13,
            "y": 3,
            "z": -9,
            "elements": [
                "enderio:block_alloy_endergy@3"
            ]
        },
        {
            "x": -14,
            "y": 3,
            "z": -9,
            "elements": [
                "gregtech:transparent_casing@1"
            ]
        },
        {
            "x": -12,
            "y": 6,
            "z": 13,
            "elements": [
                "gregtech:transparent_casing@1"
            ]
        },
        {
            "x": 14,
            "y": 2,
            "z": -9,
            "elements": [
                "gregtech:transparent_casing@1"
            ]
        },
        {
            "x": 13,
            "y": 2,
            "z": -9,
            "elements": [
                "enderio:block_alloy_endergy@3"
            ]
        },
        {
            "x": -1,
            "y": -9,
            "z": 22,
            "elements": [
                "draconicevolution:infused_obsidian@0"
            ]
        },
        {
            "x": 12,
            "y": 2,
            "z": -9,
            "elements": [
                "avaritia:block_resource@0"
            ]
        },
        {
            "x": 0,
            "y": -9,
            "z": 22,
            "elements": [
                "minecraft:bedrock@0"
            ]
        },
        {
            "x": 11,
            "y": 2,
            "z": -9,
            "elements": [
                "enderio:block_alloy_endergy@3"
            ]
        },
        {
            "x": 1,
            "y": -9,
            "z": 22,
            "elements": [
                "draconicevolution:infused_obsidian@0"
            ]
        },
        {
            "x": 10,
            "y": 2,
            "z": -9,
            "elements": [
                "gregtech:transparent_casing@1"
            ]
        },
        {
            "x": -1,
            "y": -10,
            "z": 5,
            "elements": [
                "botania:storage@1"
            ]
        },
        {
            "x": 0,
            "y": -10,
            "z": 5,
            "elements": [
                "enderio:block_alloy_endergy@3"
            ]
        },
        {
            "x": 1,
            "y": -10,
            "z": 5,
            "elements": [
                "botania:storage@1"
            ]
        },
        {
            "x": 0,
            "y": -13,
            "z": 0,
            "elements": [
                "draconicevolution:infused_obsidian@0"
            ]
        },
        {
            "x": 0,
            "y": 13,
            "z": 0,
            "elements": [
                "draconicevolution:infused_obsidian@0"
            ]
        },
        {
            "x": 12,
            "y": 6,
            "z": 13,
            "elements": [
                "gregtech:transparent_casing@1"
            ]
        },
        {
            "x": -10,
            "y": 2,
            "z": -9,
            "elements": [
                "gregtech:transparent_casing@1"
            ]
        },
        {
            "x": -11,
            "y": 2,
            "z": -9,
            "elements": [
                "enderio:block_alloy_endergy@3"
            ]
        },
        {
            "x": -12,
            "y": 2,
            "z": -9,
            "elements": [
                "avaritia:block_resource@0"
            ]
        },
        {
            "x": -13,
            "y": 2,
            "z": -9,
            "elements": [
                "enderio:block_alloy_endergy@3"
            ]
        },
        {
            "x": -14,
            "y": 2,
            "z": -9,
            "elements": [
                "gregtech:transparent_casing@1"
            ]
        },
        {
            "x": -12,
            "y": 7,
            "z": 13,
            "elements": [
                "avaritia:block_resource@2"
            ]
        },
        {
            "x": 14,
            "y": 1,
            "z": -9,
            "elements": [
                "botania:storage@1"
            ]
        },
        {
            "x": 13,
            "y": 1,
            "z": -9,
            "elements": [
                "gregtech:meta_block_compressed_26@14"
            ]
        },
        {
            "x": -2,
            "y": -8,
            "z": 22,
            "elements": [
                "draconicevolution:infused_obsidian@0"
            ]
        },
        {
            "x": -1,
            "y": -8,
            "z": 22,
            "elements": [
                "draconicevolution:infused_obsidian@0"
            ]
        },
        {
            "x": 12,
            "y": 1,
            "z": -9,
            "elements": [
                "avaritia:block_resource@0"
            ]
        },
        {
            "x": 0,
            "y": -8,
            "z": 22,
            "elements": [
                "avaritia:block_resource@0"
            ]
        },
        {
            "x": 11,
            "y": 1,
            "z": -9,
            "elements": [
                "gregtech:meta_block_compressed_26@14"
            ]
        },
        {
            "x": 1,
            "y": -8,
            "z": 22,
            "elements": [
                "draconicevolution:infused_obsidian@0"
            ]
        },
        {
            "x": 10,
            "y": 1,
            "z": -9,
            "elements": [
                "botania:storage@1"
            ]
        },
        {
            "x": 2,
            "y": -8,
            "z": 22,
            "elements": [
                "draconicevolution:infused_obsidian@0"
            ]
        },
        {
            "x": -1,
            "y": -9,
            "z": 5,
            "elements": [
                "botania:storage@1"
            ]
        },
        {
            "x": 0,
            "y": -9,
            "z": 5,
            "elements": [
                "enderio:block_alloy_endergy@3"
            ]
        },
        {
            "x": 1,
            "y": -9,
            "z": 5,
            "elements": [
                "botania:storage@1"
            ]
        },
        {
            "x": 12,
            "y": 7,
            "z": 13,
            "elements": [
                "avaritia:block_resource@2"
            ]
        },
        {
            "x": -10,
            "y": 1,
            "z": -9,
            "elements": [
                "botania:storage@1"
            ]
        },
        {
            "x": -11,
            "y": 1,
            "z": -9,
            "elements": [
                "gregtech:meta_block_compressed_26@14"
            ]
        },
        {
            "x": -12,
            "y": 1,
            "z": -9,
            "elements": [
                "avaritia:block_resource@0"
            ]
        },
        {
            "x": -13,
            "y": 1,
            "z": -9,
            "elements": [
                "gregtech:meta_block_compressed_26@14"
            ]
        },
        {
            "x": -14,
            "y": 1,
            "z": -9,
            "elements": [
                "botania:storage@1"
            ]
        },
        {
            "x": 15,
            "y": 0,
            "z": -9,
            "elements": [
                "gregtech:meta_block_compressed_7@15"
            ]
        },
        {
            "x": -12,
            "y": 8,
            "z": 13,
            "elements": [
                "draconicevolution:infused_obsidian@0"
            ]
        },
        {
            "x": 14,
            "y": 0,
            "z": -9,
            "elements": [
                "avaritia:block_resource@0"
            ]
        },
        {
            "x": -19,
            "y": -8,
            "z": 5,
            "elements": [
                "draconicevolution:infused_obsidian@0"
            ]
        },
        {
            "x": 13,
            "y": 0,
            "z": -9,
            "elements": [
                "gregtech:meta_block_compressed_7@14"
            ]
        },
        {
            "x": -2,
            "y": -7,
            "z": 22,
            "elements": [
                "avaritia:block_resource@2"
            ]
        },
        {
            "x": -1,
            "y": -7,
            "z": 22,
            "elements": [
                "avaritia:block_resource@0"
            ]
        },
        {
            "x": 12,
            "y": 0,
            "z": -9,
            "elements": [
                "avaritia:block_resource@0"
            ]
        },
        {
            "x": 0,
            "y": -7,
            "z": 22,
            "elements": [
                "draconicevolution:energy_storage_core@0"
            ]
        },
        {
            "x": 11,
            "y": 0,
            "z": -9,
            "elements": [
                "gregtech:meta_block_compressed_7@14"
            ]
        },
        {
            "x": 1,
            "y": -7,
            "z": 22,
            "elements": [
                "avaritia:block_resource@0"
            ]
        },
        {
            "x": 10,
            "y": 0,
            "z": -9,
            "elements": [
                "avaritia:block_resource@0"
            ]
        },
        {
            "x": 9,
            "y": 0,
            "z": -9,
            "elements": [
                "gregtech:meta_block_compressed_7@15"
            ]
        },
        {
            "x": 2,
            "y": -7,
            "z": 22,
            "elements": [
                "avaritia:block_resource@2"
            ]
        },
        {
            "x": -1,
            "y": -8,
            "z": 5,
            "elements": [
                "botania:storage@1"
            ]
        },
        {
            "x": 0,
            "y": -8,
            "z": 5,
            "elements": [
                "enderio:block_alloy_endergy@3"
            ]
        },
        {
            "x": 1,
            "y": -8,
            "z": 5,
            "elements": [
                "botania:storage@1"
            ]
        },
        {
            "x": -9,
            "y": 0,
            "z": -9,
            "elements": [
                "gregtech:meta_block_compressed_7@15"
            ]
        },
        {
            "x": 12,
            "y": 8,
            "z": 13,
            "elements": [
                "draconicevolution:infused_obsidian@0"
            ]
        },
        {
            "x": -10,
            "y": 0,
            "z": -9,
            "elements": [
                "avaritia:block_resource@0"
            ]
        },
        {
            "x": -11,
            "y": 0,
            "z": -9,
            "elements": [
                "gregtech:meta_block_compressed_7@14"
            ]
        },
        {
            "x": -12,
            "y": 0,
            "z": -9,
            "elements": [
                "avaritia:block_resource@0"
            ]
        },
        {
            "x": -13,
            "y": 0,
            "z": -9,
            "elements": [
                "gregtech:meta_block_compressed_7@14"
            ]
        },
        {
            "x": -14,
            "y": 0,
            "z": -9,
            "elements": [
                "avaritia:block_resource@0"
            ]
        },
        {
            "x": -15,
            "y": 0,
            "z": -9,
            "elements": [
                "gregtech:meta_block_compressed_7@15"
            ]
        },
        {
            "x": 14,
            "y": -1,
            "z": -9,
            "elements": [
                "botania:storage@1"
            ]
        },
        {
            "x": -19,
            "y": -7,
            "z": 5,
            "elements": [
                "avaritia:block_resource@2"
            ]
        },
        {
            "x": 13,
            "y": -1,
            "z": -9,
            "elements": [
                "gregtech:meta_block_compressed_26@14"
            ]
        },
        {
            "x": -2,
            "y": -6,
            "z": 22,
            "elements": [
                "gregtech:transparent_casing@1"
            ]
        },
        {
            "x": -1,
            "y": -6,
            "z": 22,
            "elements": [
                "enderio:block_alloy_endergy@3"
            ]
        },
        {
            "x": 12,
            "y": -1,
            "z": -9,
            "elements": [
                "avaritia:block_resource@0"
            ]
        },
        {
            "x": 0,
            "y": -6,
            "z": 22,
            "elements": [
                "avaritia:block_resource@1"
            ]
        },
        {
            "x": 11,
            "y": -1,
            "z": -9,
            "elements": [
                "gregtech:meta_block_compressed_26@14"
            ]
        },
        {
            "x": 1,
            "y": -6,
            "z": 22,
            "elements": [
                "enderio:block_alloy_endergy@3"
            ]
        },
        {
            "x": 10,
            "y": -1,
            "z": -9,
            "elements": [
                "botania:storage@1"
            ]
        },
        {
            "x": 2,
            "y": -6,
            "z": 22,
            "elements": [
                "gregtech:transparent_casing@1"
            ]
        },
        {
            "x": 19,
            "y": -8,
            "z": 5,
            "elements": [
                "draconicevolution:infused_obsidian@0"
            ]
        },
        {
            "x": -1,
            "y": -7,
            "z": 5,
            "elements": [
                "avaritia:block_resource@2"
            ]
        },
        {
            "x": 0,
            "y": -7,
            "z": 5,
            "elements": [
                "enderio:block_alloy_endergy@3"
            ]
        },
        {
            "x": 1,
            "y": -7,
            "z": 5,
            "elements": [
                "avaritia:block_resource@2"
            ]
        },
        {
            "x": 0,
            "y": -15,
            "z": 1,
            "elements": [
                "draconicevolution:infused_obsidian@0"
            ]
        },
        {
            "x": -10,
            "y": -1,
            "z": -9,
            "elements": [
                "botania:storage@1"
            ]
        },
        {
            "x": -11,
            "y": -1,
            "z": -9,
            "elements": [
                "gregtech:meta_block_compressed_26@14"
            ]
        },
        {
            "x": -12,
            "y": -1,
            "z": -9,
            "elements": [
                "avaritia:block_resource@0"
            ]
        },
        {
            "x": -13,
            "y": -1,
            "z": -9,
            "elements": [
                "gregtech:meta_block_compressed_26@14"
            ]
        },
        {
            "x": -14,
            "y": -1,
            "z": -9,
            "elements": [
                "botania:storage@1"
            ]
        },
        {
            "x": 14,
            "y": -2,
            "z": -9,
            "elements": [
                "gregtech:transparent_casing@1"
            ]
        },
        {
            "x": -19,
            "y": -6,
            "z": 5,
            "elements": [
                "gregtech:transparent_casing@1"
            ]
        },
        {
            "x": 13,
            "y": -2,
            "z": -9,
            "elements": [
                "enderio:block_alloy_endergy@3"
            ]
        },
        {
            "x": -2,
            "y": -5,
            "z": 22,
            "elements": [
                "gregtech:transparent_casing@1"
            ]
        },
        {
            "x": -1,
            "y": -5,
            "z": 22,
            "elements": [
                "enderio:block_alloy_endergy@3"
            ]
        },
        {
            "x": 12,
            "y": -2,
            "z": -9,
            "elements": [
                "avaritia:block_resource@0"
            ]
        },
        {
            "x": 0,
            "y": -5,
            "z": 22,
            "elements": [
                "avaritia:block_resource@1"
            ]
        },
        {
            "x": 11,
            "y": -2,
            "z": -9,
            "elements": [
                "enderio:block_alloy_endergy@3"
            ]
        },
        {
            "x": 1,
            "y": -5,
            "z": 22,
            "elements": [
                "enderio:block_alloy_endergy@3"
            ]
        },
        {
            "x": 10,
            "y": -2,
            "z": -9,
            "elements": [
                "gregtech:transparent_casing@1"
            ]
        },
        {
            "x": 2,
            "y": -5,
            "z": 22,
            "elements": [
                "gregtech:transparent_casing@1"
            ]
        },
        {
            "x": 19,
            "y": -7,
            "z": 5,
            "elements": [
                "avaritia:block_resource@2"
            ]
        },
        {
            "x": -2,
            "y": -6,
            "z": 5,
            "elements": [
                "avaritia:block_resource@2"
            ]
        },
        {
            "x": -1,
            "y": -6,
            "z": 5,
            "elements": [
                "avaritia:block_resource@2"
            ]
        },
        {
            "x": 0,
            "y": -6,
            "z": 5,
            "elements": [
                "enderio:block_alloy_endergy@3"
            ]
        },
        {
            "x": 1,
            "y": -6,
            "z": 5,
            "elements": [
                "avaritia:block_resource@2"
            ]
        },
        {
            "x": 2,
            "y": -6,
            "z": 5,
            "elements": [
                "avaritia:block_resource@2"
            ]
        },
        {
            "x": -1,
            "y": -14,
            "z": 1,
            "elements": [
                "draconicevolution:infused_obsidian@0"
            ]
        },
        {
            "x": 0,
            "y": -14,
            "z": 1,
            "elements": [
                "draconicevolution:infused_obsidian@0"
            ]
        },
        {
            "x": 1,
            "y": -14,
            "z": 1,
            "elements": [
                "draconicevolution:infused_obsidian@0"
            ]
        },
        {
            "x": -10,
            "y": -2,
            "z": -9,
            "elements": [
                "gregtech:transparent_casing@1"
            ]
        },
        {
            "x": -11,
            "y": -2,
            "z": -9,
            "elements": [
                "enderio:block_alloy_endergy@3"
            ]
        },
        {
            "x": -12,
            "y": -2,
            "z": -9,
            "elements": [
                "avaritia:block_resource@0"
            ]
        },
        {
            "x": -13,
            "y": -2,
            "z": -9,
            "elements": [
                "enderio:block_alloy_endergy@3"
            ]
        },
        {
            "x": -14,
            "y": -2,
            "z": -9,
            "elements": [
                "gregtech:transparent_casing@1"
            ]
        },
        {
            "x": 14,
            "y": -3,
            "z": -9,
            "elements": [
                "gregtech:transparent_casing@1"
            ]
        },
        {
            "x": -19,
            "y": -5,
            "z": 5,
            "elements": [
                "gregtech:transparent_casing@1"
            ]
        },
        {
            "x": 13,
            "y": -3,
            "z": -9,
            "elements": [
                "enderio:block_alloy_endergy@3"
            ]
        },
        {
            "x": -2,
            "y": -4,
            "z": 22,
            "elements": [
                "gregtech:transparent_casing@1"
            ]
        },
        {
            "x": -1,
            "y": -4,
            "z": 22,
            "elements": [
                "enderio:block_alloy_endergy@3"
            ]
        },
        {
            "x": 12,
            "y": -3,
            "z": -9,
            "elements": [
                "avaritia:block_resource@1"
            ]
        },
        {
            "x": 0,
            "y": -4,
            "z": 22,
            "elements": [
                "avaritia:block_resource@1"
            ]
        },
        {
            "x": 11,
            "y": -3,
            "z": -9,
            "elements": [
                "enderio:block_alloy_endergy@3"
            ]
        },
        {
            "x": 1,
            "y": -4,
            "z": 22,
            "elements": [
                "enderio:block_alloy_endergy@3"
            ]
        },
        {
            "x": 10,
            "y": -3,
            "z": -9,
            "elements": [
                "gregtech:transparent_casing@1"
            ]
        },
        {
            "x": 2,
            "y": -4,
            "z": 22,
            "elements": [
                "gregtech:transparent_casing@1"
            ]
        },
        {
            "x": 19,
            "y": -6,
            "z": 5,
            "elements": [
                "gregtech:transparent_casing@1"
            ]
        },
        {
            "x": -3,
            "y": -5,
            "z": 5,
            "elements": [
                "minecraft:bedrock@0"
            ]
        },
        {
            "x": -2,
            "y": -5,
            "z": 5,
            "elements": [
                "gregtech:fusion_casing@1"
            ]
        },
        {
            "x": 2,
            "y": -5,
            "z": 5,
            "elements": [
                "gregtech:fusion_casing@1"
            ]
        },
        {
            "x": -1,
            "y": -13,
            "z": 1,
            "elements": [
                "enderio:block_alloy_endergy@3"
            ]
        },
        {
            "x": 3,
            "y": -5,
            "z": 5,
            "elements": [
                "minecraft:bedrock@0"
            ]
        },
        {
            "x": 0,
            "y": -13,
            "z": 1,
            "elements": [
                "draconicevolution:infused_obsidian@0"
            ]
        },
        {
            "x": 1,
            "y": -13,
            "z": 1,
            "elements": [
                "enderio:block_alloy_endergy@3"
            ]
        },
        {
            "x": -10,
            "y": -3,
            "z": -9,
            "elements": [
                "gregtech:transparent_casing@1"
            ]
        },
        {
            "x": -11,
            "y": -3,
            "z": -9,
            "elements": [
                "enderio:block_alloy_endergy@3"
            ]
        },
        {
            "x": -12,
            "y": -3,
            "z": -9,
            "elements": [
                "avaritia:block_resource@1"
            ]
        },
        {
            "x": -13,
            "y": -3,
            "z": -9,
            "elements": [
                "enderio:block_alloy_endergy@3"
            ]
        },
        {
            "x": -14,
            "y": -3,
            "z": -9,
            "elements": [
                "gregtech:transparent_casing@1"
            ]
        },
        {
            "x": 14,
            "y": -4,
            "z": -9,
            "elements": [
                "gregtech:transparent_casing@1"
            ]
        },
        {
            "x": -19,
            "y": -4,
            "z": 5,
            "elements": [
                "gregtech:transparent_casing@1"
            ]
        },
        {
            "x": 13,
            "y": -4,
            "z": -9,
            "elements": [
                "enderio:block_alloy_endergy@3"
            ]
        },
        {
            "x": -2,
            "y": -3,
            "z": 22,
            "elements": [
                "gregtech:transparent_casing@1"
            ]
        },
        {
            "x": -1,
            "y": -3,
            "z": 22,
            "elements": [
                "enderio:block_alloy_endergy@3"
            ]
        },
        {
            "x": 12,
            "y": -4,
            "z": -9,
            "elements": [
                "avaritia:block_resource@1"
            ]
        },
        {
            "x": 0,
            "y": -3,
            "z": 22,
            "elements": [
                "avaritia:block_resource@1"
            ]
        },
        {
            "x": 11,
            "y": -4,
            "z": -9,
            "elements": [
                "enderio:block_alloy_endergy@3"
            ]
        },
        {
            "x": 1,
            "y": -3,
            "z": 22,
            "elements": [
                "enderio:block_alloy_endergy@3"
            ]
        },
        {
            "x": 10,
            "y": -4,
            "z": -9,
            "elements": [
                "gregtech:transparent_casing@1"
            ]
        },
        {
            "x": 2,
            "y": -3,
            "z": 22,
            "elements": [
                "gregtech:transparent_casing@1"
            ]
        },
        {
            "x": 19,
            "y": -5,
            "z": 5,
            "elements": [
                "gregtech:transparent_casing@1"
            ]
        },
        {
            "x": -3,
            "y": -4,
            "z": 5,
            "elements": [
                "contenttweaker:machine_coil_neutonium@0"
            ]
        },
        {
            "x": -2,
            "y": -4,
            "z": 5,
            "elements": [
                "gregtech:fusion_casing@1"
            ]
        },
        {
            "x": 2,
            "y": -4,
            "z": 5,
            "elements": [
                "gregtech:fusion_casing@1"
            ]
        },
        {
            "x": -1,
            "y": -12,
            "z": 1,
            "elements": [
                "avaritia:block_resource@2"
            ]
        },
        {
            "x": 3,
            "y": -4,
            "z": 5,
            "elements": [
                "contenttweaker:machine_coil_neutonium@0"
            ]
        },
        {
            "x": 0,
            "y": -12,
            "z": 1,
            "elements": [
                "enderio:block_alloy_endergy@3"
            ]
        },
        {
            "x": 1,
            "y": -12,
            "z": 1,
            "elements": [
                "avaritia:block_resource@2"
            ]
        },
        {
            "x": -10,
            "y": -4,
            "z": -9,
            "elements": [
                "gregtech:transparent_casing@1"
            ]
        },
        {
            "x": -11,
            "y": -4,
            "z": -9,
            "elements": [
                "enderio:block_alloy_endergy@3"
            ]
        },
        {
            "x": -12,
            "y": -4,
            "z": -9,
            "elements": [
                "avaritia:block_resource@1"
            ]
        },
        {
            "x": -13,
            "y": -4,
            "z": -9,
            "elements": [
                "enderio:block_alloy_endergy@3"
            ]
        },
        {
            "x": -14,
            "y": -4,
            "z": -9,
            "elements": [
                "gregtech:transparent_casing@1"
            ]
        },
        {
            "x": 14,
            "y": -5,
            "z": -9,
            "elements": [
                "gregtech:transparent_casing@1"
            ]
        },
        {
            "x": -19,
            "y": -3,
            "z": 5,
            "elements": [
                "gregtech:transparent_casing@1"
            ]
        },
        {
            "x": 13,
            "y": -5,
            "z": -9,
            "elements": [
                "enderio:block_alloy_endergy@3"
            ]
        },
        {
            "x": -2,
            "y": -2,
            "z": 22,
            "elements": [
                "gregtech:transparent_casing@1"
            ]
        },
        {
            "x": -1,
            "y": -2,
            "z": 22,
            "elements": [
                "enderio:block_alloy_endergy@3"
            ]
        },
        {
            "x": 12,
            "y": -5,
            "z": -9,
            "elements": [
                "avaritia:block_resource@1"
            ]
        },
        {
            "x": 0,
            "y": -2,
            "z": 22,
            "elements": [
                "avaritia:block_resource@0"
            ]
        },
        {
            "x": 11,
            "y": -5,
            "z": -9,
            "elements": [
                "enderio:block_alloy_endergy@3"
            ]
        },
        {
            "x": 1,
            "y": -2,
            "z": 22,
            "elements": [
                "enderio:block_alloy_endergy@3"
            ]
        },
        {
            "x": 10,
            "y": -5,
            "z": -9,
            "elements": [
                "gregtech:transparent_casing@1"
            ]
        },
        {
            "x": 2,
            "y": -2,
            "z": 22,
            "elements": [
                "gregtech:transparent_casing@1"
            ]
        },
        {
            "x": 19,
            "y": -4,
            "z": 5,
            "elements": [
                "gregtech:transparent_casing@1"
            ]
        },
        {
            "x": -3,
            "y": -3,
            "z": 5,
            "elements": [
                "gregtech:wire_coil@7"
            ]
        },
        {
            "x": -2,
            "y": -3,
            "z": 5,
            "elements": [
                "gregtech:fusion_casing@1"
            ]
        },
        {
            "x": 2,
            "y": -3,
            "z": 5,
            "elements": [
                "gregtech:fusion_casing@1"
            ]
        },
        {
            "x": -1,
            "y": -11,
            "z": 1,
            "elements": [
                "avaritia:block_resource@2"
            ]
        },
        {
            "x": 3,
            "y": -3,
            "z": 5,
            "elements": [
                "gregtech:wire_coil@7"
            ]
        },
        {
            "x": 0,
            "y": -11,
            "z": 1,
            "elements": [
                "enderio:block_alloy_endergy@3"
            ]
        },
        {
            "x": 1,
            "y": -11,
            "z": 1,
            "elements": [
                "avaritia:block_resource@2"
            ]
        },
        {
            "x": -10,
            "y": -5,
            "z": -9,
            "elements": [
                "gregtech:transparent_casing@1"
            ]
        },
        {
            "x": -11,
            "y": -5,
            "z": -9,
            "elements": [
                "enderio:block_alloy_endergy@3"
            ]
        },
        {
            "x": -12,
            "y": -5,
            "z": -9,
            "elements": [
                "avaritia:block_resource@1"
            ]
        },
        {
            "x": -13,
            "y": -5,
            "z": -9,
            "elements": [
                "enderio:block_alloy_endergy@3"
            ]
        },
        {
            "x": -14,
            "y": -5,
            "z": -9,
            "elements": [
                "gregtech:transparent_casing@1"
            ]
        },
        {
            "x": 14,
            "y": -6,
            "z": -9,
            "elements": [
                "gregtech:transparent_casing@1"
            ]
        },
        {
            "x": -19,
            "y": -2,
            "z": 5,
            "elements": [
                "gregtech:transparent_casing@1"
            ]
        },
        {
            "x": 13,
            "y": -6,
            "z": -9,
            "elements": [
                "enderio:block_alloy_endergy@3"
            ]
        },
        {
            "x": -2,
            "y": -1,
            "z": 22,
            "elements": [
                "botania:storage@1"
            ]
        },
        {
            "x": -1,
            "y": -1,
            "z": 22,
            "elements": [
                "gregtech:meta_block_compressed_26@14"
            ]
        },
        {
            "x": 12,
            "y": -6,
            "z": -9,
            "elements": [
                "avaritia:block_resource@1"
            ]
        },
        {
            "x": 0,
            "y": -1,
            "z": 22,
            "elements": [
                "avaritia:block_resource@0"
            ]
        },
        {
            "x": 11,
            "y": -6,
            "z": -9,
            "elements": [
                "enderio:block_alloy_endergy@3"
            ]
        },
        {
            "x": 1,
            "y": -1,
            "z": 22,
            "elements": [
                "gregtech:meta_block_compressed_26@14"
            ]
        },
        {
            "x": 10,
            "y": -6,
            "z": -9,
            "elements": [
                "gregtech:transparent_casing@1"
            ]
        },
        {
            "x": 2,
            "y": -1,
            "z": 22,
            "elements": [
                "botania:storage@1"
            ]
        },
        {
            "x": 19,
            "y": -3,
            "z": 5,
            "elements": [
                "gregtech:transparent_casing@1"
            ]
        },
        {
            "x": -3,
            "y": -2,
            "z": 5,
            "elements": [
                "gregtech:wire_coil@7"
            ]
        },
        {
            "x": -2,
            "y": -2,
            "z": 5,
            "elements": [
                "gregtech:fusion_casing@1"
            ]
        },
        {
            "x": 2,
            "y": -2,
            "z": 5,
            "elements": [
                "gregtech:fusion_casing@1"
            ]
        },
        {
            "x": -1,
            "y": -10,
            "z": 1,
            "elements": [
                "botania:storage@1"
            ]
        },
        {
            "x": 3,
            "y": -2,
            "z": 5,
            "elements": [
                "gregtech:wire_coil@7"
            ]
        },
        {
            "x": 0,
            "y": -10,
            "z": 1,
            "elements": [
                "enderio:block_alloy_endergy@3"
            ]
        },
        {
            "x": 1,
            "y": -10,
            "z": 1,
            "elements": [
                "botania:storage@1"
            ]
        },
        {
            "x": -10,
            "y": -6,
            "z": -9,
            "elements": [
                "gregtech:transparent_casing@1"
            ]
        },
        {
            "x": -11,
            "y": -6,
            "z": -9,
            "elements": [
                "enderio:block_alloy_endergy@3"
            ]
        },
        {
            "x": -12,
            "y": -6,
            "z": -9,
            "elements": [
                "avaritia:block_resource@1"
            ]
        },
        {
            "x": -13,
            "y": -6,
            "z": -9,
            "elements": [
                "enderio:block_alloy_endergy@3"
            ]
        },
        {
            "x": -14,
            "y": -6,
            "z": -9,
            "elements": [
                "gregtech:transparent_casing@1"
            ]
        },
        {
            "x": 14,
            "y": -7,
            "z": -9,
            "elements": [
                "avaritia:block_resource@2"
            ]
        },
        {
            "x": -19,
            "y": -1,
            "z": 5,
            "elements": [
                "botania:storage@1"
            ]
        },
        {
            "x": -3,
            "y": 0,
            "z": 22,
            "elements": [
                "gregtech:meta_block_compressed_7@15"
            ]
        },
        {
            "x": -2,
            "y": 0,
            "z": 22,
            "elements": [
                "avaritia:block_resource@0"
            ]
        },
        {
            "x": 13,
            "y": -7,
            "z": -9,
            "elements": [
                "avaritia:block_resource@0"
            ]
        },
        {
            "x": -1,
            "y": 0,
            "z": 22,
            "elements": [
                "gregtech:meta_block_compressed_7@14"
            ]
        },
        {
            "x": 12,
            "y": -7,
            "z": -9,
            "elements": [
                "draconicevolution:energy_storage_core@0"
            ]
        },
        {
            "x": 0,
            "y": 0,
            "z": 22,
            "elements": [
                "avaritia:block_resource@0"
            ]
        },
        {
            "x": 11,
            "y": -7,
            "z": -9,
            "elements": [
                "avaritia:block_resource@0"
            ]
        },
        {
            "x": 1,
            "y": 0,
            "z": 22,
            "elements": [
                "gregtech:meta_block_compressed_7@14"
            ]
        },
        {
            "x": 10,
            "y": -7,
            "z": -9,
            "elements": [
                "avaritia:block_resource@2"
            ]
        },
        {
            "x": 2,
            "y": 0,
            "z": 22,
            "elements": [
                "avaritia:block_resource@0"
            ]
        },
        {
            "x": 0,
            "y": 8,
            "z": -18,
            "elements": [
                "draconicevolution:infused_obsidian@0"
            ]
        },
        {
            "x": 3,
            "y": 0,
            "z": 22,
            "elements": [
                "gregtech:meta_block_compressed_7@15"
            ]
        },
        {
            "x": 19,
            "y": -2,
            "z": 5,
            "elements": [
                "gregtech:transparent_casing@1"
            ]
        },
        {
            "x": -3,
            "y": -1,
            "z": 5,
            "elements": [
                "deepmoblearning:infused_ingot_block@0"
            ]
        },
        {
            "x": -2,
            "y": -1,
            "z": 5,
            "elements": [
                "gregtech:fusion_casing@1"
            ]
        },
        {
            "x": 2,
            "y": -1,
            "z": 5,
            "elements": [
                "gregtech:fusion_casing@1"
            ]
        },
        {
            "x": -1,
            "y": -9,
            "z": 1,
            "elements": [
                "botania:storage@1"
            ]
        },
        {
            "x": 3,
            "y": -1,
            "z": 5,
            "elements": [
                "deepmoblearning:infused_ingot_block@0"
            ]
        },
        {
            "x": 0,
            "y": -9,
            "z": 1,
            "elements": [
                "enderio:block_alloy_endergy@3"
            ]
        },
        {
            "x": 1,
            "y": -9,
            "z": 1,
            "elements": [
                "botania:storage@1"
            ]
        },
        {
            "x": -10,
            "y": -7,
            "z": -9,
            "elements": [
                "avaritia:block_resource@2"
            ]
        },
        {
            "x": -11,
            "y": -7,
            "z": -9,
            "elements": [
                "avaritia:block_resource@0"
            ]
        },
        {
            "x": -12,
            "y": -7,
            "z": -9,
            "elements": [
                "draconicevolution:energy_storage_core@0"
            ]
        },
        {
            "x": -13,
            "y": -7,
            "z": -9,
            "elements": [
                "avaritia:block_resource@0"
            ]
        },
        {
            "x": -14,
            "y": -7,
            "z": -9,
            "elements": [
                "avaritia:block_resource@2"
            ]
        },
        {
            "x": -20,
            "y": 0,
            "z": 5,
            "elements": [
                "deepmoblearning:infused_ingot_block@0"
            ]
        },
        {
            "x": 14,
            "y": -8,
            "z": -9,
            "elements": [
                "draconicevolution:infused_obsidian@0"
            ]
        },
        {
            "x": -19,
            "y": 0,
            "z": 5,
            "elements": [
                "avaritia:block_resource@0"
            ]
        },
        {
            "x": -18,
            "y": 0,
            "z": 5,
            "elements": [
                "deepmoblearning:infused_ingot_block@0"
            ]
        },
        {
            "x": -2,
            "y": 1,
            "z": 22,
            "elements": [
                "botania:storage@1"
            ]
        },
        {
            "x": 13,
            "y": -8,
            "z": -9,
            "elements": [
                "draconicevolution:infused_obsidian@0"
            ]
        },
        {
            "x": -1,
            "y": 1,
            "z": 22,
            "elements": [
                "gregtech:meta_block_compressed_26@14"
            ]
        },
        {
            "x": 12,
            "y": -8,
            "z": -9,
            "elements": [
                "avaritia:block_resource@0"
            ]
        },
        {
            "x": 0,
            "y": 1,
            "z": 22,
            "elements": [
                "avaritia:block_resource@0"
            ]
        },
        {
            "x": 11,
            "y": -8,
            "z": -9,
            "elements": [
                "draconicevolution:infused_obsidian@0"
            ]
        },
        {
            "x": 1,
            "y": 1,
            "z": 22,
            "elements": [
                "gregtech:meta_block_compressed_26@14"
            ]
        },
        {
            "x": 10,
            "y": -8,
            "z": -9,
            "elements": [
                "draconicevolution:infused_obsidian@0"
            ]
        },
        {
            "x": -19,
            "y": -8,
            "z": 1,
            "elements": [
                "draconicevolution:infused_obsidian@0"
            ]
        },
        {
            "x": 2,
            "y": 1,
            "z": 22,
            "elements": [
                "botania:storage@1"
            ]
        },
        {
            "x": 0,
            "y": 7,
            "z": -18,
            "elements": [
                "avaritia:block_resource@2"
            ]
        },
        {
            "x": 19,
            "y": -1,
            "z": 5,
            "elements": [
                "botania:storage@1"
            ]
        },
        {
            "x": -3,
            "y": 0,
            "z": 5,
            "elements": [
                "deepmoblearning:infused_ingot_block@0"
            ]
        },
        {
            "x": -2,
            "y": 0,
            "z": 5,
            "elements": [
                "gregtech:fusion_casing@1"
            ]
        },
        {
            "x": 2,
            "y": 0,
            "z": 5,
            "elements": [
                "gregtech:fusion_casing@1"
            ]
        },
        {
            "x": -1,
            "y": -8,
            "z": 1,
            "elements": [
                "botania:storage@1"
            ]
        },
        {
            "x": 3,
            "y": 0,
            "z": 5,
            "elements": [
                "deepmoblearning:infused_ingot_block@0"
            ]
        },
        {
            "x": 0,
            "y": -8,
            "z": 1,
            "elements": [
                "enderio:block_alloy_endergy@3"
            ]
        },
        {
            "x": 1,
            "y": -8,
            "z": 1,
            "elements": [
                "botania:storage@1"
            ]
        },
        {
            "x": -10,
            "y": -8,
            "z": -9,
            "elements": [
                "draconicevolution:infused_obsidian@0"
            ]
        },
        {
            "x": -11,
            "y": -8,
            "z": -9,
            "elements": [
                "draconicevolution:infused_obsidian@0"
            ]
        },
        {
            "x": -12,
            "y": -8,
            "z": -9,
            "elements": [
                "avaritia:block_resource@0"
            ]
        },
        {
            "x": -13,
            "y": -8,
            "z": -9,
            "elements": [
                "draconicevolution:infused_obsidian@0"
            ]
        },
        {
            "x": -14,
            "y": -8,
            "z": -9,
            "elements": [
                "draconicevolution:infused_obsidian@0"
            ]
        },
        {
            "x": -19,
            "y": 1,
            "z": 5,
            "elements": [
                "botania:storage@1"
            ]
        },
        {
            "x": -2,
            "y": 2,
            "z": 22,
            "elements": [
                "gregtech:transparent_casing@1"
            ]
        },
        {
            "x": 13,
            "y": -9,
            "z": -9,
            "elements": [
                "draconicevolution:infused_obsidian@0"
            ]
        },
        {
            "x": -1,
            "y": 2,
            "z": 22,
            "elements": [
                "enderio:block_alloy_endergy@3"
            ]
        },
        {
            "x": 12,
            "y": -9,
            "z": -9,
            "elements": [
                "minecraft:bedrock@0"
            ]
        },
        {
            "x": 0,
            "y": 2,
            "z": 22,
            "elements": [
                "avaritia:block_resource@0"
            ]
        },
        {
            "x": 11,
            "y": -9,
            "z": -9,
            "elements": [
                "draconicevolution:infused_obsidian@0"
            ]
        },
        {
            "x": 1,
            "y": 2,
            "z": 22,
            "elements": [
                "enderio:block_alloy_endergy@3"
            ]
        },
        {
            "x": -19,
            "y": -7,
            "z": 1,
            "elements": [
                "avaritia:block_resource@2"
            ]
        },
        {
            "x": 2,
            "y": 2,
            "z": 22,
            "elements": [
                "gregtech:transparent_casing@1"
            ]
        },
        {
            "x": 0,
            "y": 6,
            "z": -18,
            "elements": [
                "gregtech:transparent_casing@1"
            ]
        },
        {
            "x": 18,
            "y": 0,
            "z": 5,
            "elements": [
                "deepmoblearning:infused_ingot_block@0"
            ]
        },
        {
            "x": 19,
            "y": 0,
            "z": 5,
            "elements": [
                "avaritia:block_resource@0"
            ]
        },
        {
            "x": 20,
            "y": 0,
            "z": 5,
            "elements": [
                "deepmoblearning:infused_ingot_block@0"
            ]
        },
        {
            "x": 19,
            "y": -8,
            "z": 1,
            "elements": [
                "draconicevolution:infused_obsidian@0"
            ]
        },
        {
            "x": -3,
            "y": 1,
            "z": 5,
            "elements": [
                "deepmoblearning:infused_ingot_block@0"
            ]
        },
        {
            "x": -2,
            "y": 1,
            "z": 5,
            "elements": [
                "gregtech:fusion_casing@1"
            ]
        },
        {
            "x": 2,
            "y": 1,
            "z": 5,
            "elements": [
                "gregtech:fusion_casing@1"
            ]
        },
        {
            "x": -1,
            "y": -7,
            "z": 1,
            "elements": [
                "avaritia:block_resource@2"
            ]
        },
        {
            "x": 3,
            "y": 1,
            "z": 5,
            "elements": [
                "deepmoblearning:infused_ingot_block@0"
            ]
        },
        {
            "x": 0,
            "y": -7,
            "z": 1,
            "elements": [
                "enderio:block_alloy_endergy@3"
            ]
        },
        {
            "x": 1,
            "y": -7,
            "z": 1,
            "elements": [
                "avaritia:block_resource@2"
            ]
        },
        {
            "x": -11,
            "y": -9,
            "z": -9,
            "elements": [
                "draconicevolution:infused_obsidian@0"
            ]
        },
        {
            "x": -12,
            "y": -9,
            "z": -9,
            "elements": [
                "minecraft:bedrock@0"
            ]
        },
        {
            "x": -13,
            "y": -9,
            "z": -9,
            "elements": [
                "draconicevolution:infused_obsidian@0"
            ]
        },
        {
            "x": -19,
            "y": 2,
            "z": 5,
            "elements": [
                "gregtech:transparent_casing@1"
            ]
        },
        {
            "x": -2,
            "y": 3,
            "z": 22,
            "elements": [
                "gregtech:transparent_casing@1"
            ]
        },
        {
            "x": -1,
            "y": 3,
            "z": 22,
            "elements": [
                "enderio:block_alloy_endergy@3"
            ]
        },
        {
            "x": 12,
            "y": -10,
            "z": -9,
            "elements": [
                "minecraft:bedrock@0"
            ]
        },
        {
            "x": 0,
            "y": 3,
            "z": 22,
            "elements": [
                "avaritia:block_resource@1"
            ]
        },
        {
            "x": 1,
            "y": 3,
            "z": 22,
            "elements": [
                "enderio:block_alloy_endergy@3"
            ]
        },
        {
            "x": -19,
            "y": -6,
            "z": 1,
            "elements": [
                "gregtech:transparent_casing@1"
            ]
        },
        {
            "x": 2,
            "y": 3,
            "z": 22,
            "elements": [
                "gregtech:transparent_casing@1"
            ]
        },
        {
            "x": 0,
            "y": 5,
            "z": -18,
            "elements": [
                "gregtech:transparent_casing@1"
            ]
        },
        {
            "x": 19,
            "y": 1,
            "z": 5,
            "elements": [
                "botania:storage@1"
            ]
        },
        {
            "x": 19,
            "y": -7,
            "z": 1,
            "elements": [
                "avaritia:block_resource@2"
            ]
        },
        {
            "x": -3,
            "y": 2,
            "z": 5,
            "elements": [
                "gregtech:wire_coil@7"
            ]
        },
        {
            "x": -2,
            "y": 2,
            "z": 5,
            "elements": [
                "gregtech:fusion_casing@1"
            ]
        },
        {
            "x": 2,
            "y": 2,
            "z": 5,
            "elements": [
                "gregtech:fusion_casing@1"
            ]
        },
        {
            "x": -2,
            "y": -6,
            "z": 1,
            "elements": [
                "avaritia:block_resource@2"
            ]
        },
        {
            "x": -1,
            "y": -6,
            "z": 1,
            "elements": [
                "avaritia:block_resource@2"
            ]
        },
        {
            "x": 3,
            "y": 2,
            "z": 5,
            "elements": [
                "gregtech:wire_coil@7"
            ]
        },
        {
            "x": 0,
            "y": -6,
            "z": 1,
            "elements": [
                "enderio:block_alloy_endergy@3"
            ]
        },
        {
            "x": 1,
            "y": -6,
            "z": 1,
            "elements": [
