{
    "registryname": "Particle_Accelerator",
    "localizedname": "Particle Accelerator",
     "color": "ff0400",
    "parts": [
        {
            "x": -2,
            "y": 0,
            "z": 0,
            "elements": [
                "modularmachinery:blockfluidoutputhatch"
            ]
        },
        {
            "x": 2,
            "y": 0,
            "z": 0,
            "elements": [
                "modularmachinery:blockfluidoutputhatch"
            ]
        },
        {
            "x": -3,
            "y": 0,
            "z": 0,
            "elements": [
                "modularmachinery:blockfluidoutputhatch"
            ]
        },
        {
            "x": 3,
            "y": 0,
            "z": 0,
            "elements": [
                "modularmachinery:blockfluidoutputhatch"
            ]
        },
        {
            "x": -4,
            "y": 0,
            "z": 0,
            "elements": [
                "modularmachinery:blockfluidoutputhatch"
            ]
        },
        {
            "x": 4,
            "y": 0,
            "z": 0,
            "elements": [
                "modularmachinery:blockfluidoutputhatch"
            ]
        },
        {
            "x": -5,
            "y": 0,
            "z": 0,
            "elements": [
                "gregtech:fusion_casing@4"
            ]
        },
        {
            "x": 5,
            "y": 0,
            "z": 0,
            "elements": [
                "gregtech:fusion_casing@4"
            ]
        },
        {
            "x": -24,
            "y": -1,
            "z": -17,
            "elements": [
                "gregtech:fusion_casing@4"
            ]
        },
        {
            "x": -10,
            "y": 0,
            "z": 0,
            "elements": [
                "gregtech:wire_coil@7"
            ]
        },
        {
            "x": -27,
            "y": -1,
            "z": -17,
            "elements": [
                "gregtech:wire_coil@7"
            ]
        },
        {
            "x": 10,
            "y": 0,
            "z": 0,
            "elements": [
                "gregtech:wire_coil@7"
            ]
        },
        {
            "x": -11,
            "y": 0,
            "z": 0,
            "elements": [
                "gregtech:wire_coil@7"
            ]
        },
        {
            "x": 19,
            "y": -1,
            "z": 0,
            "elements": [
                "modularmachinery:blockenergyinputhatch"
            ]
        },
        {
            "x": -28,
            "y": -1,
            "z": -17,
            "elements": [
                "gregtech:boiler_casing@3"
            ]
        },
        {
            "x": 11,
            "y": 0,
            "z": 0,
            "elements": [
                "gregtech:wire_coil@7"
            ]
        },
        {
            "x": -12,
            "y": 0,
            "z": 0,
            "elements": [
                "gregtech:boiler_casing@3"
            ]
        },
        {
            "x": 18,
            "y": -1,
            "z": 0,
            "elements": [
                "modularmachinery:blockenergyinputhatch"
            ]
        },
        {
            "x": -19,
            "y": 1,
            "z": 0,
            "elements": [
                "modularmachinery:blockenergyinputhatch"
            ]
        },
        {
            "x": -29,
            "y": -1,
            "z": -17,
            "elements": [
                "gregtech:wire_coil@7"
            ]
        },
        {
            "x": 12,
            "y": 0,
            "z": 0,
            "elements": [
                "gregtech:boiler_casing@3"
            ]
        },
        {
            "x": -13,
            "y": 0,
            "z": 0,
            "elements": [
                "gregtech:boiler_casing@3"
            ]
        },
        {
            "x": -18,
            "y": 1,
            "z": 0,
            "elements": [
                "modularmachinery:blockenergyinputhatch"
            ]
        },
        {
            "x": 13,
            "y": 0,
            "z": 0,
            "elements": [
                "gregtech:boiler_casing@3"
            ]
        },
        {
            "x": -14,
            "y": 0,
            "z": 0,
            "elements": [
                "gregtech:boiler_casing@3"
            ]
        },
        {
            "x": -31,
            "y": -1,
            "z": -17,
            "elements": [
                "gregtech:fusion_casing@4"
            ]
        },
        {
            "x": 14,
            "y": 0,
            "z": 0,
            "elements": [
                "gregtech:boiler_casing@3"
            ]
        },
        {
            "x": -15,
            "y": 0,
            "z": 0,
            "elements": [
                "gregtech:wire_coil@7"
            ]
        },
        {
            "x": 15,
            "y": -1,
            "z": 0,
            "elements": [
                "gregtech:wire_coil@7"
            ]
        },
        {
            "x": 15,
            "y": 0,
            "z": 0,
            "elements": [
                "gregtech:wire_coil@7"
            ]
        },
        {
            "x": 29,
            "y": -3,
            "z": -17,
            "elements": [
                "gregtech:fusion_casing@4"
            ]
        },
        {
            "x": 14,
            "y": -1,
            "z": 0,
            "elements": [
                "gregtech:boiler_casing@3"
            ]
        },
        {
            "x": -15,
            "y": 1,
            "z": 0,
            "elements": [
                "gregtech:wire_coil@7"
            ]
        },
        {
            "x": -18,
            "y": 0,
            "z": 0,
            "elements": [
                "modularmachinery:blockenergyinputhatch"
            ]
        },
        {
            "x": 28,
            "y": -3,
            "z": -17,
            "elements": [
                "gregtech:fusion_casing@4"
            ]
        },
        {
            "x": 13,
            "y": -1,
            "z": 0,
            "elements": [
                "gregtech:boiler_casing@3"
            ]
        },
        {
            "x": -14,
            "y": 1,
            "z": 0,
            "elements": [
                "gregtech:boiler_casing@3"
            ]
        },
        {
            "x": 18,
            "y": 0,
            "z": 0,
            "elements": [
                "modularmachinery:blockenergyinputhatch"
            ]
        },
        {
            "x": 27,
            "y": -3,
            "z": -17,
            "elements": [
                "gregtech:fusion_casing@4"
            ]
        },
        {
            "x": -19,
            "y": 0,
            "z": 0,
            "elements": [
                "modularmachinery:blockenergyinputhatch"
            ]
        },
        {
            "x": 12,
            "y": -1,
            "z": 0,
            "elements": [
                "gregtech:boiler_casing@3"
            ]
        },
        {
            "x": -13,
            "y": 1,
            "z": 0,
            "elements": [
                "gregtech:boiler_casing@3"
            ]
        },
        {
            "x": 19,
            "y": 0,
            "z": 0,
            "elements": [
                "modularmachinery:blockenergyinputhatch"
            ]
        },
        {
            "x": 11,
            "y": -1,
            "z": 0,
            "elements": [
                "gregtech:wire_coil@7"
            ]
        },
        {
            "x": -12,
            "y": 1,
            "z": 0,
            "elements": [
                "gregtech:boiler_casing@3"
            ]
        },
        {
            "x": 10,
            "y": -1,
            "z": 0,
            "elements": [
                "gregtech:wire_coil@7"
            ]
        },
        {
            "x": -11,
            "y": 1,
            "z": 0,
            "elements": [
                "gregtech:wire_coil@7"
            ]
        },
        {
            "x": -10,
            "y": 1,
            "z": 0,
            "elements": [
                "gregtech:wire_coil@7"
            ]
        },
        {
            "x": -27,
            "y": -3,
            "z": -34,
            "elements": [
                "gregtech:fusion_casing@4"
            ]
        },
        {
            "x": 5,
            "y": -1,
            "z": 0,
            "elements": [
                "gregtech:fusion_casing@4"
            ]
        },
        {
            "x": -28,
            "y": -3,
            "z": -34,
            "elements": [
                "gregtech:fusion_casing@4"
            ]
        },
        {
            "x": 4,
            "y": -1,
            "z": 0,
            "elements": [
                "gregtech:fusion_casing@4"
            ]
        },
        {
            "x": -5,
            "y": 1,
            "z": 0,
            "elements": [
                "gregtech:fusion_casing@4"
            ]
        },
        {
            "x": 3,
            "y": -1,
            "z": 0,
            "elements": [
                "gregtech:fusion_casing@4"
            ]
        },
        {
            "x": -29,
            "y": -3,
            "z": -34,
            "elements": [
                "gregtech:fusion_casing@4"
            ]
        },
        {
            "x": -4,
            "y": 1,
            "z": 0,
            "elements": [
                "gregtech:fusion_casing@4"
            ]
        },
        {
            "x": 2,
            "y": -1,
            "z": 0,
            "elements": [
                "gregtech:fusion_casing@4"
            ]
        },
        {
            "x": -3,
            "y": 1,
            "z": 0,
            "elements": [
                "gregtech:fusion_casing@4"
            ]
        },
        {
            "x": 1,
            "y": -1,
            "z": 0,
            "elements": [
                "gcym:large_multiblock_casing@11"
            ]
        },
        {
            "x": -2,
            "y": 1,
            "z": 0,
            "elements": [
                "gregtech:fusion_casing@4"
            ]
        },
        {
            "x": 0,
            "y": -1,
            "z": 0,
            "elements": [
                "gregtech:fusion_casing@4"
            ]
        },
        {
            "x": -1,
            "y": 1,
            "z": 0,
            "elements": [
                "gcym:large_multiblock_casing@11"
            ]
        },
        {
            "x": 0,
            "y": 1,
            "z": 0,
            "elements": [
                "gregtech:fusion_casing@4"
            ]
        },
        {
            "x": -1,
            "y": -1,
            "z": 0,
            "elements": [
                "gcym:large_multiblock_casing@11"
            ]
        },
        {
            "x": 1,
            "y": 1,
            "z": 0,
            "elements": [
                "gcym:large_multiblock_casing@11"
            ]
        },
        {
            "x": -2,
            "y": -1,
            "z": 0,
            "elements": [
                "gregtech:fusion_casing@4"
            ]
        },
        {
            "x": 2,
            "y": 1,
            "z": 0,
            "elements": [
                "gregtech:fusion_casing@4"
            ]
        },
        {
            "x": -3,
            "y": -1,
            "z": 0,
            "elements": [
                "gregtech:fusion_casing@4"
            ]
        },
        {
            "x": 3,
            "y": 1,
            "z": 0,
            "elements": [
                "gregtech:fusion_casing@4"
            ]
        },
        {
            "x": -4,
            "y": -1,
            "z": 0,
            "elements": [
                "gregtech:fusion_casing@4"
            ]
        },
        {
            "x": 4,
            "y": 1,
            "z": 0,
            "elements": [
                "gregtech:fusion_casing@4"
            ]
        },
        {
            "x": -5,
            "y": -1,
            "z": 0,
            "elements": [
                "gregtech:fusion_casing@4"
            ]
        },
        {
            "x": 5,
            "y": 1,
            "z": 0,
            "elements": [
                "gregtech:fusion_casing@4"
            ]
        },
        {
            "x": -25,
            "y": -2,
            "z": -17,
            "elements": [
                "gregtech:fusion_casing@4"
            ]
        },
        {
            "x": -26,
            "y": -2,
            "z": -17,
            "elements": [
                "gregtech:fusion_casing@4"
            ]
        },
        {
            "x": -10,
            "y": -1,
            "z": 0,
            "elements": [
                "gregtech:wire_coil@7"
            ]
        },
        {
            "x": 10,
            "y": 1,
            "z": 0,
            "elements": [
                "gregtech:wire_coil@7"
            ]
        },
        {
            "x": -11,
            "y": -1,
            "z": 0,
            "elements": [
                "gregtech:wire_coil@7"
            ]
        },
        {
            "x": -28,
            "y": -2,
            "z": -17,
            "elements": [
                "gregtech:fusion_casing@1"
            ]
        },
        {
            "x": 11,
            "y": 1,
            "z": 0,
            "elements": [
                "gregtech:wire_coil@7"
            ]
        },
        {
            "x": -12,
            "y": -1,
            "z": 0,
            "elements": [
                "gregtech:boiler_casing@3"
            ]
        },
        {
            "x": 12,
            "y": 1,
            "z": 0,
            "elements": [
                "gregtech:boiler_casing@3"
            ]
        },
        {
            "x": -13,
            "y": -1,
            "z": 0,
            "elements": [
                "gregtech:boiler_casing@3"
            ]
        },
        {
            "x": -30,
            "y": -2,
            "z": -17,
            "elements": [
                "gregtech:fusion_casing@4"
            ]
        },
        {
            "x": 13,
            "y": 1,
            "z": 0,
            "elements": [
                "gregtech:boiler_casing@3"
            ]
        },
        {
            "x": -14,
            "y": -1,
            "z": 0,
            "elements": [
                "gregtech:boiler_casing@3"
            ]
        },
        {
            "x": 17,
            "y": -2,
            "z": 0,
            "elements": [
                "gregtech:fusion_casing@4"
            ]
        },
        {
            "x": 14,
            "y": 1,
            "z": 0,
            "elements": [
                "gregtech:boiler_casing@3"
            ]
        },
        {
            "x": -15,
            "y": -1,
            "z": 0,
            "elements": [
                "gregtech:wire_coil@7"
            ]
        },
        {
            "x": 16,
            "y": -2,
            "z": 0,
            "elements": [
                "gregtech:fusion_casing@4"
            ]
        },
        {
            "x": -17,
            "y": 2,
            "z": 0,
            "elements": [
                "gregtech:fusion_casing@4"
            ]
        },
        {
            "x": 15,
            "y": 1,
            "z": 0,
            "elements": [
                "gregtech:wire_coil@7"
            ]
        },
        {
            "x": -16,
            "y": 2,
            "z": 0,
            "elements": [
                "gregtech:fusion_casing@4"
            ]
        },
        {
            "x": 14,
            "y": -2,
            "z": 0,
            "elements": [
                "gregtech:fusion_casing@1"
            ]
        },
        {
            "x": -18,
            "y": -1,
            "z": 0,
            "elements": [
                "modularmachinery:blockenergyinputhatch"
            ]
        },
        {
            "x": 13,
            "y": -2,
            "z": 0,
            "elements": [
                "gregtech:fusion_casing@1"
            ]
        },
        {
            "x": -14,
            "y": 2,
            "z": 0,
            "elements": [
                "gregtech:fusion_casing@1"
            ]
        },
        {
            "x": 18,
            "y": 1,
            "z": 0,
            "elements": [
                "modularmachinery:blockenergyinputhatch"
            ]
        },
        {
            "x": -19,
            "y": -1,
            "z": 0,
            "elements": [
                "modularmachinery:blockenergyinputhatch"
            ]
        },
        {
            "x": 12,
            "y": -2,
            "z": 0,
            "elements": [
                "gregtech:fusion_casing@1"
            ]
        },
        {
            "x": -13,
            "y": 2,
            "z": 0,
            "elements": [
                "gregtech:fusion_casing@1"
            ]
        },
        {
            "x": 19,
            "y": 1,
            "z": 0,
            "elements": [
                "modularmachinery:blockenergyinputhatch"
            ]
        },
        {
            "x": -12,
            "y": 2,
            "z": 0,
            "elements": [
                "gregtech:fusion_casing@1"
            ]
        },
        {
            "x": 9,
            "y": -2,
            "z": 0,
            "elements": [
                "gregtech:fusion_casing@4"
            ]
        },
        {
            "x": 8,
            "y": -2,
            "z": 0,
            "elements": [
                "gregtech:fusion_casing@4"
            ]
        },
        {
            "x": 7,
            "y": -2,
            "z": 0,
            "elements": [
                "gregtech:fusion_casing@4"
            ]
        },
        {
            "x": -8,
            "y": 2,
            "z": 0,
            "elements": [
                "gregtech:fusion_casing@4"
            ]
        },
        {
            "x": 6,
            "y": -2,
            "z": 0,
            "elements": [
                "gregtech:fusion_casing@4"
            ]
        },
        {
            "x": -7,
            "y": 2,
            "z": 0,
            "elements": [
                "gregtech:fusion_casing@4"
            ]
        },
        {
            "x": -6,
            "y": 2,
            "z": 0,
            "elements": [
                "gregtech:fusion_casing@4"
            ]
        },
        {
            "x": -6,
            "y": -2,
            "z": 0,
            "elements": [
                "gregtech:fusion_casing@4"
            ]
        },
        {
            "x": 6,
            "y": 2,
            "z": 0,
            "elements": [
                "gregtech:fusion_casing@4"
            ]
        },
        {
            "x": -7,
            "y": -2,
            "z": 0,
            "elements": [
                "gregtech:fusion_casing@4"
            ]
        },
        {
            "x": 7,
            "y": 2,
            "z": 0,
            "elements": [
                "gregtech:fusion_casing@4"
            ]
        },
        {
            "x": -8,
            "y": -2,
            "z": 0,
            "elements": [
                "gregtech:fusion_casing@4"
            ]
        },
        {
            "x": -9,
            "y": -2,
            "z": 0,
            "elements": [
                "gregtech:fusion_casing@4"
            ]
        },
        {
            "x": 8,
            "y": 2,
            "z": 0,
            "elements": [
                "gregtech:fusion_casing@4"
            ]
        },
        {
            "x": 9,
            "y": 2,
            "z": 0,
            "elements": [
                "gregtech:fusion_casing@4"
            ]
        },
        {
            "x": -27,
            "y": -3,
            "z": -17,
            "elements": [
                "gregtech:fusion_casing@4"
            ]
        },
        {
            "x": -28,
            "y": -3,
            "z": -17,
            "elements": [
                "gregtech:fusion_casing@4"
            ]
        },
        {
            "x": -12,
            "y": -2,
            "z": 0,
            "elements": [
                "gregtech:fusion_casing@1"
            ]
        },
        {
            "x": -29,
            "y": -3,
            "z": -17,
            "elements": [
                "gregtech:fusion_casing@4"
            ]
        },
        {
            "x": 12,
            "y": 2,
            "z": 0,
            "elements": [
                "gregtech:fusion_casing@1"
            ]
        },
        {
            "x": -13,
            "y": -2,
            "z": 0,
            "elements": [
                "gregtech:fusion_casing@1"
            ]
        },
        {
            "x": 13,
            "y": 2,
            "z": 0,
            "elements": [
                "gregtech:fusion_casing@1"
            ]
        },
        {
            "x": -14,
            "y": -2,
            "z": 0,
            "elements": [
                "gregtech:fusion_casing@1"
            ]
        },
        {
            "x": 14,
            "y": 2,
            "z": 0,
            "elements": [
                "gregtech:fusion_casing@1"
            ]
        },
        {
            "x": 15,
            "y": -3,
            "z": 0,
            "elements": [
                "gregtech:fusion_casing@4"
            ]
        },
        {
            "x": -16,
            "y": -2,
            "z": 0,
            "elements": [
                "gregtech:fusion_casing@4"
            ]
        },
        {
            "x": -17,
            "y": -2,
            "z": 0,
            "elements": [
                "gregtech:fusion_casing@4"
            ]
        },
        {
            "x": 14,
            "y": -3,
            "z": 0,
            "elements": [
                "gregtech:fusion_casing@4"
            ]
        },
        {
            "x": -15,
            "y": 3,
            "z": 0,
            "elements": [
                "gregtech:fusion_casing@4"
            ]
        },
        {
            "x": 16,
            "y": 2,
            "z": 0,
            "elements": [
                "gregtech:fusion_casing@4"
            ]
        },
        {
            "x": 17,
            "y": 2,
            "z": 0,
            "elements": [
                "gregtech:fusion_casing@4"
            ]
        },
        {
            "x": 13,
            "y": -3,
            "z": 0,
            "elements": [
                "gregtech:fusion_casing@4"
            ]
        },
        {
            "x": -14,
            "y": 3,
            "z": 0,
            "elements": [
                "gregtech:fusion_casing@4"
            ]
        },
        {
            "x": 12,
            "y": -3,
            "z": 0,
            "elements": [
                "gregtech:fusion_casing@4"
            ]
        },
        {
            "x": -13,
            "y": 3,
            "z": 0,
            "elements": [
                "gregtech:fusion_casing@4"
            ]
        },
        {
            "x": 11,
            "y": -3,
            "z": 0,
            "elements": [
                "gregtech:fusion_casing@4"
            ]
        },
        {
            "x": -12,
            "y": 3,
            "z": 0,
            "elements": [
                "gregtech:fusion_casing@4"
            ]
        },
        {
            "x": 10,
            "y": -3,
            "z": 0,
            "elements": [
                "gregtech:fusion_casing@4"
            ]
        },
        {
            "x": -11,
            "y": 3,
            "z": 0,
            "elements": [
                "gregtech:fusion_casing@4"
            ]
        },
        {
            "x": -10,
            "y": 3,
            "z": 0,
            "elements": [
                "gregtech:fusion_casing@4"
            ]
        },
        {
            "x": -9,
            "y": 3,
            "z": 0,
            "elements": [
                "gregtech:fusion_casing@4"
            ]
        },
        {
            "x": -10,
            "y": -3,
            "z": 0,
            "elements": [
                "gregtech:fusion_casing@4"
            ]
        },
        {
            "x": 10,
            "y": 3,
            "z": 0,
            "elements": [
                "gregtech:fusion_casing@4"
            ]
        },
        {
            "x": -11,
            "y": -3,
            "z": 0,
            "elements": [
                "gregtech:fusion_casing@4"
            ]
        },
        {
            "x": 11,
            "y": 3,
            "z": 0,
            "elements": [
                "gregtech:fusion_casing@4"
            ]
        },
        {
            "x": -12,
            "y": -3,
            "z": 0,
            "elements": [
                "gregtech:fusion_casing@4"
            ]
        },
        {
            "x": 12,
            "y": 3,
            "z": 0,
            "elements": [
                "gregtech:fusion_casing@4"
            ]
        },
        {
            "x": -13,
            "y": -3,
            "z": 0,
            "elements": [
                "gregtech:fusion_casing@4"
            ]
        },
        {
            "x": 13,
            "y": 3,
            "z": 0,
            "elements": [
                "gregtech:fusion_casing@4"
            ]
        },
        {
            "x": -14,
            "y": -3,
            "z": 0,
            "elements": [
                "gregtech:fusion_casing@4"
            ]
        },
        {
            "x": 14,
            "y": 3,
            "z": 0,
            "elements": [
                "gregtech:fusion_casing@4"
            ]
        },
        {
            "x": -15,
            "y": -3,
            "z": 0,
            "elements": [
                "gregtech:fusion_casing@4"
            ]
        },
        {
            "x": 15,
            "y": 3,
            "z": 0,
            "elements": [
                "gregtech:fusion_casing@4"
            ]
        },
        {
            "x": 25,
            "y": 3,
            "z": -43,
            "elements": [
                "gregtech:fusion_casing@4"
            ]
        },
        {
            "x": 24,
            "y": 3,
            "z": -43,
            "elements": [
                "gregtech:fusion_casing@4"
            ]
        },
        {
            "x": 23,
            "y": 3,
            "z": -43,
            "elements": [
                "gregtech:fusion_casing@4"
            ]
        },
        {
            "x": 22,
            "y": 3,
            "z": -43,
            "elements": [
                "gregtech:fusion_casing@4"
            ]
        },
        {
            "x": 26,
            "y": 2,
            "z": -43,
            "elements": [
                "gregtech:fusion_casing@4"
            ]
        },
        {
            "x": 24,
            "y": 2,
            "z": -43,
            "elements": [
                "gregtech:fusion_casing@1"
            ]
        },
        {
            "x": 21,
            "y": 2,
            "z": -43,
            "elements": [
                "gregtech:fusion_casing@4"
            ]
        },
        {
            "x": 30,
            "y": 3,
            "z": -26,
            "elements": [
                "gregtech:fusion_casing@4"
            ]
        },
        {
            "x": 29,
            "y": 3,
            "z": -26,
            "elements": [
                "gregtech:fusion_casing@4"
            ]
        },
        {
            "x": 28,
            "y": 3,
            "z": -26,
            "elements": [
                "gregtech:fusion_casing@4"
            ]
        },
        {
            "x": -22,
            "y": 3,
            "z": -43,
            "elements": [
                "gregtech:fusion_casing@4"
            ]
        },
        {
            "x": -23,
            "y": 3,
            "z": -43,
            "elements": [
                "gregtech:fusion_casing@4"
            ]
        },
        {
            "x": -24,
            "y": 3,
            "z": -43,
            "elements": [
                "gregtech:fusion_casing@4"
            ]
        },
        {
            "x": -25,
            "y": 3,
            "z": -43,
            "elements": [
                "gregtech:fusion_casing@4"
            ]
        },
        {
            "x": 27,
            "y": 1,
            "z": -43,
            "elements": [
                "gregtech:fusion_casing@4"
            ]
        },
        {
            "x": 25,
            "y": 1,
            "z": -43,
            "elements": [
                "gregtech:wire_coil@7"
            ]
        },
        {
            "x": 24,
            "y": 1,
            "z": -43,
            "elements": [
                "gregtech:boiler_casing@3"
            ]
        },
        {
            "x": 23,
            "y": 1,
            "z": -43,
            "elements": [
                "gregtech:wire_coil@7"
            ]
        },
        {
            "x": 20,
            "y": 1,
            "z": -43,
            "elements": [
                "modularmachinery:blockenergyinputhatch"
            ]
        },
        {
            "x": 31,
            "y": 2,
            "z": -26,
            "elements": [
                "gregtech:fusion_casing@4"
            ]
        },
        {
            "x": 29,
            "y": 2,
            "z": -26,
            "elements": [
                "gregtech:fusion_casing@1"
            ]
        },
        {
            "x": 27,
            "y": 2,
            "z": -26,
            "elements": [
                "gregtech:fusion_casing@4"
            ]
        },
        {
            "x": -21,
            "y": 2,
            "z": -43,
            "elements": [
                "gregtech:fusion_casing@4"
            ]
        },
        {
            "x": -24,
            "y": 2,
            "z": -43,
            "elements": [
                "gregtech:fusion_casing@1"
            ]
        },
        {
            "x": -26,
            "y": 2,
            "z": -43,
            "elements": [
                "gregtech:fusion_casing@4"
            ]
        },
        {
            "x": 27,
            "y": 0,
            "z": -43,
            "elements": [
                "gregtech:fusion_casing@4"
            ]
        },
        {
            "x": 25,
            "y": 0,
            "z": -43,
            "elements": [
                "gregtech:wire_coil@7"
            ]
        },
        {
            "x": 24,
            "y": 0,
            "z": -43,
            "elements": [
                "gregtech:boiler_casing@3"
            ]
        },
        {
            "x": 25,
            "y": 3,
            "z": -9,
            "elements": [
                "gregtech:fusion_casing@4"
            ]
        },
        {
            "x": 23,
            "y": 0,
            "z": -43,
            "elements": [
                "gregtech:wire_coil@7"
            ]
        },
        {
            "x": 24,
            "y": 3,
            "z": -9,
            "elements": [
                "gregtech:fusion_casing@4"
            ]
        },
        {
            "x": 23,
            "y": 3,
            "z": -9,
            "elements": [
                "gregtech:fusion_casing@4"
            ]
        },
        {
            "x": 22,
            "y": 3,
            "z": -9,
            "elements": [
                "gregtech:fusion_casing@4"
            ]
        },
        {
            "x": 20,
            "y": 0,
            "z": -43,
            "elements": [
                "modularmachinery:blockenergyinputhatch"
            ]
        },
        {
            "x": -28,
            "y": 3,
            "z": -26,
            "elements": [
                "gregtech:fusion_casing@4"
            ]
        },
        {
            "x": -29,
            "y": 3,
            "z": -26,
            "elements": [
                "gregtech:fusion_casing@4"
            ]
        },
        {
            "x": -30,
            "y": 3,
            "z": -26,
            "elements": [
                "gregtech:fusion_casing@4"
            ]
        },
        {
            "x": 32,
            "y": 1,
            "z": -26,
            "elements": [
                "gregtech:fusion_casing@4"
            ]
        },
        {
            "x": 30,
            "y": 1,
            "z": -26,
            "elements": [
                "gregtech:wire_coil@7"
            ]
        },
        {
            "x": 29,
            "y": 1,
            "z": -26,
            "elements": [
                "gregtech:boiler_casing@3"
            ]
        },
        {
            "x": 28,
            "y": 1,
            "z": -26,
            "elements": [
                "gregtech:wire_coil@7"
            ]
        },
        {
            "x": -20,
            "y": 1,
            "z": -43,
            "elements": [
                "modularmachinery:blockenergyinputhatch"
            ]
        },
        {
            "x": 26,
            "y": 1,
            "z": -26,
            "elements": [
                "gregtech:fusion_casing@4"
            ]
        },
        {
            "x": -23,
            "y": 1,
            "z": -43,
            "elements": [
                "gregtech:wire_coil@7"
            ]
        },
        {
            "x": -24,
            "y": 1,
            "z": -43,
            "elements": [
                "gregtech:boiler_casing@3"
            ]
        },
        {
            "x": -25,
            "y": 1,
            "z": -43,
            "elements": [
                "gregtech:wire_coil@7"
            ]
        },
        {
            "x": -27,
            "y": 1,
            "z": -43,
            "elements": [
                "gregtech:fusion_casing@4"
            ]
        },
        {
            "x": 27,
            "y": -1,
            "z": -43,
            "elements": [
                "gregtech:fusion_casing@4"
            ]
        },
        {
            "x": 26,
            "y": 2,
            "z": -9,
            "elements": [
                "gregtech:fusion_casing@4"
            ]
        },
        {
            "x": 25,
            "y": -1,
            "z": -43,
            "elements": [
                "gregtech:wire_coil@7"
            ]
        },
        {
            "x": 24,
            "y": -1,
            "z": -43,
            "elements": [
                "gregtech:boiler_casing@3"
            ]
        },
        {
            "x": 23,
            "y": -1,
            "z": -43,
            "elements": [
                "gregtech:wire_coil@7"
            ]
        },
        {
            "x": 24,
            "y": 2,
            "z": -9,
            "elements": [
                "gregtech:fusion_casing@1"
            ]
        },
        {
            "x": 20,
            "y": -1,
            "z": -43,
            "elements": [
                "modularmachinery:blockenergyinputhatch"
            ]
        },
        {
            "x": 21,
            "y": 2,
            "z": -9,
            "elements": [
                "gregtech:fusion_casing@4"
            ]
        },
        {
            "x": -27,
            "y": 2,
            "z": -26,
            "elements": [
                "gregtech:fusion_casing@4"
            ]
        },
        {
            "x": -29,
            "y": 2,
            "z": -26,
            "elements": [
                "gregtech:fusion_casing@1"
            ]
        },
        {
            "x": 32,
            "y": 0,
            "z": -26,
            "elements": [
                "gregtech:transparent_casing@1"
            ]
        },
        {
            "x": -31,
            "y": 2,
            "z": -26,
            "elements": [
                "gregtech:fusion_casing@4"
            ]
        },
        {
            "x": 30,
            "y": 0,
            "z": -26,
            "elements": [
                "gregtech:wire_coil@7"
            ]
        },
        {
            "x": 29,
            "y": 0,
            "z": -26,
            "elements": [
                "gregtech:boiler_casing@3"
            ]
        },
        {
            "x": 28,
            "y": 0,
            "z": -26,
            "elements": [
                "gregtech:wire_coil@7"
            ]
        },
        {
            "x": -20,
            "y": 0,
            "z": -43,
            "elements": [
                "modularmachinery:blockenergyinputhatch"
            ]
        },
        {
            "x": 26,
            "y": 0,
            "z": -26,
            "elements": [
                "gregtech:transparent_casing@1"
            ]
        },
        {
            "x": -22,
            "y": 3,
            "z": -9,
            "elements": [
                "gregtech:fusion_casing@4"
            ]
        },
        {
            "x": -23,
            "y": 0,
            "z": -43,
            "elements": [
                "gregtech:wire_coil@7"
            ]
        },
        {
            "x": -23,
            "y": 3,
            "z": -9,
            "elements": [
                "gregtech:fusion_casing@4"
            ]
        },
        {
            "x": -24,
            "y": 0,
            "z": -43,
            "elements": [
                "gregtech:boiler_casing@3"
            ]
        },
        {
            "x": -24,
            "y": 3,
            "z": -9,
            "elements": [
                "gregtech:fusion_casing@4"
            ]
        },
        {
            "x": -25,
            "y": 0,
            "z": -43,
            "elements": [
                "gregtech:wire_coil@7"
            ]
        },
        {
            "x": -25,
            "y": 3,
            "z": -9,
            "elements": [
                "gregtech:fusion_casing@4"
            ]
        },
        {
            "x": -27,
            "y": 0,
            "z": -43,
            "elements": [
                "gregtech:fusion_casing@4"
            ]
        },
        {
            "x": 26,
            "y": -2,
            "z": -43,
            "elements": [
                "gregtech:fusion_casing@4"
            ]
        },
        {
            "x": 27,
            "y": 1,
            "z": -9,
            "elements": [
                "gregtech:fusion_casing@4"
            ]
        },
        {
            "x": 24,
            "y": -2,
            "z": -43,
            "elements": [
                "gregtech:fusion_casing@1"
            ]
        },
        {
            "x": 25,
            "y": 1,
            "z": -9,
            "elements": [
                "gregtech:wire_coil@7"
            ]
        },
        {
            "x": 24,
            "y": 1,
            "z": -9,
            "elements": [
                "gregtech:boiler_casing@3"
            ]
        },
        {
            "x": 23,
            "y": 1,
            "z": -9,
            "elements": [
                "gregtech:wire_coil@7"
            ]
        },
        {
            "x": 21,
            "y": -2,
            "z": -43,
            "elements": [
                "gregtech:fusion_casing@4"
            ]
        },
        {
            "x": -26,
            "y": 1,
            "z": -26,
            "elements": [
                "gregtech:fusion_casing@4"
            ]
        },
        {
            "x": 20,
            "y": 1,
            "z": -9,
            "elements": [
                "modularmachinery:blockenergyinputhatch"
            ]
        },
        {
            "x": -28,
            "y": 1,
            "z": -26,
            "elements": [
                "gregtech:wire_coil@7"
            ]
        },
        {
            "x": -29,
            "y": 1,
            "z": -26,
            "elements": [
                "gregtech:boiler_casing@3"
            ]
        },
        {
            "x": -30,
            "y": 1,
            "z": -26,
            "elements": [
                "gregtech:wire_coil@7"
            ]
        },
        {
            "x": 32,
            "y": -1,
            "z": -26,
            "elements": [
                "gregtech:fusion_casing@4"
            ]
        },
        {
            "x": 30,
            "y": -1,
            "z": -26,
            "elements": [
                "gregtech:wire_coil@7"
            ]
        },
        {
            "x": -32,
            "y": 1,
            "z": -26,
            "elements": [
                "gregtech:fusion_casing@4"
            ]
        },
        {
            "x": 29,
            "y": -1,
            "z": -26,
            "elements": [
                "gregtech:boiler_casing@3"
            ]
        },
        {
            "x": 28,
            "y": -1,
            "z": -26,
            "elements": [
                "gregtech:wire_coil@7"
            ]
        },
        {
            "x": -20,
            "y": -1,
            "z": -43,
            "elements": [
                "modularmachinery:blockenergyinputhatch"
            ]
        },
        {
            "x": 26,
            "y": -1,
            "z": -26,
            "elements": [
                "gregtech:fusion_casing@4"
            ]
        },
        {
            "x": -21,
            "y": 2,
            "z": -9,
            "elements": [
                "gregtech:fusion_casing@4"
            ]
        },
        {
            "x": -23,
            "y": -1,
            "z": -43,
            "elements": [
                "gregtech:wire_coil@7"
            ]
        },
        {
            "x": -24,
            "y": -1,
            "z": -43,
            "elements": [
                "gregtech:boiler_casing@3"
            ]
        },
        {
            "x": -24,
            "y": 2,
            "z": -9,
            "elements": [
                "gregtech:fusion_casing@1"
            ]
        },
        {
            "x": -25,
            "y": -1,
            "z": -43,
            "elements": [
                "gregtech:wire_coil@7"
            ]
        },
        {
            "x": -26,
            "y": 2,
            "z": -9,
            "elements": [
                "gregtech:fusion_casing@4"
            ]
        },
        {
            "x": -27,
            "y": -1,
            "z": -43,
            "elements": [
                "gregtech:fusion_casing@4"
            ]
        },
        {
            "x": 27,
            "y": 0,
            "z": -9,
            "elements": [
                "gregtech:fusion_casing@4"
            ]
        },
        {
            "x": 25,
            "y": -3,
            "z": -43,
            "elements": [
                "gregtech:fusion_casing@4"
            ]
        },
        {
            "x": 24,
            "y": -3,
            "z": -43,
            "elements": [
                "gregtech:fusion_casing@4"
            ]
        },
        {
            "x": 25,
            "y": 0,
            "z": -9,
            "elements": [
                "gregtech:wire_coil@7"
            ]
        },
        {
            "x": 23,
            "y": -3,
            "z": -43,
            "elements": [
                "gregtech:fusion_casing@4"
            ]
        },
        {
            "x": 24,
            "y": 0,
            "z": -9,
            "elements": [
                "gregtech:boiler_casing@3"
            ]
        },
        {
            "x": 22,
            "y": -3,
            "z": -43,
            "elements": [
                "gregtech:fusion_casing@4"
            ]
        },
        {
            "x": 23,
            "y": 0,
            "z": -9,
            "elements": [
                "gregtech:wire_coil@7"
            ]
        },
        {
            "x": -26,
            "y": 0,
            "z": -26,
            "elements": [
                "gregtech:transparent_casing@1"
            ]
        },
        {
            "x": 20,
            "y": 0,
            "z": -9,
            "elements": [
                "modularmachinery:blockenergyinputhatch"
            ]
        },
        {
            "x": -28,
            "y": 0,
            "z": -26,
            "elements": [
                "gregtech:wire_coil@7"
            ]
        },
        {
            "x": -29,
            "y": 0,
            "z": -26,
            "elements": [
                "gregtech:boiler_casing@3"
            ]
        },
        {
            "x": -30,
            "y": 0,
            "z": -26,
            "elements": [
                "gregtech:wire_coil@7"
            ]
        },
        {
            "x": 31,
            "y": -2,
            "z": -26,
            "elements": [
                "gregtech:fusion_casing@4"
            ]
        },
        {
            "x": -32,
            "y": 0,
            "z": -26,
            "elements": [
                "gregtech:transparent_casing@1"
            ]
        },
        {
            "x": 29,
            "y": -2,
            "z": -26,
            "elements": [
                "gregtech:fusion_casing@1"
            ]
        },
        {
            "x": 27,
            "y": -2,
            "z": -26,
            "elements": [
                "gregtech:fusion_casing@4"
            ]
        },
        {
            "x": -20,
            "y": 1,
            "z": -9,
            "elements": [
                "modularmachinery:blockenergyinputhatch"
            ]
        },
        {
            "x": -21,
            "y": -2,
            "z": -43,
            "elements": [
                "gregtech:fusion_casing@4"
            ]
        },
        {
            "x": -23,
            "y": 1,
            "z": -9,
            "elements": [
                "gregtech:wire_coil@7"
            ]
        },
        {
            "x": -24,
            "y": -2,
            "z": -43,
            "elements": [
                "gregtech:fusion_casing@1"
            ]
        },
        {
            "x": -24,
            "y": 1,
            "z": -9,
            "elements": [
                "gregtech:boiler_casing@3"
            ]
        },
        {
            "x": -26,
            "y": -2,
            "z": -43,
            "elements": [
                "gregtech:fusion_casing@4"
            ]
        },
        {
            "x": -25,
            "y": 1,
            "z": -9,
            "elements": [
                "gregtech:wire_coil@7"
            ]
        },
        {
            "x": -27,
            "y": 1,
            "z": -9,
            "elements": [
                "gregtech:fusion_casing@4"
            ]
        },
        {
            "x": 27,
            "y": -1,
            "z": -9,
            "elements": [
                "gregtech:fusion_casing@4"
            ]
        },
        {
            "x": 25,
            "y": -1,
            "z": -9,
            "elements": [
                "gregtech:wire_coil@7"
            ]
        },
        {
            "x": 24,
            "y": -1,
            "z": -9,
            "elements": [
                "gregtech:boiler_casing@3"
            ]
        },
        {
            "x": 23,
            "y": -1,
            "z": -9,
            "elements": [
                "gregtech:wire_coil@7"
            ]
        },
        {
            "x": -26,
            "y": -1,
            "z": -26,
            "elements": [
                "gregtech:fusion_casing@4"
            ]
        },
        {
            "x": 20,
            "y": -1,
            "z": -9,
            "elements": [
                "modularmachinery:blockenergyinputhatch"
            ]
        },
        {
            "x": -28,
            "y": -1,
            "z": -26,
            "elements": [
                "gregtech:wire_coil@7"
            ]
        },
        {
            "x": -29,
            "y": -1,
            "z": -26,
            "elements": [
                "gregtech:boiler_casing@3"
            ]
        },
        {
            "x": -30,
            "y": -1,
            "z": -26,
            "elements": [
                "gregtech:wire_coil@7"
            ]
        },
        {
            "x": 30,
            "y": -3,
            "z": -26,
            "elements": [
                "gregtech:fusion_casing@4"
            ]
        },
        {
            "x": -32,
            "y": -1,
            "z": -26,
            "elements": [
                "gregtech:fusion_casing@4"
            ]
        },
        {
            "x": 29,
            "y": -3,
            "z": -26,
            "elements": [
                "gregtech:fusion_casing@4"
            ]
        },
        {
            "x": 28,
            "y": -3,
            "z": -26,
            "elements": [
                "gregtech:fusion_casing@4"
            ]
        },
        {
            "x": -20,
            "y": 0,
            "z": -9,
            "elements": [
                "modularmachinery:blockenergyinputhatch"
            ]
        },
        {
            "x": -22,
            "y": -3,
            "z": -43,
            "elements": [
                "gregtech:fusion_casing@4"
            ]
        },
        {
            "x": -23,
            "y": -3,
            "z": -43,
            "elements": [
                "gregtech:fusion_casing@4"
            ]
        },
        {
            "x": -23,
            "y": 0,
            "z": -9,
            "elements": [
                "gregtech:wire_coil@7"
            ]
        },
        {
            "x": -24,
            "y": -3,
            "z": -43,
            "elements": [
                "gregtech:fusion_casing@4"
            ]
        },
        {
            "x": -24,
            "y": 0,
            "z": -9,
            "elements": [
                "gregtech:boiler_casing@3"
            ]
        },
        {
            "x": -25,
            "y": -3,
            "z": -43,
            "elements": [
                "gregtech:fusion_casing@4"
            ]
        },
        {
            "x": -25,
            "y": 0,
            "z": -9,
            "elements": [
                "gregtech:wire_coil@7"
            ]
        },
        {
            "x": -27,
            "y": 0,
            "z": -9,
            "elements": [
                "gregtech:fusion_casing@4"
            ]
        },
        {
            "x": 26,
            "y": -2,
            "z": -9,
            "elements": [
                "gregtech:fusion_casing@4"
            ]
        },
        {
            "x": 24,
            "y": -2,
            "z": -9,
            "elements": [
                "gregtech:fusion_casing@1"
            ]
        },
        {
            "x": 21,
            "y": -2,
            "z": -9,
            "elements": [
                "gregtech:fusion_casing@4"
            ]
        },
        {
            "x": -27,
            "y": -2,
            "z": -26,
            "elements": [
                "gregtech:fusion_casing@4"
            ]
        },
        {
            "x": -29,
            "y": -2,
            "z": -26,
            "elements": [
                "gregtech:fusion_casing@1"
            ]
        },
        {
            "x": -31,
            "y": -2,
            "z": -26,
            "elements": [
                "gregtech:fusion_casing@4"
            ]
        },
        {
            "x": -20,
            "y": -1,
            "z": -9,
            "elements": [
                "modularmachinery:blockenergyinputhatch"
            ]
        },
        {
            "x": -23,
            "y": -1,
            "z": -9,
            "elements": [
                "gregtech:wire_coil@7"
            ]
        },
        {
            "x": -24,
            "y": -1,
            "z": -9,
            "elements": [
                "gregtech:boiler_casing@3"
            ]
        },
        {
            "x": -25,
            "y": -1,
            "z": -9,
            "elements": [
                "gregtech:wire_coil@7"
            ]
        },
        {
            "x": -27,
            "y": -1,
            "z": -9,
            "elements": [
                "gregtech:fusion_casing@4"
            ]
        },
        {
            "x": 25,
            "y": -3,
            "z": -9,
            "elements": [
                "gregtech:fusion_casing@4"
            ]
        },
        {
            "x": 24,
            "y": -3,
            "z": -9,
            "elements": [
                "gregtech:fusion_casing@4"
            ]
        },
        {
            "x": 23,
            "y": -3,
            "z": -9,
            "elements": [
                "gregtech:fusion_casing@4"
            ]
        },
        {
            "x": 22,
            "y": -3,
            "z": -9,
            "elements": [
                "gregtech:fusion_casing@4"
            ]
        },
        {
            "x": -28,
            "y": -3,
            "z": -26,
            "elements": [
                "gregtech:fusion_casing@4"
            ]
        },
        {
            "x": -29,
            "y": -3,
            "z": -26,
            "elements": [
                "gregtech:fusion_casing@4"
            ]
        },
        {
            "x": -30,
            "y": -3,
            "z": -26,
            "elements": [
                "gregtech:fusion_casing@4"
            ]
        },
        {
            "x": -21,
            "y": -2,
            "z": -9,
            "elements": [
                "gregtech:fusion_casing@4"
            ]
        },
        {
            "x": -24,
            "y": -2,
            "z": -9,
            "elements": [
                "gregtech:fusion_casing@1"
            ]
        },
        {
            "x": -26,
            "y": -2,
            "z": -9,
            "elements": [
                "gregtech:fusion_casing@4"
            ]
        },
        {
            "x": -22,
            "y": -3,
            "z": -9,
            "elements": [
                "gregtech:fusion_casing@4"
            ]
        },
        {
            "x": -23,
            "y": -3,
            "z": -9,
            "elements": [
                "gregtech:fusion_casing@4"
            ]
        },
        {
            "x": -24,
            "y": -3,
            "z": -9,
            "elements": [
                "gregtech:fusion_casing@4"
            ]
        },
        {
            "x": -25,
            "y": -3,
            "z": -9,
            "elements": [
                "gregtech:fusion_casing@4"
            ]
        },
        {
            "x": 15,
            "y": 3,
            "z": -52,
            "elements": [
                "gregtech:fusion_casing@4"
            ]
        },
        {
            "x": 14,
            "y": 3,
            "z": -52,
            "elements": [
                "gregtech:fusion_casing@4"
            ]
        },
        {
            "x": 13,
            "y": 3,
            "z": -52,
            "elements": [
                "gregtech:fusion_casing@4"
            ]
        },
        {
            "x": 12,
            "y": 3,
            "z": -52,
            "elements": [
                "gregtech:fusion_casing@4"
            ]
        },
        {
            "x": 11,
            "y": 3,
            "z": -52,
            "elements": [
                "gregtech:fusion_casing@4"
            ]
        },
        {
            "x": 10,
            "y": 3,
            "z": -52,
            "elements": [
                "gregtech:fusion_casing@4"
            ]
        },
        {
            "x": -10,
            "y": 3,
            "z": -52,
            "elements": [
                "gregtech:fusion_casing@4"
            ]
        },
        {
            "x": -11,
            "y": 3,
            "z": -52,
            "elements": [
                "gregtech:fusion_casing@4"
            ]
        },
        {
            "x": -12,
            "y": 3,
            "z": -52,
            "elements": [
                "gregtech:fusion_casing@4"
            ]
        },
        {
            "x": -13,
            "y": 3,
            "z": -52,
            "elements": [
                "gregtech:fusion_casing@4"
            ]
        },
        {
            "x": 17,
            "y": 2,
            "z": -52,
            "elements": [
                "gregtech:fusion_casing@4"
            ]
        },
        {
            "x": -14,
            "y": 3,
            "z": -52,
            "elements": [
                "gregtech:fusion_casing@4"
            ]
        },
        {
            "x": -15,
            "y": 3,
            "z": -52,
            "elements": [
                "gregtech:fusion_casing@4"
            ]
        },
        {
            "x": 16,
            "y": 2,
            "z": -52,
            "elements": [
                "gregtech:fusion_casing@4"
            ]
        },
        {
            "x": 14,
            "y": 2,
            "z": -52,
            "elements": [
                "gregtech:fusion_casing@1"
            ]
        },
        {
            "x": 29,
            "y": 3,
            "z": -35,
            "elements": [
                "gregtech:fusion_casing@4"
            ]
        },
        {
            "x": 13,
            "y": 2,
            "z": -52,
            "elements": [
                "gregtech:fusion_casing@1"
            ]
        },
        {
            "x": 28,
            "y": 3,
            "z": -35,
            "elements": [
                "gregtech:fusion_casing@4"
            ]
        },
        {
            "x": 12,
            "y": 2,
            "z": -52,
            "elements": [
                "gregtech:fusion_casing@1"
            ]
        },
        {
            "x": 27,
            "y": 3,
            "z": -35,
            "elements": [
                "gregtech:fusion_casing@4"
            ]
        },
        {
            "x": 9,
            "y": 2,
            "z": -52,
            "elements": [
                "gregtech:fusion_casing@4"
            ]
        },
        {
            "x": 8,
            "y": 2,
            "z": -52,
            "elements": [
                "gregtech:fusion_casing@4"
            ]
        },
        {
            "x": 7,
            "y": 2,
            "z": -52,
            "elements": [
                "gregtech:fusion_casing@4"
            ]
        },
        {
            "x": 6,
            "y": 2,
            "z": -52,
            "elements": [
                "gregtech:fusion_casing@4"
            ]
        },
        {
            "x": -6,
            "y": 2,
            "z": -52,
            "elements": [
                "gregtech:fusion_casing@4"
            ]
        },
        {
            "x": -7,
            "y": 2,
            "z": -52,
            "elements": [
                "gregtech:fusion_casing@4"
            ]
        },
        {
            "x": -8,
            "y": 2,
            "z": -52,
            "elements": [
                "gregtech:fusion_casing@4"
            ]
        },
        {
            "x": -9,
            "y": 2,
            "z": -52,
            "elements": [
                "gregtech:fusion_casing@4"
            ]
        },
        {
            "x": 19,
            "y": 1,
            "z": -52,
            "elements": [
                "modularmachinery:blockenergyinputhatch"
            ]
        },
        {
            "x": -12,
            "y": 2,
            "z": -52,
            "elements": [
                "gregtech:fusion_casing@1"
            ]
        },
        {
            "x": 18,
            "y": 1,
            "z": -52,
            "elements": [
                "modularmachinery:blockenergyinputhatch"
            ]
        },
        {
            "x": -13,
            "y": 2,
            "z": -52,
            "elements": [
                "gregtech:fusion_casing@1"
            ]
        },
        {
            "x": -14,
            "y": 2,
            "z": -52,
            "elements": [
                "gregtech:fusion_casing@1"
            ]
        },
        {
            "x": 15,
            "y": 1,
            "z": -52,
            "elements": [
                "gregtech:wire_coil@7"
            ]
        },
        {
            "x": -16,
            "y": 2,
            "z": -52,
            "elements": [
                "gregtech:fusion_casing@4"
            ]
        },
        {
            "x": 30,
            "y": 2,
            "z": -35,
            "elements": [
                "gregtech:fusion_casing@4"
            ]
        },
        {
            "x": 14,
            "y": 1,
            "z": -52,
            "elements": [
                "gregtech:boiler_casing@3"
            ]
        },
        {
            "x": -17,
            "y": 2,
            "z": -52,
            "elements": [
                "gregtech:fusion_casing@4"
            ]
        },
        {
            "x": 13,
            "y": 1,
            "z": -52,
            "elements": [
                "gregtech:boiler_casing@3"
            ]
        },
        {
            "x": 28,
            "y": 2,
            "z": -35,
            "elements": [
                "gregtech:fusion_casing@1"
            ]
        },
        {
            "x": 12,
            "y": 1,
            "z": -52,
            "elements": [
                "gregtech:boiler_casing@3"
            ]
        },
        {
            "x": 11,
            "y": 1,
            "z": -52,
            "elements": [
                "gregtech:wire_coil@7"
            ]
        },
        {
            "x": 26,
            "y": 2,
            "z": -35,
            "elements": [
                "gregtech:fusion_casing@4"
            ]
        },
        {
            "x": 10,
            "y": 1,
            "z": -52,
            "elements": [
                "gregtech:wire_coil@7"
            ]
        },
        {
            "x": 25,
            "y": 2,
            "z": -35,
            "elements": [
                "gregtech:fusion_casing@4"
            ]
        },
        {
            "x": 5,
            "y": 1,
            "z": -52,
            "elements": [
                "gregtech:fusion_casing@4"
            ]
        },
        {
            "x": 4,
            "y": 1,
            "z": -52,
            "elements": [
                "modularmachinery:blockfluidinputhatch"
            ]
        },
        {
            "x": 3,
            "y": 1,
            "z": -52,
            "elements": [
                "gregtech:fusion_casing@4"
            ]
        },
        {
            "x": 2,
            "y": 1,
            "z": -52,
            "elements": [
                "gregtech:fusion_casing@4"
            ]
        },
        {
            "x": 1,
            "y": 1,
            "z": -52,
            "elements": [
                "gregtech:fusion_casing@4"
            ]
        },
        {
            "x": 0,
            "y": 1,
            "z": -52,
            "elements": [
                "gregtech:fusion_casing@4"
            ]
        },
        {
            "x": -1,
            "y": 1,
            "z": -52,
            "elements": [
                "gregtech:fusion_casing@4"
            ]
        },
        {
            "x": -2,
            "y": 1,
            "z": -52,
            "elements": [
                "gregtech:fusion_casing@4"
            ]
        },
        {
            "x": -3,
            "y": 1,
            "z": -52,
            "elements": [
                "gregtech:fusion_casing@4"
            ]
        },
        {
            "x": 29,
            "y": 3,
            "z": -18,
            "elements": [
                "gregtech:fusion_casing@4"
            ]
        },
        {
            "x": 28,
            "y": 3,
            "z": -18,
            "elements": [
                "gregtech:fusion_casing@4"
            ]
        },
        {
            "x": -4,
            "y": 1,
            "z": -52,
            "elements": [
                "modularmachinery:blockfluidinputhatch"
            ]
        },
        {
            "x": 27,
            "y": 3,
            "z": -18,
            "elements": [
                "gregtech:fusion_casing@4"
            ]
        },
        {
            "x": -5,
            "y": 1,
            "z": -52,
            "elements": [
                "gregtech:fusion_casing@4"
            ]
        },
        {
            "x": -10,
            "y": 1,
            "z": -52,
            "elements": [
                "gregtech:wire_coil@7"
            ]
        },
        {
            "x": -11,
            "y": 1,
            "z": -52,
            "elements": [
                "gregtech:wire_coil@7"
            ]
        },
        {
            "x": -27,
            "y": 3,
            "z": -35,
            "elements": [
                "gregtech:fusion_casing@4"
            ]
        },
        {
            "x": 19,
            "y": 0,
            "z": -52,
            "elements": [
                "modularmachinery:blockenergyinputhatch"
            ]
        },
        {
            "x": -12,
            "y": 1,
            "z": -52,
            "elements": [
                "gregtech:boiler_casing@3"
            ]
        },
        {
            "x": 18,
            "y": 0,
            "z": -52,
            "elements": [
                "modularmachinery:blockenergyinputhatch"
            ]
        },
        {
            "x": -28,
            "y": 3,
            "z": -35,
            "elements": [
                "gregtech:fusion_casing@4"
            ]
        },
        {
            "x": -13,
            "y": 1,
            "z": -52,
            "elements": [
                "gregtech:boiler_casing@3"
            ]
        },
        {
            "x": -29,
            "y": 3,
            "z": -35,
            "elements": [
                "gregtech:fusion_casing@4"
            ]
        },
        {
            "x": -14,
            "y": 1,
            "z": -52,
            "elements": [
                "gregtech:boiler_casing@3"
            ]
        },
        {
            "x": -15,
            "y": 1,
            "z": -52,
            "elements": [
                "gregtech:wire_coil@7"
            ]
        },
        {
            "x": 31,
            "y": 1,
            "z": -35,
            "elements": [
                "gregtech:fusion_casing@4"
            ]
        },
        {
            "x": 15,
            "y": 0,
            "z": -52,
            "elements": [
                "gregtech:wire_coil@7"
            ]
        },
        {
            "x": 14,
            "y": 0,
            "z": -52,
            "elements": [
                "gregtech:boiler_casing@3"
            ]
        },
        {
            "x": -18,
            "y": 1,
            "z": -52,
            "elements": [
                "modularmachinery:blockenergyinputhatch"
            ]
        },
        {
            "x": 29,
            "y": 1,
            "z": -35,
            "elements": [
                "gregtech:wire_coil@7"
            ]
        },
        {
            "x": 13,
            "y": 0,
            "z": -52,
            "elements": [
                "gregtech:boiler_casing@3"
            ]
        },
        {
            "x": -19,
            "y": 1,
            "z": -52,
            "elements": [
                "modularmachinery:blockenergyinputhatch"
            ]
        },
        {
            "x": 28,
            "y": 1,
            "z": -35,
            "elements": [
                "gregtech:boiler_casing@3"
            ]
        },
        {
            "x": 12,
            "y": 0,
            "z": -52,
            "elements": [
                "gregtech:boiler_casing@3"
            ]
        },
        {
            "x": 27,
            "y": 1,
            "z": -35,
            "elements": [
                "gregtech:wire_coil@7"
            ]
        },
        {
            "x": 11,
            "y": 0,
            "z": -52,
            "elements": [
                "gregtech:wire_coil@7"
            ]
        },
        {
            "x": 10,
            "y": 0,
            "z": -52,
            "elements": [
                "gregtech:wire_coil@7"
            ]
        },
        {
            "x": 24,
            "y": 1,
            "z": -35,
            "elements": [
                "gregtech:fusion_casing@4"
            ]
        },
        {
            "x": 5,
            "y": 0,
            "z": -52,
            "elements": [
                "gregtech:fusion_casing@4"
            ]
        },
        {
            "x": 4,
            "y": 0,
            "z": -52,
            "elements": [
                "modularmachinery:blockfluidinputhatch"
            ]
        },
        {
            "x": 3,
            "y": 0,
            "z": -52,
            "elements": [
                "gregtech:fusion_casing@4"
            ]
        },
        {
            "x": 2,
            "y": 0,
            "z": -52,
            "elements": [
                "gregtech:transparent_casing@1"
            ]
        },
        {
            "x": 1,
            "y": 0,
            "z": -52,
            "elements": [
                "gregtech:transparent_casing@1"
            ]
        },
        {
            "x": 0,
            "y": 0,
            "z": -52,
            "elements": [
                "gregtech:transparent_casing@1"
            ]
        },
        {
            "x": -1,
            "y": 0,
            "z": -52,
            "elements": [
                "gregtech:transparent_casing@1"
            ]
        },
        {
            "x": -2,
            "y": 0,
            "z": -52,
            "elements": [
                "gregtech:transparent_casing@1"
            ]
        },
        {
            "x": 30,
            "y": 2,
            "z": -18,
            "elements": [
                "gregtech:fusion_casing@4"
            ]
        },
        {
            "x": -3,
            "y": 0,
            "z": -52,
            "elements": [
                "gregtech:fusion_casing@4"
            ]
        },
        {
            "x": 28,
            "y": 2,
            "z": -18,
            "elements": [
                "gregtech:fusion_casing@1"
            ]
        },
        {
            "x": -4,
            "y": 0,
            "z": -52,
            "elements": [
                "modularmachinery:blockfluidinputhatch"
            ]
        },
        {
            "x": -5,
            "y": 0,
            "z": -52,
            "elements": [
                "gregtech:fusion_casing@4"
            ]
        },
        {
            "x": 26,
            "y": 2,
            "z": -18,
            "elements": [
                "gregtech:fusion_casing@4"
            ]
        },
        {
            "x": -10,
            "y": 0,
            "z": -52,
            "elements": [
                "gregtech:wire_coil@7"
            ]
        },
        {
            "x": -25,
            "y": 2,
            "z": -35,
            "elements": [
                "gregtech:fusion_casing@4"
            ]
        },
        {
            "x": -26,
            "y": 2,
            "z": -35,
            "elements": [
                "gregtech:fusion_casing@4"
            ]
        },
        {
            "x": -11,
            "y": 0,
            "z": -52,
            "elements": [
                "gregtech:wire_coil@7"
            ]
        },
        {
            "x": 19,
            "y": -1,
            "z": -52,
            "elements": [
                "modularmachinery:blockenergyinputhatch"
            ]
        },
        {
            "x": -12,
            "y": 0,
            "z": -52,
            "elements": [
                "gregtech:boiler_casing@3"
            ]
        },
        {
            "x": 18,
            "y": -1,
            "z": -52,
            "elements": [
                "modularmachinery:blockenergyinputhatch"
            ]
        },
        {
            "x": -28,
            "y": 2,
            "z": -35,
            "elements": [
                "gregtech:fusion_casing@1"
            ]
        },
        {
            "x": -13,
            "y": 0,
            "z": -52,
            "elements": [
                "gregtech:boiler_casing@3"
            ]
        },
        {
            "x": -14,
            "y": 0,
            "z": -52,
            "elements": [
                "gregtech:boiler_casing@3"
            ]
        },
        {
            "x": -30,
            "y": 2,
            "z": -35,
            "elements": [
                "gregtech:fusion_casing@4"
            ]
        },
        {
            "x": -15,
            "y": 0,
            "z": -52,
            "elements": [
                "gregtech:wire_coil@7"
            ]
        },
        {
            "x": 31,
            "y": 0,
            "z": -35,
            "elements": [
                "gregtech:fusion_casing@4"
            ]
        },
        {
            "x": 15,
            "y": -1,
            "z": -52,
            "elements": [
                "gregtech:wire_coil@7"
            ]
        },
        {
            "x": 14,
            "y": -1,
            "z": -52,
            "elements": [
                "gregtech:boiler_casing@3"
            ]
        },
        {
            "x": -18,
            "y": 0,
            "z": -52,
            "elements": [
                "modularmachinery:blockenergyinputhatch"
            ]
        },
        {
            "x": 29,
            "y": 0,
            "z": -35,
            "elements": [
                "gregtech:wire_coil@7"
            ]
        },
        {
            "x": 13,
            "y": -1,
            "z": -52,
            "elements": [
                "gregtech:boiler_casing@3"
            ]
        },
        {
            "x": -19,
            "y": 0,
            "z": -52,
            "elements": [
                "modularmachinery:blockenergyinputhatch"
            ]
        },
        {
            "x": 28,
            "y": 0,
            "z": -35,
            "elements": [
                "gregtech:boiler_casing@3"
            ]
        },
        {
            "x": 12,
            "y": -1,
            "z": -52,
            "elements": [
                "gregtech:boiler_casing@3"
            ]
        },
        {
            "x": 27,
            "y": 0,
            "z": -35,
            "elements": [
                "gregtech:wire_coil@7"
            ]
        },
        {
            "x": 11,
            "y": -1,
            "z": -52,
            "elements": [
                "gregtech:wire_coil@7"
            ]
        },
        {
            "x": 10,
            "y": -1,
            "z": -52,
            "elements": [
                "gregtech:wire_coil@7"
            ]
        },
        {
            "x": 24,
            "y": 0,
            "z": -35,
            "elements": [
                "gregtech:fusion_casing@4"
            ]
        },
        {
            "x": 5,
            "y": -1,
            "z": -52,
            "elements": [
                "gregtech:fusion_casing@4"
            ]
        },
        {
            "x": 4,
            "y": -1,
            "z": -52,
            "elements": [
                "modularmachinery:blockfluidinputhatch"
            ]
        },
        {
            "x": -27,
            "y": 3,
            "z": -18,
            "elements": [
                "gregtech:fusion_casing@4"
            ]
        },
        {
            "x": 3,
            "y": -1,
            "z": -52,
            "elements": [
                "gregtech:fusion_casing@4"
            ]
        },
        {
            "x": 2,
            "y": -1,
            "z": -52,
            "elements": [
                "gregtech:fusion_casing@4"
            ]
        },
        {
            "x": -28,
            "y": 3,
            "z": -18,
            "elements": [
                "gregtech:fusion_casing@4"
            ]
        },
        {
            "x": 1,
            "y": -1,
            "z": -52,
            "elements": [
                "gregtech:fusion_casing@4"
            ]
        },
        {
            "x": -29,
            "y": 3,
            "z": -18,
            "elements": [
                "gregtech:fusion_casing@4"
            ]
        },
        {
            "x": 0,
            "y": -1,
            "z": -52,
            "elements": [
                "gregtech:fusion_casing@4"
            ]
        },
        {
            "x": 17,
            "y": 3,
            "z": -1,
            "elements": [
                "gregtech:fusion_casing@4"
            ]
        },
        {
            "x": -1,
            "y": -1,
            "z": -52,
            "elements": [
                "gregtech:fusion_casing@4"
            ]
        },
        {
            "x": 31,
            "y": 1,
            "z": -18,
            "elements": [
                "gregtech:fusion_casing@4"
            ]
        },
        {
            "x": 16,
            "y": 3,
            "z": -1,
            "elements": [
                "gregtech:fusion_casing@4"
            ]
        },
        {
            "x": -2,
            "y": -1,
            "z": -52,
            "elements": [
                "gregtech:fusion_casing@4"
            ]
        },
        {
            "x": 15,
            "y": 3,
            "z": -1,
            "elements": [
                "gregtech:fusion_casing@4"
            ]
        },
        {
            "x": -3,
            "y": -1,
            "z": -52,
            "elements": [
                "gregtech:fusion_casing@4"
            ]
        },
        {
            "x": 29,
            "y": 1,
            "z": -18,
            "elements": [
                "gregtech:wire_coil@7"
            ]
        },
        {
            "x": 14,
            "y": 3,
            "z": -1,
            "elements": [
                "gregtech:fusion_casing@4"
            ]
        },
        {
            "x": 28,
            "y": 1,
            "z": -18,
            "elements": [
                "gregtech:boiler_casing@3"
            ]
        },
        {
            "x": -4,
            "y": -1,
            "z": -52,
            "elements": [
                "modularmachinery:blockfluidinputhatch"
            ]
        },
        {
            "x": 13,
            "y": 3,
            "z": -1,
            "elements": [
                "gregtech:fusion_casing@4"
            ]
        },
        {
            "x": -14,
            "y": -3,
            "z": 1,
            "elements": [
                "gregtech:fusion_casing@4"
            ]
        },
        {
            "x": 27,
            "y": 1,
            "z": -18,
            "elements": [
                "gregtech:wire_coil@7"
            ]
        },
        {
            "x": 12,
            "y": 3,
            "z": -1,
            "elements": [
                "gregtech:fusion_casing@4"
            ]
        },
        {
            "x": -13,
            "y": -3,
            "z": 1,
            "elements": [
                "gregtech:fusion_casing@4"
            ]
        },
        {
            "x": -5,
            "y": -1,
            "z": -52,
            "elements": [
                "gregtech:fusion_casing@4"
            ]
        },
        {
            "x": -12,
            "y": -3,
            "z": 1,
            "elements": [
                "gregtech:fusion_casing@4"
            ]
        },
        {
            "x": -11,
            "y": -3,
            "z": 1,
            "elements": [
                "gregtech:fusion_casing@4"
            ]
        },
        {
            "x": 25,
            "y": 1,
            "z": -18,
            "elements": [
                "gregtech:fusion_casing@4"
            ]
        },
        {
            "x": -10,
            "y": -3,
            "z": 1,
            "elements": [
                "gregtech:fusion_casing@4"
            ]
        },
        {
            "x": -9,
            "y": -3,
            "z": 1,
            "elements": [
                "gregtech:fusion_casing@4"
            ]
        },
        {
            "x": -24,
            "y": 1,
            "z": -35,
            "elements": [
                "gregtech:fusion_casing@4"
            ]
        },
        {
            "x": -10,
            "y": -1,
            "z": -52,
            "elements": [
                "gregtech:wire_coil@7"
            ]
        },
        {
            "x": -8,
            "y": -3,
            "z": 1,
            "elements": [
                "gregtech:fusion_casing@4"
            ]
        },
        {
            "x": -11,
            "y": -1,
            "z": -52,
            "elements": [
                "gregtech:wire_coil@7"
            ]
        },
        {
            "x": -7,
            "y": -3,
            "z": 1,
            "elements": [
                "gregtech:fusion_casing@4"
            ]
        },
        {
            "x": -27,
            "y": 1,
            "z": -35,
            "elements": [
                "gregtech:wire_coil@7"
            ]
        },
        {
            "x": -12,
            "y": -1,
            "z": -52,
            "elements": [
                "gregtech:boiler_casing@3"
            ]
        },
        {
            "x": -6,
            "y": -3,
            "z": 1,
            "elements": [
                "gregtech:fusion_casing@4"
            ]
        },
        {
            "x": -28,
            "y": 1,
            "z": -35,
            "elements": [
                "gregtech:boiler_casing@3"
            ]
        },
        {
            "x": -13,
            "y": -1,
            "z": -52,
            "elements": [
                "gregtech:boiler_casing@3"
            ]
        },
        {
            "x": -29,
            "y": 1,
            "z": -35,
            "elements": [
                "gregtech:wire_coil@7"
            ]
        },
        {
            "x": -14,
            "y": -1,
            "z": -52,
            "elements": [
                "gregtech:boiler_casing@3"
            ]
        },
        {
            "x": 17,
            "y": -2,
            "z": -52,
            "elements": [
                "gregtech:fusion_casing@4"
            ]
        },
        {
            "x": -15,
            "y": -1,
            "z": -52,
            "elements": [
                "gregtech:wire_coil@7"
            ]
        },
        {
            "x": 16,
            "y": -2,
            "z": -52,
            "elements": [
                "gregtech:fusion_casing@4"
            ]
        },
        {
            "x": -31,
            "y": 1,
            "z": -35,
            "elements": [
                "gregtech:fusion_casing@4"
            ]
        },
        {
            "x": 31,
            "y": -1,
            "z": -35,
            "elements": [
                "gregtech:fusion_casing@4"
            ]
        },
        {
            "x": 14,
            "y": -2,
            "z": -52,
            "elements": [
                "gregtech:fusion_casing@1"
            ]
        },
        {
            "x": -18,
            "y": -1,
            "z": -52,
            "elements": [
                "modularmachinery:blockenergyinputhatch"
            ]
        },
        {
            "x": 29,
            "y": -1,
            "z": -35,
            "elements": [
                "gregtech:wire_coil@7"
            ]
        },
        {
            "x": 13,
            "y": -2,
            "z": -52,
            "elements": [
                "gregtech:fusion_casing@1"
            ]
        },
        {
            "x": -19,
            "y": -1,
            "z": -52,
            "elements": [
                "modularmachinery:blockenergyinputhatch"
            ]
        },
        {
            "x": 28,
            "y": -1,
            "z": -35,
            "elements": [
                "gregtech:boiler_casing@3"
            ]
        },
        {
            "x": 12,
            "y": -2,
            "z": -52,
            "elements": [
                "gregtech:fusion_casing@1"
            ]
        },
        {
            "x": 27,
            "y": -1,
            "z": -35,
            "elements": [
                "gregtech:wire_coil@7"
            ]
        },
        {
            "x": 9,
            "y": -2,
            "z": -52,
            "elements": [
                "gregtech:fusion_casing@4"
            ]
        },
        {
            "x": 24,
            "y": -1,
            "z": -35,
            "elements": [
                "gregtech:fusion_casing@4"
            ]
        },
        {
            "x": 8,
            "y": -2,
            "z": -52,
            "elements": [
                "gregtech:fusion_casing@4"
            ]
        },
        {
            "x": 6,
            "y": -3,
            "z": 1,
            "elements": [
                "gregtech:fusion_casing@4"
            ]
        },
        {
            "x": 7,
            "y": -2,
            "z": -52,
            "elements": [
                "gregtech:fusion_casing@4"
            ]
        },
        {
            "x": 6,
            "y": -2,
            "z": -52,
            "elements": [
                "gregtech:fusion_casing@4"
            ]
        },
        {
            "x": 7,
            "y": -3,
            "z": 1,
            "elements": [
                "gregtech:fusion_casing@4"
            ]
        },
        {
            "x": 8,
            "y": -3,
            "z": 1,
            "elements": [
                "gregtech:fusion_casing@4"
            ]
        },
        {
            "x": -26,
            "y": 2,
            "z": -18,
            "elements": [
                "gregtech:fusion_casing@4"
            ]
        },
        {
            "x": 9,
            "y": -3,
            "z": 1,
            "elements": [
                "gregtech:fusion_casing@4"
            ]
        },
        {
            "x": 10,
            "y": -3,
            "z": 1,
            "elements": [
                "gregtech:fusion_casing@4"
            ]
        },
        {
            "x": -28,
            "y": 2,
            "z": -18,
            "elements": [
                "gregtech:fusion_casing@1"
            ]
        },
        {
            "x": 11,
            "y": -3,
            "z": 1,
            "elements": [
                "gregtech:fusion_casing@4"
            ]
        },
        {
            "x": -12,
            "y": 3,
            "z": -1,
            "elements": [
                "gregtech:fusion_casing@4"
            ]
        },
        {
            "x": 18,
            "y": 2,
            "z": -1,
            "elements": [
                "gregtech:fusion_casing@4"
            ]
        },
        {
            "x": 12,
            "y": -3,
            "z": 1,
            "elements": [
                "gregtech:fusion_casing@4"
            ]
        },
        {
            "x": -13,
            "y": 3,
            "z": -1,
            "elements": [
                "gregtech:fusion_casing@4"
            ]
        },
        {
            "x": -30,
            "y": 2,
            "z": -18,
            "elements": [
                "gregtech:fusion_casing@4"
            ]
        },
        {
            "x": 13,
            "y": -3,
            "z": 1,
            "elements": [
                "gregtech:fusion_casing@4"
            ]
        },
        {
            "x": -14,
            "y": 3,
            "z": -1,
            "elements": [
                "gregtech:fusion_casing@4"
            ]
        },
        {
            "x": 14,
            "y": -3,
            "z": 1,
            "elements": [
                "gregtech:fusion_casing@4"
            ]
        },
        {
            "x": 31,
            "y": 0,
            "z": -18,
            "elements": [
                "gregtech:fusion_casing@4"
            ]
        },
        {
            "x": -15,
            "y": 3,
            "z": -1,
            "elements": [
                "gregtech:fusion_casing@4"
            ]
        },
        {
            "x": 15,
            "y": 2,
            "z": -1,
            "elements": [
                "gregtech:fusion_casing@1"
            ]
        },
        {
            "x": -16,
            "y": 3,
            "z": -1,
            "elements": [
                "gregtech:fusion_casing@4"
            ]
        },
        {
            "x": -16,
            "y": -2,
            "z": 1,
            "elements": [
                "gregtech:fusion_casing@4"
            ]
        },
        {
            "x": 29,
            "y": 0,
            "z": -18,
            "elements": [
                "gregtech:wire_coil@7"
            ]
        },
        {
            "x": -15,
            "y": -2,
            "z": 1,
            "elements": [
                "gregtech:fusion_casing@4"
            ]
        },
        {
            "x": -17,
            "y": 3,
            "z": -1,
            "elements": [
                "gregtech:fusion_casing@4"
            ]
        },
        {
            "x": 28,
            "y": 0,
            "z": -18,
            "elements": [
                "gregtech:boiler_casing@3"
            ]
        },
        {
            "x": 27,
            "y": 0,
            "z": -18,
            "elements": [
                "gregtech:wire_coil@7"
            ]
        },
        {
            "x": 11,
            "y": 2,
            "z": -1,
            "elements": [
                "gregtech:fusion_casing@4"
            ]
        },
        {
            "x": -6,
            "y": -2,
            "z": -52,
            "elements": [
                "gregtech:fusion_casing@4"
            ]
        },
        {
            "x": 10,
            "y": 2,
            "z": -1,
            "elements": [
                "gregtech:fusion_casing@4"
            ]
        },
        {
            "x": -11,
            "y": -2,
            "z": 1,
            "elements": [
                "gregtech:fusion_casing@1"
            ]
        },
        {
            "x": -7,
            "y": -2,
            "z": -52,
            "elements": [
                "gregtech:fusion_casing@4"
            ]
        },
        {
            "x": 25,
            "y": 0,
            "z": -18,
            "elements": [
                "gregtech:fusion_casing@4"
            ]
        },
        {
            "x": 9,
            "y": 2,
            "z": -1,
            "elements": [
                "gregtech:fusion_casing@4"
            ]
        },
        {
            "x": -10,
            "y": -2,
            "z": 1,
            "elements": [
                "gregtech:fusion_casing@1"
            ]
        },
        {
            "x": -8,
            "y": -2,
            "z": -52,
            "elements": [
                "gregtech:fusion_casing@4"
            ]
        },
        {
            "x": -9,
            "y": -2,
            "z": -52,
            "elements": [
                "gregtech:fusion_casing@4"
            ]
        },
        {
            "x": -24,
            "y": 0,
            "z": -35,
            "elements": [
                "gregtech:fusion_casing@4"
            ]
        },
        {
            "x": -27,
            "y": 0,
            "z": -35,
            "elements": [
                "gregtech:wire_coil@7"
            ]
        },
        {
            "x": -12,
            "y": -2,
            "z": -52,
            "elements": [
                "gregtech:fusion_casing@1"
            ]
        },
        {
            "x": -28,
            "y": 0,
            "z": -35,
            "elements": [
                "gregtech:boiler_casing@3"
            ]
        },
        {
            "x": -13,
            "y": -2,
            "z": -52,
            "elements": [
                "gregtech:fusion_casing@1"
            ]
        },
        {
            "x": -5,
            "y": -2,
            "z": 1,
            "elements": [
                "gregtech:fusion_casing@4"
            ]
        },
        {
            "x": -29,
            "y": 0,
            "z": -35,
            "elements": [
                "gregtech:wire_coil@7"
            ]
        },
        {
            "x": -4,
            "y": -2,
            "z": 1,
            "elements": [
                "gregtech:fusion_casing@4"
            ]
        },
        {
            "x": -14,
            "y": -2,
            "z": -52,
            "elements": [
                "gregtech:fusion_casing@1"
            ]
        },
        {
            "x": -3,
            "y": -2,
            "z": 1,
            "elements": [
                "gregtech:fusion_casing@4"
            ]
        },
        {
            "x": -2,
            "y": -2,
            "z": 1,
            "elements": [
                "gregtech:fusion_casing@4"
            ]
        },
        {
            "x": -31,
            "y": 0,
            "z": -35,
            "elements": [
                "gregtech:fusion_casing@4"
            ]
        },
        {
            "x": 15,
            "y": -3,
            "z": -52,
            "elements": [
                "gregtech:fusion_casing@4"
            ]
        },
        {
            "x": -16,
            "y": -2,
            "z": -52,
            "elements": [
                "gregtech:fusion_casing@4"
            ]
        },
        {
            "x": -1,
            "y": -2,
            "z": 1,
            "elements": [
                "gcym:large_multiblock_casing@11"
            ]
        },
        {
            "x": 30,
            "y": -2,
            "z": -35,
            "elements": [
                "gregtech:fusion_casing@4"
            ]
        },
        {
            "x": 14,
            "y": -3,
            "z": -52,
            "elements": [
                "gregtech:fusion_casing@4"
            ]
        },
        {
            "x": -17,
            "y": -2,
            "z": -52,
            "elements": [
                "gregtech:fusion_casing@4"
            ]
        },
        {
            "x": 0,
            "y": -2,
            "z": 1,
            "elements": [
                "gregtech:fusion_casing@4"
            ]
        },
        {
            "x": 13,
            "y": -3,
            "z": -52,
            "elements": [
                "gregtech:fusion_casing@4"
            ]
        },
        {
            "x": 1,
            "y": -2,
            "z": 1,
            "elements": [
                "gcym:large_multiblock_casing@11"
            ]
        },
        {
            "x": 28,
            "y": -2,
            "z": -35,
            "elements": [
                "gregtech:fusion_casing@1"
            ]
        },
        {
            "x": 12,
            "y": -3,
            "z": -52,
            "elements": [
                "gregtech:fusion_casing@4"
            ]
        },
        {
            "x": 2,
            "y": -2,
            "z": 1,
            "elements": [
                "gregtech:fusion_casing@4"
            ]
        },
        {
            "x": 11,
            "y": -3,
            "z": -52,
            "elements": [
                "gregtech:fusion_casing@4"
            ]
        },
        {
            "x": 26,
            "y": -2,
            "z": -35,
            "elements": [
                "gregtech:fusion_casing@4"
            ]
        },
        {
            "x": 10,
            "y": -3,
            "z": -52,
            "elements": [
                "gregtech:fusion_casing@4"
            ]
        },
        {
            "x": 3,
            "y": -2,
            "z": 1,
            "elements": [
                "gregtech:fusion_casing@4"
            ]
        },
        {
            "x": 4,
            "y": -2,
            "z": 1,
            "elements": [
                "gregtech:fusion_casing@4"
            ]
        },
        {
            "x": 25,
            "y": -2,
            "z": -35,
            "elements": [
                "gregtech:fusion_casing@4"
            ]
        },
        {
            "x": 5,
            "y": -2,
            "z": 1,
            "elements": [
                "gregtech:fusion_casing@4"
            ]
        },
        {
            "x": -9,
            "y": 2,
            "z": -1,
            "elements": [
                "gregtech:fusion_casing@4"
            ]
        },
        {
            "x": -25,
            "y": 1,
            "z": -18,
            "elements": [
                "gregtech:fusion_casing@4"
            ]
        },
        {
            "x": -10,
            "y": 2,
            "z": -1,
            "elements": [
                "gregtech:fusion_casing@4"
            ]
        },
        {
            "x": -27,
            "y": 1,
            "z": -18,
            "elements": [
                "gregtech:wire_coil@7"
            ]
        },
        {
            "x": 10,
            "y": -2,
            "z": 1,
            "elements": [
                "gregtech:fusion_casing@1"
            ]
        },
        {
            "x": -11,
            "y": 2,
            "z": -1,
            "elements": [
                "gregtech:fusion_casing@4"
            ]
        },
        {
            "x": 20,
            "y": 1,
            "z": -1,
            "elements": [
                "gregtech:fusion_casing@4"
            ]
        },
        {
            "x": 19,
            "y": 1,
            "z": -1,
            "elements": [
                "gregtech:fusion_casing@4"
            ]
        },
        {
            "x": -28,
            "y": 1,
            "z": -18,
            "elements": [
                "gregtech:boiler_casing@3"
            ]
        },
        {
            "x": 11,
            "y": -2,
            "z": 1,
            "elements": [
                "gregtech:fusion_casing@1"
            ]
        },
        {
            "x": -29,
            "y": 1,
            "z": -18,
            "elements": [
                "gregtech:wire_coil@7"
            ]
        },
        {
            "x": 17,
            "y": 1,
            "z": -1,
            "elements": [
                "gregtech:wire_coil@7"
            ]
        },
        {
            "x": -31,
            "y": 1,
            "z": -18,
            "elements": [
                "gregtech:fusion_casing@4"
            ]
        },
        {
            "x": 31,
            "y": -1,
            "z": -18,
            "elements": [
                "gregtech:fusion_casing@4"
            ]
        },
        {
            "x": -15,
            "y": 2,
            "z": -1,
            "elements": [
                "gregtech:fusion_casing@1"
            ]
        },
        {
            "x": 16,
            "y": 1,
            "z": -1,
            "elements": [
                "gregtech:wire_coil@7"
            ]
        },
        {
            "x": -17,
            "y": -1,
            "z": 1,
            "elements": [
                "gregtech:fusion_casing@4"
            ]
        },
        {
            "x": 15,
            "y": -2,
            "z": 1,
            "elements": [
                "gregtech:fusion_casing@4"
            ]
        },
        {
            "x": 15,
            "y": 1,
            "z": -1,
            "elements": [
                "gregtech:boiler_casing@3"
            ]
        },
        {
            "x": 29,
            "y": -1,
            "z": -18,
            "elements": [
                "gregtech:wire_coil@7"
