{
  "registryname": "Ultimate_Planetary_Drilling_Plant",
  "localizedname": "Ultimate Planetary Drilling Plant",
   "color": "ff0400",
    "parts": [
        {
            "x": -1,
            "y": 0,
            "z": 0,
            "elements": [
                "modularmachinery:blockinputbus"
            ]
        },
        {
            "x": 1,
            "y": 0,
            "z": 0,
            "elements": [
                "modularmachinery:blockinputbus"
            ]
        },
        {
            "x": -2,
            "y": 0,
            "z": 0,
            "elements": [
                "modularmachinery:blockfluidinputhatch"
            ]
        },
        {
            "x": 17,
            "y": 1,
            "z": 17,
            "elements": [
                "gregtech:meta_block_frame_187@12"
            ]
        },
        {
            "x": 2,
            "y": 0,
            "z": 0,
            "elements": [
                "modularmachinery:blockfluidinputhatch"
            ]
        },
        {
            "x": -3,
            "y": 0,
            "z": 0,
            "elements": [
                "modularmachinery:blockfluidinputhatch"
            ]
        },
        {
            "x": 0,
            "y": 26,
            "z": 29,
            "elements": [
                "gregtech:meta_block_frame_187@12"
            ]
        },
        {
            "x": 3,
            "y": 0,
            "z": 0,
            "elements": [
                "modularmachinery:blockfluidinputhatch"
            ]
        },
        {
            "x": -4,
            "y": 0,
            "z": 0,
            "elements": [
                "gregtech:metal_casing@7"
            ]
        },
        {
            "x": 4,
            "y": 0,
            "z": 0,
            "elements": [
                "gregtech:metal_casing@7"
            ]
        },
        {
            "x": -6,
            "y": 2,
            "z": 17,
            "elements": [
                "gregtech:metal_casing@7"
            ]
        },
        {
            "x": -5,
            "y": 2,
            "z": 17,
            "elements": [
                "gregtech:metal_casing@7"
            ]
        },
        {
            "x": 0,
            "y": 10,
            "z": 21,
            "elements": [
                "gregtech:metal_casing@7"
            ]
        },
        {
            "x": -4,
            "y": 2,
            "z": 17,
            "elements": [
                "gregtech:metal_casing@7"
            ]
        },
        {
            "x": -3,
            "y": 2,
            "z": 17,
            "elements": [
                "gregtech:turbine_casing@4"
            ]
        },
        {
            "x": -2,
            "y": 2,
            "z": 17,
            "elements": [
                "gregtech:boiler_casing@3"
            ]
        },
        {
            "x": -1,
            "y": 33,
            "z": 16,
            "elements": [
                "gregtech:metal_casing@7"
            ]
        },
        {
            "x": -1,
            "y": 2,
            "z": 17,
            "elements": [
                "gregtech:boiler_casing@3"
            ]
        },
        {
            "x": 0,
            "y": 2,
            "z": 17,
            "elements": [
                "gregtech:boiler_casing@3"
            ]
        },
        {
            "x": 0,
            "y": 33,
            "z": 16,
            "elements": [
                "gregtech:boiler_casing@3"
            ]
        },
        {
            "x": 1,
            "y": 2,
            "z": 17,
            "elements": [
                "gregtech:boiler_casing@3"
            ]
        },
        {
            "x": 1,
            "y": 33,
            "z": 16,
            "elements": [
                "gregtech:metal_casing@7"
            ]
        },
        {
            "x": 2,
            "y": 2,
            "z": 17,
            "elements": [
                "gregtech:boiler_casing@3"
            ]
        },
        {
            "x": 3,
            "y": 2,
            "z": 17,
            "elements": [
                "gregtech:turbine_casing@4"
            ]
        },
        {
            "x": 0,
            "y": 56,
            "z": 11,
            "elements": [
                "gregtech:meta_block_frame_187@12"
            ]
        },
        {
            "x": 4,
            "y": 2,
            "z": 17,
            "elements": [
                "gregtech:metal_casing@7"
            ]
        },
        {
            "x": 5,
            "y": 2,
            "z": 17,
            "elements": [
                "gregtech:metal_casing@7"
            ]
        },
        {
            "x": 6,
            "y": 2,
            "z": 17,
            "elements": [
                "gregtech:metal_casing@7"
            ]
        },
        {
            "x": -17,
            "y": 3,
            "z": 17,
            "elements": [
                "gregtech:meta_block_frame_187@12"
            ]
        },
        {
            "x": 0,
            "y": 1,
            "z": 0,
            "elements": [
                "gregtech:meta_block_frame_187@12"
            ]
        },
        {
            "x": 17,
            "y": 2,
            "z": 17,
            "elements": [
                "gregtech:meta_block_frame_187@12"
            ]
        },
        {
            "x": -6,
            "y": 3,
            "z": 17,
            "elements": [
                "gregtech:metal_casing@7"
            ]
        },
        {
            "x": -5,
            "y": 3,
            "z": 17,
            "elements": [
                "gregtech:metal_casing@7"
            ]
        },
        {
            "x": 0,
            "y": 11,
            "z": 21,
            "elements": [
                "gregtech:metal_casing@7"
            ]
        },
        {
            "x": 0,
            "y": 73,
            "z": 19,
            "elements": [
                "gregtech:meta_block_frame_187@12"
            ]
        },
        {
            "x": -4,
            "y": 3,
            "z": 17,
            "elements": [
                "gregtech:metal_casing@7"
            ]
        },
        {
            "x": -3,
            "y": 3,
            "z": 17,
            "elements": [
                "gregtech:turbine_casing@4"
            ]
        },
        {
            "x": -2,
            "y": 3,
            "z": 17,
            "elements": [
                "gregtech:boiler_casing@3"
            ]
        },
        {
            "x": -1,
            "y": 34,
            "z": 16,
            "elements": [
                "gregtech:metal_casing@7"
            ]
        },
        {
            "x": -1,
            "y": 3,
            "z": 17,
            "elements": [
                "gregtech:boiler_casing@3"
            ]
        },
        {
            "x": 0,
            "y": 3,
            "z": 17,
            "elements": [
                "gregtech:boiler_casing@3"
            ]
        },
        {
            "x": 0,
            "y": 34,
            "z": 16,
            "elements": [
                "gregtech:boiler_casing@3"
            ]
        },
        {
            "x": 1,
            "y": 3,
            "z": 17,
            "elements": [
                "gregtech:boiler_casing@3"
            ]
        },
        {
            "x": 1,
            "y": 34,
            "z": 16,
            "elements": [
                "gregtech:metal_casing@7"
            ]
        },
        {
            "x": 2,
            "y": 3,
            "z": 17,
            "elements": [
                "gregtech:boiler_casing@3"
            ]
        },
        {
            "x": 3,
            "y": 3,
            "z": 17,
            "elements": [
                "gregtech:turbine_casing@4"
            ]
        },
        {
            "x": 4,
            "y": 3,
            "z": 17,
            "elements": [
                "gregtech:metal_casing@7"
            ]
        },
        {
            "x": 5,
            "y": 3,
            "z": 17,
            "elements": [
                "gregtech:metal_casing@7"
            ]
        },
        {
            "x": 6,
            "y": 3,
            "z": 17,
            "elements": [
                "gregtech:metal_casing@7"
            ]
        },
        {
            "x": -16,
            "y": 4,
            "z": 17,
            "elements": [
                "gregtech:meta_block_frame_187@12"
            ]
        },
        {
            "x": 0,
            "y": 2,
            "z": 0,
            "elements": [
                "gregtech:meta_block_frame_187@12"
            ]
        },
        {
            "x": 17,
            "y": 3,
            "z": 17,
            "elements": [
                "gregtech:meta_block_frame_187@12"
            ]
        },
        {
            "x": -5,
            "y": 4,
            "z": 17,
            "elements": [
                "gregtech:metal_casing@7"
            ]
        },
        {
            "x": 0,
            "y": 74,
            "z": 19,
            "elements": [
                "gregtech:meta_block_frame_187@12"
            ]
        },
        {
            "x": -4,
            "y": 4,
            "z": 17,
            "elements": [
                "gregtech:metal_casing@7"
            ]
        },
        {
            "x": -3,
            "y": 4,
            "z": 17,
            "elements": [
                "gregtech:turbine_casing@4"
            ]
        },
        {
            "x": -2,
            "y": 4,
            "z": 17,
            "elements": [
                "gregtech:boiler_casing@3"
            ]
        },
        {
            "x": -1,
            "y": 35,
            "z": 16,
            "elements": [
                "gregtech:metal_casing@7"
            ]
        },
        {
            "x": -1,
            "y": 4,
            "z": 17,
            "elements": [
                "gregtech:boiler_casing@3"
            ]
        },
        {
            "x": 0,
            "y": 4,
            "z": 17,
            "elements": [
                "gregtech:boiler_casing@3"
            ]
        },
        {
            "x": 0,
            "y": 35,
            "z": 16,
            "elements": [
                "gregtech:boiler_casing@3"
            ]
        },
        {
            "x": 1,
            "y": 4,
            "z": 17,
            "elements": [
                "gregtech:boiler_casing@3"
            ]
        },
        {
            "x": 1,
            "y": 35,
            "z": 16,
            "elements": [
                "gregtech:metal_casing@7"
            ]
        },
        {
            "x": 2,
            "y": 4,
            "z": 17,
            "elements": [
                "gregtech:boiler_casing@3"
            ]
        },
        {
            "x": 3,
            "y": 4,
            "z": 17,
            "elements": [
                "gregtech:turbine_casing@4"
            ]
        },
        {
            "x": 4,
            "y": 4,
            "z": 17,
            "elements": [
                "gregtech:metal_casing@7"
            ]
        },
        {
            "x": 5,
            "y": 4,
            "z": 17,
            "elements": [
                "gregtech:metal_casing@7"
            ]
        },
        {
            "x": -16,
            "y": 5,
            "z": 17,
            "elements": [
                "gregtech:meta_block_frame_187@12"
            ]
        },
        {
            "x": 0,
            "y": 3,
            "z": 0,
            "elements": [
                "gregtech:meta_block_frame_187@12"
            ]
        },
        {
            "x": 16,
            "y": 4,
            "z": 17,
            "elements": [
                "gregtech:meta_block_frame_187@12"
            ]
        },
        {
            "x": -5,
            "y": 5,
            "z": 17,
            "elements": [
                "gregtech:metal_casing@7"
            ]
        },
        {
            "x": 0,
            "y": 75,
            "z": 19,
            "elements": [
                "gregtech:meta_block_frame_187@12"
            ]
        },
        {
            "x": -4,
            "y": 5,
            "z": 17,
            "elements": [
                "gregtech:metal_casing@7"
            ]
        },
        {
            "x": -3,
            "y": 5,
            "z": 17,
            "elements": [
                "gregtech:turbine_casing@4"
            ]
        },
        {
            "x": -2,
            "y": 5,
            "z": 17,
            "elements": [
                "gregtech:boiler_casing@3"
            ]
        },
        {
            "x": -1,
            "y": 36,
            "z": 16,
            "elements": [
                "gregtech:metal_casing@7"
            ]
        },
        {
            "x": -1,
            "y": 5,
            "z": 17,
            "elements": [
                "gregtech:boiler_casing@3"
            ]
        },
        {
            "x": 0,
            "y": 5,
            "z": 17,
            "elements": [
                "gregtech:boiler_casing@3"
            ]
        },
        {
            "x": 0,
            "y": 36,
            "z": 16,
            "elements": [
                "gregtech:boiler_casing@3"
            ]
        },
        {
            "x": 1,
            "y": 5,
            "z": 17,
            "elements": [
                "gregtech:boiler_casing@3"
            ]
        },
        {
            "x": 1,
            "y": 36,
            "z": 16,
            "elements": [
                "gregtech:metal_casing@7"
            ]
        },
        {
            "x": 2,
            "y": 5,
            "z": 17,
            "elements": [
                "gregtech:boiler_casing@3"
            ]
        },
        {
            "x": 3,
            "y": 5,
            "z": 17,
            "elements": [
                "gregtech:turbine_casing@4"
            ]
        },
        {
            "x": 4,
            "y": 5,
            "z": 17,
            "elements": [
                "gregtech:metal_casing@7"
            ]
        },
        {
            "x": 5,
            "y": 5,
            "z": 17,
            "elements": [
                "gregtech:metal_casing@7"
            ]
        },
        {
            "x": -16,
            "y": 6,
            "z": 17,
            "elements": [
                "gregtech:meta_block_frame_187@12"
            ]
        },
        {
            "x": 16,
            "y": 5,
            "z": 17,
            "elements": [
                "gregtech:meta_block_frame_187@12"
            ]
        },
        {
            "x": -5,
            "y": 6,
            "z": 17,
            "elements": [
                "gregtech:metal_casing@7"
            ]
        },
        {
            "x": 0,
            "y": 76,
            "z": 19,
            "elements": [
                "gregtech:meta_block_frame_187@12"
            ]
        },
        {
            "x": -4,
            "y": 6,
            "z": 17,
            "elements": [
                "gregtech:metal_casing@7"
            ]
        },
        {
            "x": -3,
            "y": 6,
            "z": 17,
            "elements": [
                "gregtech:turbine_casing@4"
            ]
        },
        {
            "x": -2,
            "y": 6,
            "z": 17,
            "elements": [
                "gregtech:boiler_casing@3"
            ]
        },
        {
            "x": -1,
            "y": 37,
            "z": 16,
            "elements": [
                "gregtech:metal_casing@7"
            ]
        },
        {
            "x": -1,
            "y": 6,
            "z": 17,
            "elements": [
                "gregtech:boiler_casing@3"
            ]
        },
        {
            "x": 0,
            "y": 6,
            "z": 17,
            "elements": [
                "gregtech:boiler_casing@3"
            ]
        },
        {
            "x": 0,
            "y": 37,
            "z": 16,
            "elements": [
                "gregtech:boiler_casing@3"
            ]
        },
        {
            "x": 1,
            "y": 6,
            "z": 17,
            "elements": [
                "gregtech:boiler_casing@3"
            ]
        },
        {
            "x": 1,
            "y": 37,
            "z": 16,
            "elements": [
                "gregtech:metal_casing@7"
            ]
        },
        {
            "x": 2,
            "y": 6,
            "z": 17,
            "elements": [
                "gregtech:boiler_casing@3"
            ]
        },
        {
            "x": 3,
            "y": 6,
            "z": 17,
            "elements": [
                "gregtech:turbine_casing@4"
            ]
        },
        {
            "x": 4,
            "y": 6,
            "z": 17,
            "elements": [
                "gregtech:metal_casing@7"
            ]
        },
        {
            "x": 5,
            "y": 6,
            "z": 17,
            "elements": [
                "gregtech:metal_casing@7"
            ]
        },
        {
            "x": -11,
            "y": 0,
            "z": 30,
            "elements": [
                "gregtech:metal_casing@7"
            ]
        },
        {
            "x": -10,
            "y": 0,
            "z": 30,
            "elements": [
                "gregtech:metal_casing@7"
            ]
        },
        {
            "x": -9,
            "y": 0,
            "z": 30,
            "elements": [
                "gregtech:metal_casing@7"
            ]
        },
        {
            "x": -8,
            "y": 0,
            "z": 30,
            "elements": [
                "gregtech:metal_casing@7"
            ]
        },
        {
            "x": -7,
            "y": 0,
            "z": 30,
            "elements": [
                "gregtech:metal_casing@7"
            ]
        },
        {
            "x": -6,
            "y": 0,
            "z": 30,
            "elements": [
                "gregtech:metal_casing@7"
            ]
        },
        {
            "x": -5,
            "y": 0,
            "z": 30,
            "elements": [
                "gregtech:metal_casing@7"
            ]
        },
        {
            "x": -16,
            "y": 7,
            "z": 17,
            "elements": [
                "gregtech:meta_block_frame_187@12"
            ]
        },
        {
            "x": -4,
            "y": 0,
            "z": 30,
            "elements": [
                "gregtech:metal_casing@7"
            ]
        },
        {
            "x": -3,
            "y": 0,
            "z": 30,
            "elements": [
                "gregtech:metal_casing@7"
            ]
        },
        {
            "x": 16,
            "y": 6,
            "z": 17,
            "elements": [
                "gregtech:meta_block_frame_187@12"
            ]
        },
        {
            "x": -2,
            "y": 0,
            "z": 30,
            "elements": [
                "gregtech:metal_casing@7"
            ]
        },
        {
            "x": -1,
            "y": 0,
            "z": 30,
            "elements": [
                "gregtech:metal_casing@7"
            ]
        },
        {
            "x": 0,
            "y": 0,
            "z": 30,
            "elements": [
                "gregtech:metal_casing@7"
            ]
        },
        {
            "x": 1,
            "y": 0,
            "z": 30,
            "elements": [
                "gregtech:metal_casing@7"
            ]
        },
        {
            "x": 2,
            "y": 0,
            "z": 30,
            "elements": [
                "gregtech:metal_casing@7"
            ]
        },
        {
            "x": 3,
            "y": 0,
            "z": 30,
            "elements": [
                "gregtech:metal_casing@7"
            ]
        },
        {
            "x": 4,
            "y": 0,
            "z": 30,
            "elements": [
                "gregtech:metal_casing@7"
            ]
        },
        {
            "x": 5,
            "y": 0,
            "z": 30,
            "elements": [
                "gregtech:metal_casing@7"
            ]
        },
        {
            "x": 6,
            "y": 0,
            "z": 30,
            "elements": [
                "gregtech:metal_casing@7"
            ]
        },
        {
            "x": 7,
            "y": 0,
            "z": 30,
            "elements": [
                "gregtech:metal_casing@7"
            ]
        },
        {
            "x": 0,
            "y": 77,
            "z": 19,
            "elements": [
                "gregtech:meta_block_frame_187@12"
            ]
        },
        {
            "x": 8,
            "y": 0,
            "z": 30,
            "elements": [
                "gregtech:metal_casing@7"
            ]
        },
        {
            "x": -4,
            "y": 7,
            "z": 17,
            "elements": [
                "gregtech:metal_casing@7"
            ]
        },
        {
            "x": 9,
            "y": 0,
            "z": 30,
            "elements": [
                "gregtech:metal_casing@7"
            ]
        },
        {
            "x": -3,
            "y": 7,
            "z": 17,
            "elements": [
                "gregtech:turbine_casing@4"
            ]
        },
        {
            "x": 10,
            "y": 0,
            "z": 30,
            "elements": [
                "gregtech:metal_casing@7"
            ]
        },
        {
            "x": -2,
            "y": 7,
            "z": 17,
            "elements": [
                "gregtech:boiler_casing@3"
            ]
        },
        {
            "x": -1,
            "y": 38,
            "z": 16,
            "elements": [
                "gregtech:metal_casing@7"
            ]
        },
        {
            "x": -1,
            "y": 7,
            "z": 17,
            "elements": [
                "gregtech:boiler_casing@3"
            ]
        },
        {
            "x": 11,
            "y": 0,
            "z": 30,
            "elements": [
                "gregtech:metal_casing@7"
            ]
        },
        {
            "x": 0,
            "y": 7,
            "z": 17,
            "elements": [
                "gregtech:boiler_casing@3"
            ]
        },
        {
            "x": 0,
            "y": 38,
            "z": 16,
            "elements": [
                "gregtech:boiler_casing@3"
            ]
        },
        {
            "x": 1,
            "y": 7,
            "z": 17,
            "elements": [
                "gregtech:boiler_casing@3"
            ]
        },
        {
            "x": 1,
            "y": 38,
            "z": 16,
            "elements": [
                "gregtech:metal_casing@7"
            ]
        },
        {
            "x": 2,
            "y": 7,
            "z": 17,
            "elements": [
                "gregtech:boiler_casing@3"
            ]
        },
        {
            "x": 3,
            "y": 7,
            "z": 17,
            "elements": [
                "gregtech:turbine_casing@4"
            ]
        },
        {
            "x": 4,
            "y": 7,
            "z": 17,
            "elements": [
                "gregtech:metal_casing@7"
            ]
        },
        {
            "x": -16,
            "y": 8,
            "z": 17,
            "elements": [
                "gregtech:meta_block_frame_187@12"
            ]
        },
        {
            "x": 16,
            "y": 7,
            "z": 17,
            "elements": [
                "gregtech:meta_block_frame_187@12"
            ]
        },
        {
            "x": -17,
            "y": 0,
            "z": 13,
            "elements": [
                "gregtech:metal_casing@7"
            ]
        },
        {
            "x": -16,
            "y": 0,
            "z": 13,
            "elements": [
                "gregtech:metal_casing@7"
            ]
        },
        {
            "x": -15,
            "y": 0,
            "z": 13,
            "elements": [
                "gregtech:metal_casing@7"
            ]
        },
        {
            "x": -14,
            "y": 0,
            "z": 13,
            "elements": [
                "gregtech:metal_casing@7"
            ]
        },
        {
            "x": -13,
            "y": 0,
            "z": 13,
            "elements": [
                "gregtech:metal_casing@7"
            ]
        },
        {
            "x": -12,
            "y": 0,
            "z": 13,
            "elements": [
                "gregtech:metal_casing@7"
            ]
        },
        {
            "x": -11,
            "y": 0,
            "z": 13,
            "elements": [
                "gregtech:metal_casing@7"
            ]
        },
        {
            "x": -10,
            "y": 0,
            "z": 13,
            "elements": [
                "gregtech:metal_casing@7"
            ]
        },
        {
            "x": -9,
            "y": 0,
            "z": 13,
            "elements": [
                "gregtech:metal_casing@7"
            ]
        },
        {
            "x": -8,
            "y": 0,
            "z": 13,
            "elements": [
                "gregtech:metal_casing@7"
            ]
        },
        {
            "x": -4,
            "y": 8,
            "z": 17,
            "elements": [
                "gregtech:metal_casing@7"
            ]
        },
        {
            "x": -7,
            "y": 0,
            "z": 13,
            "elements": [
                "gregtech:metal_casing@7"
            ]
        },
        {
            "x": -3,
            "y": 8,
            "z": 17,
            "elements": [
                "gregtech:turbine_casing@4"
            ]
        },
        {
            "x": -6,
            "y": 0,
            "z": 13,
            "elements": [
                "gregtech:metal_casing@7"
            ]
        },
        {
            "x": -2,
            "y": 8,
            "z": 17,
            "elements": [
                "gregtech:boiler_casing@3"
            ]
        },
        {
            "x": -1,
            "y": 39,
            "z": 16,
            "elements": [
                "gregtech:metal_casing@7"
            ]
        },
        {
            "x": -5,
            "y": 0,
            "z": 13,
            "elements": [
                "gregtech:metal_casing@7"
            ]
        },
        {
            "x": -1,
            "y": 8,
            "z": 17,
            "elements": [
                "gregtech:boiler_casing@3"
            ]
        },
        {
            "x": 0,
            "y": 8,
            "z": 17,
            "elements": [
                "gregtech:boiler_casing@3"
            ]
        },
        {
            "x": 0,
            "y": 39,
            "z": 16,
            "elements": [
                "gregtech:boiler_casing@3"
            ]
        },
        {
            "x": -4,
            "y": 0,
            "z": 13,
            "elements": [
                "gregtech:metal_casing@7"
            ]
        },
        {
            "x": 1,
            "y": 8,
            "z": 17,
            "elements": [
                "gregtech:boiler_casing@3"
            ]
        },
        {
            "x": 1,
            "y": 39,
            "z": 16,
            "elements": [
                "gregtech:metal_casing@7"
            ]
        },
        {
            "x": -3,
            "y": 0,
            "z": 13,
            "elements": [
                "gregtech:metal_casing@7"
            ]
        },
        {
            "x": -2,
            "y": 0,
            "z": 13,
            "elements": [
                "gregtech:metal_casing@7"
            ]
        },
        {
            "x": 2,
            "y": 8,
            "z": 17,
            "elements": [
                "gregtech:boiler_casing@3"
            ]
        },
        {
            "x": -1,
            "y": 0,
            "z": 13,
            "elements": [
                "gregtech:metal_casing@7"
            ]
        },
        {
            "x": 3,
            "y": 8,
            "z": 17,
            "elements": [
                "gregtech:turbine_casing@4"
            ]
        },
        {
            "x": 0,
            "y": 0,
            "z": 13,
            "elements": [
                "gregtech:metal_casing@7"
            ]
        },
        {
            "x": 4,
            "y": 8,
            "z": 17,
            "elements": [
                "gregtech:metal_casing@7"
            ]
        },
        {
            "x": 1,
            "y": 0,
            "z": 13,
            "elements": [
                "gregtech:metal_casing@7"
            ]
        },
        {
            "x": 2,
            "y": 0,
            "z": 13,
            "elements": [
                "gregtech:metal_casing@7"
            ]
        },
        {
            "x": 3,
            "y": 0,
            "z": 13,
            "elements": [
                "gregtech:metal_casing@7"
            ]
        },
        {
            "x": 4,
            "y": 0,
            "z": 13,
            "elements": [
                "gregtech:metal_casing@7"
            ]
        },
        {
            "x": 5,
            "y": 0,
            "z": 13,
            "elements": [
                "gregtech:metal_casing@7"
            ]
        },
        {
            "x": 6,
            "y": 0,
            "z": 13,
            "elements": [
                "gregtech:metal_casing@7"
            ]
        },
        {
            "x": 7,
            "y": 0,
            "z": 13,
            "elements": [
                "gregtech:metal_casing@7"
            ]
        },
        {
            "x": 8,
            "y": 0,
            "z": 13,
            "elements": [
                "gregtech:metal_casing@7"
            ]
        },
        {
            "x": 9,
            "y": 0,
            "z": 13,
            "elements": [
                "gregtech:metal_casing@7"
            ]
        },
        {
            "x": 10,
            "y": 0,
            "z": 13,
            "elements": [
                "gregtech:metal_casing@7"
            ]
        },
        {
            "x": 11,
            "y": 0,
            "z": 13,
            "elements": [
                "gregtech:metal_casing@7"
            ]
        },
        {
            "x": -15,
            "y": 9,
            "z": 17,
            "elements": [
                "gregtech:meta_block_frame_187@12"
            ]
        },
        {
            "x": 16,
            "y": 8,
            "z": 17,
            "elements": [
                "gregtech:meta_block_frame_187@12"
            ]
        },
        {
            "x": 12,
            "y": 0,
            "z": 13,
            "elements": [
                "gregtech:metal_casing@7"
            ]
        },
        {
            "x": 13,
            "y": 0,
            "z": 13,
            "elements": [
                "gregtech:metal_casing@7"
            ]
        },
        {
            "x": 14,
            "y": 0,
            "z": 13,
            "elements": [
                "gregtech:metal_casing@7"
            ]
        },
        {
            "x": 15,
            "y": 0,
            "z": 13,
            "elements": [
                "gregtech:metal_casing@7"
            ]
        },
        {
            "x": 16,
            "y": 0,
            "z": 13,
            "elements": [
                "gregtech:metal_casing@7"
            ]
        },
        {
            "x": 17,
            "y": 0,
            "z": 13,
            "elements": [
                "gregtech:metal_casing@7"
            ]
        },
        {
            "x": -4,
            "y": 9,
            "z": 17,
            "elements": [
                "gregtech:metal_casing@7"
            ]
        },
        {
            "x": -3,
            "y": 9,
            "z": 17,
            "elements": [
                "gregtech:turbine_casing@4"
            ]
        },
        {
            "x": -2,
            "y": 9,
            "z": 17,
            "elements": [
                "gregtech:boiler_casing@3"
            ]
        },
        {
            "x": -1,
            "y": 40,
            "z": 16,
            "elements": [
                "gregtech:metal_casing@7"
            ]
        },
        {
            "x": -1,
            "y": 9,
            "z": 17,
            "elements": [
                "gregtech:boiler_casing@3"
            ]
        },
        {
            "x": 0,
            "y": 9,
            "z": 17,
            "elements": [
                "gregtech:boiler_casing@3"
            ]
        },
        {
            "x": 0,
            "y": 40,
            "z": 16,
            "elements": [
                "gregtech:boiler_casing@3"
            ]
        },
        {
            "x": 1,
            "y": 9,
            "z": 17,
            "elements": [
                "gregtech:boiler_casing@3"
            ]
        },
        {
            "x": 1,
            "y": 40,
            "z": 16,
            "elements": [
                "gregtech:metal_casing@7"
            ]
        },
        {
            "x": -2,
            "y": 1,
            "z": 13,
            "elements": [
                "gregtech:metal_casing@7"
            ]
        },
        {
            "x": 2,
            "y": 9,
            "z": 17,
            "elements": [
                "gregtech:boiler_casing@3"
            ]
        },
        {
            "x": -1,
            "y": 1,
            "z": 13,
            "elements": [
                "gregtech:metal_casing@7"
            ]
        },
        {
            "x": 3,
            "y": 9,
            "z": 17,
            "elements": [
                "gregtech:turbine_casing@4"
            ]
        },
        {
            "x": 4,
            "y": 9,
            "z": 17,
            "elements": [
                "gregtech:metal_casing@7"
            ]
        },
        {
            "x": 0,
            "y": 1,
            "z": 13,
            "elements": [
                "gregtech:metal_casing@7"
            ]
        },
        {
            "x": 1,
            "y": 1,
            "z": 13,
            "elements": [
                "gregtech:metal_casing@7"
            ]
        },
        {
            "x": 2,
            "y": 1,
            "z": 13,
            "elements": [
                "gregtech:metal_casing@7"
            ]
        },
        {
            "x": 15,
            "y": 9,
            "z": 17,
            "elements": [
                "gregtech:meta_block_frame_187@12"
            ]
        },
        {
            "x": -15,
            "y": 10,
            "z": 17,
            "elements": [
                "gregtech:meta_block_frame_187@12"
            ]
        },
        {
            "x": -4,
            "y": 10,
            "z": 17,
            "elements": [
                "gregtech:metal_casing@7"
            ]
        },
        {
            "x": -3,
            "y": 10,
            "z": 17,
            "elements": [
                "gregtech:turbine_casing@4"
            ]
        },
        {
            "x": -2,
            "y": 10,
            "z": 17,
            "elements": [
                "gregtech:boiler_casing@3"
            ]
        },
        {
            "x": -1,
            "y": 41,
            "z": 16,
            "elements": [
                "gregtech:metal_casing@7"
            ]
        },
        {
            "x": -1,
            "y": 10,
            "z": 17,
            "elements": [
                "gregtech:boiler_casing@3"
            ]
        },
        {
            "x": 0,
            "y": 10,
            "z": 17,
            "elements": [
                "gregtech:boiler_casing@3"
            ]
        },
        {
            "x": 0,
            "y": 41,
            "z": 16,
            "elements": [
                "gregtech:boiler_casing@3"
            ]
        },
        {
            "x": 1,
            "y": 10,
            "z": 17,
            "elements": [
                "gregtech:boiler_casing@3"
            ]
        },
        {
            "x": 1,
            "y": 41,
            "z": 16,
            "elements": [
                "gregtech:metal_casing@7"
            ]
        },
        {
            "x": -2,
            "y": 2,
            "z": 13,
            "elements": [
                "gregtech:metal_casing@7"
            ]
        },
        {
            "x": 2,
            "y": 10,
            "z": 17,
            "elements": [
                "gregtech:boiler_casing@3"
            ]
        },
        {
            "x": -1,
            "y": 2,
            "z": 13,
            "elements": [
                "gregtech:metal_casing@7"
            ]
        },
        {
            "x": 3,
            "y": 10,
            "z": 17,
            "elements": [
                "gregtech:turbine_casing@4"
            ]
        },
        {
            "x": 4,
            "y": 10,
            "z": 17,
            "elements": [
                "gregtech:metal_casing@7"
            ]
        },
        {
            "x": 0,
            "y": 2,
            "z": 13,
            "elements": [
                "gregtech:metal_casing@7"
            ]
        },
        {
            "x": 1,
            "y": 2,
            "z": 13,
            "elements": [
                "gregtech:metal_casing@7"
            ]
        },
        {
            "x": 2,
            "y": 2,
            "z": 13,
            "elements": [
                "gregtech:metal_casing@7"
            ]
        },
        {
            "x": 15,
            "y": 10,
            "z": 17,
            "elements": [
                "gregtech:meta_block_frame_187@12"
            ]
        },
        {
            "x": -15,
            "y": 11,
            "z": 17,
            "elements": [
                "gregtech:meta_block_frame_187@12"
            ]
        },
        {
            "x": -4,
            "y": 11,
            "z": 17,
            "elements": [
                "gregtech:metal_casing@7"
            ]
        },
        {
            "x": -3,
            "y": 11,
            "z": 17,
            "elements": [
                "gregtech:turbine_casing@4"
            ]
        },
        {
            "x": -2,
            "y": 11,
            "z": 17,
            "elements": [
                "gregtech:boiler_casing@3"
            ]
        },
        {
            "x": -1,
            "y": 42,
            "z": 16,
            "elements": [
                "gregtech:metal_casing@7"
            ]
        },
        {
            "x": -1,
            "y": 11,
            "z": 17,
            "elements": [
                "gregtech:boiler_casing@3"
            ]
        },
        {
            "x": 0,
            "y": 11,
            "z": 17,
            "elements": [
                "gregtech:boiler_casing@3"
            ]
        },
        {
            "x": 0,
            "y": 42,
            "z": 16,
            "elements": [
                "gregtech:boiler_casing@3"
            ]
        },
        {
            "x": 0,
            "y": 73,
            "z": 15,
            "elements": [
                "gregtech:meta_block_frame_187@12"
            ]
        },
        {
            "x": 1,
            "y": 11,
            "z": 17,
            "elements": [
                "gregtech:boiler_casing@3"
            ]
        },
        {
            "x": 1,
            "y": 42,
            "z": 16,
            "elements": [
                "gregtech:metal_casing@7"
            ]
        },
        {
            "x": -2,
            "y": 3,
            "z": 13,
            "elements": [
                "gregtech:metal_casing@7"
            ]
        },
        {
            "x": 2,
            "y": 11,
            "z": 17,
            "elements": [
                "gregtech:boiler_casing@3"
            ]
        },
        {
            "x": -1,
            "y": 3,
            "z": 13,
            "elements": [
                "gregtech:metal_casing@7"
            ]
        },
        {
            "x": 3,
            "y": 11,
            "z": 17,
            "elements": [
                "gregtech:turbine_casing@4"
            ]
        },
        {
            "x": 4,
            "y": 11,
            "z": 17,
            "elements": [
                "gregtech:metal_casing@7"
            ]
        },
        {
            "x": 0,
            "y": 3,
            "z": 13,
            "elements": [
                "gregtech:metal_casing@7"
            ]
        },
        {
            "x": 1,
            "y": 3,
            "z": 13,
            "elements": [
                "gregtech:metal_casing@7"
            ]
        },
        {
            "x": 2,
            "y": 3,
            "z": 13,
            "elements": [
                "gregtech:metal_casing@7"
            ]
        },
        {
            "x": 0,
            "y": 18,
            "z": 4,
            "elements": [
                "gregtech:meta_block_frame_187@12"
            ]
        },
        {
            "x": 15,
            "y": 11,
            "z": 17,
            "elements": [
                "gregtech:meta_block_frame_187@12"
            ]
        },
        {
            "x": -15,
            "y": 12,
            "z": 17,
            "elements": [
                "gregtech:meta_block_frame_187@12"
            ]
        },
        {
            "x": -3,
            "y": 12,
            "z": 17,
            "elements": [
                "gregtech:metal_casing@7"
            ]
        },
        {
            "x": -2,
            "y": 12,
            "z": 17,
            "elements": [
                "gregtech:boiler_casing@3"
            ]
        },
        {
            "x": -1,
            "y": 43,
            "z": 16,
            "elements": [
                "gregtech:metal_casing@7"
            ]
        },
        {
            "x": -1,
            "y": 12,
            "z": 17,
            "elements": [
                "gregtech:boiler_casing@3"
            ]
        },
        {
            "x": 0,
            "y": 12,
            "z": 17,
            "elements": [
                "gregtech:boiler_casing@3"
            ]
        },
        {
            "x": 0,
            "y": 43,
            "z": 16,
            "elements": [
                "gregtech:boiler_casing@3"
            ]
        },
        {
            "x": 0,
            "y": 74,
            "z": 15,
            "elements": [
                "gregtech:meta_block_frame_187@12"
            ]
        },
        {
            "x": 1,
            "y": 12,
            "z": 17,
            "elements": [
                "gregtech:boiler_casing@3"
            ]
        },
        {
            "x": 1,
            "y": 43,
            "z": 16,
            "elements": [
                "gregtech:metal_casing@7"
            ]
        },
        {
            "x": 2,
            "y": 12,
            "z": 17,
            "elements": [
                "gregtech:boiler_casing@3"
            ]
        },
        {
            "x": -1,
            "y": 4,
            "z": 13,
            "elements": [
                "gregtech:metal_casing@7"
            ]
        },
        {
            "x": 3,
            "y": 12,
            "z": 17,
            "elements": [
                "gregtech:metal_casing@7"
            ]
        },
        {
            "x": 0,
            "y": 4,
            "z": 13,
            "elements": [
                "gregtech:metal_casing@7"
            ]
        },
        {
            "x": 1,
            "y": 4,
            "z": 13,
            "elements": [
                "gregtech:metal_casing@7"
            ]
        },
        {
            "x": 0,
            "y": 19,
            "z": 4,
            "elements": [
                "gregtech:meta_block_frame_187@12"
            ]
        },
        {
            "x": 15,
            "y": 12,
            "z": 17,
            "elements": [
                "gregtech:meta_block_frame_187@12"
            ]
        },
        {
            "x": -15,
            "y": 13,
            "z": 17,
            "elements": [
                "gregtech:meta_block_frame_187@12"
            ]
        },
        {
            "x": -3,
            "y": 13,
            "z": 17,
            "elements": [
                "gregtech:metal_casing@7"
            ]
        },
        {
            "x": -2,
            "y": 13,
            "z": 17,
            "elements": [
                "gregtech:boiler_casing@3"
            ]
        },
        {
            "x": -1,
            "y": 44,
            "z": 16,
            "elements": [
                "gregtech:metal_casing@7"
            ]
        },
        {
            "x": -1,
            "y": 13,
            "z": 17,
            "elements": [
                "gregtech:boiler_casing@3"
            ]
        },
        {
            "x": 0,
            "y": 13,
            "z": 17,
            "elements": [
                "gregtech:boiler_casing@3"
            ]
        },
        {
            "x": 0,
            "y": 44,
            "z": 16,
            "elements": [
                "gregtech:boiler_casing@3"
            ]
        },
        {
            "x": 0,
            "y": 75,
            "z": 15,
            "elements": [
                "gregtech:meta_block_frame_187@12"
            ]
        },
        {
            "x": 1,
            "y": 13,
            "z": 17,
            "elements": [
                "gregtech:boiler_casing@3"
            ]
        },
        {
            "x": 1,
            "y": 44,
            "z": 16,
            "elements": [
                "gregtech:metal_casing@7"
            ]
        },
        {
            "x": 2,
            "y": 13,
            "z": 17,
            "elements": [
                "gregtech:boiler_casing@3"
            ]
        },
        {
            "x": -1,
            "y": 5,
            "z": 13,
            "elements": [
                "gregtech:metal_casing@7"
            ]
        },
        {
            "x": 3,
            "y": 13,
            "z": 17,
            "elements": [
                "gregtech:metal_casing@7"
            ]
        },
        {
            "x": 0,
            "y": 5,
            "z": 13,
            "elements": [
                "gregtech:metal_casing@7"
            ]
        },
        {
            "x": 1,
            "y": 5,
            "z": 13,
            "elements": [
                "gregtech:metal_casing@7"
            ]
        },
        {
            "x": 0,
            "y": 20,
            "z": 4,
            "elements": [
                "gregtech:meta_block_frame_187@12"
            ]
        },
        {
            "x": 15,
            "y": 13,
            "z": 17,
            "elements": [
                "gregtech:meta_block_frame_187@12"
            ]
        },
        {
            "x": -15,
            "y": 14,
            "z": 17,
            "elements": [
                "gregtech:meta_block_frame_187@12"
            ]
        },
        {
            "x": -3,
            "y": 14,
            "z": 17,
            "elements": [
                "gregtech:metal_casing@7"
            ]
        },
        {
            "x": -2,
            "y": 14,
            "z": 17,
            "elements": [
                "gregtech:boiler_casing@3"
            ]
        },
        {
            "x": -1,
            "y": 45,
            "z": 16,
            "elements": [
                "gregtech:metal_casing@7"
            ]
        },
        {
            "x": -1,
            "y": 14,
            "z": 17,
            "elements": [
                "gregtech:boiler_casing@3"
            ]
        },
        {
            "x": 0,
            "y": 14,
            "z": 17,
            "elements": [
                "gregtech:boiler_casing@3"
            ]
        },
        {
            "x": 0,
            "y": 45,
            "z": 16,
            "elements": [
                "gregtech:boiler_casing@3"
            ]
        },
        {
            "x": 0,
            "y": 76,
            "z": 15,
            "elements": [
                "gregtech:meta_block_frame_187@12"
            ]
        },
        {
            "x": 1,
            "y": 14,
            "z": 17,
            "elements": [
                "gregtech:boiler_casing@3"
            ]
        },
        {
            "x": 1,
            "y": 45,
            "z": 16,
            "elements": [
                "gregtech:metal_casing@7"
            ]
        },
        {
            "x": 2,
            "y": 14,
            "z": 17,
            "elements": [
                "gregtech:boiler_casing@3"
            ]
        },
        {
            "x": -1,
            "y": 6,
            "z": 13,
            "elements": [
                "gregtech:metal_casing@7"
            ]
        },
        {
            "x": 3,
            "y": 14,
            "z": 17,
            "elements": [
                "gregtech:metal_casing@7"
            ]
        },
        {
            "x": 0,
            "y": 6,
            "z": 13,
            "elements": [
                "gregtech:metal_casing@7"
            ]
        },
        {
            "x": 1,
            "y": 6,
            "z": 13,
            "elements": [
                "gregtech:metal_casing@7"
            ]
        },
        {
            "x": -14,
            "y": 0,
            "z": 26,
            "elements": [
                "modularmachinery:blockoutputbus"
            ]
        },
        {
            "x": -13,
            "y": 0,
            "z": 26,
            "elements": [
                "gregtech:metal_casing@7"
            ]
        },
        {
            "x": -12,
            "y": 0,
            "z": 26,
            "elements": [
                "gregtech:metal_casing@7"
            ]
        },
        {
            "x": -11,
            "y": 0,
            "z": 26,
            "elements": [
                "gregtech:metal_casing@7"
            ]
        },
        {
            "x": -10,
            "y": 0,
            "z": 26,
            "elements": [
                "gregtech:metal_casing@7"
            ]
        },
        {
            "x": -9,
            "y": 0,
            "z": 26,
            "elements": [
                "gregtech:metal_casing@7"
            ]
        },
        {
            "x": 15,
            "y": 14,
            "z": 17,
            "elements": [
                "gregtech:meta_block_frame_187@12"
            ]
        },
        {
            "x": -8,
            "y": 0,
            "z": 26,
            "elements": [
                "gregtech:metal_casing@7"
            ]
        },
        {
            "x": -7,
            "y": 0,
            "z": 26,
            "elements": [
                "gregtech:metal_casing@7"
            ]
        },
        {
            "x": -14,
            "y": 15,
            "z": 17,
            "elements": [
                "gregtech:meta_block_frame_187@12"
            ]
        },
        {
            "x": -6,
            "y": 0,
            "z": 26,
            "elements": [
                "gregtech:metal_casing@7"
            ]
        },
        {
            "x": -5,
            "y": 0,
            "z": 26,
            "elements": [
                "gregtech:metal_casing@7"
            ]
        },
        {
            "x": -4,
            "y": 0,
            "z": 26,
            "elements": [
                "gregtech:metal_casing@7"
            ]
        },
        {
            "x": -3,
            "y": 0,
            "z": 26,
            "elements": [
                "gregtech:metal_casing@7"
            ]
        },
        {
            "x": -2,
            "y": 0,
            "z": 26,
            "elements": [
                "gregtech:metal_casing@7"
            ]
        },
        {
            "x": -1,
            "y": 0,
            "z": 26,
            "elements": [
                "gregtech:metal_casing@7"
            ]
        },
        {
            "x": 0,
            "y": 0,
            "z": 26,
            "elements": [
                "gregtech:metal_casing@7"
            ]
        },
        {
            "x": 1,
            "y": 0,
            "z": 26,
            "elements": [
                "gregtech:metal_casing@7"
            ]
        },
        {
            "x": 2,
            "y": 0,
            "z": 26,
            "elements": [
                "gregtech:metal_casing@7"
            ]
        },
        {
            "x": 3,
            "y": 0,
            "z": 26,
            "elements": [
                "gregtech:metal_casing@7"
            ]
        },
        {
            "x": 4,
            "y": 0,
            "z": 26,
            "elements": [
                "gregtech:metal_casing@7"
            ]
        },
        {
            "x": 5,
            "y": 0,
            "z": 26,
            "elements": [
                "gregtech:metal_casing@7"
            ]
        },
        {
            "x": -3,
            "y": 15,
            "z": 17,
            "elements": [
                "gregtech:metal_casing@7"
            ]
        },
        {
            "x": -2,
            "y": 15,
            "z": 17,
            "elements": [
                "gregtech:boiler_casing@3"
            ]
        },
        {
            "x": 6,
            "y": 0,
            "z": 26,
            "elements": [
                "gregtech:metal_casing@7"
            ]
        },
        {
            "x": -1,
            "y": 46,
            "z": 16,
            "elements": [
                "gregtech:metal_casing@7"
            ]
        },
        {
            "x": -1,
            "y": 15,
            "z": 17,
            "elements": [
                "gregtech:boiler_casing@3"
            ]
        },
        {
            "x": 7,
            "y": 0,
            "z": 26,
            "elements": [
                "gregtech:metal_casing@7"
            ]
        },
        {
            "x": 0,
            "y": 15,
            "z": 17,
            "elements": [
                "gregtech:boiler_casing@3"
            ]
        },
        {
            "x": 0,
            "y": 46,
            "z": 16,
            "elements": [
                "gregtech:boiler_casing@3"
            ]
        },
        {
            "x": 0,
            "y": 77,
            "z": 15,
            "elements": [
                "gregtech:meta_block_frame_187@12"
            ]
        },
        {
            "x": 8,
            "y": 0,
            "z": 26,
            "elements": [
                "gregtech:metal_casing@7"
            ]
        },
        {
            "x": 9,
            "y": 0,
            "z": 26,
            "elements": [
                "gregtech:metal_casing@7"
            ]
        },
        {
            "x": 1,
            "y": 15,
            "z": 17,
            "elements": [
                "gregtech:boiler_casing@3"
            ]
        },
        {
            "x": 1,
            "y": 46,
            "z": 16,
            "elements": [
                "gregtech:metal_casing@7"
            ]
        },
        {
            "x": 10,
            "y": 0,
            "z": 26,
            "elements": [
                "gregtech:metal_casing@7"
            ]
        },
        {
            "x": 2,
            "y": 15,
            "z": 17,
            "elements": [
                "gregtech:boiler_casing@3"
            ]
        },
        {
            "x": 11,
            "y": 0,
            "z": 26,
            "elements": [
                "gregtech:metal_casing@7"
            ]
        },
        {
            "x": 3,
            "y": 15,
            "z": 17,
            "elements": [
                "gregtech:metal_casing@7"
            ]
        },
        {
            "x": 0,
            "y": 7,
            "z": 13,
            "elements": [
                "gregtech:metal_casing@7"
            ]
        },
        {
            "x": 12,
            "y": 0,
            "z": 26,
            "elements": [
                "gregtech:metal_casing@7"
            ]
        },
        {
            "x": 13,
            "y": 0,
            "z": 26,
            "elements": [
                "gregtech:metal_casing@7"
            ]
        },
        {
            "x": 14,
            "y": 0,
            "z": 26,
            "elements": [
                "modularmachinery:blockoutputbus"
            ]
        },
        {
            "x": 14,
            "y": 15,
            "z": 17,
            "elements": [
                "gregtech:meta_block_frame_187@12"
            ]
        },
        {
            "x": -8,
            "y": 1,
            "z": 26,
            "elements": [
                "modularmachinery:blockfluidoutputhatch"
            ]
        },
        {
            "x": -14,
            "y": 16,
            "z": 17,
            "elements": [
                "gregtech:meta_block_frame_187@12"
            ]
        },
        {
            "x": -15,
            "y": 0,
            "z": 9,
            "elements": [
                "gregtech:metal_casing@7"
            ]
        },
        {
            "x": -14,
            "y": 0,
            "z": 9,
            "elements": [
                "gregtech:metal_casing@7"
            ]
        },
        {
            "x": -13,
            "y": 0,
            "z": 9,
            "elements": [
                "gregtech:metal_casing@7"
            ]
        },
        {
            "x": -12,
            "y": 0,
            "z": 9,
            "elements": [
                "gregtech:metal_casing@7"
            ]
        },
        {
            "x": -11,
            "y": 0,
            "z": 9,
            "elements": [
                "gregtech:metal_casing@7"
            ]
        },
        {
            "x": -3,
            "y": 16,
            "z": 17,
            "elements": [
                "gregtech:metal_casing@7"
            ]
        },
        {
            "x": -10,
            "y": 0,
            "z": 9,
            "elements": [
                "gregtech:metal_casing@7"
            ]
        },
        {
            "x": -2,
            "y": 16,
            "z": 17,
            "elements": [
                "gregtech:boiler_casing@3"
            ]
        },
        {
            "x": -9,
            "y": 0,
            "z": 9,
            "elements": [
                "gregtech:metal_casing@7"
            ]
        },
        {
            "x": -1,
            "y": 16,
            "z": 17,
            "elements": [
                "gregtech:boiler_casing@3"
            ]
        },
        {
            "x": 0,
            "y": 16,
            "z": 17,
            "elements": [
                "gregtech:boiler_casing@3"
            ]
        },
        {
            "x": 0,
            "y": 47,
            "z": 16,
            "elements": [
                "gregtech:metal_casing@7"
            ]
        },
        {
            "x": 8,
            "y": 1,
            "z": 26,
            "elements": [
                "modularmachinery:blockfluidoutputhatch"
            ]
        },
        {
            "x": -8,
            "y": 0,
            "z": 9,
            "elements": [
                "gregtech:metal_casing@7"
            ]
        },
        {
            "x": 1,
            "y": 16,
            "z": 17,
            "elements": [
                "gregtech:boiler_casing@3"
            ]
        },
        {
            "x": -7,
            "y": 0,
            "z": 9,
            "elements": [
                "gregtech:metal_casing@7"
            ]
        },
        {
            "x": -6,
            "y": 0,
            "z": 9,
            "elements": [
                "gregtech:metal_casing@7"
            ]
        },
        {
            "x": 2,
            "y": 16,
            "z": 17,
            "elements": [
                "gregtech:boiler_casing@3"
            ]
        },
        {
            "x": -5,
            "y": 0,
            "z": 9,
            "elements": [
                "gregtech:metal_casing@7"
            ]
        },
        {
            "x": 3,
            "y": 16,
            "z": 17,
            "elements": [
                "gregtech:metal_casing@7"
            ]
        },
        {
            "x": 0,
            "y": 8,
            "z": 13,
            "elements": [
                "gregtech:metal_casing@7"
            ]
        },
        {
            "x": -4,
            "y": 0,
            "z": 9,
            "elements": [
                "gregtech:metal_casing@7"
            ]
        },
        {
            "x": -3,
            "y": 0,
            "z": 9,
            "elements": [
                "gregtech:metal_casing@7"
            ]
        },
        {
            "x": -2,
            "y": 0,
            "z": 9,
            "elements": [
                "gregtech:metal_casing@7"
            ]
        },
        {
            "x": -1,
            "y": 0,
            "z": 9,
            "elements": [
                "gregtech:metal_casing@7"
            ]
        },
        {
            "x": 0,
            "y": 0,
            "z": 9,
            "elements": [
                "gregtech:metal_casing@7"
            ]
        },
        {
            "x": 1,
            "y": 0,
            "z": 9,
            "elements": [
                "gregtech:metal_casing@7"
            ]
        },
        {
            "x": 2,
            "y": 0,
            "z": 9,
            "elements": [
                "gregtech:metal_casing@7"
            ]
        },
        {
            "x": 3,
            "y": 0,
            "z": 9,
            "elements": [
                "gregtech:metal_casing@7"
            ]
        },
        {
            "x": 4,
            "y": 0,
            "z": 9,
            "elements": [
                "gregtech:metal_casing@7"
            ]
        },
        {
            "x": 5,
            "y": 0,
            "z": 9,
            "elements": [
                "gregtech:metal_casing@7"
            ]
        },
        {
            "x": 14,
            "y": 16,
            "z": 17,
            "elements": [
                "gregtech:meta_block_frame_187@12"
            ]
        },
        {
            "x": 6,
            "y": 0,
            "z": 9,
            "elements": [
                "gregtech:metal_casing@7"
            ]
        },
        {
            "x": 7,
            "y": 0,
            "z": 9,
            "elements": [
                "gregtech:metal_casing@7"
            ]
        },
        {
            "x": -8,
            "y": 2,
            "z": 26,
            "elements": [
                "gregtech:metal_casing@7"
            ]
        },
        {
            "x": 8,
            "y": 0,
            "z": 9,
            "elements": [
                "gregtech:metal_casing@7"
            ]
        },
        {
            "x": 9,
            "y": 0,
            "z": 9,
            "elements": [
                "gregtech:metal_casing@7"
            ]
        },
        {
            "x": -14,
            "y": 17,
            "z": 17,
            "elements": [
                "gregtech:meta_block_frame_187@12"
            ]
        },
        {
            "x": 10,
            "y": 0,
            "z": 9,
            "elements": [
                "gregtech:metal_casing@7"
            ]
        },
        {
            "x": 11,
            "y": 0,
            "z": 9,
            "elements": [
                "gregtech:metal_casing@7"
            ]
        },
        {
            "x": 12,
            "y": 0,
            "z": 9,
            "elements": [
                "gregtech:metal_casing@7"
            ]
        },
        {
            "x": 13,
            "y": 0,
            "z": 9,
            "elements": [
                "gregtech:metal_casing@7"
            ]
        },
        {
            "x": 14,
            "y": 0,
            "z": 9,
            "elements": [
                "gregtech:metal_casing@7"
            ]
        },
        {
            "x": 15,
            "y": 0,
            "z": 9,
            "elements": [
                "gregtech:metal_casing@7"
            ]
        },
        {
            "x": -3,
            "y": 17,
            "z": 17,
            "elements": [
                "gregtech:metal_casing@7"
            ]
        },
        {
            "x": -2,
            "y": 17,
            "z": 17,
            "elements": [
                "gregtech:boiler_casing@3"
            ]
        },
        {
            "x": -9,
            "y": 1,
            "z": 9,
            "elements": [
                "modularmachinery:blockfluidoutputhatch"
            ]
        },
        {
            "x": -1,
            "y": 17,
            "z": 17,
            "elements": [
                "gregtech:boiler_casing@3"
            ]
        },
        {
            "x": 0,
            "y": 17,
            "z": 17,
            "elements": [
                "gregtech:boiler_casing@3"
            ]
        },
        {
            "x": 0,
            "y": 48,
            "z": 16,
            "elements": [
                "gregtech:metal_casing@7"
            ]
        },
        {
            "x": -8,
            "y": 1,
            "z": 9,
            "elements": [
                "gregtech:boiler_casing@3"
            ]
        },
        {
            "x": 8,
            "y": 2,
            "z": 26,
            "elements": [
                "gregtech:metal_casing@7"
            ]
        },
        {
            "x": 1,
            "y": 17,
            "z": 17,
            "elements": [
                "gregtech:boiler_casing@3"
            ]
        },
        {
            "x": -7,
            "y": 1,
            "z": 9,
            "elements": [
                "modularmachinery:blockfluidoutputhatch"
            ]
        },
        {
            "x": 2,
            "y": 17,
            "z": 17,
            "elements": [
                "gregtech:boiler_casing@3"
            ]
        },
        {
            "x": 3,
            "y": 17,
            "z": 17,
            "elements": [
                "gregtech:metal_casing@7"
            ]
        },
        {
            "x": 0,
            "y": 9,
            "z": 13,
            "elements": [
                "gregtech:metal_casing@7"
            ]
        },
        {
            "x": 14,
            "y": 17,
            "z": 17,
            "elements": [
                "gregtech:meta_block_frame_187@12"
            ]
        },
        {
            "x": 7,
            "y": 1,
            "z": 9,
            "elements": [
                "modularmachinery:blockfluidoutputhatch"
            ]
        },
        {
            "x": -8,
            "y": 3,
            "z": 26,
            "elements": [
                "gregtech:metal_casing@7"
            ]
        },
        {
            "x": 8,
            "y": 1,
            "z": 9,
            "elements": [
                "gregtech:boiler_casing@3"
            ]
        },
        {
            "x": 9,
            "y": 1,
            "z": 9,
            "elements": [
                "modularmachinery:blockfluidoutputhatch"
            ]
        },
        {
            "x": -13,
            "y": 18,
            "z": 17,
            "elements": [
                "gregtech:meta_block_frame_187@12"
            ]
        },
        {
            "x": -3,
            "y": 18,
            "z": 17,
            "elements": [
                "gregtech:metal_casing@7"
            ]
        },
        {
            "x": -2,
            "y": 18,
            "z": 17,
            "elements": [
                "gregtech:boiler_casing@3"
            ]
        },
        {
            "x": -9,
            "y": 2,
            "z": 9,
            "elements": [
                "gregtech:metal_casing@7"
            ]
        },
        {
            "x": -1,
            "y": 18,
            "z": 17,
            "elements": [
                "gregtech:boiler_casing@3"
            ]
        },
        {
            "x": 0,
            "y": 18,
            "z": 17,
            "elements": [
                "gregtech:boiler_casing@3"
            ]
        },
        {
            "x": 0,
            "y": 49,
            "z": 16,
            "elements": [
                "gregtech:metal_casing@7"
            ]
        },
        {
            "x": -8,
            "y": 2,
            "z": 9,
            "elements": [
                "gregtech:boiler_casing@3"
            ]
        },
        {
            "x": 8,
            "y": 3,
            "z": 26,
            "elements": [
                "gregtech:metal_casing@7"
            ]
        },
        {
            "x": 1,
            "y": 18,
            "z": 17,
            "elements": [
                "gregtech:boiler_casing@3"
            ]
        },
        {
            "x": -7,
            "y": 2,
            "z": 9,
            "elements": [
                "gregtech:metal_casing@7"
            ]
        },
        {
            "x": 2,
            "y": 18,
            "z": 17,
            "elements": [
                "gregtech:boiler_casing@3"
            ]
        },
        {
            "x": 3,
            "y": 18,
            "z": 17,
            "elements": [
                "gregtech:metal_casing@7"
            ]
        },
        {
            "x": 0,
            "y": 10,
            "z": 13,
            "elements": [
                "gregtech:metal_casing@7"
            ]
        },
        {
            "x": 13,
            "y": 18,
            "z": 17,
            "elements": [
                "gregtech:meta_block_frame_187@12"
            ]
        },
        {
            "x": 7,
            "y": 2,
            "z": 9,
            "elements": [
                "gregtech:metal_casing@7"
            ]
        },
        {
            "x": -8,
            "y": 4,
            "z": 26,
            "elements": [
                "gregtech:metal_casing@7"
            ]
        },
        {
            "x": 8,
            "y": 2,
            "z": 9,
            "elements": [
                "gregtech:boiler_casing@3"
            ]
        },
        {
            "x": 9,
            "y": 2,
            "z": 9,
            "elements": [
                "gregtech:metal_casing@7"
            ]
        },
        {
            "x": -13,
            "y": 19,
            "z": 17,
            "elements": [
                "gregtech:meta_block_frame_187@12"
            ]
        },
        {
            "x": -3,
            "y": 19,
            "z": 17,
            "elements": [
                "gregtech:metal_casing@7"
            ]
        },
        {
            "x": -2,
            "y": 19,
            "z": 17,
            "elements": [
                "gregtech:boiler_casing@3"
            ]
        },
        {
            "x": -9,
            "y": 3,
            "z": 9,
            "elements": [
                "gregtech:metal_casing@7"
            ]
        },
        {
            "x": -1,
            "y": 19,
            "z": 17,
            "elements": [
                "gregtech:boiler_casing@3"
            ]
        },
        {
            "x": 0,
            "y": 19,
            "z": 17,
            "elements": [
                "gregtech:boiler_casing@3"
            ]
        },
        {
            "x": 0,
            "y": 50,
            "z": 16,
            "elements": [
                "gregtech:metal_casing@7"
            ]
        },
        {
            "x": -8,
            "y": 3,
            "z": 9,
            "elements": [
                "gregtech:boiler_casing@3"
            ]
        },
        {
            "x": 8,
            "y": 4,
            "z": 26,
            "elements": [
                "gregtech:metal_casing@7"
            ]
        },
        {
            "x": 1,
            "y": 19,
            "z": 17,
            "elements": [
                "gregtech:boiler_casing@3"
            ]
        },
        {
            "x": -7,
            "y": 3,
            "z": 9,
            "elements": [
                "gregtech:metal_casing@7"
            ]
        },
        {
            "x": 2,
            "y": 19,
            "z": 17,
            "elements": [
                "gregtech:boiler_casing@3"
            ]
        },
        {
            "x": 3,
            "y": 19,
            "z": 17,
            "elements": [
                "gregtech:metal_casing@7"
            ]
        },
        {
            "x": 0,
            "y": 11,
            "z": 13,
            "elements": [
                "gregtech:metal_casing@7"
            ]
        },
        {
            "x": 13,
            "y": 19,
            "z": 17,
            "elements": [
                "gregtech:meta_block_frame_187@12"
            ]
        },
        {
            "x": 7,
            "y": 3,
            "z": 9,
            "elements": [
                "gregtech:metal_casing@7"
            ]
        },
        {
            "x": -8,
            "y": 5,
            "z": 26,
            "elements": [
                "gregtech:metal_casing@7"
            ]
        },
        {
            "x": 8,
            "y": 3,
            "z": 9,
            "elements": [
                "gregtech:boiler_casing@3"
            ]
        },
        {
            "x": 9,
            "y": 3,
            "z": 9,
            "elements": [
                "gregtech:metal_casing@7"
            ]
        },
        {
            "x": -13,
            "y": 20,
            "z": 17,
            "elements": [
                "gregtech:meta_block_frame_187@12"
            ]
        },
        {
            "x": -3,
            "y": 20,
            "z": 17,
            "elements": [
                "gregtech:metal_casing@7"
            ]
        },
        {
            "x": -2,
            "y": 20,
            "z": 17,
            "elements": [
                "gregtech:boiler_casing@3"
            ]
        },
        {
            "x": -9,
            "y": 4,
            "z": 9,
            "elements": [
                "gregtech:metal_casing@7"
            ]
        },
        {
            "x": -1,
            "y": 20,
            "z": 17,
            "elements": [
                "gregtech:boiler_casing@3"
            ]
        },
        {
            "x": 0,
            "y": 20,
            "z": 17,
            "elements": [
                "gregtech:boiler_casing@3"
            ]
        },
        {
            "x": 0,
            "y": 51,
            "z": 16,
            "elements": [
                "gregtech:metal_casing@7"
            ]
        },
        {
            "x": -8,
            "y": 4,
            "z": 9,
            "elements": [
                "gregtech:boiler_casing@3"
            ]
        },
        {
            "x": 8,
            "y": 5,
            "z": 26,
            "elements": [
                "gregtech:metal_casing@7"
            ]
        },
        {
            "x": 1,
            "y": 20,
            "z": 17,
            "elements": [
                "gregtech:boiler_casing@3"
            ]
        },
        {
            "x": -7,
            "y": 4,
            "z": 9,
            "elements": [
                "gregtech:metal_casing@7"
            ]
        },
        {
            "x": 2,
            "y": 20,
            "z": 17,
            "elements": [
                "gregtech:boiler_casing@3"
            ]
        },
        {
            "x": 3,
            "y": 20,
            "z": 17,
            "elements": [
                "gregtech:metal_casing@7"
            ]
        },
        {
            "x": 0,
            "y": 35,
            "z": 8,
            "elements": [
                "gregtech:meta_block_frame_187@12"
            ]
        },
        {
            "x": 13,
            "y": 20,
            "z": 17,
            "elements": [
                "gregtech:meta_block_frame_187@12"
            ]
        },
        {
            "x": 7,
            "y": 4,
            "z": 9,
            "elements": [
                "gregtech:metal_casing@7"
            ]
        },
        {
            "x": -8,
            "y": 6,
            "z": 26,
            "elements": [
                "gregtech:metal_casing@7"
            ]
        },
        {
            "x": 8,
            "y": 4,
            "z": 9,
            "elements": [
                "gregtech:boiler_casing@3"
            ]
        },
        {
            "x": 9,
            "y": 4,
            "z": 9,
            "elements": [
                "gregtech:metal_casing@7"
            ]
        },
        {
            "x": -12,
            "y": 21,
            "z": 17,
            "elements": [
                "gregtech:meta_block_frame_187@12"
            ]
        },
        {
            "x": -3,
            "y": 21,
            "z": 17,
            "elements": [
                "gregtech:metal_casing@7"
            ]
        },
        {
            "x": -2,
            "y": 21,
            "z": 17,
            "elements": [
                "gregtech:boiler_casing@3"
            ]
        },
        {
            "x": -9,
            "y": 5,
            "z": 9,
            "elements": [
                "gregtech:metal_casing@7"
            ]
        },
        {
            "x": -1,
            "y": 21,
            "z": 17,
            "elements": [
                "gregtech:boiler_casing@3"
            ]
        },
        {
            "x": 0,
            "y": 21,
            "z": 17,
            "elements": [
                "gregtech:boiler_casing@3"
            ]
        },
        {
            "x": 0,
            "y": 52,
            "z": 16,
            "elements": [
                "gregtech:metal_casing@7"
            ]
        },
        {
            "x": -8,
            "y": 5,
            "z": 9,
            "elements": [
                "gregtech:boiler_casing@3"
            ]
        },
        {
            "x": 8,
            "y": 6,
            "z": 26,
            "elements": [
                "gregtech:metal_casing@7"
            ]
        },
        {
            "x": 1,
            "y": 21,
            "z": 17,
            "elements": [
                "gregtech:boiler_casing@3"
            ]
        },
        {
            "x": -7,
            "y": 5,
            "z": 9,
            "elements": [
                "gregtech:metal_casing@7"
            ]
        },
        {
            "x": 2,
            "y": 21,
            "z": 17,
            "elements": [
                "gregtech:boiler_casing@3"
            ]
        },
        {
            "x": 3,
            "y": 21,
            "z": 17,
            "elements": [
                "gregtech:metal_casing@7"
            ]
        },
        {
            "x": 0,
            "y": 36,
            "z": 8,
            "elements": [
                "gregtech:meta_block_frame_187@12"
            ]
        },
        {
            "x": 12,
            "y": 21,
            "z": 17,
            "elements": [
                "gregtech:meta_block_frame_187@12"
            ]
        },
        {
            "x": 7,
            "y": 5,
            "z": 9,
            "elements": [
                "gregtech:metal_casing@7"
            ]
        },
        {
            "x": -8,
            "y": 7,
            "z": 26,
            "elements": [
                "gregtech:metal_casing@7"
            ]
        },
        {
            "x": 8,
            "y": 5,
            "z": 9,
            "elements": [
                "gregtech:boiler_casing@3"
            ]
        },
        {
            "x": 9,
            "y": 5,
            "z": 9,
            "elements": [
                "gregtech:metal_casing@7"
            ]
        },
        {
            "x": -12,
            "y": 22,
            "z": 17,
            "elements": [
                "gregtech:meta_block_frame_187@12"
            ]
        },
        {
            "x": -3,
            "y": 22,
            "z": 17,
            "elements": [
                "gregtech:metal_casing@7"
            ]
        },
        {
            "x": -2,
            "y": 22,
            "z": 17,
            "elements": [
                "gregtech:boiler_casing@3"
            ]
        },
        {
            "x": -9,
            "y": 6,
            "z": 9,
            "elements": [
                "gregtech:metal_casing@7"
            ]
        },
        {
            "x": -1,
            "y": 22,
            "z": 17,
            "elements": [
                "gregtech:boiler_casing@3"
            ]
        },
        {
            "x": 0,
            "y": 22,
            "z": 17,
            "elements": [
                "gregtech:boiler_casing@3"
            ]
        },
        {
            "x": 0,
            "y": 53,
            "z": 16,
            "elements": [
                "gregtech:metal_casing@7"
            ]
        },
        {
            "x": -8,
            "y": 6,
            "z": 9,
            "elements": [
                "gregtech:boiler_casing@3"
            ]
        },
        {
            "x": 8,
            "y": 7,
            "z": 26,
            "elements": [
                "gregtech:metal_casing@7"
            ]
        },
        {
            "x": 1,
            "y": 22,
            "z": 17,
            "elements": [
                "gregtech:boiler_casing@3"
            ]
        },
        {
            "x": -7,
            "y": 6,
            "z": 9,
            "elements": [
                "gregtech:metal_casing@7"
            ]
        },
        {
            "x": 2,
            "y": 22,
            "z": 17,
            "elements": [
                "gregtech:boiler_casing@3"
            ]
        },
        {
            "x": 3,
            "y": 22,
            "z": 17,
            "elements": [
                "gregtech:metal_casing@7"
            ]
        },
        {
            "x": 0,
            "y": 37,
            "z": 8,
            "elements": [
                "gregtech:meta_block_frame_187@12"
            ]
        },
        {
            "x": -16,
            "y": 0,
            "z": 22,
            "elements": [
                "gregtech:metal_casing@7"
            ]
        },
        {
            "x": -15,
            "y": 0,
            "z": 22,
            "elements": [
                "gregtech:metal_casing@7"
            ]
        },
        {
            "x": 12,
            "y": 22,
            "z": 17,
            "elements": [
                "gregtech:meta_block_frame_187@12"
            ]
        },
        {
            "x": -14,
            "y": 0,
            "z": 22,
            "elements": [
                "gregtech:metal_casing@7"
            ]
        },
        {
            "x": -13,
            "y": 0,
            "z": 22,
            "elements": [
                "gregtech:metal_casing@7"
            ]
        },
        {
            "x": 7,
            "y": 6,
            "z": 9,
            "elements": [
                "gregtech:metal_casing@7"
            ]
        },
        {
            "x": -12,
            "y": 0,
            "z": 22,
            "elements": [
                "gregtech:metal_casing@7"
            ]
        },
        {
            "x": -8,
            "y": 8,
            "z": 26,
            "elements": [
                "gregtech:metal_casing@7"
            ]
        },
        {
            "x": -11,
            "y": 0,
            "z": 22,
            "elements": [
                "gregtech:metal_casing@7"
            ]
        },
        {
            "x": 8,
            "y": 6,
            "z": 9,
            "elements": [
                "gregtech:boiler_casing@3"
            ]
        },
        {
            "x": 9,
            "y": 6,
            "z": 9,
            "elements": [
                "gregtech:metal_casing@7"
            ]
        },
        {
            "x": -10,
            "y": 0,
            "z": 22,
            "elements": [
                "gregtech:metal_casing@7"
            ]
        },
        {
            "x": -9,
            "y": 0,
            "z": 22,
            "elements": [
                "gregtech:metal_casing@7"
            ]
        },
        {
            "x": -12,
            "y": 23,
            "z": 17,
            "elements": [
                "gregtech:meta_block_frame_187@12"
            ]
        },
        {
            "x": -8,
            "y": 0,
            "z": 22,
            "elements": [
                "gregtech:metal_casing@7"
            ]
        },
        {
            "x": -7,
            "y": 0,
            "z": 22,
            "elements": [
                "gregtech:metal_casing@7"
            ]
        },
        {
            "x": -6,
            "y": 0,
            "z": 22,
            "elements": [
                "gregtech:metal_casing@7"
            ]
        },
        {
            "x": -5,
            "y": 0,
            "z": 22,
            "elements": [
                "gregtech:metal_casing@7"
            ]
        },
        {
            "x": -4,
            "y": 0,
            "z": 22,
            "elements": [
                "gregtech:metal_casing@7"
            ]
        },
        {
            "x": -3,
            "y": 0,
            "z": 22,
            "elements": [
                "gregtech:metal_casing@7"
            ]
        },
        {
            "x": -2,
            "y": 0,
            "z": 22,
            "elements": [
                "gregtech:metal_casing@7"
            ]
        },
        {
            "x": -1,
            "y": 0,
            "z": 22,
            "elements": [
                "gregtech:metal_casing@7"
            ]
        },
        {
            "x": 0,
            "y": 0,
            "z": 22,
            "elements": [
                "gregtech:metal_casing@7"
            ]
        },
        {
            "x": 1,
            "y": 0,
            "z": 22,
            "elements": [
                "gregtech:metal_casing@7"
            ]
        },
        {
            "x": -3,
            "y": 23,
            "z": 17,
            "elements": [
                "gregtech:metal_casing@7"
            ]
        },
        {
            "x": -2,
            "y": 23,
            "z": 17,
            "elements": [
                "gregtech:boiler_casing@3"
            ]
        },
        {
            "x": 2,
            "y": 0,
            "z": 22,
            "elements": [
                "gregtech:metal_casing@7"
            ]
        },
        {
            "x": -9,
            "y": 7,
            "z": 9,
            "elements": [
                "gregtech:metal_casing@7"
            ]
        },
        {
            "x": -1,
            "y": 23,
            "z": 17,
            "elements": [
                "gregtech:boiler_casing@3"
            ]
        },
        {
            "x": 3,
            "y": 0,
            "z": 22,
            "elements": [
                "gregtech:metal_casing@7"
            ]
        },
        {
            "x": 0,
            "y": 23,
            "z": 17,
            "elements": [
                "gregtech:boiler_casing@3"
            ]
        },
        {
            "x": 0,
            "y": 54,
            "z": 16,
            "elements": [
                "gregtech:metal_casing@7"
            ]
        },
        {
            "x": -8,
            "y": 7,
            "z": 9,
            "elements": [
                "gregtech:boiler_casing@3"
            ]
        },
        {
            "x": 8,
            "y": 8,
            "z": 26,
            "elements": [
                "gregtech:metal_casing@7"
            ]
        },
        {
            "x": 4,
            "y": 0,
            "z": 22,
            "elements": [
                "gregtech:metal_casing@7"
            ]
        },
        {
            "x": 5,
            "y": 0,
            "z": 22,
            "elements": [
                "gregtech:metal_casing@7"
            ]
        },
        {
            "x": 1,
            "y": 23,
            "z": 17,
            "elements": [
                "gregtech:boiler_casing@3"
            ]
        },
        {
            "x": -7,
            "y": 7,
            "z": 9,
            "elements": [
                "gregtech:metal_casing@7"
            ]
        },
        {
            "x": 6,
            "y": 0,
            "z": 22,
            "elements": [
                "gregtech:metal_casing@7"
            ]
        },
        {
            "x": 2,
            "y": 23,
            "z": 17,
            "elements": [
                "gregtech:boiler_casing@3"
            ]
        },
        {
            "x": 7,
            "y": 0,
            "z": 22,
            "elements": [
                "gregtech:metal_casing@7"
            ]
        },
        {
            "x": 3,
            "y": 23,
            "z": 17,
            "elements": [
                "gregtech:metal_casing@7"
            ]
        },
        {
            "x": 8,
            "y": 0,
            "z": 22,
            "elements": [
                "gregtech:metal_casing@7"
            ]
        },
        {
            "x": 9,
            "y": 0,
            "z": 22,
            "elements": [
                "gregtech:metal_casing@7"
            ]
        },
        {
            "x": 10,
            "y": 0,
            "z": 22,
            "elements": [
                "gregtech:metal_casing@7"
            ]
        },
        {
            "x": 11,
            "y": 0,
            "z": 22,
            "elements": [
                "gregtech:metal_casing@7"
            ]
        },
        {
            "x": 0,
            "y": 38,
            "z": 8,
            "elements": [
                "gregtech:meta_block_frame_187@12"
            ]
        },
        {
            "x": 12,
            "y": 0,
            "z": 22,
            "elements": [
                "gregtech:metal_casing@7"
            ]
        },
        {
            "x": 13,
            "y": 0,
            "z": 22,
            "elements": [
                "gregtech:metal_casing@7"
            ]
        },
        {
            "x": 14,
            "y": 0,
            "z": 22,
            "elements": [
                "gregtech:metal_casing@7"
            ]
        },
        {
            "x": 15,
            "y": 0,
            "z": 22,
            "elements": [
                "gregtech:metal_casing@7"
            ]
        },
        {
            "x": 16,
            "y": 0,
            "z": 22,
            "elements": [
                "gregtech:metal_casing@7"
            ]
        },
        {
            "x": 12,
            "y": 23,
            "z": 17,
            "elements": [
                "gregtech:meta_block_frame_187@12"
            ]
        },
        {
            "x": 7,
            "y": 7,
            "z": 9,
            "elements": [
                "gregtech:metal_casing@7"
            ]
        },
        {
            "x": -8,
            "y": 9,
            "z": 26,
            "elements": [
                "gregtech:metal_casing@7"
            ]
        },
        {
            "x": 8,
            "y": 7,
            "z": 9,
            "elements": [
                "gregtech:boiler_casing@3"
            ]
        },
        {
            "x": 9,
            "y": 7,
            "z": 9,
            "elements": [
                "gregtech:metal_casing@7"
            ]
        },
        {
            "x": -12,
            "y": 24,
            "z": 17,
            "elements": [
                "gregtech:meta_block_frame_187@12"
            ]
        },
        {
            "x": 0,
            "y": 40,
            "z": 25,
            "elements": [
                "gregtech:meta_block_frame_187@12"
            ]
        },
        {
            "x": -1,
            "y": 1,
            "z": 22,
            "elements": [
                "gregtech:metal_casing@7"
            ]
        },
        {
            "x": 0,
            "y": 1,
            "z": 22,
            "elements": [
                "gregtech:metal_casing@7"
            ]
        },
        {
            "x": 1,
            "y": 1,
            "z": 22,
            "elements": [
                "gregtech:metal_casing@7"
            ]
        },
        {
            "x": -3,
            "y": 24,
            "z": 17,
            "elements": [
                "gregtech:metal_casing@7"
            ]
        },
        {
            "x": -2,
            "y": 24,
            "z": 17,
            "elements": [
                "gregtech:boiler_casing@3"
            ]
        },
        {
            "x": -9,
            "y": 8,
            "z": 9,
            "elements": [
                "gregtech:metal_casing@7"
            ]
        },
        {
            "x": -1,
            "y": 24,
            "z": 17,
            "elements": [
                "gregtech:boiler_casing@3"
            ]
        },
        {
            "x": 0,
            "y": 24,
            "z": 17,
            "elements": [
                "gregtech:boiler_casing@3"
            ]
        },
        {
            "x": 0,
            "y": 55,
            "z": 16,
            "elements": [
                "gregtech:metal_casing@7"
            ]
        },
        {
            "x": -12,
            "y": 0,
            "z": 5,
            "elements": [
                "gregtech:metal_casing@7"
            ]
        },
        {
            "x": -8,
            "y": 8,
            "z": 9,
            "elements": [
                "gregtech:boiler_casing@3"
            ]
        },
        {
            "x": 8,
            "y": 9,
            "z": 26,
            "elements": [
                "gregtech:metal_casing@7"
            ]
        },
        {
            "x": 1,
            "y": 24,
            "z": 17,
            "elements": [
                "gregtech:boiler_casing@3"
            ]
        },
        {
            "x": -11,
            "y": 0,
            "z": 5,
            "elements": [
                "gregtech:metal_casing@7"
            ]
        },
        {
            "x": -7,
            "y": 8,
            "z": 9,
            "elements": [
                "gregtech:metal_casing@7"
            ]
        },
        {
            "x": -10,
            "y": 0,
            "z": 5,
            "elements": [
                "gregtech:metal_casing@7"
            ]
        },
        {
            "x": 2,
            "y": 24,
            "z": 17,
            "elements": [
                "gregtech:boiler_casing@3"
            ]
        },
        {
            "x": -9,
            "y": 0,
            "z": 5,
            "elements": [
                "gregtech:metal_casing@7"
            ]
        },
        {
            "x": 3,
            "y": 24,
            "z": 17,
            "elements": [
                "gregtech:metal_casing@7"
            ]
        },
        {
            "x": -8,
            "y": 0,
            "z": 5,
            "elements": [
                "gregtech:metal_casing@7"
            ]
        },
        {
            "x": -7,
            "y": 0,
            "z": 5,
            "elements": [
                "gregtech:metal_casing@7"
            ]
        },
        {
            "x": -6,
            "y": 0,
            "z": 5,
            "elements": [
                "gregtech:metal_casing@7"
            ]
        },
        {
            "x": -5,
            "y": 0,
            "z": 5,
            "elements": [
                "gregtech:metal_casing@7"
            ]
        },
        {
            "x": 0,
            "y": 39,
            "z": 8,
            "elements": [
                "gregtech:meta_block_frame_187@12"
            ]
        },
        {
            "x": -4,
            "y": 0,
            "z": 5,
            "elements": [
                "gregtech:metal_casing@7"
            ]
        },
        {
            "x": -3,
            "y": 0,
            "z": 5,
            "elements": [
                "gregtech:metal_casing@7"
            ]
        },
        {
            "x": -2,
            "y": 0,
            "z": 5,
            "elements": [
                "gregtech:metal_casing@7"
            ]
        },
        {
            "x": -1,
            "y": 0,
            "z": 5,
            "elements": [
                "gregtech:metal_casing@7"
            ]
        },
        {
            "x": 0,
            "y": 0,
            "z": 5,
            "elements": [
                "gregtech:metal_casing@7"
            ]
        },
        {
            "x": 12,
            "y": 24,
            "z": 17,
            "elements": [
                "gregtech:meta_block_frame_187@12"
            ]
        },
        {
            "x": 1,
            "y": 0,
            "z": 5,
            "elements": [
                "gregtech:metal_casing@7"
            ]
        },
        {
            "x": 2,
            "y": 0,
            "z": 5,
            "elements": [
                "gregtech:metal_casing@7"
            ]
        },
        {
            "x": 7,
            "y": 8,
            "z": 9,
            "elements": [
                "gregtech:metal_casing@7"
            ]
        },
        {
            "x": 3,
            "y": 0,
            "z": 5,
            "elements": [
                "gregtech:metal_casing@7"
            ]
        },
        {
            "x": -8,
            "y": 10,
            "z": 26,
            "elements": [
                "gregtech:metal_casing@7"
            ]
        },
        {
            "x": 8,
            "y": 8,
            "z": 9,
            "elements": [
                "gregtech:boiler_casing@3"
            ]
        },
        {
            "x": 4,
            "y": 0,
            "z": 5,
            "elements": [
                "gregtech:metal_casing@7"
            ]
        },
        {
            "x": 9,
            "y": 8,
            "z": 9,
            "elements": [
                "gregtech:metal_casing@7"
            ]
        },
        {
            "x": 5,
            "y": 0,
            "z": 5,
            "elements": [
                "gregtech:metal_casing@7"
            ]
        },
        {
            "x": 6,
            "y": 0,
            "z": 5,
            "elements": [
                "gregtech:metal_casing@7"
            ]
        },
        {
            "x": 0,
            "y": 18,
            "z": 30,
            "elements": [
                "gregtech:meta_block_frame_187@12"
            ]
        },
        {
            "x": -12,
            "y": 25,
            "z": 17,
            "elements": [
                "gregtech:meta_block_frame_187@12"
            ]
        },
        {
            "x": 7,
            "y": 0,
            "z": 5,
            "elements": [
                "gregtech:metal_casing@7"
            ]
        },
        {
            "x": 8,
            "y": 0,
            "z": 5,
            "elements": [
                "gregtech:metal_casing@7"
            ]
        },
        {
            "x": 9,
            "y": 0,
            "z": 5,
            "elements": [
                "gregtech:metal_casing@7"
